Workbook

Sheet Person_0
J3: k=0.25
Q4: 1 | V4: 2 | AA4: 3 | AF4: 4 | AK4: 5 | AP4: 6
A5: k | B5: Task 1 | C5: Task 2 | D5: Task 3 | E5: Task 4 | F5: Task 5 | G5: Task 6 | I5: ID | J5: Task 1 | K5: Task 2 | L5: Task 3 | M5: Task 4 | N5: Task 5 | O5: Task 6 | Q5: Task 2 | R5: Task 3 | S5: Task 4 | T5: Task 5 | U5: Task 6 | V5: Task 2 | W5: Task 3 | X5: Task 4 | Y5: Task 5 | Z5: Task 6 | AA5: Task 2 | AB5: Task 3 | AC5: Task 4 | AD5: Task 5 | AE5: Task 6 | AF5: Task 2 | AG5: Task 3 | AH5: Task 4 | AI5: Task 5 | AJ5: Task 6 | AK5: Task 2 | AL5: Task 3 | AM5: Task 4 | AN5: Task 5 | AO5: Task 6 | AP5: Task 2 | AQ5: Task 3 | AR5: Task 4 | AS5: Task 5 | AT5: Task 6 | AV5: =A6 -> 0.25 | AW5: Task 2 | AX5: Task 3 | AY5: Task 4 | AZ5: Task 5 | BA5: Task 6
A6: 0.25 | B6: =AVERAGE(J6:J35) -> 0.96560007 | C6: =AVERAGE(K6:K35) -> 0.78004217 | D6: =AVERAGE(L6:L35) -> #DIV/0! | E6: =AVERAGE(M6:M35) -> #DIV/0! | F6: =AVERAGE(N6:N35) -> #DIV/0! | G6: =AVERAGE(O6:O35) -> #DIV/0! | J6: 0.95633333 | K6: =AVERAGE(Q6,V6,AA6,AF6,AK6,AP6) -> 0.79633333 | L6: =AVERAGE(R6,W6,AB6,AG6,AL6,AQ6) -> #DIV/0! | M6: =AVERAGE(S6,X6,AC6,AH6,AM6,AR6) -> #DIV/0! | N6: =AVERAGE(T6,Y6,AD6,AI6,AN6,AS6) -> #DIV/0! | O6: =AVERAGE(U6,Z6,AE6,AJ6,AO6,AT6) -> #DIV/0! | Q6: 0.792 | V6: 0.782 | AA6: 0.758 | AF6: 0.848 | AK6: 0.768 | AP6: 0.83 | AV6: 1 | AW6: =$Q$37 -> 0.79880544 | AX6: =$R$37 -> #DIV/0! | AY6: =$S$37 -> #DIV/0! | AZ6: =$T$37 -> #DIV/0! | BA6: =$U$37 -> #DIV/0!
A7: 0.5 | B7: =AVERAGE(J43:J72) -> 0.96591873 | C7: =AVERAGE(K43:K72) -> 0.80606715 | D7: =AVERAGE(L43:L72) -> #DIV/0! | E7: =AVERAGE(M43:M72) -> #DIV/0! | F7: =AVERAGE(N43:N72) -> #DIV/0! | G7: =AVERAGE(O43:O72) -> #DIV/0! | J7: 0.95275591 | K7: =AVERAGE(Q7,V7,AA7,AF7,AK7,AP7) -> 0.69389764 | L7: =AVERAGE(R7,W7,AB7,AG7,AL7,AQ7) -> #DIV/0! | M7: =AVERAGE(S7,X7,AC7,AH7,AM7,AR7) -> #DIV/0! | N7: =AVERAGE(T7,Y7,AD7,AI7,AN7,AS7) -> #DIV/0! | O7: =AVERAGE(U7,Z7,AE7,AJ7,AO7,AT7) -> #DIV/0! | Q7: 0.70866142 | V7: 0.57086614 | AA7: 0.60629921 | AF7: 0.71456693 | AK7: 0.77559055 | AP7: 0.78740157 | AV7: 2 | AW7: =$V$37 -> 0.77671387 | AX7: =$W$37 -> #DIV/0! | AY7: =$X$37 -> #DIV/0! | AZ7: =$Y$37 -> #DIV/0! | BA7: =$Z$37 -> #DIV/0!
A8: 1 | B8: =AVERAGE(J80:J109) -> 0.96612148 | C8: =AVERAGE(K80:K109) -> 0.78344584 | D8: =AVERAGE(L80:L109) -> #DIV/0! | E8: =AVERAGE(M80:M109) -> #DIV/0! | F8: =AVERAGE(N80:N109) -> #DIV/0! | G8: =AVERAGE(O80:O109) -> #DIV/0! | J8: 0.95926563 | K8: =AVERAGE(Q8,V8,AA8,AF8,AK8,AP8) -> 0.79718876 | L8: =AVERAGE(R8,W8,AB8,AG8,AL8,AQ8) -> #DIV/0! | M8: =AVERAGE(S8,X8,AC8,AH8,AM8,AR8) -> #DIV/0! | N8: =AVERAGE(T8,Y8,AD8,AI8,AN8,AS8) -> #DIV/0! | O8: =AVERAGE(U8,Z8,AE8,AJ8,AO8,AT8) -> #DIV/0! | Q8: 0.79518072 | V8: 0.75387263 | AA8: 0.87263339 | AF8: 0.75731497 | AK8: 0.82271945 | AP8: 0.78141136 | AV8: 3 | AW8: =$AA$37 -> 0.77709159 | AX8: =$AB$37 -> #DIV/0! | AY8: =$AC$37 -> #DIV/0! | AZ8: =$AD$37 -> #DIV/0! | BA8: =$AE$37 -> #DIV/0!
A9: 2 | B9: =AVERAGE(J117:J146) -> 0.96527543 | C9: =AVERAGE(K117:K146) -> 0.83077919 | D9: =AVERAGE(L117:L146) -> #DIV/0! | E9: =AVERAGE(M117:M146) -> #DIV/0! | F9: =AVERAGE(N117:N146) -> #DIV/0! | G9: =AVERAGE(O117:O146) -> #DIV/0! | J9: 0.97875817 | K9: =AVERAGE(Q9,V9,AA9,AF9,AK9,AP9) -> 0.88235294 | L9: =AVERAGE(R9,W9,AB9,AG9,AL9,AQ9) -> #DIV/0! | M9: =AVERAGE(S9,X9,AC9,AH9,AM9,AR9) -> #DIV/0! | N9: =AVERAGE(T9,Y9,AD9,AI9,AN9,AS9) -> #DIV/0! | O9: =AVERAGE(U9,Z9,AE9,AJ9,AO9,AT9) -> #DIV/0! | Q9: 0.89215686 | V9: 0.91421569 | AA9: 0.87254902 | AF9: 0.90196078 | AK9: 0.81372549 | AP9: 0.8995098 | AV9: 4 | AW9: =$AF$37 -> 0.77763075 | AX9: =$AG$37 -> #DIV/0! | AY9: =$AH$37 -> #DIV/0! | AZ9: =$AI$37 -> #DIV/0! | BA9: =$AJ$37 -> #DIV/0!
A10: 3 | B10: =AVERAGE(J154:J183) -> 0.96510655 | C10: =AVERAGE(K154:K183) -> 0.83320577 | D10: =AVERAGE(L154:L183) -> #DIV/0! | E10: =AVERAGE(M154:M183) -> #DIV/0! | F10: =AVERAGE(N154:N183) -> #DIV/0! | G10: =AVERAGE(O154:O183) -> #DIV/0! | J10: 0.97427035 | K10: =AVERAGE(Q10,V10,AA10,AF10,AK10,AP10) -> 0.81989247 | L10: =AVERAGE(R10,W10,AB10,AG10,AL10,AQ10) -> #DIV/0! | M10: =AVERAGE(S10,X10,AC10,AH10,AM10,AR10) -> #DIV/0! | N10: =AVERAGE(T10,Y10,AD10,AI10,AN10,AS10) -> #DIV/0! | O10: =AVERAGE(U10,Z10,AE10,AJ10,AO10,AT10) -> #DIV/0! | Q10: 0.75345622 | V10: 0.85483871 | AA10: 0.83870968 | AF10: 0.88248848 | AK10: 0.8156682 | AP10: 0.77419355 | AV10: 5 | AW10: =$AK$37 -> 0.77143725 | AX10: =$AL$37 -> #DIV/0! | AY10: =$AM$37 -> #DIV/0! | AZ10: =$AN$37 -> #DIV/0! | BA10: =$AO$37 -> #DIV/0!
J11: 0.97015426 | K11: =AVERAGE(Q11,V11,AA11,AF11,AK11,AP11) -> 0.65560027 | L11: =AVERAGE(R11,W11,AB11,AG11,AL11,AQ11) -> #DIV/0! | M11: =AVERAGE(S11,X11,AC11,AH11,AM11,AR11) -> #DIV/0! | N11: =AVERAGE(T11,Y11,AD11,AI11,AN11,AS11) -> #DIV/0! | O11: =AVERAGE(U11,Z11,AE11,AJ11,AO11,AT11) -> #DIV/0! | Q11: 0.78269618 | V11: 0.69014085 | AA11: 0.51710262 | AF11: 0.60160966 | AK11: 0.64788732 | AP11: 0.69416499 | AV11: 6 | AW11: =$AP$37 -> 0.7785741 | AX11: =$AQ$37 -> #DIV/0! | AY11: =$AR$37 -> #DIV/0! | AZ11: =$AS$37 -> #DIV/0! | BA11: =$AT$37 -> #DIV/0!
J12: 0.98477564 | K12: =AVERAGE(Q12,V12,AA12,AF12,AK12,AP12) -> 0.82011218 | L12: =AVERAGE(R12,W12,AB12,AG12,AL12,AQ12) -> #DIV/0! | M12: =AVERAGE(S12,X12,AC12,AH12,AM12,AR12) -> #DIV/0! | N12: =AVERAGE(T12,Y12,AD12,AI12,AN12,AS12) -> #DIV/0! | O12: =AVERAGE(U12,Z12,AE12,AJ12,AO12,AT12) -> #DIV/0! | Q12: 0.82932692 | V12: 0.76923077 | AA12: 0.85817308 | AF12: 0.77884615 | AK12: 0.85817308 | AP12: 0.82692308
J13: 0.95263158 | K13: =AVERAGE(Q13,V13,AA13,AF13,AK13,AP13) -> 0.73304094 | L13: =AVERAGE(R13,W13,AB13,AG13,AL13,AQ13) -> #DIV/0! | M13: =AVERAGE(S13,X13,AC13,AH13,AM13,AR13) -> #DIV/0! | N13: =AVERAGE(T13,Y13,AD13,AI13,AN13,AS13) -> #DIV/0! | O13: =AVERAGE(U13,Z13,AE13,AJ13,AO13,AT13) -> #DIV/0! | Q13: 0.76666667 | V13: 0.71403509 | AA13: 0.82982456 | AF13: 0.78596491 | AK13: 0.57894737 | AP13: 0.72280702
J14: 0.95764463 | K14: =AVERAGE(Q14,V14,AA14,AF14,AK14,AP14) -> 0.74517906 | L14: =AVERAGE(R14,W14,AB14,AG14,AL14,AQ14) -> #DIV/0! | M14: =AVERAGE(S14,X14,AC14,AH14,AM14,AR14) -> #DIV/0! | N14: =AVERAGE(T14,Y14,AD14,AI14,AN14,AS14) -> #DIV/0! | O14: =AVERAGE(U14,Z14,AE14,AJ14,AO14,AT14) -> #DIV/0! | Q14: 0.82644628 | V14: 0.74793388 | AA14: 0.64049587 | AF14: 0.71900826 | AK14: 0.77892562 | AP14: 0.75826446
J15: 0.95683931 | K15: =AVERAGE(Q15,V15,AA15,AF15,AK15,AP15) -> 0.71580345 | L15: =AVERAGE(R15,W15,AB15,AG15,AL15,AQ15) -> #DIV/0! | M15: =AVERAGE(S15,X15,AC15,AH15,AM15,AR15) -> #DIV/0! | N15: =AVERAGE(T15,Y15,AD15,AI15,AN15,AS15) -> #DIV/0! | O15: =AVERAGE(U15,Z15,AE15,AJ15,AO15,AT15) -> #DIV/0! | Q15: 0.59561753 | V15: 0.70318725 | AA15: 0.77689243 | AF15: 0.7310757 | AK15: 0.74302789 | AP15: 0.74501992 | AV15: =A7 -> 0.5 | AW15: Task 2 | AX15: Task 3 | AY15: Task 4 | AZ15: Task 5 | BA15: Task 6
J16: 0.95096022 | K16: =AVERAGE(Q16,V16,AA16,AF16,AK16,AP16) -> 0.70438957 | L16: =AVERAGE(R16,W16,AB16,AG16,AL16,AQ16) -> #DIV/0! | M16: =AVERAGE(S16,X16,AC16,AH16,AM16,AR16) -> #DIV/0! | N16: =AVERAGE(T16,Y16,AD16,AI16,AN16,AS16) -> #DIV/0! | O16: =AVERAGE(U16,Z16,AE16,AJ16,AO16,AT16) -> #DIV/0! | Q16: 0.79012346 | V16: 0.74897119 | AA16: 0.71399177 | AF16: 0.7654321 | AK16: 0.63580247 | AP16: 0.57201646 | AV16: 1 | AW16: =$Q$74 -> 0.81324377 | AX16: =$R$74 -> #DIV/0! | AY16: =$S$74 -> #DIV/0! | AZ16: =$T$74 -> #DIV/0! | BA16: =$U$74 -> #DIV/0!
J17: 0.9670913 | K17: =AVERAGE(Q17,V17,AA17,AF17,AK17,AP17) -> 0.81245577 | L17: =AVERAGE(R17,W17,AB17,AG17,AL17,AQ17) -> #DIV/0! | M17: =AVERAGE(S17,X17,AC17,AH17,AM17,AR17) -> #DIV/0! | N17: =AVERAGE(T17,Y17,AD17,AI17,AN17,AS17) -> #DIV/0! | O17: =AVERAGE(U17,Z17,AE17,AJ17,AO17,AT17) -> #DIV/0! | Q17: 0.80042463 | V17: 0.83864119 | AA17: 0.84713376 | AF17: 0.85138004 | AK17: 0.75796178 | AP17: 0.77919321 | AV17: 2 | AW17: =$V$74 -> 0.79695373 | AX17: =$W$74 -> #DIV/0! | AY17: =$X$74 -> #DIV/0! | AZ17: =$Y$74 -> #DIV/0! | BA17: =$Z$74 -> #DIV/0!
J18: 0.95840407 | K18: =AVERAGE(Q18,V18,AA18,AF18,AK18,AP18) -> 0.75947934 | L18: =AVERAGE(R18,W18,AB18,AG18,AL18,AQ18) -> #DIV/0! | M18: =AVERAGE(S18,X18,AC18,AH18,AM18,AR18) -> #DIV/0! | N18: =AVERAGE(T18,Y18,AD18,AI18,AN18,AS18) -> #DIV/0! | O18: =AVERAGE(U18,Z18,AE18,AJ18,AO18,AT18) -> #DIV/0! | Q18: 0.78438031 | V18: 0.78777589 | AA18: 0.66044143 | AF18: 0.75212224 | AK18: 0.81324278 | AP18: 0.75891341 | AV18: 3 | AW18: =$AA$74 -> 0.80663223 | AX18: =$AB$74 -> #DIV/0! | AY18: =$AC$74 -> #DIV/0! | AZ18: =$AD$74 -> #DIV/0! | BA18: =$AE$74 -> #DIV/0!
J19: 0.98191214 | K19: =AVERAGE(Q19,V19,AA19,AF19,AK19,AP19) -> 0.90600775 | L19: =AVERAGE(R19,W19,AB19,AG19,AL19,AQ19) -> #DIV/0! | M19: =AVERAGE(S19,X19,AC19,AH19,AM19,AR19) -> #DIV/0! | N19: =AVERAGE(T19,Y19,AD19,AI19,AN19,AS19) -> #DIV/0! | O19: =AVERAGE(U19,Z19,AE19,AJ19,AO19,AT19) -> #DIV/0! | Q19: 0.93217054 | V19: 0.89728682 | AA19: 0.89534884 | AF19: 0.87596899 | AK19: 0.89922481 | AP19: 0.93604651 | AV19: 4 | AW19: =$AF$74 -> 0.80359497 | AX19: =$AG$74 -> #DIV/0! | AY19: =$AH$74 -> #DIV/0! | AZ19: =$AI$74 -> #DIV/0! | BA19: =$AJ$74 -> #DIV/0!
J20: 0.9665328 | K20: =AVERAGE(Q20,V20,AA20,AF20,AK20,AP20) -> 0.79518072 | L20: =AVERAGE(R20,W20,AB20,AG20,AL20,AQ20) -> #DIV/0! | M20: =AVERAGE(S20,X20,AC20,AH20,AM20,AR20) -> #DIV/0! | N20: =AVERAGE(T20,Y20,AD20,AI20,AN20,AS20) -> #DIV/0! | O20: =AVERAGE(U20,Z20,AE20,AJ20,AO20,AT20) -> #DIV/0! | Q20: 0.86546185 | V20: 0.78915663 | AA20: 0.8253012 | AF20: 0.77911647 | AK20: 0.72690763 | AP20: 0.78514056 | AV20: 5 | AW20: =$AK$74 -> 0.80926225 | AX20: =$AL$74 -> #DIV/0! | AY20: =$AM$74 -> #DIV/0! | AZ20: =$AN$74 -> #DIV/0! | BA20: =$AO$74 -> #DIV/0!
J21: 0.95366667 | K21: =AVERAGE(Q21,V21,AA21,AF21,AK21,AP21) -> 0.79033333 | L21: =AVERAGE(R21,W21,AB21,AG21,AL21,AQ21) -> #DIV/0! | M21: =AVERAGE(S21,X21,AC21,AH21,AM21,AR21) -> #DIV/0! | N21: =AVERAGE(T21,Y21,AD21,AI21,AN21,AS21) -> #DIV/0! | O21: =AVERAGE(U21,Z21,AE21,AJ21,AO21,AT21) -> #DIV/0! | Q21: 0.862 | V21: 0.748 | AA21: 0.718 | AF21: 0.794 | AK21: 0.828 | AP21: 0.792 | AV21: 6 | AW21: =$AP$74 -> 0.80671595 | AX21: =$AQ$74 -> #DIV/0! | AY21: =$AR$74 -> #DIV/0! | AZ21: =$AS$74 -> #DIV/0! | BA21: =$AT$74 -> #DIV/0!
J22: 0.96720334 | K22: =AVERAGE(Q22,V22,AA22,AF22,AK22,AP22) -> 0.71049493 | L22: =AVERAGE(R22,W22,AB22,AG22,AL22,AQ22) -> #DIV/0! | M22: =AVERAGE(S22,X22,AC22,AH22,AM22,AR22) -> #DIV/0! | N22: =AVERAGE(T22,Y22,AD22,AI22,AN22,AS22) -> #DIV/0! | O22: =AVERAGE(U22,Z22,AE22,AJ22,AO22,AT22) -> #DIV/0! | Q22: 0.6332737 | V22: 0.74955277 | AA22: 0.73166369 | AF22: 0.74418605 | AK22: 0.62432916 | AP22: 0.77996422
J23: 0.96541443 | K23: =AVERAGE(Q23,V23,AA23,AF23,AK23,AP23) -> 0.70244484 | L23: =AVERAGE(R23,W23,AB23,AG23,AL23,AQ23) -> #DIV/0! | M23: =AVERAGE(S23,X23,AC23,AH23,AM23,AR23) -> #DIV/0! | N23: =AVERAGE(T23,Y23,AD23,AI23,AN23,AS23) -> #DIV/0! | O23: =AVERAGE(U23,Z23,AE23,AJ23,AO23,AT23) -> #DIV/0! | Q23: 0.70483005 | V23: 0.72987478 | AA23: 0.68157424 | AF23: 0.75849732 | AK23: 0.67799642 | AP23: 0.66189624
J24: 0.98527132 | K24: =AVERAGE(Q24,V24,AA24,AF24,AK24,AP24) -> 0.92403101 | L24: =AVERAGE(R24,W24,AB24,AG24,AL24,AQ24) -> #DIV/0! | M24: =AVERAGE(S24,X24,AC24,AH24,AM24,AR24) -> #DIV/0! | N24: =AVERAGE(T24,Y24,AD24,AI24,AN24,AS24) -> #DIV/0! | O24: =AVERAGE(U24,Z24,AE24,AJ24,AO24,AT24) -> #DIV/0! | Q24: 0.87209302 | V24: 0.96976744 | AA24: 0.94186047 | AF24: 0.93023256 | AK24: 0.93255814 | AP24: 0.89767442
J25: 0.96426529 | K25: =AVERAGE(Q25,V25,AA25,AF25,AK25,AP25) -> 0.73899371 | L25: =AVERAGE(R25,W25,AB25,AG25,AL25,AQ25) -> #DIV/0! | M25: =AVERAGE(S25,X25,AC25,AH25,AM25,AR25) -> #DIV/0! | N25: =AVERAGE(T25,Y25,AD25,AI25,AN25,AS25) -> #DIV/0! | O25: =AVERAGE(U25,Z25,AE25,AJ25,AO25,AT25) -> #DIV/0! | Q25: 0.78559177 | V25: 0.74785592 | AA25: 0.67409949 | AF25: 0.82675815 | AK25: 0.69296741 | AP25: 0.70668954 | AV25: =A8 -> 1 | AW25: Task 2 | AX25: Task 3 | AY25: Task 4 | AZ25: Task 5 | BA25: Task 6
J26: 0.98532731 | K26: =AVERAGE(Q26,V26,AA26,AF26,AK26,AP26) -> 0.90970655 | L26: =AVERAGE(R26,W26,AB26,AG26,AL26,AQ26) -> #DIV/0! | M26: =AVERAGE(S26,X26,AC26,AH26,AM26,AR26) -> #DIV/0! | N26: =AVERAGE(T26,Y26,AD26,AI26,AN26,AS26) -> #DIV/0! | O26: =AVERAGE(U26,Z26,AE26,AJ26,AO26,AT26) -> #DIV/0! | Q26: 0.91873589 | V26: 0.89841986 | AA26: 0.92776524 | AF26: 0.89164786 | AK26: 0.90744921 | AP26: 0.91422122 | AV26: 1 | AW26: =$Q$111 -> 0.78120722 | AX26: =$R$111 -> #DIV/0! | AY26: =$S$111 -> #DIV/0! | AZ26: =$T$111 -> #DIV/0! | BA26: =$U$111 -> #DIV/0!
J27: 0.95238095 | K27: =AVERAGE(Q27,V27,AA27,AF27,AK27,AP27) -> 0.78956583 | L27: =AVERAGE(R27,W27,AB27,AG27,AL27,AQ27) -> #DIV/0! | M27: =AVERAGE(S27,X27,AC27,AH27,AM27,AR27) -> #DIV/0! | N27: =AVERAGE(T27,Y27,AD27,AI27,AN27,AS27) -> #DIV/0! | O27: =AVERAGE(U27,Z27,AE27,AJ27,AO27,AT27) -> #DIV/0! | Q27: 0.82563025 | V27: 0.75210084 | AA27: 0.86344538 | AF27: 0.65336134 | AK27: 0.82563025 | AP27: 0.81722689 | AV27: 2 | AW27: =$V$111 -> 0.80334883 | AX27: =$W$111 -> #DIV/0! | AY27: =$X$111 -> #DIV/0! | AZ27: =$Y$111 -> #DIV/0! | BA27: =$Z$111 -> #DIV/0!
J28: 0.95451527 | K28: =AVERAGE(Q28,V28,AA28,AF28,AK28,AP28) -> 0.69289509 | L28: =AVERAGE(R28,W28,AB28,AG28,AL28,AQ28) -> #DIV/0! | M28: =AVERAGE(S28,X28,AC28,AH28,AM28,AR28) -> #DIV/0! | N28: =AVERAGE(T28,Y28,AD28,AI28,AN28,AS28) -> #DIV/0! | O28: =AVERAGE(U28,Z28,AE28,AJ28,AO28,AT28) -> #DIV/0! | Q28: 0.73505976 | V28: 0.65537849 | AA28: 0.72111554 | AF28: 0.69920319 | AK28: 0.76294821 | AP28: 0.58366534 | AV28: 3 | AW28: =$AA$111 -> 0.8118928 | AX28: =$AB$111 -> #DIV/0! | AY28: =$AC$111 -> #DIV/0! | AZ28: =$AD$111 -> #DIV/0! | BA28: =$AE$111 -> #DIV/0!
J29: 0.97364819 | K29: =AVERAGE(Q29,V29,AA29,AF29,AK29,AP29) -> 0.74058864 | L29: =AVERAGE(R29,W29,AB29,AG29,AL29,AQ29) -> #DIV/0! | M29: =AVERAGE(S29,X29,AC29,AH29,AM29,AR29) -> #DIV/0! | N29: =AVERAGE(T29,Y29,AD29,AI29,AN29,AS29) -> #DIV/0! | O29: =AVERAGE(U29,Z29,AE29,AJ29,AO29,AT29) -> #DIV/0! | Q29: 0.78028747 | V29: 0.81519507 | AA29: 0.73305955 | AF29: 0.72895277 | AK29: 0.67967146 | AP29: 0.7063655 | AV29: 4 | AW29: =$AF$111 -> 0.74578992 | AX29: =$AG$111 -> #DIV/0! | AY29: =$AH$111 -> #DIV/0! | AZ29: =$AI$111 -> #DIV/0! | BA29: =$AJ$111 -> #DIV/0!
J30: 0.98372093 | K30: =AVERAGE(Q30,V30,AA30,AF30,AK30,AP30) -> 0.9375969 | L30: =AVERAGE(R30,W30,AB30,AG30,AL30,AQ30) -> #DIV/0! | M30: =AVERAGE(S30,X30,AC30,AH30,AM30,AR30) -> #DIV/0! | N30: =AVERAGE(T30,Y30,AD30,AI30,AN30,AS30) -> #DIV/0! | O30: =AVERAGE(U30,Z30,AE30,AJ30,AO30,AT30) -> #DIV/0! | Q30: 0.95813953 | V30: 0.93023256 | AA30: 0.93255814 | AF30: 0.96046512 | AK30: 0.92093023 | AP30: 0.92325581 | AV30: 5 | AW30: =$AK$111 -> 0.82089814 | AX30: =$AL$111 -> #DIV/0! | AY30: =$AM$111 -> #DIV/0! | AZ30: =$AN$111 -> #DIV/0! | BA30: =$AO$111 -> #DIV/0!
J31: 0.97482838 | K31: =AVERAGE(Q31,V31,AA31,AF31,AK31,AP31) -> 0.84553776 | L31: =AVERAGE(R31,W31,AB31,AG31,AL31,AQ31) -> #DIV/0! | M31: =AVERAGE(S31,X31,AC31,AH31,AM31,AR31) -> #DIV/0! | N31: =AVERAGE(T31,Y31,AD31,AI31,AN31,AS31) -> #DIV/0! | O31: =AVERAGE(U31,Z31,AE31,AJ31,AO31,AT31) -> #DIV/0! | Q31: 0.94508009 | V31: 0.80778032 | AA31: 0.88558352 | AF31: 0.80549199 | AK31: 0.89244851 | AP31: 0.73684211 | AV31: 6 | AW31: =$AP$111 -> 0.73753814 | AX31: =$AQ$111 -> #DIV/0! | AY31: =$AR$111 -> #DIV/0! | AZ31: =$AS$111 -> #DIV/0! | BA31: =$AT$111 -> #DIV/0!
J32: 0.96455351 | K32: =AVERAGE(Q32,V32,AA32,AF32,AK32,AP32) -> 0.79277437 | L32: =AVERAGE(R32,W32,AB32,AG32,AL32,AQ32) -> #DIV/0! | M32: =AVERAGE(S32,X32,AC32,AH32,AM32,AR32) -> #DIV/0! | N32: =AVERAGE(T32,Y32,AD32,AI32,AN32,AS32) -> #DIV/0! | O32: =AVERAGE(U32,Z32,AE32,AJ32,AO32,AT32) -> #DIV/0! | Q32: 0.75869121 | V32: 0.86298569 | AA32: 0.78527607 | AF32: 0.799591 | AK32: 0.76278119 | AP32: 0.78732106
J33: 0.97022587 | K33: =AVERAGE(Q33,V33,AA33,AF33,AK33,AP33) -> 0.73682409 | L33: =AVERAGE(R33,W33,AB33,AG33,AL33,AQ33) -> #DIV/0! | M33: =AVERAGE(S33,X33,AC33,AH33,AM33,AR33) -> #DIV/0! | N33: =AVERAGE(T33,Y33,AD33,AI33,AN33,AS33) -> #DIV/0! | O33: =AVERAGE(U33,Z33,AE33,AJ33,AO33,AT33) -> #DIV/0! | Q33: 0.70431211 | V33: 0.75359343 | AA33: 0.75359343 | AF33: 0.61806982 | AK33: 0.76180698 | AP33: 0.82956879
J34: 0.95091123 | K34: =AVERAGE(Q34,V34,AA34,AF34,AK34,AP34) -> 0.71634333 | L34: =AVERAGE(R34,W34,AB34,AG34,AL34,AQ34) -> #DIV/0! | M34: =AVERAGE(S34,X34,AC34,AH34,AM34,AR34) -> #DIV/0! | N34: =AVERAGE(T34,Y34,AD34,AI34,AN34,AS34) -> #DIV/0! | O34: =AVERAGE(U34,Z34,AE34,AJ34,AO34,AT34) -> #DIV/0! | Q34: 0.75661376 | V34: 0.64726631 | AA34: 0.68253968 | AF34: 0.6984127 | AK34: 0.73897707 | AP34: 0.77425044
J35: 0.95374016 | K35: =AVERAGE(Q35,V35,AA35,AF35,AK35,AP35) -> 0.73622047 | L35: =AVERAGE(R35,W35,AB35,AG35,AL35,AQ35) -> #DIV/0! | M35: =AVERAGE(S35,X35,AC35,AH35,AM35,AR35) -> #DIV/0! | N35: =AVERAGE(T35,Y35,AD35,AI35,AN35,AS35) -> #DIV/0! | O35: =AVERAGE(U35,Z35,AE35,AJ35,AO35,AT35) -> #DIV/0! | Q35: 0.80905512 | V35: 0.67125984 | AA35: 0.76771654 | AF35: 0.67519685 | AK35: 0.6988189 | AP35: 0.79527559 | AV35: =A9 -> 2 | AW35: Task 2 | AX35: Task 3 | AY35: Task 4 | AZ35: Task 5 | BA35: Task 6
AV36: 1 | AW36: =$Q$148 -> 0.83213649 | AX36: =$R$148 -> #DIV/0! | AY36: =$S$148 -> #DIV/0! | AZ36: =$T$148 -> #DIV/0! | BA36: =$U$148 -> #DIV/0!
J37: 0.98844568 | K37: =AVERAGE(K6:K35) -> 0.78004217 | L37: =AVERAGE(L6:L35) -> #DIV/0! | M37: =AVERAGE(M6:M35) -> #DIV/0! | N37: =AVERAGE(N6:N35) -> #DIV/0! | O37: =AVERAGE(O6:O35) -> #DIV/0! | Q37: =AVERAGE(Q6:Q35) -> 0.79880544 | R37: =AVERAGE(R6:R35) -> #DIV/0! | S37: =AVERAGE(S6:S35) -> #DIV/0! | T37: =AVERAGE(T6:T35) -> #DIV/0! | U37: =AVERAGE(U6:U35) -> #DIV/0! | V37: =AVERAGE(V6:V35) -> 0.77671387 | W37: =AVERAGE(W6:W35) -> #DIV/0! | X37: =AVERAGE(X6:X35) -> #DIV/0! | ... AT37: =AVERAGE(AT6:AT35) -> #DIV/0! | AV37: 2 | AW37: =$V$148 -> 0.82400397 | AX37: =$W$148 -> #DIV/0! | AY37: =$X$148 -> #DIV/0! | AZ37: =$Y$148 -> #DIV/0! | BA37: =$Z$148 -> #DIV/0!
AV38: 3 | AW38: =$AA$148 -> 0.82979851 | AX38: =$AB$148 -> #DIV/0! | AY38: =$AC$148 -> #DIV/0! | AZ38: =$AD$148 -> #DIV/0! | BA38: =$AE$148 -> #DIV/0!
AV39: 4 | AW39: =$AF$148 -> 0.84592899 | AX39: =$AG$148 -> #DIV/0! | AY39: =$AH$148 -> #DIV/0! | AZ39: =$AI$148 -> #DIV/0! | BA39: =$AJ$148 -> #DIV/0!
J40: k=0.5 | AV40: 5 | AW40: =$AK$148 -> 0.83175941 | AX40: =$AL$148 -> #DIV/0! | AY40: =$AM$148 -> #DIV/0! | AZ40: =$AN$148 -> #DIV/0! | BA40: =$AO$148 -> #DIV/0!
Q41: 1 | V41: 2 | AA41: 3 | AF41: 4 | AK41: 5 | AP41: 6 | AV41: 6 | AW41: =$AP$148 -> 0.82104776 | AX41: =$AQ$148 -> #DIV/0! | AY41: =$AR$148 -> #DIV/0! | AZ41: =$AS$148 -> #DIV/0! | BA41: =$AT$148 -> #DIV/0!
I42: ID | J42: Task 1 | K42: Task 2 | L42: Task 3 | M42: Task 4 | N42: Task 5 | O42: Task 6 | Q42: Task 2 | R42: Task 3 | S42: Task 4 | T42: Task 5 | U42: Task 6 | V42: Task 2 | W42: Task 3 | X42: Task 4 | Y42: Task 5 | Z42: Task 6 | AA42: Task 2 | AB42: Task 3 | AC42: Task 4 | AD42: Task 5 | AE42: Task 6 | AF42: Task 2 | AG42: Task 3 | AH42: Task 4 | AI42: Task 5 | AJ42: Task 6 | AK42: Task 2 | AL42: Task 3 | AM42: Task 4 | AN42: Task 5 | AO42: Task 6 | AP42: Task 2 | AQ42: Task 3 | AR42: Task 4 | AS42: Task 5 | AT42: Task 6
...

Sheet Person_1
J3: k=0.25
Q4: 1 | V4: 2 | AA4: 3 | AF4: 4 | AK4: 5 | AP4: 6
A5: k | B5: Task 1 | C5: Task 2 | D5: Task 3 | E5: Task 4 | F5: Task 5 | G5: Task 6 | I5: ID | J5: Task 1 | K5: Task 2 | L5: Task 3 | M5: Task 4 | N5: Task 5 | O5: Task 6 | Q5: Task 2 | R5: Task 3 | S5: Task 4 | T5: Task 5 | U5: Task 6 | V5: Task 2 | W5: Task 3 | X5: Task 4 | Y5: Task 5 | Z5: Task 6 | AA5: Task 2 | AB5: Task 3 | AC5: Task 4 | AD5: Task 5 | AE5: Task 6 | AF5: Task 2 | AG5: Task 3 | AH5: Task 4 | AI5: Task 5 | AJ5: Task 6 | AK5: Task 2 | AL5: Task 3 | AM5: Task 4 | AN5: Task 5 | AO5: Task 6 | AP5: Task 2 | AQ5: Task 3 | AR5: Task 4 | AS5: Task 5 | AT5: Task 6 | AV5: =A6 -> 0.25 | AW5: Task 2 | AX5: Task 3 | AY5: Task 4 | AZ5: Task 5 | BA5: Task 6
A6: 0.25 | B6: =AVERAGE(J6:J35) -> 0.93614896 | C6: =AVERAGE(K6:K35) -> 0.6767195 | D6: =AVERAGE(L6:L35) -> #DIV/0! | E6: =AVERAGE(M6:M35) -> #DIV/0! | F6: =AVERAGE(N6:N35) -> #DIV/0! | G6: =AVERAGE(O6:O35) -> #DIV/0! | J6: 0.95773688 | K6: =AVERAGE(Q6,V6,AA6,AF6,AK6,AP6) -> 0.6605317 | L6: =AVERAGE(R6,W6,AB6,AG6,AL6,AQ6) -> #DIV/0! | M6: =AVERAGE(S6,X6,AC6,AH6,AM6,AR6) -> #DIV/0! | N6: =AVERAGE(T6,Y6,AD6,AI6,AN6,AS6) -> #DIV/0! | O6: =AVERAGE(U6,Z6,AE6,AJ6,AO6,AT6) -> #DIV/0! | Q6: 0.72801636 | V6: 0.59100204 | AA6: 0.599182 | AF6: 0.64212679 | AK6: 0.73210634 | AP6: 0.67075665 | AV6: 1 | AW6: =$Q$37 -> 0.69501295 | AX6: =$R$37 -> #DIV/0! | AY6: =$S$37 -> #DIV/0! | AZ6: =$T$37 -> #DIV/0! | BA6: =$U$37 -> #DIV/0!
A7: 0.5 | B7: =AVERAGE(J43:J72) -> 0.93688897 | C7: =AVERAGE(K43:K72) -> 0.70334452 | D7: =AVERAGE(L43:L72) -> #DIV/0! | E7: =AVERAGE(M43:M72) -> #DIV/0! | F7: =AVERAGE(N43:N72) -> #DIV/0! | G7: =AVERAGE(O43:O72) -> #DIV/0! | J7: 0.97174535 | K7: =AVERAGE(Q7,V7,AA7,AF7,AK7,AP7) -> 0.60228898 | L7: =AVERAGE(R7,W7,AB7,AG7,AL7,AQ7) -> #DIV/0! | M7: =AVERAGE(S7,X7,AC7,AH7,AM7,AR7) -> #DIV/0! | N7: =AVERAGE(T7,Y7,AD7,AI7,AN7,AS7) -> #DIV/0! | O7: =AVERAGE(U7,Z7,AE7,AJ7,AO7,AT7) -> #DIV/0! | Q7: 0.55793991 | V7: 0.6416309 | AA7: 0.6695279 | AF7: 0.65879828 | AK7: 0.57725322 | AP7: 0.50858369 | AV7: 2 | AW7: =$V$37 -> 0.66209855 | AX7: =$W$37 -> #DIV/0! | AY7: =$X$37 -> #DIV/0! | AZ7: =$Y$37 -> #DIV/0! | BA7: =$Z$37 -> #DIV/0!
A8: 1 | B8: =AVERAGE(J80:J109) -> 0.93418296 | C8: =AVERAGE(K80:K109) -> 0.70708711 | D8: =AVERAGE(L80:L109) -> #DIV/0! | E8: =AVERAGE(M80:M109) -> #DIV/0! | F8: =AVERAGE(N80:N109) -> #DIV/0! | G8: =AVERAGE(O80:O109) -> #DIV/0! | J8: 0.84009406 | K8: =AVERAGE(Q8,V8,AA8,AF8,AK8,AP8) -> 0.64226925 | L8: =AVERAGE(R8,W8,AB8,AG8,AL8,AQ8) -> #DIV/0! | M8: =AVERAGE(S8,X8,AC8,AH8,AM8,AR8) -> #DIV/0! | N8: =AVERAGE(T8,Y8,AD8,AI8,AN8,AS8) -> #DIV/0! | O8: =AVERAGE(U8,Z8,AE8,AJ8,AO8,AT8) -> #DIV/0! | Q8: 0.59259259 | V8: 0.65079365 | AA8: 0.66313933 | AF8: 0.66313933 | AK8: 0.61728395 | AP8: 0.66666667 | AV8: 3 | AW8: =$AA$37 -> 0.68746603 | AX8: =$AB$37 -> #DIV/0! | AY8: =$AC$37 -> #DIV/0! | AZ8: =$AD$37 -> #DIV/0! | BA8: =$AE$37 -> #DIV/0!
A9: 2 | B9: =AVERAGE(J117:J146) -> 0.93727722 | C9: =AVERAGE(K117:K146) -> 0.72835621 | D9: =AVERAGE(L117:L146) -> #DIV/0! | E9: =AVERAGE(M117:M146) -> #DIV/0! | F9: =AVERAGE(N117:N146) -> #DIV/0! | G9: =AVERAGE(O117:O146) -> #DIV/0! | J9: 0.96239113 | K9: =AVERAGE(Q9,V9,AA9,AF9,AK9,AP9) -> 0.89904988 | L9: =AVERAGE(R9,W9,AB9,AG9,AL9,AQ9) -> #DIV/0! | M9: =AVERAGE(S9,X9,AC9,AH9,AM9,AR9) -> #DIV/0! | N9: =AVERAGE(T9,Y9,AD9,AI9,AN9,AS9) -> #DIV/0! | O9: =AVERAGE(U9,Z9,AE9,AJ9,AO9,AT9) -> #DIV/0! | Q9: 0.92874109 | V9: 0.91686461 | AA9: 0.89786223 | AF9: 0.9239905 | AK9: 0.82660333 | AP9: 0.90023753 | AV9: 4 | AW9: =$AF$37 -> 0.66730712 | AX9: =$AG$37 -> #DIV/0! | AY9: =$AH$37 -> #DIV/0! | AZ9: =$AI$37 -> #DIV/0! | BA9: =$AJ$37 -> #DIV/0!
A10: 3 | B10: =AVERAGE(J154:J183) -> 0.9365298 | C10: =AVERAGE(K154:K183) -> 0.73761423 | D10: =AVERAGE(L154:L183) -> #DIV/0! | E10: =AVERAGE(M154:M183) -> #DIV/0! | F10: =AVERAGE(N154:N183) -> #DIV/0! | G10: =AVERAGE(O154:O183) -> #DIV/0! | J10: 0.96223958 | K10: =AVERAGE(Q10,V10,AA10,AF10,AK10,AP10) -> 0.71571181 | L10: =AVERAGE(R10,W10,AB10,AG10,AL10,AQ10) -> #DIV/0! | M10: =AVERAGE(S10,X10,AC10,AH10,AM10,AR10) -> #DIV/0! | N10: =AVERAGE(T10,Y10,AD10,AI10,AN10,AS10) -> #DIV/0! | O10: =AVERAGE(U10,Z10,AE10,AJ10,AO10,AT10) -> #DIV/0! | Q10: 0.65104167 | V10: 0.73177083 | AA10: 0.68489583 | AF10: 0.76822917 | AK10: 0.734375 | AP10: 0.72395833 | AV10: 5 | AW10: =$AK$37 -> 0.6760716 | AX10: =$AL$37 -> #DIV/0! | AY10: =$AM$37 -> #DIV/0! | AZ10: =$AN$37 -> #DIV/0! | BA10: =$AO$37 -> #DIV/0!
J11: 0.89364035 | K11: =AVERAGE(Q11,V11,AA11,AF11,AK11,AP11) -> 0.50109649 | L11: =AVERAGE(R11,W11,AB11,AG11,AL11,AQ11) -> #DIV/0! | M11: =AVERAGE(S11,X11,AC11,AH11,AM11,AR11) -> #DIV/0! | N11: =AVERAGE(T11,Y11,AD11,AI11,AN11,AS11) -> #DIV/0! | O11: =AVERAGE(U11,Z11,AE11,AJ11,AO11,AT11) -> #DIV/0! | Q11: 0.57017544 | V11: 0.49561404 | AA11: 0.51096491 | AF11: 0.47587719 | AK11: 0.5372807 | AP11: 0.41666667 | AV11: 6 | AW11: =$AP$37 -> 0.67236076 | AX11: =$AQ$37 -> #DIV/0! | AY11: =$AR$37 -> #DIV/0! | AZ11: =$AS$37 -> #DIV/0! | BA11: =$AT$37 -> #DIV/0!
J12: 0.96901173 | K12: =AVERAGE(Q12,V12,AA12,AF12,AK12,AP12) -> 0.84505863 | L12: =AVERAGE(R12,W12,AB12,AG12,AL12,AQ12) -> #DIV/0! | M12: =AVERAGE(S12,X12,AC12,AH12,AM12,AR12) -> #DIV/0! | N12: =AVERAGE(T12,Y12,AD12,AI12,AN12,AS12) -> #DIV/0! | O12: =AVERAGE(U12,Z12,AE12,AJ12,AO12,AT12) -> #DIV/0! | Q12: 0.88442211 | V12: 0.81155779 | AA12: 0.89949749 | AF12: 0.84673367 | AK12: 0.76633166 | AP12: 0.86180905
J13: 0.96319199 | K13: =AVERAGE(Q13,V13,AA13,AF13,AK13,AP13) -> 0.82656066 | L13: =AVERAGE(R13,W13,AB13,AG13,AL13,AQ13) -> #DIV/0! | M13: =AVERAGE(S13,X13,AC13,AH13,AM13,AR13) -> #DIV/0! | N13: =AVERAGE(T13,Y13,AD13,AI13,AN13,AS13) -> #DIV/0! | O13: =AVERAGE(U13,Z13,AE13,AJ13,AO13,AT13) -> #DIV/0! | Q13: 0.87985866 | V13: 0.76855124 | AA13: 0.8745583 | AF13: 0.7385159 | AK13: 0.85335689 | AP13: 0.84452297
J14: 0.97146834 | K14: =AVERAGE(Q14,V14,AA14,AF14,AK14,AP14) -> 0.78844816 | L14: =AVERAGE(R14,W14,AB14,AG14,AL14,AQ14) -> #DIV/0! | M14: =AVERAGE(S14,X14,AC14,AH14,AM14,AR14) -> #DIV/0! | N14: =AVERAGE(T14,Y14,AD14,AI14,AN14,AS14) -> #DIV/0! | O14: =AVERAGE(U14,Z14,AE14,AJ14,AO14,AT14) -> #DIV/0! | Q14: 0.9039666 | V14: 0.63674322 | AA14: 0.83507307 | AF14: 0.80793319 | AK14: 0.73903967 | AP14: 0.80793319
J15: 0.96666667 | K15: =AVERAGE(Q15,V15,AA15,AF15,AK15,AP15) -> 0.55734767 | L15: =AVERAGE(R15,W15,AB15,AG15,AL15,AQ15) -> #DIV/0! | M15: =AVERAGE(S15,X15,AC15,AH15,AM15,AR15) -> #DIV/0! | N15: =AVERAGE(T15,Y15,AD15,AI15,AN15,AS15) -> #DIV/0! | O15: =AVERAGE(U15,Z15,AE15,AJ15,AO15,AT15) -> #DIV/0! | Q15: 0.50537634 | V15: 0.49462366 | AA15: 0.65591398 | AF15: 0.52043011 | AK15: 0.58709677 | AP15: 0.58064516 | AV15: =A7 -> 0.5 | AW15: Task 2 | AX15: Task 3 | AY15: Task 4 | AZ15: Task 5 | BA15: Task 6
J16: 0.96370684 | K16: =AVERAGE(Q16,V16,AA16,AF16,AK16,AP16) -> 0.73890063 | L16: =AVERAGE(R16,W16,AB16,AG16,AL16,AQ16) -> #DIV/0! | M16: =AVERAGE(S16,X16,AC16,AH16,AM16,AR16) -> #DIV/0! | N16: =AVERAGE(T16,Y16,AD16,AI16,AN16,AS16) -> #DIV/0! | O16: =AVERAGE(U16,Z16,AE16,AJ16,AO16,AT16) -> #DIV/0! | Q16: 0.7167019 | V16: 0.794926 | AA16: 0.75264271 | AF16: 0.7230444 | AK16: 0.7230444 | AP16: 0.7230444 | AV16: 1 | AW16: =$Q$74 -> 0.69831592 | AX16: =$R$74 -> #DIV/0! | AY16: =$S$74 -> #DIV/0! | AZ16: =$T$74 -> #DIV/0! | BA16: =$U$74 -> #DIV/0!
J17: 0.87525355 | K17: =AVERAGE(Q17,V17,AA17,AF17,AK17,AP17) -> 0.71805274 | L17: =AVERAGE(R17,W17,AB17,AG17,AL17,AQ17) -> #DIV/0! | M17: =AVERAGE(S17,X17,AC17,AH17,AM17,AR17) -> #DIV/0! | N17: =AVERAGE(T17,Y17,AD17,AI17,AN17,AS17) -> #DIV/0! | O17: =AVERAGE(U17,Z17,AE17,AJ17,AO17,AT17) -> #DIV/0! | Q17: 0.7484787 | V17: 0.72008114 | AA17: 0.70993915 | AF17: 0.77687627 | AK17: 0.72008114 | AP17: 0.63286004 | AV17: 2 | AW17: =$V$74 -> 0.69811311 | AX17: =$W$74 -> #DIV/0! | AY17: =$X$74 -> #DIV/0! | AZ17: =$Y$74 -> #DIV/0! | BA17: =$Z$74 -> #DIV/0!
J18: 0.90471814 | K18: =AVERAGE(Q18,V18,AA18,AF18,AK18,AP18) -> 0.53553922 | L18: =AVERAGE(R18,W18,AB18,AG18,AL18,AQ18) -> #DIV/0! | M18: =AVERAGE(S18,X18,AC18,AH18,AM18,AR18) -> #DIV/0! | N18: =AVERAGE(T18,Y18,AD18,AI18,AN18,AS18) -> #DIV/0! | O18: =AVERAGE(U18,Z18,AE18,AJ18,AO18,AT18) -> #DIV/0! | Q18: 0.59558824 | V18: 0.46507353 | AA18: 0.52941176 | AF18: 0.50551471 | AK18: 0.59375 | AP18: 0.52389706 | AV18: 3 | AW18: =$AA$74 -> 0.69918688 | AX18: =$AB$74 -> #DIV/0! | AY18: =$AC$74 -> #DIV/0! | AZ18: =$AD$74 -> #DIV/0! | BA18: =$AE$74 -> #DIV/0!
J19: 0.95442448 | K19: =AVERAGE(Q19,V19,AA19,AF19,AK19,AP19) -> 0.77644711 | L19: =AVERAGE(R19,W19,AB19,AG19,AL19,AQ19) -> #DIV/0! | M19: =AVERAGE(S19,X19,AC19,AH19,AM19,AR19) -> #DIV/0! | N19: =AVERAGE(T19,Y19,AD19,AI19,AN19,AS19) -> #DIV/0! | O19: =AVERAGE(U19,Z19,AE19,AJ19,AO19,AT19) -> #DIV/0! | Q19: 0.81836327 | V19: 0.83433134 | AA19: 0.70658683 | AF19: 0.71457086 | AK19: 0.80838323 | AP19: 0.77644711 | AV19: 4 | AW19: =$AF$74 -> 0.71041532 | AX19: =$AG$74 -> #DIV/0! | AY19: =$AH$74 -> #DIV/0! | AZ19: =$AI$74 -> #DIV/0! | BA19: =$AJ$74 -> #DIV/0!
J20: 0.96599327 | K20: =AVERAGE(Q20,V20,AA20,AF20,AK20,AP20) -> 0.6043771 | L20: =AVERAGE(R20,W20,AB20,AG20,AL20,AQ20) -> #DIV/0! | M20: =AVERAGE(S20,X20,AC20,AH20,AM20,AR20) -> #DIV/0! | N20: =AVERAGE(T20,Y20,AD20,AI20,AN20,AS20) -> #DIV/0! | O20: =AVERAGE(U20,Z20,AE20,AJ20,AO20,AT20) -> #DIV/0! | Q20: 0.64444444 | V20: 0.53333333 | AA20: 0.58787879 | AF20: 0.48686869 | AK20: 0.75757576 | AP20: 0.61616162 | AV20: 5 | AW20: =$AK$74 -> 0.69299221 | AX20: =$AL$74 -> #DIV/0! | AY20: =$AM$74 -> #DIV/0! | AZ20: =$AN$74 -> #DIV/0! | BA20: =$AO$74 -> #DIV/0!
J21: 0.95944104 | K21: =AVERAGE(Q21,V21,AA21,AF21,AK21,AP21) -> 0.63156101 | L21: =AVERAGE(R21,W21,AB21,AG21,AL21,AQ21) -> #DIV/0! | M21: =AVERAGE(S21,X21,AC21,AH21,AM21,AR21) -> #DIV/0! | N21: =AVERAGE(T21,Y21,AD21,AI21,AN21,AS21) -> #DIV/0! | O21: =AVERAGE(U21,Z21,AE21,AJ21,AO21,AT21) -> #DIV/0! | Q21: 0.71370143 | V21: 0.62576687 | AA21: 0.65030675 | AF21: 0.58895706 | AK21: 0.599182 | AP21: 0.61145194 | AV21: 6 | AW21: =$AP$74 -> 0.72104368 | AX21: =$AQ$74 -> #DIV/0! | AY21: =$AR$74 -> #DIV/0! | AZ21: =$AS$74 -> #DIV/0! | BA21: =$AT$74 -> #DIV/0!
J22: 0.88309353 | K22: =AVERAGE(Q22,V22,AA22,AF22,AK22,AP22) -> 0.73890887 | L22: =AVERAGE(R22,W22,AB22,AG22,AL22,AQ22) -> #DIV/0! | M22: =AVERAGE(S22,X22,AC22,AH22,AM22,AR22) -> #DIV/0! | N22: =AVERAGE(T22,Y22,AD22,AI22,AN22,AS22) -> #DIV/0! | O22: =AVERAGE(U22,Z22,AE22,AJ22,AO22,AT22) -> #DIV/0! | Q22: 0.75 | V22: 0.74100719 | AA22: 0.75179856 | AF22: 0.7176259 | AK22: 0.73920863 | AP22: 0.73381295
J23: 0.89958034 | K23: =AVERAGE(Q23,V23,AA23,AF23,AK23,AP23) -> 0.73171463 | L23: =AVERAGE(R23,W23,AB23,AG23,AL23,AQ23) -> #DIV/0! | M23: =AVERAGE(S23,X23,AC23,AH23,AM23,AR23) -> #DIV/0! | N23: =AVERAGE(T23,Y23,AD23,AI23,AN23,AS23) -> #DIV/0! | O23: =AVERAGE(U23,Z23,AE23,AJ23,AO23,AT23) -> #DIV/0! | Q23: 0.74280576 | V23: 0.73561151 | AA23: 0.75 | AF23: 0.72841727 | AK23: 0.73920863 | AP23: 0.6942446
J24: 0.96417069 | K24: =AVERAGE(Q24,V24,AA24,AF24,AK24,AP24) -> 0.75201288 | L24: =AVERAGE(R24,W24,AB24,AG24,AL24,AQ24) -> #DIV/0! | M24: =AVERAGE(S24,X24,AC24,AH24,AM24,AR24) -> #DIV/0! | N24: =AVERAGE(T24,Y24,AD24,AI24,AN24,AS24) -> #DIV/0! | O24: =AVERAGE(U24,Z24,AE24,AJ24,AO24,AT24) -> #DIV/0! | Q24: 0.83091787 | V24: 0.647343 | AA24: 0.74396135 | AF24: 0.76811594 | AK24: 0.76570048 | AP24: 0.75603865
J25: 0.89871087 | K25: =AVERAGE(Q25,V25,AA25,AF25,AK25,AP25) -> 0.49324739 | L25: =AVERAGE(R25,W25,AB25,AG25,AL25,AQ25) -> #DIV/0! | M25: =AVERAGE(S25,X25,AC25,AH25,AM25,AR25) -> #DIV/0! | N25: =AVERAGE(T25,Y25,AD25,AI25,AN25,AS25) -> #DIV/0! | O25: =AVERAGE(U25,Z25,AE25,AJ25,AO25,AT25) -> #DIV/0! | Q25: 0.54511971 | V25: 0.51565378 | AA25: 0.46961326 | AF25: 0.45856354 | AK25: 0.47882136 | AP25: 0.49171271 | AV25: =A8 -> 1 | AW25: Task 2 | AX25: Task 3 | AY25: Task 4 | AZ25: Task 5 | BA25: Task 6
J26: 0.96625 | K26: =AVERAGE(Q26,V26,AA26,AF26,AK26,AP26) -> 0.76041667 | L26: =AVERAGE(R26,W26,AB26,AG26,AL26,AQ26) -> #DIV/0! | M26: =AVERAGE(S26,X26,AC26,AH26,AM26,AR26) -> #DIV/0! | N26: =AVERAGE(T26,Y26,AD26,AI26,AN26,AS26) -> #DIV/0! | O26: =AVERAGE(U26,Z26,AE26,AJ26,AO26,AT26) -> #DIV/0! | Q26: 0.7325 | V26: 0.6775 | AA26: 0.855 | AF26: 0.85 | AK26: 0.715 | AP26: 0.7325 | AV26: 1 | AW26: =$Q$111 -> 0.6836478 | AX26: =$R$111 -> #DIV/0! | AY26: =$S$111 -> #DIV/0! | AZ26: =$T$111 -> #DIV/0! | BA26: =$U$111 -> #DIV/0!
J27: 0.95949535 | K27: =AVERAGE(Q27,V27,AA27,AF27,AK27,AP27) -> 0.82636122 | L27: =AVERAGE(R27,W27,AB27,AG27,AL27,AQ27) -> #DIV/0! | M27: =AVERAGE(S27,X27,AC27,AH27,AM27,AR27) -> #DIV/0! | N27: =AVERAGE(T27,Y27,AD27,AI27,AN27,AS27) -> #DIV/0! | O27: =AVERAGE(U27,Z27,AE27,AJ27,AO27,AT27) -> #DIV/0! | Q27: 0.84063745 | V27: 0.92828685 | AA27: 0.81673307 | AF27: 0.90836653 | AK27: 0.66733068 | AP27: 0.79681275 | AV27: 2 | AW27: =$V$111 -> 0.72178714 | AX27: =$W$111 -> #DIV/0! | AY27: =$X$111 -> #DIV/0! | AZ27: =$Y$111 -> #DIV/0! | BA27: =$Z$111 -> #DIV/0!
J28: 0.96487455 | K28: =AVERAGE(Q28,V28,AA28,AF28,AK28,AP28) -> 0.54623656 | L28: =AVERAGE(R28,W28,AB28,AG28,AL28,AQ28) -> #DIV/0! | M28: =AVERAGE(S28,X28,AC28,AH28,AM28,AR28) -> #DIV/0! | N28: =AVERAGE(T28,Y28,AD28,AI28,AN28,AS28) -> #DIV/0! | O28: =AVERAGE(U28,Z28,AE28,AJ28,AO28,AT28) -> #DIV/0! | Q28: 0.51397849 | V28: 0.49032258 | AA28: 0.6172043 | AF28: 0.48172043 | AK28: 0.54193548 | AP28: 0.63225806 | AV28: 3 | AW28: =$AA$111 -> 0.72107647 | AX28: =$AB$111 -> #DIV/0! | AY28: =$AC$111 -> #DIV/0! | AZ28: =$AD$111 -> #DIV/0! | BA28: =$AE$111 -> #DIV/0!
J29: 0.89175258 | K29: =AVERAGE(Q29,V29,AA29,AF29,AK29,AP29) -> 0.52542955 | L29: =AVERAGE(R29,W29,AB29,AG29,AL29,AQ29) -> #DIV/0! | M29: =AVERAGE(S29,X29,AC29,AH29,AM29,AR29) -> #DIV/0! | N29: =AVERAGE(T29,Y29,AD29,AI29,AN29,AS29) -> #DIV/0! | O29: =AVERAGE(U29,Z29,AE29,AJ29,AO29,AT29) -> #DIV/0! | Q29: 0.53814433 | V29: 0.53195876 | AA29: 0.56494845 | AF29: 0.42680412 | AK29: 0.53814433 | AP29: 0.55257732 | AV29: 4 | AW29: =$AF$111 -> 0.70975513 | AX29: =$AG$111 -> #DIV/0! | AY29: =$AH$111 -> #DIV/0! | AZ29: =$AI$111 -> #DIV/0! | BA29: =$AJ$111 -> #DIV/0!
J30: 0.9605475 | K30: =AVERAGE(Q30,V30,AA30,AF30,AK30,AP30) -> 0.7773752 | L30: =AVERAGE(R30,W30,AB30,AG30,AL30,AQ30) -> #DIV/0! | M30: =AVERAGE(S30,X30,AC30,AH30,AM30,AR30) -> #DIV/0! | N30: =AVERAGE(T30,Y30,AD30,AI30,AN30,AS30) -> #DIV/0! | O30: =AVERAGE(U30,Z30,AE30,AJ30,AO30,AT30) -> #DIV/0! | Q30: 0.78985507 | V30: 0.68115942 | AA30: 0.78019324 | AF30: 0.74879227 | AK30: 0.82125604 | AP30: 0.84299517 | AV30: 5 | AW30: =$AK$111 -> 0.69964612 | AX30: =$AL$111 -> #DIV/0! | AY30: =$AM$111 -> #DIV/0! | AZ30: =$AN$111 -> #DIV/0! | BA30: =$AO$111 -> #DIV/0!
J31: 0.96908939 | K31: =AVERAGE(Q31,V31,AA31,AF31,AK31,AP31) -> 0.74143693 | L31: =AVERAGE(R31,W31,AB31,AG31,AL31,AQ31) -> #DIV/0! | M31: =AVERAGE(S31,X31,AC31,AH31,AM31,AR31) -> #DIV/0! | N31: =AVERAGE(T31,Y31,AD31,AI31,AN31,AS31) -> #DIV/0! | O31: =AVERAGE(U31,Z31,AE31,AJ31,AO31,AT31) -> #DIV/0! | Q31: 0.6641604 | V31: 0.81453634 | AA31: 0.76942356 | AF31: 0.68421053 | AK31: 0.81453634 | AP31: 0.70175439 | AV31: 6 | AW31: =$AP$111 -> 0.70660999 | AX31: =$AQ$111 -> #DIV/0! | AY31: =$AR$111 -> #DIV/0! | AZ31: =$AS$111 -> #DIV/0! | BA31: =$AT$111 -> #DIV/0!
J32: 0.8914405 | K32: =AVERAGE(Q32,V32,AA32,AF32,AK32,AP32) -> 0.56367432 | L32: =AVERAGE(R32,W32,AB32,AG32,AL32,AQ32) -> #DIV/0! | M32: =AVERAGE(S32,X32,AC32,AH32,AM32,AR32) -> #DIV/0! | N32: =AVERAGE(T32,Y32,AD32,AI32,AN32,AS32) -> #DIV/0! | O32: =AVERAGE(U32,Z32,AE32,AJ32,AO32,AT32) -> #DIV/0! | Q32: 0.56993737 | V32: 0.56367432 | AA32: 0.53235908 | AF32: 0.56158664 | AK32: 0.58455115 | AP32: 0.56993737
J33: 0.88659794 | K33: =AVERAGE(Q33,V33,AA33,AF33,AK33,AP33) -> 0.52955326 | L33: =AVERAGE(R33,W33,AB33,AG33,AL33,AQ33) -> #DIV/0! | M33: =AVERAGE(S33,X33,AC33,AH33,AM33,AR33) -> #DIV/0! | N33: =AVERAGE(T33,Y33,AD33,AI33,AN33,AS33) -> #DIV/0! | O33: =AVERAGE(U33,Z33,AE33,AJ33,AO33,AT33) -> #DIV/0! | Q33: 0.59381443 | V33: 0.5257732 | AA33: 0.45979381 | AF33: 0.58969072 | AK33: 0.51752577 | AP33: 0.49072165
J34: 0.89503932 | K34: =AVERAGE(Q34,V34,AA34,AF34,AK34,AP34) -> 0.67755596 | L34: =AVERAGE(R34,W34,AB34,AG34,AL34,AQ34) -> #DIV/0! | M34: =AVERAGE(S34,X34,AC34,AH34,AM34,AR34) -> #DIV/0! | N34: =AVERAGE(T34,Y34,AD34,AI34,AN34,AS34) -> #DIV/0! | O34: =AVERAGE(U34,Z34,AE34,AJ34,AO34,AT34) -> #DIV/0! | Q34: 0.66606171 | V34: 0.65154265 | AA34: 0.66969147 | AF34: 0.66787659 | AK34: 0.6969147 | AP34: 0.71324864
J35: 0.972103 | K35: =AVERAGE(Q35,V35,AA35,AF35,AK35,AP35) -> 0.5944206 | L35: =AVERAGE(R35,W35,AB35,AG35,AL35,AQ35) -> #DIV/0! | M35: =AVERAGE(S35,X35,AC35,AH35,AM35,AR35) -> #DIV/0! | N35: =AVERAGE(T35,Y35,AD35,AI35,AN35,AS35) -> #DIV/0! | O35: =AVERAGE(U35,Z35,AE35,AJ35,AO35,AT35) -> #DIV/0! | Q35: 0.63304721 | V35: 0.64592275 | AA35: 0.61587983 | AF35: 0.58583691 | AK35: 0.48927039 | AP35: 0.59656652 | AV35: =A9 -> 2 | AW35: Task 2 | AX35: Task 3 | AY35: Task 4 | AZ35: Task 5 | BA35: Task 6
AV36: 1 | AW36: =$Q$148 -> 0.74218221 | AX36: =$R$148 -> #DIV/0! | AY36: =$S$148 -> #DIV/0! | AZ36: =$T$148 -> #DIV/0! | BA36: =$U$148 -> #DIV/0!
J37: 0.98844568 | K37: =AVERAGE(K6:K35) -> 0.6767195 | L37: =AVERAGE(L6:L35) -> #DIV/0! | M37: =AVERAGE(M6:M35) -> #DIV/0! | N37: =AVERAGE(N6:N35) -> #DIV/0! | O37: =AVERAGE(O6:O35) -> #DIV/0! | Q37: =AVERAGE(Q6:Q35) -> 0.69501295 | R37: =AVERAGE(R6:R35) -> #DIV/0! | S37: =AVERAGE(S6:S35) -> #DIV/0! | T37: =AVERAGE(T6:T35) -> #DIV/0! | U37: =AVERAGE(U6:U35) -> #DIV/0! | V37: =AVERAGE(V6:V35) -> 0.66209855 | W37: =AVERAGE(W6:W35) -> #DIV/0! | X37: =AVERAGE(X6:X35) -> #DIV/0! | ... AT37: =AVERAGE(AT6:AT35) -> #DIV/0! | AV37: 2 | AW37: =$V$148 -> 0.7393051 | AX37: =$W$148 -> #DIV/0! | AY37: =$X$148 -> #DIV/0! | AZ37: =$Y$148 -> #DIV/0! | BA37: =$Z$148 -> #DIV/0!
AV38: 3 | AW38: =$AA$148 -> 0.74251423 | AX38: =$AB$148 -> #DIV/0! | AY38: =$AC$148 -> #DIV/0! | AZ38: =$AD$148 -> #DIV/0! | BA38: =$AE$148 -> #DIV/0!
AV39: 4 | AW39: =$AF$148 -> 0.72434215 | AX39: =$AG$148 -> #DIV/0! | AY39: =$AH$148 -> #DIV/0! | AZ39: =$AI$148 -> #DIV/0! | BA39: =$AJ$148 -> #DIV/0!
J40: k=0.5 | AV40: 5 | AW40: =$AK$148 -> 0.71379219 | AX40: =$AL$148 -> #DIV/0! | AY40: =$AM$148 -> #DIV/0! | AZ40: =$AN$148 -> #DIV/0! | BA40: =$AO$148 -> #DIV/0!
Q41: 1 | V41: 2 | AA41: 3 | AF41: 4 | AK41: 5 | AP41: 6 | AV41: 6 | AW41: =$AP$148 -> 0.70800142 | AX41: =$AQ$148 -> #DIV/0! | AY41: =$AR$148 -> #DIV/0! | AZ41: =$AS$148 -> #DIV/0! | BA41: =$AT$148 -> #DIV/0!
I42: ID | J42: Task 1 | K42: Task 2 | L42: Task 3 | M42: Task 4 | N42: Task 5 | O42: Task 6 | Q42: Task 2 | R42: Task 3 | S42: Task 4 | T42: Task 5 | U42: Task 6 | V42: Task 2 | W42: Task 3 | X42: Task 4 | Y42: Task 5 | Z42: Task 6 | AA42: Task 2 | AB42: Task 3 | AC42: Task 4 | AD42: Task 5 | AE42: Task 6 | AF42: Task 2 | AG42: Task 3 | AH42: Task 4 | AI42: Task 5 | AJ42: Task 6 | AK42: Task 2 | AL42: Task 3 | AM42: Task 4 | AN42: Task 5 | AO42: Task 6 | AP42: Task 2 | AQ42: Task 3 | AR42: Task 4 | AS42: Task 5 | AT42: Task 6
...

Sheet Person_2
J3: k=0.25
Q4: 1 | V4: 2 | AA4: 3 | AF4: 4 | AK4: 5 | AP4: 6
A5: k | B5: Task 1 | C5: Task 2 | D5: Task 3 | E5: Task 4 | F5: Task 5 | G5: Task 6 | I5: ID | J5: Task 1 | K5: Task 2 | L5: Task 3 | M5: Task 4 | N5: Task 5 | O5: Task 6 | Q5: Task 2 | R5: Task 3 | S5: Task 4 | T5: Task 5 | U5: Task 6 | V5: Task 2 | W5: Task 3 | X5: Task 4 | Y5: Task 5 | Z5: Task 6 | AA5: Task 2 | AB5: Task 3 | AC5: Task 4 | AD5: Task 5 | AE5: Task 6 | AF5: Task 2 | AG5: Task 3 | AH5: Task 4 | AI5: Task 5 | AJ5: Task 6 | AK5: Task 2 | AL5: Task 3 | AM5: Task 4 | AN5: Task 5 | AO5: Task 6 | AP5: Task 2 | AQ5: Task 3 | AR5: Task 4 | AS5: Task 5 | AT5: Task 6 | AV5: =A6 -> 0.25 | AW5: Task 2 | AX5: Task 3 | AY5: Task 4 | AZ5: Task 5 | BA5: Task 6
A6: 0.25 | B6: =AVERAGE(J6:J35) -> 0.98800682 | C6: =AVERAGE(K6:K35) -> 0.83977432 | D6: =AVERAGE(L6:L35) -> #DIV/0! | E6: =AVERAGE(M6:M35) -> #DIV/0! | F6: =AVERAGE(N6:N35) -> #DIV/0! | G6: =AVERAGE(O6:O35) -> #DIV/0! | J6: 0.99390244 | K6: =AVERAGE(Q6,V6,AA6,AF6,AK6,AP6) -> 0.87703252 | L6: =AVERAGE(R6,W6,AB6,AG6,AL6,AQ6) -> #DIV/0! | M6: =AVERAGE(S6,X6,AC6,AH6,AM6,AR6) -> #DIV/0! | N6: =AVERAGE(T6,Y6,AD6,AI6,AN6,AS6) -> #DIV/0! | O6: =AVERAGE(U6,Z6,AE6,AJ6,AO6,AT6) -> #DIV/0! | Q6: 0.93089431 | V6: 0.89227642 | AA6: 0.92073171 | AF6: 0.86788618 | AK6: 0.90243902 | AP6: 0.74796748 | AV6: 1 | AW6: =$Q$37 -> 0.83116237 | AX6: =$R$37 -> #DIV/0! | AY6: =$S$37 -> #DIV/0! | AZ6: =$T$37 -> #DIV/0! | BA6: =$U$37 -> #DIV/0!
A7: 0.5 | B7: =AVERAGE(J43:J72) -> 0.98811749 | C7: =AVERAGE(K43:K72) -> 0.86032135 | D7: =AVERAGE(L43:L72) -> #DIV/0! | E7: =AVERAGE(M43:M72) -> #DIV/0! | F7: =AVERAGE(N43:N72) -> #DIV/0! | G7: =AVERAGE(O43:O72) -> #DIV/0! | J7: 0.98874365 | K7: =AVERAGE(Q7,V7,AA7,AF7,AK7,AP7) -> 0.77777778 | L7: =AVERAGE(R7,W7,AB7,AG7,AL7,AQ7) -> #DIV/0! | M7: =AVERAGE(S7,X7,AC7,AH7,AM7,AR7) -> #DIV/0! | N7: =AVERAGE(T7,Y7,AD7,AI7,AN7,AS7) -> #DIV/0! | O7: =AVERAGE(U7,Z7,AE7,AJ7,AO7,AT7) -> #DIV/0! | Q7: 0.64705882 | V7: 0.80392157 | AA7: 0.8453159 | AF7: 0.68409586 | AK7: 0.81481481 | AP7: 0.87145969 | AV7: 2 | AW7: =$V$37 -> 0.8535087 | AX7: =$W$37 -> #DIV/0! | AY7: =$X$37 -> #DIV/0! | AZ7: =$Y$37 -> #DIV/0! | BA7: =$Z$37 -> #DIV/0!
A8: 1 | B8: =AVERAGE(J80:J109) -> 0.98817145 | C8: =AVERAGE(K80:K109) -> 0.86103677 | D8: =AVERAGE(L80:L109) -> #DIV/0! | E8: =AVERAGE(M80:M109) -> #DIV/0! | F8: =AVERAGE(N80:N109) -> #DIV/0! | G8: =AVERAGE(O80:O109) -> #DIV/0! | J8: 0.98702422 | K8: =AVERAGE(Q8,V8,AA8,AF8,AK8,AP8) -> 0.93310265 | L8: =AVERAGE(R8,W8,AB8,AG8,AL8,AQ8) -> #DIV/0! | M8: =AVERAGE(S8,X8,AC8,AH8,AM8,AR8) -> #DIV/0! | N8: =AVERAGE(T8,Y8,AD8,AI8,AN8,AS8) -> #DIV/0! | O8: =AVERAGE(U8,Z8,AE8,AJ8,AO8,AT8) -> #DIV/0! | Q8: 0.90138408 | V8: 0.96020761 | AA8: 0.9550173 | AF8: 0.92906574 | AK8: 0.88408304 | AP8: 0.96885813 | AV8: 3 | AW8: =$AA$37 -> 0.86202213 | AX8: =$AB$37 -> #DIV/0! | AY8: =$AC$37 -> #DIV/0! | AZ8: =$AD$37 -> #DIV/0! | BA8: =$AE$37 -> #DIV/0!
A9: 2 | B9: =AVERAGE(J117:J146) -> 0.98784424 | C9: =AVERAGE(K117:K146) -> 0.90563102 | D9: =AVERAGE(L117:L146) -> #DIV/0! | E9: =AVERAGE(M117:M146) -> #DIV/0! | F9: =AVERAGE(N117:N146) -> #DIV/0! | G9: =AVERAGE(O117:O146) -> #DIV/0! | J9: 0.98607796 | K9: =AVERAGE(Q9,V9,AA9,AF9,AK9,AP9) -> 0.96618934 | L9: =AVERAGE(R9,W9,AB9,AG9,AL9,AQ9) -> #DIV/0! | M9: =AVERAGE(S9,X9,AC9,AH9,AM9,AR9) -> #DIV/0! | N9: =AVERAGE(T9,Y9,AD9,AI9,AN9,AS9) -> #DIV/0! | O9: =AVERAGE(U9,Z9,AE9,AJ9,AO9,AT9) -> #DIV/0! | Q9: 0.96897375 | V9: 0.95704057 | AA9: 0.9451074 | AF9: 0.97136038 | AK9: 0.97136038 | AP9: 0.98329356 | AV9: 4 | AW9: =$AF$37 -> 0.79618854 | AX9: =$AG$37 -> #DIV/0! | AY9: =$AH$37 -> #DIV/0! | AZ9: =$AI$37 -> #DIV/0! | BA9: =$AJ$37 -> #DIV/0!
A10: 3 | B10: =AVERAGE(J154:J183) -> 0.98797343 | C10: =AVERAGE(K154:K183) -> 0.92763189 | D10: =AVERAGE(L154:L183) -> #DIV/0! | E10: =AVERAGE(M154:M183) -> #DIV/0! | F10: =AVERAGE(N154:N183) -> #DIV/0! | G10: =AVERAGE(O154:O183) -> #DIV/0! | J10: 0.98679515 | K10: =AVERAGE(Q10,V10,AA10,AF10,AK10,AP10) -> 0.88793719 | L10: =AVERAGE(R10,W10,AB10,AG10,AL10,AQ10) -> #DIV/0! | M10: =AVERAGE(S10,X10,AC10,AH10,AM10,AR10) -> #DIV/0! | N10: =AVERAGE(T10,Y10,AD10,AI10,AN10,AS10) -> #DIV/0! | O10: =AVERAGE(U10,Z10,AE10,AJ10,AO10,AT10) -> #DIV/0! | Q10: 0.93361884 | V10: 0.91648822 | AA10: 0.85010707 | AF10: 0.84154176 | AK10: 0.87152034 | AP10: 0.9143469 | AV10: 5 | AW10: =$AK$37 -> 0.8641581 | AX10: =$AL$37 -> #DIV/0! | AY10: =$AM$37 -> #DIV/0! | AZ10: =$AN$37 -> #DIV/0! | BA10: =$AO$37 -> #DIV/0!
J11: 0.99240781 | K11: =AVERAGE(Q11,V11,AA11,AF11,AK11,AP11) -> 0.80621837 | L11: =AVERAGE(R11,W11,AB11,AG11,AL11,AQ11) -> #DIV/0! | M11: =AVERAGE(S11,X11,AC11,AH11,AM11,AR11) -> #DIV/0! | N11: =AVERAGE(T11,Y11,AD11,AI11,AN11,AS11) -> #DIV/0! | O11: =AVERAGE(U11,Z11,AE11,AJ11,AO11,AT11) -> #DIV/0! | Q11: 0.670282 | V11: 0.94793926 | AA11: 0.88286334 | AF11: 0.76572668 | AK11: 0.77440347 | AP11: 0.79609544 | AV11: 6 | AW11: =$AP$37 -> 0.83160605 | AX11: =$AQ$37 -> #DIV/0! | AY11: =$AR$37 -> #DIV/0! | AZ11: =$AS$37 -> #DIV/0! | BA11: =$AT$37 -> #DIV/0!
J12: 0.98316062 | K12: =AVERAGE(Q12,V12,AA12,AF12,AK12,AP12) -> 0.90803109 | L12: =AVERAGE(R12,W12,AB12,AG12,AL12,AQ12) -> #DIV/0! | M12: =AVERAGE(S12,X12,AC12,AH12,AM12,AR12) -> #DIV/0! | N12: =AVERAGE(T12,Y12,AD12,AI12,AN12,AS12) -> #DIV/0! | O12: =AVERAGE(U12,Z12,AE12,AJ12,AO12,AT12) -> #DIV/0! | Q12: 0.9015544 | V12: 0.86787565 | AA12: 0.91968912 | AF12: 0.89637306 | AK12: 0.92487047 | AP12: 0.93782383
J13: 0.98254986 | K13: =AVERAGE(Q13,V13,AA13,AF13,AK13,AP13) -> 0.88782051 | L13: =AVERAGE(R13,W13,AB13,AG13,AL13,AQ13) -> #DIV/0! | M13: =AVERAGE(S13,X13,AC13,AH13,AM13,AR13) -> #DIV/0! | N13: =AVERAGE(T13,Y13,AD13,AI13,AN13,AS13) -> #DIV/0! | O13: =AVERAGE(U13,Z13,AE13,AJ13,AO13,AT13) -> #DIV/0! | Q13: 0.92735043 | V13: 0.94017094 | AA13: 0.95940171 | AF13: 0.74358974 | AK13: 0.85470085 | AP13: 0.9017094
J14: 0.98206474 | K14: =AVERAGE(Q14,V14,AA14,AF14,AK14,AP14) -> 0.84033246 | L14: =AVERAGE(R14,W14,AB14,AG14,AL14,AQ14) -> #DIV/0! | M14: =AVERAGE(S14,X14,AC14,AH14,AM14,AR14) -> #DIV/0! | N14: =AVERAGE(T14,Y14,AD14,AI14,AN14,AS14) -> #DIV/0! | O14: =AVERAGE(U14,Z14,AE14,AJ14,AO14,AT14) -> #DIV/0! | Q14: 0.80052493 | V14: 0.90288714 | AA14: 0.87139108 | AF14: 0.90026247 | AK14: 0.79527559 | AP14: 0.77165354
J15: 0.98953824 | K15: =AVERAGE(Q15,V15,AA15,AF15,AK15,AP15) -> 0.78463203 | L15: =AVERAGE(R15,W15,AB15,AG15,AL15,AQ15) -> #DIV/0! | M15: =AVERAGE(S15,X15,AC15,AH15,AM15,AR15) -> #DIV/0! | N15: =AVERAGE(T15,Y15,AD15,AI15,AN15,AS15) -> #DIV/0! | O15: =AVERAGE(U15,Z15,AE15,AJ15,AO15,AT15) -> #DIV/0! | Q15: 0.73160173 | V15: 0.83549784 | AA15: 0.85714286 | AF15: 0.86796537 | AK15: 0.79220779 | AP15: 0.62337662 | AV15: =A7 -> 0.5 | AW15: Task 2 | AX15: Task 3 | AY15: Task 4 | AZ15: Task 5 | BA15: Task 6
J16: 0.98075241 | K16: =AVERAGE(Q16,V16,AA16,AF16,AK16,AP16) -> 0.8600175 | L16: =AVERAGE(R16,W16,AB16,AG16,AL16,AQ16) -> #DIV/0! | M16: =AVERAGE(S16,X16,AC16,AH16,AM16,AR16) -> #DIV/0! | N16: =AVERAGE(T16,Y16,AD16,AI16,AN16,AS16) -> #DIV/0! | O16: =AVERAGE(U16,Z16,AE16,AJ16,AO16,AT16) -> #DIV/0! | Q16: 0.88188976 | V16: 0.832021 | AA16: 0.88451444 | AF16: 0.88976378 | AK16: 0.89238845 | AP16: 0.77952756 | AV16: 1 | AW16: =$Q$74 -> 0.87744559 | AX16: =$R$74 -> #DIV/0! | AY16: =$S$74 -> #DIV/0! | AZ16: =$T$74 -> #DIV/0! | BA16: =$U$74 -> #DIV/0!
J17: 0.98910412 | K17: =AVERAGE(Q17,V17,AA17,AF17,AK17,AP17) -> 0.87046005 | L17: =AVERAGE(R17,W17,AB17,AG17,AL17,AQ17) -> #DIV/0! | M17: =AVERAGE(S17,X17,AC17,AH17,AM17,AR17) -> #DIV/0! | N17: =AVERAGE(T17,Y17,AD17,AI17,AN17,AS17) -> #DIV/0! | O17: =AVERAGE(U17,Z17,AE17,AJ17,AO17,AT17) -> #DIV/0! | Q17: 0.91767554 | V17: 0.91283293 | AA17: 0.89588378 | AF17: 0.94188862 | AK17: 0.937046 | AP17: 0.61743341 | AV17: 2 | AW17: =$V$74 -> 0.89841247 | AX17: =$W$74 -> #DIV/0! | AY17: =$X$74 -> #DIV/0! | AZ17: =$Y$74 -> #DIV/0! | BA17: =$Z$74 -> #DIV/0!
J18: 0.98929664 | K18: =AVERAGE(Q18,V18,AA18,AF18,AK18,AP18) -> 0.80366972 | L18: =AVERAGE(R18,W18,AB18,AG18,AL18,AQ18) -> #DIV/0! | M18: =AVERAGE(S18,X18,AC18,AH18,AM18,AR18) -> #DIV/0! | N18: =AVERAGE(T18,Y18,AD18,AI18,AN18,AS18) -> #DIV/0! | O18: =AVERAGE(U18,Z18,AE18,AJ18,AO18,AT18) -> #DIV/0! | Q18: 0.72293578 | V18: 0.88623853 | AA18: 0.79449541 | AF18: 0.6733945 | AK18: 0.80733945 | AP18: 0.93761468 | AV18: 3 | AW18: =$AA$74 -> 0.81448973 | AX18: =$AB$74 -> #DIV/0! | AY18: =$AC$74 -> #DIV/0! | AZ18: =$AD$74 -> #DIV/0! | BA18: =$AE$74 -> #DIV/0!
J19: 0.98515982 | K19: =AVERAGE(Q19,V19,AA19,AF19,AK19,AP19) -> 0.92865297 | L19: =AVERAGE(R19,W19,AB19,AG19,AL19,AQ19) -> #DIV/0! | M19: =AVERAGE(S19,X19,AC19,AH19,AM19,AR19) -> #DIV/0! | N19: =AVERAGE(T19,Y19,AD19,AI19,AN19,AS19) -> #DIV/0! | O19: =AVERAGE(U19,Z19,AE19,AJ19,AO19,AT19) -> #DIV/0! | Q19: 0.92123288 | V19: 0.95719178 | AA19: 0.92294521 | AF19: 0.96061644 | AK19: 0.875 | AP19: 0.93493151 | AV19: 4 | AW19: =$AF$74 -> 0.77296592 | AX19: =$AG$74 -> #DIV/0! | AY19: =$AH$74 -> #DIV/0! | AZ19: =$AI$74 -> #DIV/0! | BA19: =$AJ$74 -> #DIV/0!
J20: 0.99322493 | K20: =AVERAGE(Q20,V20,AA20,AF20,AK20,AP20) -> 0.79607046 | L20: =AVERAGE(R20,W20,AB20,AG20,AL20,AQ20) -> #DIV/0! | M20: =AVERAGE(S20,X20,AC20,AH20,AM20,AR20) -> #DIV/0! | N20: =AVERAGE(T20,Y20,AD20,AI20,AN20,AS20) -> #DIV/0! | O20: =AVERAGE(U20,Z20,AE20,AJ20,AO20,AT20) -> #DIV/0! | Q20: 0.90853659 | V20: 0.72560976 | AA20: 0.63821138 | AF20: 0.88617886 | AK20: 0.75609756 | AP20: 0.86178862 | AV20: 5 | AW20: =$AK$74 -> 0.91162767 | AX20: =$AL$74 -> #DIV/0! | AY20: =$AM$74 -> #DIV/0! | AZ20: =$AN$74 -> #DIV/0! | BA20: =$AO$74 -> #DIV/0!
J21: 0.99254743 | K21: =AVERAGE(Q21,V21,AA21,AF21,AK21,AP21) -> 0.89363144 | L21: =AVERAGE(R21,W21,AB21,AG21,AL21,AQ21) -> #DIV/0! | M21: =AVERAGE(S21,X21,AC21,AH21,AM21,AR21) -> #DIV/0! | N21: =AVERAGE(T21,Y21,AD21,AI21,AN21,AS21) -> #DIV/0! | O21: =AVERAGE(U21,Z21,AE21,AJ21,AO21,AT21) -> #DIV/0! | Q21: 0.93902439 | V21: 0.90650407 | AA21: 0.88821138 | AF21: 0.94308943 | AK21: 0.94105691 | AP21: 0.74390244 | AV21: 6 | AW21: =$AP$74 -> 0.88698675 | AX21: =$AQ$74 -> #DIV/0! | AY21: =$AR$74 -> #DIV/0! | AZ21: =$AS$74 -> #DIV/0! | BA21: =$AT$74 -> #DIV/0!
J22: 0.98049645 | K22: =AVERAGE(Q22,V22,AA22,AF22,AK22,AP22) -> 0.76595745 | L22: =AVERAGE(R22,W22,AB22,AG22,AL22,AQ22) -> #DIV/0! | M22: =AVERAGE(S22,X22,AC22,AH22,AM22,AR22) -> #DIV/0! | N22: =AVERAGE(T22,Y22,AD22,AI22,AN22,AS22) -> #DIV/0! | O22: =AVERAGE(U22,Z22,AE22,AJ22,AO22,AT22) -> #DIV/0! | Q22: 0.92978723 | V22: 0.85106383 | AA22: 0.88297872 | AF22: 0.46595745 | AK22: 0.78297872 | AP22: 0.68297872
J23: 0.98475177 | K23: =AVERAGE(Q23,V23,AA23,AF23,AK23,AP23) -> 0.81241135 | L23: =AVERAGE(R23,W23,AB23,AG23,AL23,AQ23) -> #DIV/0! | M23: =AVERAGE(S23,X23,AC23,AH23,AM23,AR23) -> #DIV/0! | N23: =AVERAGE(T23,Y23,AD23,AI23,AN23,AS23) -> #DIV/0! | O23: =AVERAGE(U23,Z23,AE23,AJ23,AO23,AT23) -> #DIV/0! | Q23: 0.69574468 | V23: 0.82340426 | AA23: 0.87659574 | AF23: 0.85531915 | AK23: 0.8893617 | AP23: 0.73404255
J24: 0.99429913 | K24: =AVERAGE(Q24,V24,AA24,AF24,AK24,AP24) -> 0.88195842 | L24: =AVERAGE(R24,W24,AB24,AG24,AL24,AQ24) -> #DIV/0! | M24: =AVERAGE(S24,X24,AC24,AH24,AM24,AR24) -> #DIV/0! | N24: =AVERAGE(T24,Y24,AD24,AI24,AN24,AS24) -> #DIV/0! | O24: =AVERAGE(U24,Z24,AE24,AJ24,AO24,AT24) -> #DIV/0! | Q24: 0.86519115 | V24: 0.92957746 | AA24: 0.83299799 | AF24: 0.8832998 | AK24: 0.9637827 | AP24: 0.81690141
J25: 0.98692214 | K25: =AVERAGE(Q25,V25,AA25,AF25,AK25,AP25) -> 0.81234793 | L25: =AVERAGE(R25,W25,AB25,AG25,AL25,AQ25) -> #DIV/0! | M25: =AVERAGE(S25,X25,AC25,AH25,AM25,AR25) -> #DIV/0! | N25: =AVERAGE(T25,Y25,AD25,AI25,AN25,AS25) -> #DIV/0! | O25: =AVERAGE(U25,Z25,AE25,AJ25,AO25,AT25) -> #DIV/0! | Q25: 0.63321168 | V25: 0.89416058 | AA25: 0.82664234 | AF25: 0.75364964 | AK25: 0.88321168 | AP25: 0.88321168 | AV25: =A8 -> 1 | AW25: Task 2 | AX25: Task 3 | AY25: Task 4 | AZ25: Task 5 | BA25: Task 6
J26: 0.98673835 | K26: =AVERAGE(Q26,V26,AA26,AF26,AK26,AP26) -> 0.72544803 | L26: =AVERAGE(R26,W26,AB26,AG26,AL26,AQ26) -> #DIV/0! | M26: =AVERAGE(S26,X26,AC26,AH26,AM26,AR26) -> #DIV/0! | N26: =AVERAGE(T26,Y26,AD26,AI26,AN26,AS26) -> #DIV/0! | O26: =AVERAGE(U26,Z26,AE26,AJ26,AO26,AT26) -> #DIV/0! | Q26: 0.87311828 | V26: 0.80215054 | AA26: 0.87526882 | AF26: 0.11612903 | AK26: 0.89462366 | AP26: 0.79139785 | AV26: 1 | AW26: =$Q$111 -> 0.89148763 | AX26: =$R$111 -> #DIV/0! | AY26: =$S$111 -> #DIV/0! | AZ26: =$T$111 -> #DIV/0! | BA26: =$U$111 -> #DIV/0!
J27: 0.9863124 | K27: =AVERAGE(Q27,V27,AA27,AF27,AK27,AP27) -> 0.93438003 | L27: =AVERAGE(R27,W27,AB27,AG27,AL27,AQ27) -> #DIV/0! | M27: =AVERAGE(S27,X27,AC27,AH27,AM27,AR27) -> #DIV/0! | N27: =AVERAGE(T27,Y27,AD27,AI27,AN27,AS27) -> #DIV/0! | O27: =AVERAGE(U27,Z27,AE27,AJ27,AO27,AT27) -> #DIV/0! | Q27: 0.94927536 | V27: 0.92028986 | AA27: 0.92753623 | AF27: 0.89855072 | AK27: 0.96135266 | AP27: 0.94927536 | AV27: 2 | AW27: =$V$111 -> 0.90754691 | AX27: =$W$111 -> #DIV/0! | AY27: =$X$111 -> #DIV/0! | AZ27: =$Y$111 -> #DIV/0! | BA27: =$Z$111 -> #DIV/0!
J28: 0.99134199 | K28: =AVERAGE(Q28,V28,AA28,AF28,AK28,AP28) -> 0.78751804 | L28: =AVERAGE(R28,W28,AB28,AG28,AL28,AQ28) -> #DIV/0! | M28: =AVERAGE(S28,X28,AC28,AH28,AM28,AR28) -> #DIV/0! | N28: =AVERAGE(T28,Y28,AD28,AI28,AN28,AS28) -> #DIV/0! | O28: =AVERAGE(U28,Z28,AE28,AJ28,AO28,AT28) -> #DIV/0! | Q28: 0.87878788 | V28: 0.74025974 | AA28: 0.71645022 | AF28: 0.75757576 | AK28: 0.78787879 | AP28: 0.84415584 | AV28: 3 | AW28: =$AA$111 -> 0.83109212 | AX28: =$AB$111 -> #DIV/0! | AY28: =$AC$111 -> #DIV/0! | AZ28: =$AD$111 -> #DIV/0! | BA28: =$AE$111 -> #DIV/0!
J29: 0.99595142 | K29: =AVERAGE(Q29,V29,AA29,AF29,AK29,AP29) -> 0.68387314 | L29: =AVERAGE(R29,W29,AB29,AG29,AL29,AQ29) -> #DIV/0! | M29: =AVERAGE(S29,X29,AC29,AH29,AM29,AR29) -> #DIV/0! | N29: =AVERAGE(T29,Y29,AD29,AI29,AN29,AS29) -> #DIV/0! | O29: =AVERAGE(U29,Z29,AE29,AJ29,AO29,AT29) -> #DIV/0! | Q29: 0.44736842 | V29: 0.59109312 | AA29: 0.62955466 | AF29: 0.62955466 | AK29: 0.94939271 | AP29: 0.8562753 | AV29: 4 | AW29: =$AF$111 -> 0.7211392 | AX29: =$AG$111 -> #DIV/0! | AY29: =$AH$111 -> #DIV/0! | AZ29: =$AI$111 -> #DIV/0! | BA29: =$AJ$111 -> #DIV/0!
J30: 0.99295775 | K30: =AVERAGE(Q30,V30,AA30,AF30,AK30,AP30) -> 0.8648558 | L30: =AVERAGE(R30,W30,AB30,AG30,AL30,AQ30) -> #DIV/0! | M30: =AVERAGE(S30,X30,AC30,AH30,AM30,AR30) -> #DIV/0! | N30: =AVERAGE(T30,Y30,AD30,AI30,AN30,AS30) -> #DIV/0! | O30: =AVERAGE(U30,Z30,AE30,AJ30,AO30,AT30) -> #DIV/0! | Q30: 0.85110664 | V30: 0.90744467 | AA30: 0.92756539 | AF30: 0.91750503 | AK30: 0.67404427 | AP30: 0.91146881 | AV30: 5 | AW30: =$AK$111 -> 0.90313631 | AX30: =$AL$111 -> #DIV/0! | AY30: =$AM$111 -> #DIV/0! | AZ30: =$AN$111 -> #DIV/0! | BA30: =$AO$111 -> #DIV/0!
J31: 0.99323362 | K31: =AVERAGE(Q31,V31,AA31,AF31,AK31,AP31) -> 0.86253561 | L31: =AVERAGE(R31,W31,AB31,AG31,AL31,AQ31) -> #DIV/0! | M31: =AVERAGE(S31,X31,AC31,AH31,AM31,AR31) -> #DIV/0! | N31: =AVERAGE(T31,Y31,AD31,AI31,AN31,AS31) -> #DIV/0! | O31: =AVERAGE(U31,Z31,AE31,AJ31,AO31,AT31) -> #DIV/0! | Q31: 0.77136752 | V31: 0.89102564 | AA31: 0.73717949 | AF31: 0.92948718 | AK31: 0.95512821 | AP31: 0.89102564 | AV31: 6 | AW31: =$AP$111 -> 0.91181849 | AX31: =$AQ$111 -> #DIV/0! | AY31: =$AR$111 -> #DIV/0! | AZ31: =$AS$111 -> #DIV/0! | BA31: =$AT$111 -> #DIV/0!
J32: 0.98582996 | K32: =AVERAGE(Q32,V32,AA32,AF32,AK32,AP32) -> 0.79554656 | L32: =AVERAGE(R32,W32,AB32,AG32,AL32,AQ32) -> #DIV/0! | M32: =AVERAGE(S32,X32,AC32,AH32,AM32,AR32) -> #DIV/0! | N32: =AVERAGE(T32,Y32,AD32,AI32,AN32,AS32) -> #DIV/0! | O32: =AVERAGE(U32,Z32,AE32,AJ32,AO32,AT32) -> #DIV/0! | Q32: 0.81983806 | V32: 0.82591093 | AA32: 0.89878543 | AF32: 0.86842105 | AK32: 0.77327935 | AP32: 0.58704453
J33: 0.99527665 | K33: =AVERAGE(Q33,V33,AA33,AF33,AK33,AP33) -> 0.69635628 | L33: =AVERAGE(R33,W33,AB33,AG33,AL33,AQ33) -> #DIV/0! | M33: =AVERAGE(S33,X33,AC33,AH33,AM33,AR33) -> #DIV/0! | N33: =AVERAGE(T33,Y33,AD33,AI33,AN33,AS33) -> #DIV/0! | O33: =AVERAGE(U33,Z33,AE33,AJ33,AO33,AT33) -> #DIV/0! | Q33: 0.89068826 | V33: 0.58299595 | AA33: 0.82591093 | AF33: 0.16194332 | AK33: 0.82591093 | AP33: 0.89068826
J34: 0.97608851 | K34: =AVERAGE(Q34,V34,AA34,AF34,AK34,AP34) -> 0.9318344 | L34: =AVERAGE(R34,W34,AB34,AG34,AL34,AQ34) -> #DIV/0! | M34: =AVERAGE(S34,X34,AC34,AH34,AM34,AR34) -> #DIV/0! | N34: =AVERAGE(T34,Y34,AD34,AI34,AN34,AS34) -> #DIV/0! | O34: =AVERAGE(U34,Z34,AE34,AJ34,AO34,AT34) -> #DIV/0! | Q34: 0.8993576 | V34: 0.88222698 | AA34: 0.95931478 | AF34: 0.94646681 | AK34: 0.97002141 | AP34: 0.93361884
J35: 0.98765432 | K35: =AVERAGE(Q35,V35,AA35,AF35,AK35,AP35) -> 0.81663036 | L35: =AVERAGE(R35,W35,AB35,AG35,AL35,AQ35) -> #DIV/0! | M35: =AVERAGE(S35,X35,AC35,AH35,AM35,AR35) -> #DIV/0! | N35: =AVERAGE(T35,Y35,AD35,AI35,AN35,AS35) -> #DIV/0! | O35: =AVERAGE(U35,Z35,AE35,AJ35,AO35,AT35) -> #DIV/0! | Q35: 0.7254902 | V35: 0.71895425 | AA35: 0.91285403 | AF35: 0.93899782 | AK35: 0.81917211 | AP35: 0.78431373 | AV35: =A9 -> 2 | AW35: Task 2 | AX35: Task 3 | AY35: Task 4 | AZ35: Task 5 | BA35: Task 6
AV36: 1 | AW36: =$Q$148 -> 0.93839639 | AX36: =$R$148 -> #DIV/0! | AY36: =$S$148 -> #DIV/0! | AZ36: =$T$148 -> #DIV/0! | BA36: =$U$148 -> #DIV/0!
J37: 0.98844568 | K37: =AVERAGE(K6:K35) -> 0.83977432 | L37: =AVERAGE(L6:L35) -> #DIV/0! | M37: =AVERAGE(M6:M35) -> #DIV/0! | N37: =AVERAGE(N6:N35) -> #DIV/0! | O37: =AVERAGE(O6:O35) -> #DIV/0! | Q37: =AVERAGE(Q6:Q35) -> 0.83116237 | R37: =AVERAGE(R6:R35) -> #DIV/0! | S37: =AVERAGE(S6:S35) -> #DIV/0! | T37: =AVERAGE(T6:T35) -> #DIV/0! | U37: =AVERAGE(U6:U35) -> #DIV/0! | V37: =AVERAGE(V6:V35) -> 0.8535087 | W37: =AVERAGE(W6:W35) -> #DIV/0! | X37: =AVERAGE(X6:X35) -> #DIV/0! | ... AT37: =AVERAGE(AT6:AT35) -> #DIV/0! | AV37: 2 | AW37: =$V$148 -> 0.92620604 | AX37: =$W$148 -> #DIV/0! | AY37: =$X$148 -> #DIV/0! | AZ37: =$Y$148 -> #DIV/0! | BA37: =$Z$148 -> #DIV/0!
AV38: 3 | AW38: =$AA$148 -> 0.88821364 | AX38: =$AB$148 -> #DIV/0! | AY38: =$AC$148 -> #DIV/0! | AZ38: =$AD$148 -> #DIV/0! | BA38: =$AE$148 -> #DIV/0!
AV39: 4 | AW39: =$AF$148 -> 0.83170658 | AX39: =$AG$148 -> #DIV/0! | AY39: =$AH$148 -> #DIV/0! | AZ39: =$AI$148 -> #DIV/0! | BA39: =$AJ$148 -> #DIV/0!
J40: k=0.5 | AV40: 5 | AW40: =$AK$148 -> 0.9226554 | AX40: =$AL$148 -> #DIV/0! | AY40: =$AM$148 -> #DIV/0! | AZ40: =$AN$148 -> #DIV/0! | BA40: =$AO$148 -> #DIV/0!
Q41: 1 | V41: 2 | AA41: 3 | AF41: 4 | AK41: 5 | AP41: 6 | AV41: 6 | AW41: =$AP$148 -> 0.92660805 | AX41: =$AQ$148 -> #DIV/0! | AY41: =$AR$148 -> #DIV/0! | AZ41: =$AS$148 -> #DIV/0! | BA41: =$AT$148 -> #DIV/0!
I42: ID | J42: Task 1 | K42: Task 2 | L42: Task 3 | M42: Task 4 | N42: Task 5 | O42: Task 6 | Q42: Task 2 | R42: Task 3 | S42: Task 4 | T42: Task 5 | U42: Task 6 | V42: Task 2 | W42: Task 3 | X42: Task 4 | Y42: Task 5 | Z42: Task 6 | AA42: Task 2 | AB42: Task 3 | AC42: Task 4 | AD42: Task 5 | AE42: Task 6 | AF42: Task 2 | AG42: Task 3 | AH42: Task 4 | AI42: Task 5 | AJ42: Task 6 | AK42: Task 2 | AL42: Task 3 | AM42: Task 4 | AN42: Task 5 | AO42: Task 6 | AP42: Task 2 | AQ42: Task 3 | AR42: Task 4 | AS42: Task 5 | AT42: Task 6
...

Sheet Statistics
H3: Person 1 | N3: Person 2 | T3: Person 3
G4: Task 1 | H4: Task 2 | I4: Task 3 | J4: Task 4 | K4: Task 5 | L4: Task 6 | M4: Task 1 | N4: Task 2 | O4: Task 3 | P4: Task 4 | Q4: Task 5 | R4: Task 6 | S4: Task 1 | T4: Task 2 | U4: Task 3 | V4: Task 4 | W4: Task 5 | X4: Task 6
F5: 0.25 | G5: =Person_0!B6 -> 0.96560007 | H5: =Person_0!C6 -> 0.78004217 | I5: =Person_0!D6 -> #DIV/0! | J5: =Person_0!E6 -> #DIV/0! | K5: =Person_0!F6 -> #DIV/0! | L5: =Person_0!G6 -> #DIV/0! | M5: =Person_1!B6 -> 0.93614896 | N5: =Person_1!C6 -> 0.6767195 | O5: =Person_1!D6 -> #DIV/0! | P5: =Person_1!E6 -> #DIV/0! | Q5: =Person_1!F6 -> #DIV/0! | R5: =Person_1!G6 -> #DIV/0! | S5: =Person_2!B6 -> 0.98800682 | T5: =Person_2!C6 -> 0.83977432 | U5: =Person_2!D6 -> #DIV/0! | V5: =Person_2!E6 -> #DIV/0! | W5: =Person_2!F6 -> #DIV/0! | X5: =Person_2!G6 -> #DIV/0!
F6: 0.5 | G6: =Person_0!B7 -> 0.96591873 | H6: =Person_0!C7 -> 0.80606715 | I6: =Person_0!D7 -> #DIV/0! | J6: =Person_0!E7 -> #DIV/0! | K6: =Person_0!F7 -> #DIV/0! | L6: =Person_0!G7 -> #DIV/0! | M6: =Person_1!B7 -> 0.93688897 | N6: =Person_1!C7 -> 0.70334452 | O6: =Person_1!D7 -> #DIV/0! | P6: =Person_1!E7 -> #DIV/0! | Q6: =Person_1!F7 -> #DIV/0! | R6: =Person_1!G7 -> #DIV/0! | S6: =Person_2!B7 -> 0.98811749 | T6: =Person_2!C7 -> 0.86032135 | U6: =Person_2!D7 -> #DIV/0! | V6: =Person_2!E7 -> #DIV/0! | W6: =Person_2!F7 -> #DIV/0! | X6: =Person_2!G7 -> #DIV/0!
F7: 1 | G7: =Person_0!B8 -> 0.96612148 | H7: =Person_0!C8 -> 0.78344584 | I7: =Person_0!D8 -> #DIV/0! | J7: =Person_0!E8 -> #DIV/0! | K7: =Person_0!F8 -> #DIV/0! | L7: =Person_0!G8 -> #DIV/0! | M7: =Person_1!B8 -> 0.93418296 | N7: =Person_1!C8 -> 0.70708711 | O7: =Person_1!D8 -> #DIV/0! | P7: =Person_1!E8 -> #DIV/0! | Q7: =Person_1!F8 -> #DIV/0! | R7: =Person_1!G8 -> #DIV/0! | S7: =Person_2!B8 -> 0.98817145 | T7: =Person_2!C8 -> 0.86103677 | U7: =Person_2!D8 -> #DIV/0! | V7: =Person_2!E8 -> #DIV/0! | W7: =Person_2!F8 -> #DIV/0! | X7: =Person_2!G8 -> #DIV/0!
F8: 2 | G8: =Person_0!B9 -> 0.96527543 | H8: =Person_0!C9 -> 0.83077919 | I8: =Person_0!D9 -> #DIV/0! | J8: =Person_0!E9 -> #DIV/0! | K8: =Person_0!F9 -> #DIV/0! | L8: =Person_0!G9 -> #DIV/0! | M8: =Person_1!B9 -> 0.93727722 | N8: =Person_1!C9 -> 0.72835621 | O8: =Person_1!D9 -> #DIV/0! | P8: =Person_1!E9 -> #DIV/0! | Q8: =Person_1!F9 -> #DIV/0! | R8: =Person_1!G9 -> #DIV/0! | S8: =Person_2!B9 -> 0.98784424 | T8: =Person_2!C9 -> 0.90563102 | U8: =Person_2!D9 -> #DIV/0! | V8: =Person_2!E9 -> #DIV/0! | W8: =Person_2!F9 -> #DIV/0! | X8: =Person_2!G9 -> #DIV/0!
F9: 3 | G9: =Person_0!B10 -> 0.96510655 | H9: =Person_0!C10 -> 0.83320577 | I9: =Person_0!D10 -> #DIV/0! | J9: =Person_0!E10 -> #DIV/0! | K9: =Person_0!F10 -> #DIV/0! | L9: =Person_0!G10 -> #DIV/0! | M9: =Person_1!B10 -> 0.9365298 | N9: =Person_1!C10 -> 0.73761423 | O9: =Person_1!D10 -> #DIV/0! | P9: =Person_1!E10 -> #DIV/0! | Q9: =Person_1!F10 -> #DIV/0! | R9: =Person_1!G10 -> #DIV/0! | S9: =Person_2!B10 -> 0.98797343 | T9: =Person_2!C10 -> 0.92763189 | U9: =Person_2!D10 -> #DIV/0! | V9: =Person_2!E10 -> #DIV/0! | W9: =Person_2!F10 -> #DIV/0! | X9: =Person_2!G10 -> #DIV/0!
