Workbook

Sheet Person_0
J3: k=0.25
Q4: 1 | V4: 2 | AA4: 3 | AF4: 4 | AK4: 5 | AP4: 6
A5: k | B5: Task 1 | C5: Task 2 | D5: Task 3 | E5: Task 4 | F5: Task 5 | G5: Task 6 | I5: ID | J5: Task 1 | K5: Task 2 | L5: Task 3 | M5: Task 4 | N5: Task 5 | O5: Task 6 | Q5: Task 2 | R5: Task 3 | S5: Task 4 | T5: Task 5 | U5: Task 6 | V5: Task 2 | W5: Task 3 | X5: Task 4 | Y5: Task 5 | Z5: Task 6 | AA5: Task 2 | AB5: Task 3 | AC5: Task 4 | AD5: Task 5 | AE5: Task 6 | AF5: Task 2 | AG5: Task 3 | AH5: Task 4 | AI5: Task 5 | AJ5: Task 6 | AK5: Task 2 | AL5: Task 3 | AM5: Task 4 | AN5: Task 5 | AO5: Task 6 | AP5: Task 2 | AQ5: Task 3 | AR5: Task 4 | AS5: Task 5 | AT5: Task 6 | AV5: =A6 -> 0.25 | AW5: Task 2 | AX5: Task 3 | AY5: Task 4 | AZ5: Task 5 | BA5: Task 6
A6: 0.25 | B6: =AVERAGE(J6:J35) -> 0.97771712 | C6: =AVERAGE(K6:K35) -> 0.82111599 | D6: =AVERAGE(L6:L35) -> 0.64512126 | E6: =AVERAGE(M6:M35) -> #DIV/0! | F6: =AVERAGE(N6:N35) -> #DIV/0! | G6: =AVERAGE(O6:O35) -> #DIV/0! | J6: 0.96494845 | K6: =AVERAGE(Q6,V6,AA6,AF6,AK6,AP6) -> 0.83195876 | L6: =AVERAGE(R6,W6,AB6,AG6,AL6,AQ6) -> 0.48731466 | M6: =AVERAGE(S6,X6,AC6,AH6,AM6,AR6) -> #DIV/0! | N6: =AVERAGE(T6,Y6,AD6,AI6,AN6,AS6) -> #DIV/0! | O6: =AVERAGE(U6,Z6,AE6,AJ6,AO6,AT6) -> #DIV/0! | Q6: 0.82474227 | R6: 0.53706755 | V6: 0.83505155 | W6: 0.58484349 | AA6: 0.91494845 | AB6: 0.50576606 | AF6: 0.79896907 | AG6: 0.45963756 | AK6: 0.78608247 | AL6: 0.34925865 | AV6: 1 | AW6: =$Q$37 -> 0.81789744 | AX6: =$R$37 -> 0.64662221 | AY6: =$S$37 -> #DIV/0! | AZ6: =$T$37 -> #DIV/0! | BA6: =$U$37 -> #DIV/0!
A7: 0.5 | B7: =AVERAGE(J43:J72) -> 0.97733109 | C7: =AVERAGE(K43:K72) -> 0.8352316 | D7: =AVERAGE(L43:L72) -> 0.67190365 | E7: =AVERAGE(M43:M72) -> #DIV/0! | F7: =AVERAGE(N43:N72) -> #DIV/0! | G7: =AVERAGE(O43:O72) -> #DIV/0! | J7: 0.97702703 | K7: =AVERAGE(Q7,V7,AA7,AF7,AK7,AP7) -> 0.80810811 | L7: =AVERAGE(R7,W7,AB7,AG7,AL7,AQ7) -> 0.59269103 | M7: =AVERAGE(S7,X7,AC7,AH7,AM7,AR7) -> #DIV/0! | N7: =AVERAGE(T7,Y7,AD7,AI7,AN7,AS7) -> #DIV/0! | O7: =AVERAGE(U7,Z7,AE7,AJ7,AO7,AT7) -> #DIV/0! | Q7: 0.83108108 | R7: 0.58637874 | V7: 0.86486486 | W7: 0.52657807 | AA7: 0.82432432 | AB7: 0.60299003 | AF7: 0.64864865 | AG7: 0.61461794 | AK7: 0.87162162 | AL7: 0.63289037 | AV7: 2 | AW7: =$V$37 -> 0.82420435 | AX7: =$W$37 -> 0.65021874 | AY7: =$X$37 -> #DIV/0! | AZ7: =$Y$37 -> #DIV/0! | BA7: =$Z$37 -> #DIV/0!
A8: 1 | B8: =AVERAGE(J80:J109) -> 0.97661224 | C8: =AVERAGE(K80:K109) -> 0.85786553 | D8: =AVERAGE(L80:L109) -> 0.67638602 | E8: =AVERAGE(M80:M109) -> #DIV/0! | F8: =AVERAGE(N80:N109) -> #DIV/0! | G8: =AVERAGE(O80:O109) -> #DIV/0! | J8: 0.994375 | K8: =AVERAGE(Q8,V8,AA8,AF8,AK8,AP8) -> 0.89875 | L8: =AVERAGE(R8,W8,AB8,AG8,AL8,AQ8) -> 0.72996633 | M8: =AVERAGE(S8,X8,AC8,AH8,AM8,AR8) -> #DIV/0! | N8: =AVERAGE(T8,Y8,AD8,AI8,AN8,AS8) -> #DIV/0! | O8: =AVERAGE(U8,Z8,AE8,AJ8,AO8,AT8) -> #DIV/0! | Q8: 0.8875 | R8: 0.74242424 | V8: 0.91875 | W8: 0.68518519 | AA8: 0.85625 | AB8: 0.72895623 | AF8: 0.871875 | AG8: 0.75252525 | AK8: 0.959375 | AL8: 0.74074074 | AV8: 3 | AW8: =$AA$37 -> 0.82747399 | AX8: =$AB$37 -> 0.6341166 | AY8: =$AC$37 -> #DIV/0! | AZ8: =$AD$37 -> #DIV/0! | BA8: =$AE$37 -> #DIV/0!
A9: 2 | B9: =AVERAGE(J117:J146) -> 0.97792353 | C9: =AVERAGE(K117:K146) -> 0.85223348 | D9: =AVERAGE(L117:L146) -> 0.67936394 | E9: =AVERAGE(M117:M146) -> #DIV/0! | F9: =AVERAGE(N117:N146) -> #DIV/0! | G9: =AVERAGE(O117:O146) -> #DIV/0! | J9: 0.99705882 | K9: =AVERAGE(Q9,V9,AA9,AF9,AK9,AP9) -> 0.93431373 | L9: =AVERAGE(R9,W9,AB9,AG9,AL9,AQ9) -> 0.68506616 | M9: =AVERAGE(S9,X9,AC9,AH9,AM9,AR9) -> #DIV/0! | N9: =AVERAGE(T9,Y9,AD9,AI9,AN9,AS9) -> #DIV/0! | O9: =AVERAGE(U9,Z9,AE9,AJ9,AO9,AT9) -> #DIV/0! | Q9: 0.94117647 | R9: 0.80151229 | V9: 0.80882353 | W9: 0.56521739 | AA9: 0.97058824 | AB9: 0.35349716 | AF9: 0.98529412 | AG9: 0.82797732 | AK9: 0.96568627 | AL9: 0.87712665 | AV9: 4 | AW9: =$AF$37 -> 0.814566 | AX9: =$AG$37 -> 0.64214174 | AY9: =$AH$37 -> #DIV/0! | AZ9: =$AI$37 -> #DIV/0! | BA9: =$AJ$37 -> #DIV/0!
A10: 3 | B10: =AVERAGE(J154:J183) -> 0.97710003 | C10: =AVERAGE(K154:K183) -> 0.85932622 | D10: =AVERAGE(L154:L183) -> 0.64845604 | E10: =AVERAGE(M154:M183) -> #DIV/0! | F10: =AVERAGE(N154:N183) -> #DIV/0! | G10: =AVERAGE(O154:O183) -> #DIV/0! | J10: 0.97087379 | K10: =AVERAGE(Q10,V10,AA10,AF10,AK10,AP10) -> 0.83592233 | L10: =AVERAGE(R10,W10,AB10,AG10,AL10,AQ10) -> 0.69792844 | M10: =AVERAGE(S10,X10,AC10,AH10,AM10,AR10) -> #DIV/0! | N10: =AVERAGE(T10,Y10,AD10,AI10,AN10,AS10) -> #DIV/0! | O10: =AVERAGE(U10,Z10,AE10,AJ10,AO10,AT10) -> #DIV/0! | Q10: 0.81553398 | R10: 0.70998117 | V10: 0.82524272 | W10: 0.7212806 | AA10: 0.82038835 | AB10: 0.61581921 | AF10: 0.80582524 | AG10: 0.68173258 | AK10: 0.91262136 | AL10: 0.76082863 | AV10: 5 | AW10: =$AK$37 -> 0.82143818 | AX10: =$AL$37 -> 0.652507 | AY10: =$AM$37 -> #DIV/0! | AZ10: =$AN$37 -> #DIV/0! | BA10: =$AO$37 -> #DIV/0!
J11: 0.98364312 | K11: =AVERAGE(Q11,V11,AA11,AF11,AK11,AP11) -> 0.77918216 | L11: =AVERAGE(R11,W11,AB11,AG11,AL11,AQ11) -> 0.54309764 | M11: =AVERAGE(S11,X11,AC11,AH11,AM11,AR11) -> #DIV/0! | N11: =AVERAGE(T11,Y11,AD11,AI11,AN11,AS11) -> #DIV/0! | O11: =AVERAGE(U11,Z11,AE11,AJ11,AO11,AT11) -> #DIV/0! | Q11: 0.77695167 | R11: 0.51178451 | V11: 0.84386617 | W11: 0.71885522 | AA11: 0.64312268 | AB11: 0.61279461 | AF11: 0.82899628 | AG11: 0.43097643 | AK11: 0.80297398 | AL11: 0.44107744 | AV11: 6 | AW11: =$AP$37 -> #DIV/0! | AX11: =$AQ$37 -> #DIV/0! | AY11: =$AR$37 -> #DIV/0! | AZ11: =$AS$37 -> #DIV/0! | BA11: =$AT$37 -> #DIV/0!
J12: 0.98317152 | K12: =AVERAGE(Q12,V12,AA12,AF12,AK12,AP12) -> 0.83495146 | L12: =AVERAGE(R12,W12,AB12,AG12,AL12,AQ12) -> 0.63456311 | M12: =AVERAGE(S12,X12,AC12,AH12,AM12,AR12) -> #DIV/0! | N12: =AVERAGE(T12,Y12,AD12,AI12,AN12,AS12) -> #DIV/0! | O12: =AVERAGE(U12,Z12,AE12,AJ12,AO12,AT12) -> #DIV/0! | Q12: 0.8381877 | R12: 0.54174757 | V12: 0.83495146 | W12: 0.79029126 | AA12: 0.80906149 | AB12: 0.64854369 | AF12: 0.82200647 | AG12: 0.63495146 | AK12: 0.87055016 | AL12: 0.55728155
J13: 0.96502732 | K13: =AVERAGE(Q13,V13,AA13,AF13,AK13,AP13) -> 0.7431694 | L13: =AVERAGE(R13,W13,AB13,AG13,AL13,AQ13) -> 0.58118669 | M13: =AVERAGE(S13,X13,AC13,AH13,AM13,AR13) -> #DIV/0! | N13: =AVERAGE(T13,Y13,AD13,AI13,AN13,AS13) -> #DIV/0! | O13: =AVERAGE(U13,Z13,AE13,AJ13,AO13,AT13) -> #DIV/0! | Q13: 0.80601093 | R13: 0.4602026 | V13: 0.64754098 | W13: 0.58755427 | AA13: 0.79781421 | AB13: 0.61505065 | AF13: 0.73497268 | AG13: 0.5658466 | AK13: 0.7295082 | AL13: 0.67727931
J14: 0.96099291 | K14: =AVERAGE(Q14,V14,AA14,AF14,AK14,AP14) -> 0.6141844 | L14: =AVERAGE(R14,W14,AB14,AG14,AL14,AQ14) -> 0.65619835 | M14: =AVERAGE(S14,X14,AC14,AH14,AM14,AR14) -> #DIV/0! | N14: =AVERAGE(T14,Y14,AD14,AI14,AN14,AS14) -> #DIV/0! | O14: =AVERAGE(U14,Z14,AE14,AJ14,AO14,AT14) -> #DIV/0! | Q14: 0.56382979 | R14: 0.65619835 | V14: 0.60992908 | W14: 0.63636364 | AA14: 0.70921986 | AB14: 0.6677686 | AF14: 0.64184397 | AG14: 0.70413223 | AK14: 0.54609929 | AL14: 0.61652893
J15: 0.97702703 | K15: =AVERAGE(Q15,V15,AA15,AF15,AK15,AP15) -> 0.77297297 | L15: =AVERAGE(R15,W15,AB15,AG15,AL15,AQ15) -> 0.55492487 | M15: =AVERAGE(S15,X15,AC15,AH15,AM15,AR15) -> #DIV/0! | N15: =AVERAGE(T15,Y15,AD15,AI15,AN15,AS15) -> #DIV/0! | O15: =AVERAGE(U15,Z15,AE15,AJ15,AO15,AT15) -> #DIV/0! | Q15: 0.75675676 | R15: 0.49248748 | V15: 0.78378378 | W15: 0.6293823 | AA15: 0.74324324 | AB15: 0.48580968 | AF15: 0.73310811 | AG15: 0.65609349 | AK15: 0.84797297 | AL15: 0.51085142 | AV15: =A7 -> 0.5 | AW15: Task 2 | AX15: Task 3 | AY15: Task 4 | AZ15: Task 5 | BA15: Task 6
J16: 0.95846995 | K16: =AVERAGE(Q16,V16,AA16,AF16,AK16,AP16) -> 0.71967213 | L16: =AVERAGE(R16,W16,AB16,AG16,AL16,AQ16) -> 0.52137931 | M16: =AVERAGE(S16,X16,AC16,AH16,AM16,AR16) -> #DIV/0! | N16: =AVERAGE(T16,Y16,AD16,AI16,AN16,AS16) -> #DIV/0! | O16: =AVERAGE(U16,Z16,AE16,AJ16,AO16,AT16) -> #DIV/0! | Q16: 0.73224044 | R16: 0.50862069 | V16: 0.82786885 | W16: 0.46206897 | AA16: 0.6010929 | AB16: 0.5862069 | AF16: 0.72677596 | AG16: 0.59827586 | AK16: 0.71038251 | AL16: 0.45172414 | AV16: 1 | AW16: =$Q$74 -> 0.81890592 | AX16: =$R$74 -> 0.64775623 | AY16: =$S$74 -> #DIV/0! | AZ16: =$T$74 -> #DIV/0! | BA16: =$U$74 -> #DIV/0!
J17: 0.96786704 | K17: =AVERAGE(Q17,V17,AA17,AF17,AK17,AP17) -> 0.78614958 | L17: =AVERAGE(R17,W17,AB17,AG17,AL17,AQ17) -> 0.54561404 | M17: =AVERAGE(S17,X17,AC17,AH17,AM17,AR17) -> #DIV/0! | N17: =AVERAGE(T17,Y17,AD17,AI17,AN17,AS17) -> #DIV/0! | O17: =AVERAGE(U17,Z17,AE17,AJ17,AO17,AT17) -> #DIV/0! | Q17: 0.80055402 | R17: 0.53508772 | V17: 0.81440443 | W17: 0.48070175 | AA17: 0.85595568 | AB17: 0.59298246 | AF17: 0.7700831 | AG17: 0.31403509 | AK17: 0.68975069 | AL17: 0.80526316 | AV17: 2 | AW17: =$V$74 -> 0.83503853 | AX17: =$W$74 -> 0.67022441 | AY17: =$X$74 -> #DIV/0! | AZ17: =$Y$74 -> #DIV/0! | BA17: =$Z$74 -> #DIV/0!
J18: 0.98823529 | K18: =AVERAGE(Q18,V18,AA18,AF18,AK18,AP18) -> 0.80980392 | L18: =AVERAGE(R18,W18,AB18,AG18,AL18,AQ18) -> 0.71982507 | M18: =AVERAGE(S18,X18,AC18,AH18,AM18,AR18) -> #DIV/0! | N18: =AVERAGE(T18,Y18,AD18,AI18,AN18,AS18) -> #DIV/0! | O18: =AVERAGE(U18,Z18,AE18,AJ18,AO18,AT18) -> #DIV/0! | Q18: 0.73529412 | R18: 0.69825073 | V18: 0.83986928 | W18: 0.75218659 | AA18: 0.81045752 | AB18: 0.59475219 | AF18: 0.7745098 | AG18: 0.7244898 | AK18: 0.88888889 | AL18: 0.82944606 | AV18: 3 | AW18: =$AA$74 -> 0.84046073 | AX18: =$AB$74 -> 0.68847356 | AY18: =$AC$74 -> #DIV/0! | AZ18: =$AD$74 -> #DIV/0! | BA18: =$AE$74 -> #DIV/0!
J19: 0.98216561 | K19: =AVERAGE(Q19,V19,AA19,AF19,AK19,AP19) -> 0.85541401 | L19: =AVERAGE(R19,W19,AB19,AG19,AL19,AQ19) -> 0.81361059 | M19: =AVERAGE(S19,X19,AC19,AH19,AM19,AR19) -> #DIV/0! | N19: =AVERAGE(T19,Y19,AD19,AI19,AN19,AS19) -> #DIV/0! | O19: =AVERAGE(U19,Z19,AE19,AJ19,AO19,AT19) -> #DIV/0! | Q19: 0.9044586 | R19: 0.86389414 | V19: 0.77707006 | W19: 0.71833648 | AA19: 0.92356688 | AB19: 0.80907372 | AF19: 0.85350318 | AG19: 0.82230624 | AK19: 0.81847134 | AL19: 0.85444234 | AV19: 4 | AW19: =$AF$74 -> 0.84180901 | AX19: =$AG$74 -> 0.66964356 | AY19: =$AH$74 -> #DIV/0! | AZ19: =$AI$74 -> #DIV/0! | BA19: =$AJ$74 -> #DIV/0!
J20: 0.98976744 | K20: =AVERAGE(Q20,V20,AA20,AF20,AK20,AP20) -> 0.89953488 | L20: =AVERAGE(R20,W20,AB20,AG20,AL20,AQ20) -> 0.81959459 | M20: =AVERAGE(S20,X20,AC20,AH20,AM20,AR20) -> #DIV/0! | N20: =AVERAGE(T20,Y20,AD20,AI20,AN20,AS20) -> #DIV/0! | O20: =AVERAGE(U20,Z20,AE20,AJ20,AO20,AT20) -> #DIV/0! | Q20: 0.94418605 | R20: 0.83783784 | V20: 0.89302326 | W20: 0.83783784 | AA20: 0.8744186 | AB20: 0.875 | AF20: 0.8372093 | AG20: 0.85304054 | AK20: 0.94883721 | AL20: 0.69425676 | AV20: 5 | AW20: =$AK$74 -> 0.83994384 | AX20: =$AL$74 -> 0.68342046 | AY20: =$AM$74 -> #DIV/0! | AZ20: =$AN$74 -> #DIV/0! | BA20: =$AO$74 -> #DIV/0!
J21: 0.96701571 | K21: =AVERAGE(Q21,V21,AA21,AF21,AK21,AP21) -> 0.7973822 | L21: =AVERAGE(R21,W21,AB21,AG21,AL21,AQ21) -> 0.42727273 | M21: =AVERAGE(S21,X21,AC21,AH21,AM21,AR21) -> #DIV/0! | N21: =AVERAGE(T21,Y21,AD21,AI21,AN21,AS21) -> #DIV/0! | O21: =AVERAGE(U21,Z21,AE21,AJ21,AO21,AT21) -> #DIV/0! | Q21: 0.84554974 | R21: 0.41077441 | V21: 0.72774869 | W21: 0.45117845 | AA21: 0.79057592 | AB21: 0.42255892 | AF21: 0.85602094 | AG21: 0.45286195 | AK21: 0.76701571 | AL21: 0.3989899 | AV21: 6 | AW21: =$AP$74 -> #DIV/0! | AX21: =$AQ$74 -> #DIV/0! | AY21: =$AR$74 -> #DIV/0! | AZ21: =$AS$74 -> #DIV/0! | BA21: =$AT$74 -> #DIV/0!
J22: 0.97355372 | K22: =AVERAGE(Q22,V22,AA22,AF22,AK22,AP22) -> 0.71460055 | L22: =AVERAGE(R22,W22,AB22,AG22,AL22,AQ22) -> 0.56468531 | M22: =AVERAGE(S22,X22,AC22,AH22,AM22,AR22) -> #DIV/0! | N22: =AVERAGE(T22,Y22,AD22,AI22,AN22,AS22) -> #DIV/0! | O22: =AVERAGE(U22,Z22,AE22,AJ22,AO22,AT22) -> #DIV/0! | Q22: 0.68870523 | R22: 0.52272727 | V22: 0.67217631 | W22: 0.66083916 | AA22: 0.76033058 | AB22: 0.53321678 | AF22: 0.71349862 | AG22: 0.58216783 | AK22: 0.73829201 | AL22: 0.52447552
J23: 0.97408451 | K23: =AVERAGE(Q23,V23,AA23,AF23,AK23,AP23) -> 0.78760563 | L23: =AVERAGE(R23,W23,AB23,AG23,AL23,AQ23) -> 0.54307229 | M23: =AVERAGE(S23,X23,AC23,AH23,AM23,AR23) -> #DIV/0! | N23: =AVERAGE(T23,Y23,AD23,AI23,AN23,AS23) -> #DIV/0! | O23: =AVERAGE(U23,Z23,AE23,AJ23,AO23,AT23) -> #DIV/0! | Q23: 0.78309859 | R23: 0.68674699 | V23: 0.83380282 | W23: 0.42771084 | AA23: 0.78028169 | AB23: 0.60240964 | AF23: 0.82816901 | AG23: 0.49849398 | AK23: 0.71267606 | AL23: 0.5
J24: 0.99459459 | K24: =AVERAGE(Q24,V24,AA24,AF24,AK24,AP24) -> 0.91756757 | L24: =AVERAGE(R24,W24,AB24,AG24,AL24,AQ24) -> 0.83389199 | M24: =AVERAGE(S24,X24,AC24,AH24,AM24,AR24) -> #DIV/0! | N24: =AVERAGE(T24,Y24,AD24,AI24,AN24,AS24) -> #DIV/0! | O24: =AVERAGE(U24,Z24,AE24,AJ24,AO24,AT24) -> #DIV/0! | Q24: 0.85135135 | R24: 0.75418994 | V24: 0.92567568 | W24: 0.87523277 | AA24: 0.91554054 | AB24: 0.76536313 | AF24: 0.93243243 | AG24: 0.89571695 | AK24: 0.96283784 | AL24: 0.87895717
J25: 0.97961783 | K25: =AVERAGE(Q25,V25,AA25,AF25,AK25,AP25) -> 0.90318471 | L25: =AVERAGE(R25,W25,AB25,AG25,AL25,AQ25) -> 0.67449664 | M25: =AVERAGE(S25,X25,AC25,AH25,AM25,AR25) -> #DIV/0! | N25: =AVERAGE(T25,Y25,AD25,AI25,AN25,AS25) -> #DIV/0! | O25: =AVERAGE(U25,Z25,AE25,AJ25,AO25,AT25) -> #DIV/0! | Q25: 0.88853503 | R25: 0.79697987 | V25: 0.91401274 | W25: 0.59563758 | AA25: 0.89808917 | AB25: 0.68791946 | AF25: 0.89171975 | AG25: 0.48154362 | AK25: 0.92356688 | AL25: 0.81040268 | AV25: =A8 -> 1 | AW25: Task 2 | AX25: Task 3 | AY25: Task 4 | AZ25: Task 5 | BA25: Task 6
J26: 0.98894009 | K26: =AVERAGE(Q26,V26,AA26,AF26,AK26,AP26) -> 0.75483871 | L26: =AVERAGE(R26,W26,AB26,AG26,AL26,AQ26) -> 0.72513966 | M26: =AVERAGE(S26,X26,AC26,AH26,AM26,AR26) -> #DIV/0! | N26: =AVERAGE(T26,Y26,AD26,AI26,AN26,AS26) -> #DIV/0! | O26: =AVERAGE(U26,Z26,AE26,AJ26,AO26,AT26) -> #DIV/0! | Q26: 0.65437788 | R26: 0.76163873 | V26: 0.84331797 | W26: 0.76536313 | AA26: 0.83410138 | AB26: 0.67970205 | AF26: 0.75115207 | AG26: 0.63500931 | AK26: 0.69124424 | AL26: 0.7839851 | AV26: 1 | AW26: =$Q$111 -> 0.8553969 | AX26: =$R$111 -> 0.67514764 | AY26: =$S$111 -> #DIV/0! | AZ26: =$T$111 -> #DIV/0! | BA26: =$U$111 -> #DIV/0!
J27: 0.96569343 | K27: =AVERAGE(Q27,V27,AA27,AF27,AK27,AP27) -> 0.78686131 | L27: =AVERAGE(R27,W27,AB27,AG27,AL27,AQ27) -> 0.60140351 | M27: =AVERAGE(S27,X27,AC27,AH27,AM27,AR27) -> #DIV/0! | N27: =AVERAGE(T27,Y27,AD27,AI27,AN27,AS27) -> #DIV/0! | O27: =AVERAGE(U27,Z27,AE27,AJ27,AO27,AT27) -> #DIV/0! | Q27: 0.85036496 | R27: 0.61578947 | V27: 0.77372263 | W27: 0.58245614 | AA27: 0.75547445 | AB27: 0.53859649 | AF27: 0.8649635 | AG27: 0.71578947 | AK27: 0.68978102 | AL27: 0.55438596 | AV27: 2 | AW27: =$V$111 -> 0.85482717 | AX27: =$W$111 -> 0.66939174 | AY27: =$X$111 -> #DIV/0! | AZ27: =$Y$111 -> #DIV/0! | BA27: =$Z$111 -> #DIV/0!
J28: 0.96649215 | K28: =AVERAGE(Q28,V28,AA28,AF28,AK28,AP28) -> 0.7539267 | L28: =AVERAGE(R28,W28,AB28,AG28,AL28,AQ28) -> 0.48105437 | M28: =AVERAGE(S28,X28,AC28,AH28,AM28,AR28) -> #DIV/0! | N28: =AVERAGE(T28,Y28,AD28,AI28,AN28,AS28) -> #DIV/0! | O28: =AVERAGE(U28,Z28,AE28,AJ28,AO28,AT28) -> #DIV/0! | Q28: 0.81675393 | R28: 0.47775947 | V28: 0.79581152 | W28: 0.55189456 | AA28: 0.80628272 | AB28: 0.45469522 | AF28: 0.70157068 | AG28: 0.50411862 | AK28: 0.64921466 | AL28: 0.41680395 | AV28: 3 | AW28: =$AA$111 -> 0.86402296 | AX28: =$AB$111 -> 0.69429383 | AY28: =$AC$111 -> #DIV/0! | AZ28: =$AD$111 -> #DIV/0! | BA28: =$AE$111 -> #DIV/0!
J29: 0.99509804 | K29: =AVERAGE(Q29,V29,AA29,AF29,AK29,AP29) -> 0.94019608 | L29: =AVERAGE(R29,W29,AB29,AG29,AL29,AQ29) -> 0.69191919 | M29: =AVERAGE(S29,X29,AC29,AH29,AM29,AR29) -> #DIV/0! | N29: =AVERAGE(T29,Y29,AD29,AI29,AN29,AS29) -> #DIV/0! | O29: =AVERAGE(U29,Z29,AE29,AJ29,AO29,AT29) -> #DIV/0! | Q29: 0.96568627 | R29: 0.74242424 | V29: 0.94117647 | W29: 0.65656566 | AA29: 0.93137255 | AB29: 0.69023569 | AF29: 0.92156863 | AG29: 0.63973064 | AK29: 0.94117647 | AL29: 0.73063973 | AV29: 4 | AW29: =$AF$111 -> 0.85998694 | AX29: =$AG$111 -> 0.68140017 | AY29: =$AH$111 -> #DIV/0! | AZ29: =$AI$111 -> #DIV/0! | BA29: =$AJ$111 -> #DIV/0!
J30: 0.99255814 | K30: =AVERAGE(Q30,V30,AA30,AF30,AK30,AP30) -> 0.93674419 | L30: =AVERAGE(R30,W30,AB30,AG30,AL30,AQ30) -> 0.86405959 | M30: =AVERAGE(S30,X30,AC30,AH30,AM30,AR30) -> #DIV/0! | N30: =AVERAGE(T30,Y30,AD30,AI30,AN30,AS30) -> #DIV/0! | O30: =AVERAGE(U30,Z30,AE30,AJ30,AO30,AT30) -> #DIV/0! | Q30: 0.8744186 | R30: 0.81191806 | V30: 0.97674419 | W30: 0.85288641 | AA30: 0.9627907 | AB30: 0.88081937 | AF30: 0.94418605 | AG30: 0.88268156 | AK30: 0.9255814 | AL30: 0.89199255 | AV30: 5 | AW30: =$AK$111 -> 0.85509367 | AX30: =$AL$111 -> 0.66169672 | AY30: =$AM$111 -> #DIV/0! | AZ30: =$AN$111 -> #DIV/0! | BA30: =$AO$111 -> #DIV/0!
J31: 0.97431193 | K31: =AVERAGE(Q31,V31,AA31,AF31,AK31,AP31) -> 0.87278287 | L31: =AVERAGE(R31,W31,AB31,AG31,AL31,AQ31) -> 0.71352254 | M31: =AVERAGE(S31,X31,AC31,AH31,AM31,AR31) -> #DIV/0! | N31: =AVERAGE(T31,Y31,AD31,AI31,AN31,AS31) -> #DIV/0! | O31: =AVERAGE(U31,Z31,AE31,AJ31,AO31,AT31) -> #DIV/0! | Q31: 0.86544343 | R31: 0.68948247 | V31: 0.79510703 | W31: 0.68280467 | AA31: 0.87767584 | AB31: 0.72621035 | AF31: 0.90825688 | AG31: 0.76627713 | AK31: 0.91743119 | AL31: 0.70283806 | AV31: 6 | AW31: =$AP$111 -> #DIV/0! | AX31: =$AQ$111 -> #DIV/0! | AY31: =$AR$111 -> #DIV/0! | AZ31: =$AS$111 -> #DIV/0! | BA31: =$AT$111 -> #DIV/0!
J32: 0.97087379 | K32: =AVERAGE(Q32,V32,AA32,AF32,AK32,AP32) -> 0.87087379 | L32: =AVERAGE(R32,W32,AB32,AG32,AL32,AQ32) -> 0.71208054 | M32: =AVERAGE(S32,X32,AC32,AH32,AM32,AR32) -> #DIV/0! | N32: =AVERAGE(T32,Y32,AD32,AI32,AN32,AS32) -> #DIV/0! | O32: =AVERAGE(U32,Z32,AE32,AJ32,AO32,AT32) -> #DIV/0! | Q32: 0.84466019 | R32: 0.69966443 | V32: 0.91262136 | W32: 0.69798658 | AA32: 0.87864078 | AB32: 0.77013423 | AF32: 0.89805825 | AG32: 0.77684564 | AK32: 0.82038835 | AL32: 0.61577181
J33: 0.97432432 | K33: =AVERAGE(Q33,V33,AA33,AF33,AK33,AP33) -> 0.73716216 | L33: =AVERAGE(R33,W33,AB33,AG33,AL33,AQ33) -> 0.6597973 | M33: =AVERAGE(S33,X33,AC33,AH33,AM33,AR33) -> #DIV/0! | N33: =AVERAGE(T33,Y33,AD33,AI33,AN33,AS33) -> #DIV/0! | O33: =AVERAGE(U33,Z33,AE33,AJ33,AO33,AT33) -> #DIV/0! | Q33: 0.71621622 | R33: 0.57094595 | V33: 0.73986486 | W33: 0.65371622 | AA33: 0.75337838 | AB33: 0.64527027 | AF33: 0.66891892 | AG33: 0.72128378 | AK33: 0.80743243 | AL33: 0.70777027
J34: 0.95956284 | K34: =AVERAGE(Q34,V34,AA34,AF34,AK34,AP34) -> 0.82185792 | L34: =AVERAGE(R34,W34,AB34,AG34,AL34,AQ34) -> 0.60120482 | M34: =AVERAGE(S34,X34,AC34,AH34,AM34,AR34) -> #DIV/0! | N34: =AVERAGE(T34,Y34,AD34,AI34,AN34,AS34) -> #DIV/0! | O34: =AVERAGE(U34,Z34,AE34,AJ34,AO34,AT34) -> #DIV/0! | Q34: 0.81693989 | R34: 0.57680723 | V34: 0.84972678 | W34: 0.67620482 | AA34: 0.80054645 | AB34: 0.65361446 | AF34: 0.78142077 | AG34: 0.56777108 | AK34: 0.86065574 | AL34: 0.53162651
J35: 0.99414226 | K35: =AVERAGE(Q35,V35,AA35,AF35,AK35,AP35) -> 0.91380753 | L35: =AVERAGE(R35,W35,AB35,AG35,AL35,AQ35) -> 0.67707641 | M35: =AVERAGE(S35,X35,AC35,AH35,AM35,AR35) -> #DIV/0! | N35: =AVERAGE(T35,Y35,AD35,AI35,AN35,AS35) -> #DIV/0! | O35: =AVERAGE(U35,Z35,AE35,AJ35,AO35,AT35) -> #DIV/0! | Q35: 0.91631799 | R35: 0.79734219 | V35: 0.89958159 | W35: 0.67940199 | AA35: 0.92468619 | AB35: 0.67774086 | AF35: 0.94142259 | AG35: 0.50332226 | AK35: 0.88702929 | AL35: 0.72757475 | AV35: =A9 -> 2 | AW35: Task 2 | AX35: Task 3 | AY35: Task 4 | AZ35: Task 5 | BA35: Task 6
AV36: 1 | AW36: =$Q$148 -> 0.85884987 | AX36: =$R$148 -> 0.66689231 | AY36: =$S$148 -> #DIV/0! | AZ36: =$T$148 -> #DIV/0! | BA36: =$U$148 -> #DIV/0!
J37: 0.98844568 | K37: =AVERAGE(K6:K35) -> 0.82111599 | L37: =AVERAGE(L6:L35) -> 0.64512126 | M37: =AVERAGE(M6:M35) -> #DIV/0! | N37: =AVERAGE(N6:N35) -> #DIV/0! | O37: =AVERAGE(O6:O35) -> #DIV/0! | Q37: =AVERAGE(Q6:Q35) -> 0.81789744 | R37: =AVERAGE(R6:R35) -> 0.64662221 | S37: =AVERAGE(S6:S35) -> #DIV/0! | T37: =AVERAGE(T6:T35) -> #DIV/0! | U37: =AVERAGE(U6:U35) -> #DIV/0! | V37: =AVERAGE(V6:V35) -> 0.82420435 | W37: =AVERAGE(W6:W35) -> 0.65021874 | X37: =AVERAGE(X6:X35) -> #DIV/0! | ... AT37: =AVERAGE(AT6:AT35) -> #DIV/0! | AV37: 2 | AW37: =$V$148 -> 0.85194689 | AX37: =$W$148 -> 0.69510322 | AY37: =$X$148 -> #DIV/0! | AZ37: =$Y$148 -> #DIV/0! | BA37: =$Z$148 -> #DIV/0!
AV38: 3 | AW38: =$AA$148 -> 0.84466991 | AX38: =$AB$148 -> 0.68407483 | AY38: =$AC$148 -> #DIV/0! | AZ38: =$AD$148 -> #DIV/0! | BA38: =$AE$148 -> #DIV/0!
AV39: 4 | AW39: =$AF$148 -> 0.85358583 | AX39: =$AG$148 -> 0.66570165 | AY39: =$AH$148 -> #DIV/0! | AZ39: =$AI$148 -> #DIV/0! | BA39: =$AJ$148 -> #DIV/0!
J40: k=0.5 | AV40: 5 | AW40: =$AK$148 -> 0.85211491 | AX40: =$AL$148 -> 0.68504768 | AY40: =$AM$148 -> #DIV/0! | AZ40: =$AN$148 -> #DIV/0! | BA40: =$AO$148 -> #DIV/0!
Q41: 1 | V41: 2 | AA41: 3 | AF41: 4 | AK41: 5 | AP41: 6 | AV41: 6 | AW41: =$AP$148 -> #DIV/0! | AX41: =$AQ$148 -> #DIV/0! | AY41: =$AR$148 -> #DIV/0! | AZ41: =$AS$148 -> #DIV/0! | BA41: =$AT$148 -> #DIV/0!
I42: ID | J42: Task 1 | K42: Task 2 | L42: Task 3 | M42: Task 4 | N42: Task 5 | O42: Task 6 | Q42: Task 2 | R42: Task 3 | S42: Task 4 | T42: Task 5 | U42: Task 6 | V42: Task 2 | W42: Task 3 | X42: Task 4 | Y42: Task 5 | Z42: Task 6 | AA42: Task 2 | AB42: Task 3 | AC42: Task 4 | AD42: Task 5 | AE42: Task 6 | AF42: Task 2 | AG42: Task 3 | AH42: Task 4 | AI42: Task 5 | AJ42: Task 6 | AK42: Task 2 | AL42: Task 3 | AM42: Task 4 | AN42: Task 5 | AO42: Task 6 | AP42: Task 2 | AQ42: Task 3 | AR42: Task 4 | AS42: Task 5 | AT42: Task 6
...

Sheet Person_1
J3: k=0.25
Q4: 1 | V4: 2 | AA4: 3 | AF4: 4 | AK4: 5 | AP4: 6
A5: k | B5: Task 1 | C5: Task 2 | D5: Task 3 | E5: Task 4 | F5: Task 5 | G5: Task 6 | I5: ID | J5: Task 1 | K5: Task 2 | L5: Task 3 | M5: Task 4 | N5: Task 5 | O5: Task 6 | Q5: Task 2 | R5: Task 3 | S5: Task 4 | T5: Task 5 | U5: Task 6 | V5: Task 2 | W5: Task 3 | X5: Task 4 | Y5: Task 5 | Z5: Task 6 | AA5: Task 2 | AB5: Task 3 | AC5: Task 4 | AD5: Task 5 | AE5: Task 6 | AF5: Task 2 | AG5: Task 3 | AH5: Task 4 | AI5: Task 5 | AJ5: Task 6 | AK5: Task 2 | AL5: Task 3 | AM5: Task 4 | AN5: Task 5 | AO5: Task 6 | AP5: Task 2 | AQ5: Task 3 | AR5: Task 4 | AS5: Task 5 | AT5: Task 6 | AV5: =A6 -> 0.25 | AW5: Task 2 | AX5: Task 3 | AY5: Task 4 | AZ5: Task 5 | BA5: Task 6
A6: 0.25 | B6: =AVERAGE(J6:J35) -> 0.95929409 | C6: =AVERAGE(K6:K35) -> 0.75243325 | D6: =AVERAGE(L6:L35) -> 0.5519229 | E6: =AVERAGE(M6:M35) -> #DIV/0! | F6: =AVERAGE(N6:N35) -> #DIV/0! | G6: =AVERAGE(O6:O35) -> #DIV/0! | J6: 0.97258065 | K6: =AVERAGE(Q6,V6,AA6,AF6,AK6,AP6) -> 0.65053763 | L6: =AVERAGE(R6,W6,AB6,AG6,AL6,AQ6) -> 0.53697183 | M6: =AVERAGE(S6,X6,AC6,AH6,AM6,AR6) -> #DIV/0! | N6: =AVERAGE(T6,Y6,AD6,AI6,AN6,AS6) -> #DIV/0! | O6: =AVERAGE(U6,Z6,AE6,AJ6,AO6,AT6) -> #DIV/0! | Q6: 0.55913978 | R6: 0.54929577 | V6: 0.63172043 | W6: 0.5915493 | AA6: 0.72580645 | AB6: 0.47183099 | AF6: 0.64784946 | AG6: 0.58978873 | AK6: 0.68817204 | AL6: 0.48239437 | AV6: 1 | AW6: =$Q$37 -> 0.75474869 | AX6: =$R$37 -> 0.50724541 | AY6: =$S$37 -> #DIV/0! | AZ6: =$T$37 -> #DIV/0! | BA6: =$U$37 -> #DIV/0!
A7: 0.5 | B7: =AVERAGE(J43:J72) -> 0.95869258 | C7: =AVERAGE(K43:K72) -> 0.76644592 | D7: =AVERAGE(L43:L72) -> 0.58857374 | E7: =AVERAGE(M43:M72) -> #DIV/0! | F7: =AVERAGE(N43:N72) -> #DIV/0! | G7: =AVERAGE(O43:O72) -> #DIV/0! | J7: 0.98028169 | K7: =AVERAGE(Q7,V7,AA7,AF7,AK7,AP7) -> 0.56619718 | L7: =AVERAGE(R7,W7,AB7,AG7,AL7,AQ7) -> 0.49230769 | M7: =AVERAGE(S7,X7,AC7,AH7,AM7,AR7) -> #DIV/0! | N7: =AVERAGE(T7,Y7,AD7,AI7,AN7,AS7) -> #DIV/0! | O7: =AVERAGE(U7,Z7,AE7,AJ7,AO7,AT7) -> #DIV/0! | Q7: 0.58098592 | R7: 0.6118068 | V7: 0.52112676 | W7: 0.56529517 | AA7: 0.66901408 | AB7: 0.58497317 | AF7: 0.49647887 | AG7: 0.15563506 | AK7: 0.56338028 | AL7: 0.54382826 | AV7: 2 | AW7: =$V$37 -> 0.68923658 | AX7: =$W$37 -> 0.55471035 | AY7: =$X$37 -> #DIV/0! | AZ7: =$Y$37 -> #DIV/0! | BA7: =$Z$37 -> #DIV/0!
A8: 1 | B8: =AVERAGE(J80:J109) -> 0.95986443 | C8: =AVERAGE(K80:K109) -> 0.77173524 | D8: =AVERAGE(L80:L109) -> 0.57854987 | E8: =AVERAGE(M80:M109) -> #DIV/0! | F8: =AVERAGE(N80:N109) -> #DIV/0! | G8: =AVERAGE(O80:O109) -> #DIV/0! | J8: 0.96426117 | K8: =AVERAGE(Q8,V8,AA8,AF8,AK8,AP8) -> 0.6838488 | L8: =AVERAGE(R8,W8,AB8,AG8,AL8,AQ8) -> 0.53402062 | M8: =AVERAGE(S8,X8,AC8,AH8,AM8,AR8) -> #DIV/0! | N8: =AVERAGE(T8,Y8,AD8,AI8,AN8,AS8) -> #DIV/0! | O8: =AVERAGE(U8,Z8,AE8,AJ8,AO8,AT8) -> #DIV/0! | Q8: 0.73539519 | R8: 0.56357388 | V8: 0.43298969 | W8: 0.33161512 | AA8: 0.79725086 | AB8: 0.58762887 | AF8: 0.72852234 | AG8: 0.44329897 | AK8: 0.72508591 | AL8: 0.74398625 | AV8: 3 | AW8: =$AA$37 -> 0.76185971 | AX8: =$AB$37 -> 0.60533527 | AY8: =$AC$37 -> #DIV/0! | AZ8: =$AD$37 -> #DIV/0! | BA8: =$AE$37 -> #DIV/0!
A9: 2 | B9: =AVERAGE(J117:J146) -> 0.9588441 | C9: =AVERAGE(K117:K146) -> 0.78816491 | D9: =AVERAGE(L117:L146) -> 0.58254337 | E9: =AVERAGE(M117:M146) -> #DIV/0! | F9: =AVERAGE(N117:N146) -> #DIV/0! | G9: =AVERAGE(O117:O146) -> #DIV/0! | J9: 0.98240741 | K9: =AVERAGE(Q9,V9,AA9,AF9,AK9,AP9) -> 0.84907407 | L9: =AVERAGE(R9,W9,AB9,AG9,AL9,AQ9) -> 0.58604651 | M9: =AVERAGE(S9,X9,AC9,AH9,AM9,AR9) -> #DIV/0! | N9: =AVERAGE(T9,Y9,AD9,AI9,AN9,AS9) -> #DIV/0! | O9: =AVERAGE(U9,Z9,AE9,AJ9,AO9,AT9) -> #DIV/0! | Q9: 0.83796296 | R9: 0.70155039 | V9: 0.8287037 | W9: 0.61627907 | AA9: 0.7962963 | AB9: 0.46317829 | AF9: 0.87962963 | AG9: 0.50775194 | AK9: 0.90277778 | AL9: 0.64147287 | AV9: 4 | AW9: =$AF$37 -> 0.77450701 | AX9: =$AG$37 -> 0.46573983 | AY9: =$AH$37 -> #DIV/0! | AZ9: =$AI$37 -> #DIV/0! | BA9: =$AJ$37 -> #DIV/0!
A10: 3 | B10: =AVERAGE(J154:J183) -> 0.95895378 | C10: =AVERAGE(K154:K183) -> 0.79844021 | D10: =AVERAGE(L154:L183) -> 0.58215571 | E10: =AVERAGE(M154:M183) -> #DIV/0! | F10: =AVERAGE(N154:N183) -> #DIV/0! | G10: =AVERAGE(O154:O183) -> #DIV/0! | J10: 0.9647619 | K10: =AVERAGE(Q10,V10,AA10,AF10,AK10,AP10) -> 0.76571429 | L10: =AVERAGE(R10,W10,AB10,AG10,AL10,AQ10) -> 0.56626016 | M10: =AVERAGE(S10,X10,AC10,AH10,AM10,AR10) -> #DIV/0! | N10: =AVERAGE(T10,Y10,AD10,AI10,AN10,AS10) -> #DIV/0! | O10: =AVERAGE(U10,Z10,AE10,AJ10,AO10,AT10) -> #DIV/0! | Q10: 0.84761905 | R10: 0.38211382 | V10: 0.34761905 | W10: 0.45934959 | AA10: 0.82857143 | AB10: 0.73170732 | AF10: 0.87619048 | AG10: 0.45325203 | AK10: 0.92857143 | AL10: 0.80487805 | AV10: 5 | AW10: =$AK$37 -> 0.78181428 | AX10: =$AL$37 -> 0.62658366 | AY10: =$AM$37 -> #DIV/0! | AZ10: =$AN$37 -> #DIV/0! | BA10: =$AO$37 -> #DIV/0!
J11: 0.85744681 | K11: =AVERAGE(Q11,V11,AA11,AF11,AK11,AP11) -> 0.6964539 | L11: =AVERAGE(R11,W11,AB11,AG11,AL11,AQ11) -> 0.51524823 | M11: =AVERAGE(S11,X11,AC11,AH11,AM11,AR11) -> #DIV/0! | N11: =AVERAGE(T11,Y11,AD11,AI11,AN11,AS11) -> #DIV/0! | O11: =AVERAGE(U11,Z11,AE11,AJ11,AO11,AT11) -> #DIV/0! | Q11: 0.68085106 | R11: 0.58156028 | V11: 0.65602837 | W11: 0.39893617 | AA11: 0.69858156 | AB11: 0.65957447 | AF11: 0.77304965 | AG11: 0.41489362 | AK11: 0.67375887 | AL11: 0.5212766 | AV11: 6 | AW11: =$AP$37 -> #DIV/0! | AX11: =$AQ$37 -> #DIV/0! | AY11: =$AR$37 -> #DIV/0! | AZ11: =$AS$37 -> #DIV/0! | BA11: =$AT$37 -> #DIV/0!
J12: 0.97862069 | K12: =AVERAGE(Q12,V12,AA12,AF12,AK12,AP12) -> 0.88758621 | L12: =AVERAGE(R12,W12,AB12,AG12,AL12,AQ12) -> 0.468 | M12: =AVERAGE(S12,X12,AC12,AH12,AM12,AR12) -> #DIV/0! | N12: =AVERAGE(T12,Y12,AD12,AI12,AN12,AS12) -> #DIV/0! | O12: =AVERAGE(U12,Z12,AE12,AJ12,AO12,AT12) -> #DIV/0! | Q12: 0.96551724 | R12: 0.448 | V12: 0.89655172 | W12: 0.714 | AA12: 0.81034483 | AB12: 0.502 | AF12: 0.85862069 | AG12: 0.28 | AK12: 0.90689655 | AL12: 0.396
J13: 0.97894737 | K13: =AVERAGE(Q13,V13,AA13,AF13,AK13,AP13) -> 0.80498615 | L13: =AVERAGE(R13,W13,AB13,AG13,AL13,AQ13) -> 0.56490166 | M13: =AVERAGE(S13,X13,AC13,AH13,AM13,AR13) -> #DIV/0! | N13: =AVERAGE(T13,Y13,AD13,AI13,AN13,AS13) -> #DIV/0! | O13: =AVERAGE(U13,Z13,AE13,AJ13,AO13,AT13) -> #DIV/0! | Q13: 0.80886427 | R13: 0.50832073 | V13: 0.75900277 | W13: 0.59909228 | AA13: 0.78116343 | AB13: 0.58850227 | AF13: 0.80055402 | AG13: 0.55673222 | AK13: 0.87534626 | AL13: 0.57186082
J14: 0.98656716 | K14: =AVERAGE(Q14,V14,AA14,AF14,AK14,AP14) -> 0.69029851 | L14: =AVERAGE(R14,W14,AB14,AG14,AL14,AQ14) -> 0.58710801 | M14: =AVERAGE(S14,X14,AC14,AH14,AM14,AR14) -> #DIV/0! | N14: =AVERAGE(T14,Y14,AD14,AI14,AN14,AS14) -> #DIV/0! | O14: =AVERAGE(U14,Z14,AE14,AJ14,AO14,AT14) -> #DIV/0! | Q14: 0.67910448 | R14: 0.68815331 | V14: 0.74253731 | W14: 0.56968641 | AA14: 0.63432836 | AB14: 0.53832753 | AF14: 0.72761194 | AG14: 0.51219512 | AK14: 0.66791045 | AL14: 0.6271777
J15: 0.97887324 | K15: =AVERAGE(Q15,V15,AA15,AF15,AK15,AP15) -> 0.56478873 | L15: =AVERAGE(R15,W15,AB15,AG15,AL15,AQ15) -> 0.57975567 | M15: =AVERAGE(S15,X15,AC15,AH15,AM15,AR15) -> #DIV/0! | N15: =AVERAGE(T15,Y15,AD15,AI15,AN15,AS15) -> #DIV/0! | O15: =AVERAGE(U15,Z15,AE15,AJ15,AO15,AT15) -> #DIV/0! | Q15: 0.72183099 | R15: 0.51308901 | V15: 0.43309859 | W15: 0.61431065 | AA15: 0.46478873 | AB15: 0.60383944 | AF15: 0.63028169 | AG15: 0.46422339 | AK15: 0.57394366 | AL15: 0.70331588 | AV15: =A7 -> 0.5 | AW15: Task 2 | AX15: Task 3 | AY15: Task 4 | AZ15: Task 5 | BA15: Task 6
J16: 0.96358839 | K16: =AVERAGE(Q16,V16,AA16,AF16,AK16,AP16) -> 0.86965699 | L16: =AVERAGE(R16,W16,AB16,AG16,AL16,AQ16) -> 0.6024735 | M16: =AVERAGE(S16,X16,AC16,AH16,AM16,AR16) -> #DIV/0! | N16: =AVERAGE(T16,Y16,AD16,AI16,AN16,AS16) -> #DIV/0! | O16: =AVERAGE(U16,Z16,AE16,AJ16,AO16,AT16) -> #DIV/0! | Q16: 0.93139842 | R16: 0.47526502 | V16: 0.91556728 | W16: 0.49646643 | AA16: 0.80211082 | AB16: 0.82862191 | AF16: 0.75989446 | AG16: 0.40282686 | AK16: 0.93931398 | AL16: 0.80918728 | AV16: 1 | AW16: =$Q$74 -> 0.73882195 | AX16: =$R$74 -> 0.56533843 | AY16: =$S$74 -> #DIV/0! | AZ16: =$T$74 -> #DIV/0! | BA16: =$U$74 -> #DIV/0!
J17: 0.8772973 | K17: =AVERAGE(Q17,V17,AA17,AF17,AK17,AP17) -> 0.73513514 | L17: =AVERAGE(R17,W17,AB17,AG17,AL17,AQ17) -> 0.57747899 | M17: =AVERAGE(S17,X17,AC17,AH17,AM17,AR17) -> #DIV/0! | N17: =AVERAGE(T17,Y17,AD17,AI17,AN17,AS17) -> #DIV/0! | O17: =AVERAGE(U17,Z17,AE17,AJ17,AO17,AT17) -> #DIV/0! | Q17: 0.72972973 | R17: 0.5512605 | V17: 0.77027027 | W17: 0.40336134 | AA17: 0.71081081 | AB17: 0.60840336 | AF17: 0.74864865 | AG17: 0.54117647 | AK17: 0.71621622 | AL17: 0.78319328 | AV17: 2 | AW17: =$V$74 -> 0.75156716 | AX17: =$W$74 -> 0.58364599 | AY17: =$X$74 -> #DIV/0! | AZ17: =$Y$74 -> #DIV/0! | BA17: =$Z$74 -> #DIV/0!
J18: 0.97745455 | K18: =AVERAGE(Q18,V18,AA18,AF18,AK18,AP18) -> 0.83854545 | L18: =AVERAGE(R18,W18,AB18,AG18,AL18,AQ18) -> 0.48803681 | M18: =AVERAGE(S18,X18,AC18,AH18,AM18,AR18) -> #DIV/0! | N18: =AVERAGE(T18,Y18,AD18,AI18,AN18,AS18) -> #DIV/0! | O18: =AVERAGE(U18,Z18,AE18,AJ18,AO18,AT18) -> #DIV/0! | Q18: 0.89454545 | R18: 0.46779141 | V18: 0.90181818 | W18: 0.46165644 | AA18: 0.83636364 | AB18: 0.61656442 | AF18: 0.81090909 | AG18: 0.35276074 | AK18: 0.74909091 | AL18: 0.54141104 | AV18: 3 | AW18: =$AA$74 -> 0.79120913 | AX18: =$AB$74 -> 0.58239238 | AY18: =$AC$74 -> #DIV/0! | AZ18: =$AD$74 -> #DIV/0! | BA18: =$AE$74 -> #DIV/0!
J19: 0.95862069 | K19: =AVERAGE(Q19,V19,AA19,AF19,AK19,AP19) -> 0.83793103 | L19: =AVERAGE(R19,W19,AB19,AG19,AL19,AQ19) -> 0.59496124 | M19: =AVERAGE(S19,X19,AC19,AH19,AM19,AR19) -> #DIV/0! | N19: =AVERAGE(T19,Y19,AD19,AI19,AN19,AS19) -> #DIV/0! | O19: =AVERAGE(U19,Z19,AE19,AJ19,AO19,AT19) -> #DIV/0! | Q19: 0.85862069 | R19: 0.53875969 | V19: 0.79310345 | W19: 0.60271318 | AA19: 0.86551724 | AB19: 0.63372093 | AF19: 0.8 | AG19: 0.58139535 | AK19: 0.87241379 | AL19: 0.61821705 | AV19: 4 | AW19: =$AF$74 -> 0.76760366 | AX19: =$AG$74 -> 0.56895077 | AY19: =$AH$74 -> #DIV/0! | AZ19: =$AI$74 -> #DIV/0! | BA19: =$AJ$74 -> #DIV/0!
J20: 0.97345133 | K20: =AVERAGE(Q20,V20,AA20,AF20,AK20,AP20) -> 0.89911504 | L20: =AVERAGE(R20,W20,AB20,AG20,AL20,AQ20) -> 0.37108844 | M20: =AVERAGE(S20,X20,AC20,AH20,AM20,AR20) -> #DIV/0! | N20: =AVERAGE(T20,Y20,AD20,AI20,AN20,AS20) -> #DIV/0! | O20: =AVERAGE(U20,Z20,AE20,AJ20,AO20,AT20) -> #DIV/0! | Q20: 0.87610619 | R20: 0.30272109 | V20: 0.92035398 | W20: 0.29081633 | AA20: 0.82300885 | AB20: 0.57993197 | AF20: 0.94690265 | AG20: 0.31462585 | AK20: 0.92920354 | AL20: 0.36734694 | AV20: 5 | AW20: =$AK$74 -> 0.7830277 | AX20: =$AL$74 -> 0.64254115 | AY20: =$AM$74 -> #DIV/0! | AZ20: =$AN$74 -> #DIV/0! | BA20: =$AO$74 -> #DIV/0!
J21: 0.96549865 | K21: =AVERAGE(Q21,V21,AA21,AF21,AK21,AP21) -> 0.49433962 | L21: =AVERAGE(R21,W21,AB21,AG21,AL21,AQ21) -> 0.46494845 | M21: =AVERAGE(S21,X21,AC21,AH21,AM21,AR21) -> #DIV/0! | N21: =AVERAGE(T21,Y21,AD21,AI21,AN21,AS21) -> #DIV/0! | O21: =AVERAGE(U21,Z21,AE21,AJ21,AO21,AT21) -> #DIV/0! | Q21: 0.045822102 | R21: 0.38487973 | V21: 0.58490566 | W21: 0.49656357 | AA21: 0.65229111 | AB21: 0.50859107 | AF21: 0.64150943 | AG21: 0.50515464 | AK21: 0.54716981 | AL21: 0.42955326 | AV21: 6 | AW21: =$AP$74 -> #DIV/0! | AX21: =$AQ$74 -> #DIV/0! | AY21: =$AR$74 -> #DIV/0! | AZ21: =$AS$74 -> #DIV/0! | BA21: =$AT$74 -> #DIV/0!
J22: 0.9017341 | K22: =AVERAGE(Q22,V22,AA22,AF22,AK22,AP22) -> 0.60809249 | L22: =AVERAGE(R22,W22,AB22,AG22,AL22,AQ22) -> 0.52329247 | M22: =AVERAGE(S22,X22,AC22,AH22,AM22,AR22) -> #DIV/0! | N22: =AVERAGE(T22,Y22,AD22,AI22,AN22,AS22) -> #DIV/0! | O22: =AVERAGE(U22,Z22,AE22,AJ22,AO22,AT22) -> #DIV/0! | Q22: 0.52023121 | R22: 0.42556918 | V22: 0.63294798 | W22: 0.59894921 | AA22: 0.53468208 | AB22: 0.47985989 | AF22: 0.68208092 | AG22: 0.48336252 | AK22: 0.67052023 | AL22: 0.62872154
J23: 0.87533875 | K23: =AVERAGE(Q23,V23,AA23,AF23,AK23,AP23) -> 0.75230352 | L23: =AVERAGE(R23,W23,AB23,AG23,AL23,AQ23) -> 0.57814871 | M23: =AVERAGE(S23,X23,AC23,AH23,AM23,AR23) -> #DIV/0! | N23: =AVERAGE(T23,Y23,AD23,AI23,AN23,AS23) -> #DIV/0! | O23: =AVERAGE(U23,Z23,AE23,AJ23,AO23,AT23) -> #DIV/0! | Q23: 0.7804878 | R23: 0.61456753 | V23: 0.74525745 | W23: 0.60394537 | AA23: 0.7398374 | AB23: 0.45827011 | AF23: 0.78319783 | AG23: 0.57663126 | AK23: 0.71273713 | AL23: 0.63732929
J24: 0.975 | K24: =AVERAGE(Q24,V24,AA24,AF24,AK24,AP24) -> 0.90263158 | L24: =AVERAGE(R24,W24,AB24,AG24,AL24,AQ24) -> 0.52819473 | M24: =AVERAGE(S24,X24,AC24,AH24,AM24,AR24) -> #DIV/0! | N24: =AVERAGE(T24,Y24,AD24,AI24,AN24,AS24) -> #DIV/0! | O24: =AVERAGE(U24,Z24,AE24,AJ24,AO24,AT24) -> #DIV/0! | Q24: 0.92434211 | R24: 0.28803245 | V24: 0.88486842 | W24: 0.63286004 | AA24: 0.88157895 | AB24: 0.61663286 | AF24: 0.91447368 | AG24: 0.46653144 | AK24: 0.90789474 | AL24: 0.63691684
J25: 0.95448276 | K25: =AVERAGE(Q25,V25,AA25,AF25,AK25,AP25) -> 0.77517241 | L25: =AVERAGE(R25,W25,AB25,AG25,AL25,AQ25) -> 0.55376344 | M25: =AVERAGE(S25,X25,AC25,AH25,AM25,AR25) -> #DIV/0! | N25: =AVERAGE(T25,Y25,AD25,AI25,AN25,AS25) -> #DIV/0! | O25: =AVERAGE(U25,Z25,AE25,AJ25,AO25,AT25) -> #DIV/0! | Q25: 0.78275862 | R25: 0.49820789 | V25: 0.71034483 | W25: 0.55376344 | AA25: 0.73103448 | AB25: 0.65770609 | AF25: 0.82068966 | AG25: 0.3781362 | AK25: 0.83103448 | AL25: 0.68100358 | AV25: =A8 -> 1 | AW25: Task 2 | AX25: Task 3 | AY25: Task 4 | AZ25: Task 5 | BA25: Task 6
J26: 0.97722772 | K26: =AVERAGE(Q26,V26,AA26,AF26,AK26,AP26) -> 0.6980198 | L26: =AVERAGE(R26,W26,AB26,AG26,AL26,AQ26) -> 0.55456389 | M26: =AVERAGE(S26,X26,AC26,AH26,AM26,AR26) -> #DIV/0! | N26: =AVERAGE(T26,Y26,AD26,AI26,AN26,AS26) -> #DIV/0! | O26: =AVERAGE(U26,Z26,AE26,AJ26,AO26,AT26) -> #DIV/0! | Q26: 0.71287129 | R26: 0.46855984 | V26: 0.18316832 | W26: 0.5030426 | AA26: 0.87128713 | AB26: 0.57606491 | AF26: 0.82673267 | AG26: 0.4969574 | AK26: 0.8960396 | AL26: 0.72819473 | AV26: 1 | AW26: =$Q$111 -> 0.75804493 | AX26: =$R$111 -> 0.57772724 | AY26: =$S$111 -> #DIV/0! | AZ26: =$T$111 -> #DIV/0! | BA26: =$U$111 -> #DIV/0!
J27: 0.96701031 | K27: =AVERAGE(Q27,V27,AA27,AF27,AK27,AP27) -> 0.69553265 | L27: =AVERAGE(R27,W27,AB27,AG27,AL27,AQ27) -> 0.62386555 | M27: =AVERAGE(S27,X27,AC27,AH27,AM27,AR27) -> #DIV/0! | N27: =AVERAGE(T27,Y27,AD27,AI27,AN27,AS27) -> #DIV/0! | O27: =AVERAGE(U27,Z27,AE27,AJ27,AO27,AT27) -> #DIV/0! | Q27: 0.89690722 | R27: 0.66218487 | V27: 0.27147766 | W27: 0.49243697 | AA27: 0.82474227 | AB27: 0.66386555 | AF27: 0.68041237 | AG27: 0.66218487 | AK27: 0.80412371 | AL27: 0.63865546 | AV27: 2 | AW27: =$V$111 -> 0.79454245 | AX27: =$W$111 -> 0.58456228 | AY27: =$X$111 -> #DIV/0! | AZ27: =$Y$111 -> #DIV/0! | BA27: =$Z$111 -> #DIV/0!
J28: 0.96334232 | K28: =AVERAGE(Q28,V28,AA28,AF28,AK28,AP28) -> 0.57196765 | L28: =AVERAGE(R28,W28,AB28,AG28,AL28,AQ28) -> 0.56302817 | M28: =AVERAGE(S28,X28,AC28,AH28,AM28,AR28) -> #DIV/0! | N28: =AVERAGE(T28,Y28,AD28,AI28,AN28,AS28) -> #DIV/0! | O28: =AVERAGE(U28,Z28,AE28,AJ28,AO28,AT28) -> #DIV/0! | Q28: 0.51752022 | R28: 0.4665493 | V28: 0.51212938 | W28: 0.6584507 | AA28: 0.61725067 | AB28: 0.58802817 | AF28: 0.60107817 | AG28: 0.43309859 | AK28: 0.61185984 | AL28: 0.66901408 | AV28: 3 | AW28: =$AA$111 -> 0.80040792 | AX28: =$AB$111 -> 0.5537183 | AY28: =$AC$111 -> #DIV/0! | AZ28: =$AD$111 -> #DIV/0! | BA28: =$AE$111 -> #DIV/0!
J29: 0.98148148 | K29: =AVERAGE(Q29,V29,AA29,AF29,AK29,AP29) -> 0.83240741 | L29: =AVERAGE(R29,W29,AB29,AG29,AL29,AQ29) -> 0.51950355 | M29: =AVERAGE(S29,X29,AC29,AH29,AM29,AR29) -> #DIV/0! | N29: =AVERAGE(T29,Y29,AD29,AI29,AN29,AS29) -> #DIV/0! | O29: =AVERAGE(U29,Z29,AE29,AJ29,AO29,AT29) -> #DIV/0! | Q29: 0.89351852 | R29: 0.40780142 | V29: 0.66203704 | W29: 0.47163121 | AA29: 0.86574074 | AB29: 0.59219858 | AF29: 0.86574074 | AG29: 0.49822695 | AK29: 0.875 | AL29: 0.62765957 | AV29: 4 | AW29: =$AF$111 -> 0.73049347 | AX29: =$AG$111 -> 0.5218141 | AY29: =$AH$111 -> #DIV/0! | AZ29: =$AI$111 -> #DIV/0! | BA29: =$AJ$111 -> #DIV/0!
J30: 0.97433628 | K30: =AVERAGE(Q30,V30,AA30,AF30,AK30,AP30) -> 0.92743363 | L30: =AVERAGE(R30,W30,AB30,AG30,AL30,AQ30) -> 0.6653144 | M30: =AVERAGE(S30,X30,AC30,AH30,AM30,AR30) -> #DIV/0! | N30: =AVERAGE(T30,Y30,AD30,AI30,AN30,AS30) -> #DIV/0! | O30: =AVERAGE(U30,Z30,AE30,AJ30,AO30,AT30) -> #DIV/0! | Q30: 0.90707965 | R30: 0.76064909 | V30: 0.95132743 | W30: 0.60851927 | AA30: 0.90707965 | AB30: 0.8296146 | AF30: 0.92477876 | AG30: 0.39350913 | AK30: 0.94690265 | AL30: 0.73427992 | AV30: 5 | AW30: =$AK$111 -> 0.77518741 | AX30: =$AL$111 -> 0.65492742 | AY30: =$AM$111 -> #DIV/0! | AZ30: =$AN$111 -> #DIV/0! | BA30: =$AO$111 -> #DIV/0!
J31: 0.97826087 | K31: =AVERAGE(Q31,V31,AA31,AF31,AK31,AP31) -> 0.81449275 | L31: =AVERAGE(R31,W31,AB31,AG31,AL31,AQ31) -> 0.57870855 | M31: =AVERAGE(S31,X31,AC31,AH31,AM31,AR31) -> #DIV/0! | N31: =AVERAGE(T31,Y31,AD31,AI31,AN31,AS31) -> #DIV/0! | O31: =AVERAGE(U31,Z31,AE31,AJ31,AO31,AT31) -> #DIV/0! | Q31: 0.81884058 | R31: 0.44328098 | V31: 0.83695652 | W31: 0.59685864 | AA31: 0.8115942 | AB31: 0.71378709 | AF31: 0.89492754 | AG31: 0.51483421 | AK31: 0.71014493 | AL31: 0.62478185 | AV31: 6 | AW31: =$AP$111 -> #DIV/0! | AX31: =$AQ$111 -> #DIV/0! | AY31: =$AR$111 -> #DIV/0! | AZ31: =$AS$111 -> #DIV/0! | BA31: =$AT$111 -> #DIV/0!
J32: 0.96 | K32: =AVERAGE(Q32,V32,AA32,AF32,AK32,AP32) -> 0.85809524 | L32: =AVERAGE(R32,W32,AB32,AG32,AL32,AQ32) -> 0.63154122 | M32: =AVERAGE(S32,X32,AC32,AH32,AM32,AR32) -> #DIV/0! | N32: =AVERAGE(T32,Y32,AD32,AI32,AN32,AS32) -> #DIV/0! | O32: =AVERAGE(U32,Z32,AE32,AJ32,AO32,AT32) -> #DIV/0! | Q32: 0.79047619 | R32: 0.42831541 | V32: 0.87619048 | W32: 0.76523297 | AA32: 0.87619048 | AB32: 0.69354839 | AF32: 0.91428571 | AG32: 0.6827957 | AK32: 0.83333333 | AL32: 0.58781362
J33: 0.97816901 | K33: =AVERAGE(Q33,V33,AA33,AF33,AK33,AP33) -> 0.56338028 | L33: =AVERAGE(R33,W33,AB33,AG33,AL33,AQ33) -> 0.52312925 | M33: =AVERAGE(S33,X33,AC33,AH33,AM33,AR33) -> #DIV/0! | N33: =AVERAGE(T33,Y33,AD33,AI33,AN33,AS33) -> #DIV/0! | O33: =AVERAGE(U33,Z33,AE33,AJ33,AO33,AT33) -> #DIV/0! | Q33: 0.61619718 | R33: 0.49829932 | V33: 0.54225352 | W33: 0.50680272 | AA33: 0.47887324 | AB33: 0.56972789 | AF33: 0.49647887 | AG33: 0.46598639 | AK33: 0.68309859 | AL33: 0.57482993
J34: 0.9646438 | K34: =AVERAGE(Q34,V34,AA34,AF34,AK34,AP34) -> 0.93456464 | L34: =AVERAGE(R34,W34,AB34,AG34,AL34,AQ34) -> 0.68770865 | M34: =AVERAGE(S34,X34,AC34,AH34,AM34,AR34) -> #DIV/0! | N34: =AVERAGE(T34,Y34,AD34,AI34,AN34,AS34) -> #DIV/0! | O34: =AVERAGE(U34,Z34,AE34,AJ34,AO34,AT34) -> #DIV/0! | Q34: 0.95778364 | R34: 0.61153263 | V34: 0.93931398 | W34: 0.86646434 | AA34: 0.87598945 | AB34: 0.63732929 | AF34: 0.9525066 | AG34: 0.50075873 | AK34: 0.94722955 | AL34: 0.82245827
J35: 0.96713615 | K35: =AVERAGE(Q35,V35,AA35,AF35,AK35,AP35) -> 0.80469484 | L35: =AVERAGE(R35,W35,AB35,AG35,AL35,AQ35) -> 0.49731664 | M35: =AVERAGE(S35,X35,AC35,AH35,AM35,AR35) -> #DIV/0! | N35: =AVERAGE(T35,Y35,AD35,AI35,AN35,AS35) -> #DIV/0! | O35: =AVERAGE(U35,Z35,AE35,AJ35,AO35,AT35) -> #DIV/0! | Q35: 0.76995305 | R35: 0.37567084 | V35: 0.79342723 | W35: 0.5706619 | AA35: 0.94366197 | AB35: 0.57602862 | AF35: 0.75117371 | AG35: 0.34347048 | AK35: 0.76525822 | AL35: 0.62075134 | AV35: =A9 -> 2 | AW35: Task 2 | AX35: Task 3 | AY35: Task 4 | AZ35: Task 5 | BA35: Task 6
AV36: 1 | AW36: =$Q$148 -> 0.78797902 | AX36: =$R$148 -> 0.57076163 | AY36: =$S$148 -> #DIV/0! | AZ36: =$T$148 -> #DIV/0! | BA36: =$U$148 -> #DIV/0!
J37: 0.98844568 | K37: =AVERAGE(K6:K35) -> 0.75243325 | L37: =AVERAGE(L6:L35) -> 0.5519229 | M37: =AVERAGE(M6:M35) -> #DIV/0! | N37: =AVERAGE(N6:N35) -> #DIV/0! | O37: =AVERAGE(O6:O35) -> #DIV/0! | Q37: =AVERAGE(Q6:Q35) -> 0.75474869 | R37: =AVERAGE(R6:R35) -> 0.50724541 | S37: =AVERAGE(S6:S35) -> #DIV/0! | T37: =AVERAGE(T6:T35) -> #DIV/0! | U37: =AVERAGE(U6:U35) -> #DIV/0! | V37: =AVERAGE(V6:V35) -> 0.68923658 | W37: =AVERAGE(W6:W35) -> 0.55471035 | X37: =AVERAGE(X6:X35) -> #DIV/0! | ... AT37: =AVERAGE(AT6:AT35) -> #DIV/0! | AV37: 2 | AW37: =$V$148 -> 0.7896032 | AX37: =$W$148 -> 0.59699513 | AY37: =$X$148 -> #DIV/0! | AZ37: =$Y$148 -> #DIV/0! | BA37: =$Z$148 -> #DIV/0!
AV38: 3 | AW38: =$AA$148 -> 0.78865593 | AX38: =$AB$148 -> 0.54791646 | AY38: =$AC$148 -> #DIV/0! | AZ38: =$AD$148 -> #DIV/0! | BA38: =$AE$148 -> #DIV/0!
AV39: 4 | AW39: =$AF$148 -> 0.77117465 | AX39: =$AG$148 -> 0.53168534 | AY39: =$AH$148 -> #DIV/0! | AZ39: =$AI$148 -> #DIV/0! | BA39: =$AJ$148 -> #DIV/0!
J40: k=0.5 | AV40: 5 | AW40: =$AK$148 -> 0.80341176 | AX40: =$AL$148 -> 0.66535828 | AY40: =$AM$148 -> #DIV/0! | AZ40: =$AN$148 -> #DIV/0! | BA40: =$AO$148 -> #DIV/0!
Q41: 1 | V41: 2 | AA41: 3 | AF41: 4 | AK41: 5 | AP41: 6 | AV41: 6 | AW41: =$AP$148 -> #DIV/0! | AX41: =$AQ$148 -> #DIV/0! | AY41: =$AR$148 -> #DIV/0! | AZ41: =$AS$148 -> #DIV/0! | BA41: =$AT$148 -> #DIV/0!
I42: ID | J42: Task 1 | K42: Task 2 | L42: Task 3 | M42: Task 4 | N42: Task 5 | O42: Task 6 | Q42: Task 2 | R42: Task 3 | S42: Task 4 | T42: Task 5 | U42: Task 6 | V42: Task 2 | W42: Task 3 | X42: Task 4 | Y42: Task 5 | Z42: Task 6 | AA42: Task 2 | AB42: Task 3 | AC42: Task 4 | AD42: Task 5 | AE42: Task 6 | AF42: Task 2 | AG42: Task 3 | AH42: Task 4 | AI42: Task 5 | AJ42: Task 6 | AK42: Task 2 | AL42: Task 3 | AM42: Task 4 | AN42: Task 5 | AO42: Task 6 | AP42: Task 2 | AQ42: Task 3 | AR42: Task 4 | AS42: Task 5 | AT42: Task 6
...

Sheet Person_2
J3: k=0.25
Q4: 1 | V4: 2 | AA4: 3 | AF4: 4 | AK4: 5 | AP4: 6
A5: k | B5: Task 1 | C5: Task 2 | D5: Task 3 | E5: Task 4 | F5: Task 5 | G5: Task 6 | I5: ID | J5: Task 1 | K5: Task 2 | L5: Task 3 | M5: Task 4 | N5: Task 5 | O5: Task 6 | Q5: Task 2 | R5: Task 3 | S5: Task 4 | T5: Task 5 | U5: Task 6 | V5: Task 2 | W5: Task 3 | X5: Task 4 | Y5: Task 5 | Z5: Task 6 | AA5: Task 2 | AB5: Task 3 | AC5: Task 4 | AD5: Task 5 | AE5: Task 6 | AF5: Task 2 | AG5: Task 3 | AH5: Task 4 | AI5: Task 5 | AJ5: Task 6 | AK5: Task 2 | AL5: Task 3 | AM5: Task 4 | AN5: Task 5 | AO5: Task 6 | AP5: Task 2 | AQ5: Task 3 | AR5: Task 4 | AS5: Task 5 | AT5: Task 6 | AV5: =A6 -> 0.25 | AW5: Task 2 | AX5: Task 3 | AY5: Task 4 | AZ5: Task 5 | BA5: Task 6
A6: 0.25 | B6: =AVERAGE(J6:J35) -> 0.99247324 | C6: =AVERAGE(K6:K35) -> 0.89019955 | D6: =AVERAGE(L6:L35) -> 0.74311312 | E6: =AVERAGE(M6:M35) -> #DIV/0! | F6: =AVERAGE(N6:N35) -> #DIV/0! | G6: =AVERAGE(O6:O35) -> #DIV/0! | J6: 0.99626667 | K6: =AVERAGE(Q6,V6,AA6,AF6,AK6,AP6) -> 0.832 | L6: =AVERAGE(R6,W6,AB6,AG6,AL6,AQ6) -> 0.6516934 | M6: =AVERAGE(S6,X6,AC6,AH6,AM6,AR6) -> #DIV/0! | N6: =AVERAGE(T6,Y6,AD6,AI6,AN6,AS6) -> #DIV/0! | O6: =AVERAGE(U6,Z6,AE6,AJ6,AO6,AT6) -> #DIV/0! | Q6: 0.67733333 | R6: 0.5026738 | V6: 0.97866667 | W6: 0.79500891 | AA6: 0.816 | AB6: 0.68627451 | AF6: 0.744 | AG6: 0.59536542 | AK6: 0.944 | AL6: 0.67914439 | AV6: 1 | AW6: =$Q$37 -> 0.88599298 | AX6: =$R$37 -> 0.73507943 | AY6: =$S$37 -> #DIV/0! | AZ6: =$T$37 -> #DIV/0! | BA6: =$U$37 -> #DIV/0!
A7: 0.5 | B7: =AVERAGE(J43:J72) -> 0.99218933 | C7: =AVERAGE(K43:K72) -> 0.88519347 | D7: =AVERAGE(L43:L72) -> 0.77256356 | E7: =AVERAGE(M43:M72) -> #DIV/0! | F7: =AVERAGE(N43:N72) -> #DIV/0! | G7: =AVERAGE(O43:O72) -> #DIV/0! | J7: 0.99862543 | K7: =AVERAGE(Q7,V7,AA7,AF7,AK7,AP7) -> 0.76975945 | L7: =AVERAGE(R7,W7,AB7,AG7,AL7,AQ7) -> 0.60321429 | M7: =AVERAGE(S7,X7,AC7,AH7,AM7,AR7) -> #DIV/0! | N7: =AVERAGE(T7,Y7,AD7,AI7,AN7,AS7) -> #DIV/0! | O7: =AVERAGE(U7,Z7,AE7,AJ7,AO7,AT7) -> #DIV/0! | Q7: 0.75257732 | R7: 0.62142857 | V7: 0.60824742 | W7: 0.49642857 | AA7: 0.83161512 | AB7: 0.675 | AF7: 0.81099656 | AG7: 0.67321429 | AK7: 0.84536082 | AL7: 0.55 | AV7: 2 | AW7: =$V$37 -> 0.9061601 | AX7: =$W$37 -> 0.76247792 | AY7: =$X$37 -> #DIV/0! | AZ7: =$Y$37 -> #DIV/0! | BA7: =$Z$37 -> #DIV/0!
A8: 1 | B8: =AVERAGE(J80:J109) -> 0.99147797 | C8: =AVERAGE(K80:K109) -> 0.91003783 | D8: =AVERAGE(L80:L109) -> 0.79044994 | E8: =AVERAGE(M80:M109) -> #DIV/0! | F8: =AVERAGE(N80:N109) -> #DIV/0! | G8: =AVERAGE(O80:O109) -> #DIV/0! | J8: 0.99368421 | K8: =AVERAGE(Q8,V8,AA8,AF8,AK8,AP8) -> 0.91789474 | L8: =AVERAGE(R8,W8,AB8,AG8,AL8,AQ8) -> 0.68499157 | M8: =AVERAGE(S8,X8,AC8,AH8,AM8,AR8) -> #DIV/0! | N8: =AVERAGE(T8,Y8,AD8,AI8,AN8,AS8) -> #DIV/0! | O8: =AVERAGE(U8,Z8,AE8,AJ8,AO8,AT8) -> #DIV/0! | Q8: 0.94473684 | R8: 0.60539629 | V8: 0.93947368 | W8: 0.7925801 | AA8: 0.94210526 | AB8: 0.47554806 | AF8: 0.90789474 | AG8: 0.78583474 | AK8: 0.85526316 | AL8: 0.76559865 | AV8: 3 | AW8: =$AA$37 -> 0.90233103 | AX8: =$AB$37 -> 0.72990941 | AY8: =$AC$37 -> #DIV/0! | AZ8: =$AD$37 -> #DIV/0! | BA8: =$AE$37 -> #DIV/0!
A9: 2 | B9: =AVERAGE(J117:J146) -> 0.99218617 | C9: =AVERAGE(K117:K146) -> 0.9280538 | D9: =AVERAGE(L117:L146) -> 0.80850462 | E9: =AVERAGE(M117:M146) -> #DIV/0! | F9: =AVERAGE(N117:N146) -> #DIV/0! | G9: =AVERAGE(O117:O146) -> #DIV/0! | J9: 1 | K9: =AVERAGE(Q9,V9,AA9,AF9,AK9,AP9) -> 0.93211009 | L9: =AVERAGE(R9,W9,AB9,AG9,AL9,AQ9) -> 0.73355593 | M9: =AVERAGE(S9,X9,AC9,AH9,AM9,AR9) -> #DIV/0! | N9: =AVERAGE(T9,Y9,AD9,AI9,AN9,AS9) -> #DIV/0! | O9: =AVERAGE(U9,Z9,AE9,AJ9,AO9,AT9) -> #DIV/0! | Q9: 0.90825688 | R9: 0.83806344 | V9: 0.93577982 | W9: 0.65776294 | AA9: 0.94954128 | AB9: 0.67111853 | AF9: 0.94495413 | AG9: 0.77462437 | AK9: 0.92201835 | AL9: 0.72621035 | AV9: 4 | AW9: =$AF$37 -> 0.8723797 | AX9: =$AG$37 -> 0.74654806 | AY9: =$AH$37 -> #DIV/0! | AZ9: =$AI$37 -> #DIV/0! | BA9: =$AJ$37 -> #DIV/0!
A10: 3 | B10: =AVERAGE(J154:J183) -> 0.99181402 | C10: =AVERAGE(K154:K183) -> 0.92534981 | D10: =AVERAGE(L154:L183) -> 0.80719876 | E10: =AVERAGE(M154:M183) -> #DIV/0! | F10: =AVERAGE(N154:N183) -> #DIV/0! | G10: =AVERAGE(O154:O183) -> #DIV/0! | J10: 0.98807339 | K10: =AVERAGE(Q10,V10,AA10,AF10,AK10,AP10) -> 0.91100917 | L10: =AVERAGE(R10,W10,AB10,AG10,AL10,AQ10) -> 0.87100176 | M10: =AVERAGE(S10,X10,AC10,AH10,AM10,AR10) -> #DIV/0! | N10: =AVERAGE(T10,Y10,AD10,AI10,AN10,AS10) -> #DIV/0! | O10: =AVERAGE(U10,Z10,AE10,AJ10,AO10,AT10) -> #DIV/0! | Q10: 0.88990826 | R10: 0.79964851 | V10: 0.89908257 | W10: 0.88400703 | AA10: 0.96788991 | AB10: 0.94376098 | AF10: 0.85321101 | AG10: 0.87697715 | AK10: 0.94495413 | AL10: 0.85061511 | AV10: 5 | AW10: =$AK$37 -> 0.88413395 | AX10: =$AL$37 -> 0.74155076 | AY10: =$AM$37 -> #DIV/0! | AZ10: =$AN$37 -> #DIV/0! | BA10: =$AO$37 -> #DIV/0!
J11: 0.9990566 | K11: =AVERAGE(Q11,V11,AA11,AF11,AK11,AP11) -> 0.90566038 | L11: =AVERAGE(R11,W11,AB11,AG11,AL11,AQ11) -> 0.79928952 | M11: =AVERAGE(S11,X11,AC11,AH11,AM11,AR11) -> #DIV/0! | N11: =AVERAGE(T11,Y11,AD11,AI11,AN11,AS11) -> #DIV/0! | O11: =AVERAGE(U11,Z11,AE11,AJ11,AO11,AT11) -> #DIV/0! | Q11: 0.91509434 | R11: 0.73534636 | V11: 0.9009434 | W11: 0.87921847 | AA11: 0.91509434 | AB11: 0.79218472 | AF11: 0.88207547 | AG11: 0.77264654 | AK11: 0.91509434 | AL11: 0.81705151 | AV11: 6 | AW11: =$AP$37 -> #DIV/0! | AX11: =$AQ$37 -> #DIV/0! | AY11: =$AR$37 -> #DIV/0! | AZ11: =$AS$37 -> #DIV/0! | BA11: =$AT$37 -> #DIV/0!
J12: 0.97703704 | K12: =AVERAGE(Q12,V12,AA12,AF12,AK12,AP12) -> 0.92296296 | L12: =AVERAGE(R12,W12,AB12,AG12,AL12,AQ12) -> 0.69590164 | M12: =AVERAGE(S12,X12,AC12,AH12,AM12,AR12) -> #DIV/0! | N12: =AVERAGE(T12,Y12,AD12,AI12,AN12,AS12) -> #DIV/0! | O12: =AVERAGE(U12,Z12,AE12,AJ12,AO12,AT12) -> #DIV/0! | Q12: 0.93703704 | R12: 0.56352459 | V12: 0.93333333 | W12: 0.87909836 | AA12: 0.94444444 | AB12: 0.67622951 | AF12: 0.93333333 | AG12: 0.60655738 | AK12: 0.86666667 | AL12: 0.75409836
J13: 0.9917603 | K13: =AVERAGE(Q13,V13,AA13,AF13,AK13,AP13) -> 0.78052434 | L13: =AVERAGE(R13,W13,AB13,AG13,AL13,AQ13) -> 0.72932099 | M13: =AVERAGE(S13,X13,AC13,AH13,AM13,AR13) -> #DIV/0! | N13: =AVERAGE(T13,Y13,AD13,AI13,AN13,AS13) -> #DIV/0! | O13: =AVERAGE(U13,Z13,AE13,AJ13,AO13,AT13) -> #DIV/0! | Q13: 0.82771536 | R13: 0.71450617 | V13: 0.77902622 | W13: 0.76234568 | AA13: 0.77153558 | AB13: 0.73611111 | AF13: 0.86516854 | AG13: 0.74845679 | AK13: 0.65917603 | AL13: 0.68518519
J14: 0.98888889 | K14: =AVERAGE(Q14,V14,AA14,AF14,AK14,AP14) -> 0.77222222 | L14: =AVERAGE(R14,W14,AB14,AG14,AL14,AQ14) -> 0.74901961 | M14: =AVERAGE(S14,X14,AC14,AH14,AM14,AR14) -> #DIV/0! | N14: =AVERAGE(T14,Y14,AD14,AI14,AN14,AS14) -> #DIV/0! | O14: =AVERAGE(U14,Z14,AE14,AJ14,AO14,AT14) -> #DIV/0! | Q14: 0.76666667 | R14: 0.75935829 | V14: 0.61111111 | W14: 0.78966132 | AA14: 0.83333333 | AB14: 0.78787879 | AF14: 0.85555556 | AG14: 0.61319073 | AK14: 0.79444444 | AL14: 0.79500891
J15: 0.99793814 | K15: =AVERAGE(Q15,V15,AA15,AF15,AK15,AP15) -> 0.82405498 | L15: =AVERAGE(R15,W15,AB15,AG15,AL15,AQ15) -> 0.69751773 | M15: =AVERAGE(S15,X15,AC15,AH15,AM15,AR15) -> #DIV/0! | N15: =AVERAGE(T15,Y15,AD15,AI15,AN15,AS15) -> #DIV/0! | O15: =AVERAGE(U15,Z15,AE15,AJ15,AO15,AT15) -> #DIV/0! | Q15: 0.85910653 | R15: 0.70744681 | V15: 0.91408935 | W15: 0.65780142 | AA15: 0.84536082 | AB15: 0.7606383 | AF15: 0.58419244 | AG15: 0.63297872 | AK15: 0.91752577 | AL15: 0.7287234 | AV15: =A7 -> 0.5 | AW15: Task 2 | AX15: Task 3 | AY15: Task 4 | AZ15: Task 5 | BA15: Task 6
J16: 0.99057239 | K16: =AVERAGE(Q16,V16,AA16,AF16,AK16,AP16) -> 0.98249158 | L16: =AVERAGE(R16,W16,AB16,AG16,AL16,AQ16) -> 0.8780083 | M16: =AVERAGE(S16,X16,AC16,AH16,AM16,AR16) -> #DIV/0! | N16: =AVERAGE(T16,Y16,AD16,AI16,AN16,AS16) -> #DIV/0! | O16: =AVERAGE(U16,Z16,AE16,AJ16,AO16,AT16) -> #DIV/0! | Q16: 0.98989899 | R16: 0.90248963 | V16: 0.98316498 | W16: 0.83817427 | AA16: 0.98316498 | AB16: 0.85684647 | AF16: 0.98653199 | AG16: 0.93360996 | AK16: 0.96969697 | AL16: 0.85892116 | AV16: 1 | AW16: =$Q$74 -> 0.81939052 | AX16: =$R$74 -> 0.73609052 | AY16: =$S$74 -> #DIV/0! | AZ16: =$T$74 -> #DIV/0! | BA16: =$U$74 -> #DIV/0!
J17: 0.98986486 | K17: =AVERAGE(Q17,V17,AA17,AF17,AK17,AP17) -> 0.85743243 | L17: =AVERAGE(R17,W17,AB17,AG17,AL17,AQ17) -> 0.69475728 | M17: =AVERAGE(S17,X17,AC17,AH17,AM17,AR17) -> #DIV/0! | N17: =AVERAGE(T17,Y17,AD17,AI17,AN17,AS17) -> #DIV/0! | O17: =AVERAGE(U17,Z17,AE17,AJ17,AO17,AT17) -> #DIV/0! | Q17: 0.97635135 | R17: 0.86019417 | V17: 0.96621622 | W17: 0.7961165 | AA17: 0.95945946 | AB17: 0.66796117 | AF17: 0.66554054 | AG17: 0.57475728 | AK17: 0.71959459 | AL17: 0.57475728 | AV17: 2 | AW17: =$V$74 -> 0.91621685 | AX17: =$W$74 -> 0.76079933 | AY17: =$X$74 -> #DIV/0! | AZ17: =$Y$74 -> #DIV/0! | BA17: =$Z$74 -> #DIV/0!
J18: 0.98289963 | K18: =AVERAGE(Q18,V18,AA18,AF18,AK18,AP18) -> 0.95315985 | L18: =AVERAGE(R18,W18,AB18,AG18,AL18,AQ18) -> 0.7935085 | M18: =AVERAGE(S18,X18,AC18,AH18,AM18,AR18) -> #DIV/0! | N18: =AVERAGE(T18,Y18,AD18,AI18,AN18,AS18) -> #DIV/0! | O18: =AVERAGE(U18,Z18,AE18,AJ18,AO18,AT18) -> #DIV/0! | Q18: 0.89219331 | R18: 0.79907264 | V18: 0.9739777 | W18: 0.73570325 | AA18: 0.95539033 | AB18: 0.92272025 | AF18: 0.9739777 | AG18: 0.812983 | AK18: 0.97026022 | AL18: 0.69706337 | AV18: 3 | AW18: =$AA$74 -> 0.86388749 | AX18: =$AB$74 -> 0.79716305 | AY18: =$AC$74 -> #DIV/0! | AZ18: =$AD$74 -> #DIV/0! | BA18: =$AE$74 -> #DIV/0!
J19: 0.99060052 | K19: =AVERAGE(Q19,V19,AA19,AF19,AK19,AP19) -> 0.88563969 | L19: =AVERAGE(R19,W19,AB19,AG19,AL19,AQ19) -> 0.67512521 | M19: =AVERAGE(S19,X19,AC19,AH19,AM19,AR19) -> #DIV/0! | N19: =AVERAGE(T19,Y19,AD19,AI19,AN19,AS19) -> #DIV/0! | O19: =AVERAGE(U19,Z19,AE19,AJ19,AO19,AT19) -> #DIV/0! | Q19: 0.89817232 | R19: 0.639399 | V19: 0.94516971 | W19: 0.79131886 | AA19: 0.92950392 | AB19: 0.64440735 | AF19: 0.93472585 | AG19: 0.57429048 | AK19: 0.72062663 | AL19: 0.72621035 | AV19: 4 | AW19: =$AF$74 -> 0.91348218 | AX19: =$AG$74 -> 0.79101586 | AY19: =$AH$74 -> #DIV/0! | AZ19: =$AI$74 -> #DIV/0! | BA19: =$AJ$74 -> #DIV/0!
J20: 0.99351852 | K20: =AVERAGE(Q20,V20,AA20,AF20,AK20,AP20) -> 0.93333333 | L20: =AVERAGE(R20,W20,AB20,AG20,AL20,AQ20) -> 0.68634064 | M20: =AVERAGE(S20,X20,AC20,AH20,AM20,AR20) -> #DIV/0! | N20: =AVERAGE(T20,Y20,AD20,AI20,AN20,AS20) -> #DIV/0! | O20: =AVERAGE(U20,Z20,AE20,AJ20,AO20,AT20) -> #DIV/0! | Q20: 0.91203704 | R20: 0.80944351 | V20: 0.96759259 | W20: 0.76053963 | AA20: 0.91203704 | AB20: 0.44182125 | AF20: 0.91203704 | AG20: 0.6762226 | AK20: 0.96296296 | AL20: 0.74367622 | AV20: 5 | AW20: =$AK$74 -> 0.9129903 | AX20: =$AL$74 -> 0.77774903 | AY20: =$AM$74 -> #DIV/0! | AZ20: =$AN$74 -> #DIV/0! | BA20: =$AO$74 -> #DIV/0!
J21: 0.9994709 | K21: =AVERAGE(Q21,V21,AA21,AF21,AK21,AP21) -> 0.90582011 | L21: =AVERAGE(R21,W21,AB21,AG21,AL21,AQ21) -> 0.63743676 | M21: =AVERAGE(S21,X21,AC21,AH21,AM21,AR21) -> #DIV/0! | N21: =AVERAGE(T21,Y21,AD21,AI21,AN21,AS21) -> #DIV/0! | O21: =AVERAGE(U21,Z21,AE21,AJ21,AO21,AT21) -> #DIV/0! | Q21: 0.97883598 | R21: 0.75042159 | V21: 0.95502646 | W21: 0.62394604 | AA21: 0.92857143 | AB21: 0.52107926 | AF21: 0.69047619 | AG21: 0.68296796 | AK21: 0.97619048 | AL21: 0.60876897 | AV21: 6 | AW21: =$AP$74 -> #DIV/0! | AX21: =$AQ$74 -> #DIV/0! | AY21: =$AR$74 -> #DIV/0! | AZ21: =$AS$74 -> #DIV/0! | BA21: =$AT$74 -> #DIV/0!
J22: 0.98721805 | K22: =AVERAGE(Q22,V22,AA22,AF22,AK22,AP22) -> 0.90526316 | L22: =AVERAGE(R22,W22,AB22,AG22,AL22,AQ22) -> 0.61525773 | M22: =AVERAGE(S22,X22,AC22,AH22,AM22,AR22) -> #DIV/0! | N22: =AVERAGE(T22,Y22,AD22,AI22,AN22,AS22) -> #DIV/0! | O22: =AVERAGE(U22,Z22,AE22,AJ22,AO22,AT22) -> #DIV/0! | Q22: 0.85714286 | R22: 0.70309278 | V22: 0.91353383 | W22: 0.65979381 | AA22: 0.92857143 | AB22: 0.59793814 | AF22: 0.92105263 | AG22: 0.57113402 | AK22: 0.90601504 | AL22: 0.5443299
J23: 0.98528428 | K23: =AVERAGE(Q23,V23,AA23,AF23,AK23,AP23) -> 0.94916388 | L23: =AVERAGE(R23,W23,AB23,AG23,AL23,AQ23) -> 0.82987698 | M23: =AVERAGE(S23,X23,AC23,AH23,AM23,AR23) -> #DIV/0! | N23: =AVERAGE(T23,Y23,AD23,AI23,AN23,AS23) -> #DIV/0! | O23: =AVERAGE(U23,Z23,AE23,AJ23,AO23,AT23) -> #DIV/0! | Q23: 0.95986622 | R23: 0.60281195 | V23: 0.98662207 | W23: 0.89806678 | AA23: 0.98662207 | AB23: 0.91915641 | AF23: 0.84615385 | AG23: 0.88224956 | AK23: 0.96655518 | AL23: 0.84710018
J24: 0.98940397 | K24: =AVERAGE(Q24,V24,AA24,AF24,AK24,AP24) -> 0.97350993 | L24: =AVERAGE(R24,W24,AB24,AG24,AL24,AQ24) -> 0.81625442 | M24: =AVERAGE(S24,X24,AC24,AH24,AM24,AR24) -> #DIV/0! | N24: =AVERAGE(T24,Y24,AD24,AI24,AN24,AS24) -> #DIV/0! | O24: =AVERAGE(U24,Z24,AE24,AJ24,AO24,AT24) -> #DIV/0! | Q24: 0.99006623 | R24: 0.81978799 | V24: 0.9602649 | W24: 0.75088339 | AA24: 0.97682119 | AB24: 0.92932862 | AF24: 0.97019868 | AG24: 0.87809187 | AK24: 0.97019868 | AL24: 0.70318021
J25: 0.98798956 | K25: =AVERAGE(Q25,V25,AA25,AF25,AK25,AP25) -> 0.82767624 | L25: =AVERAGE(R25,W25,AB25,AG25,AL25,AQ25) -> 0.78294849 | M25: =AVERAGE(S25,X25,AC25,AH25,AM25,AR25) -> #DIV/0! | N25: =AVERAGE(T25,Y25,AD25,AI25,AN25,AS25) -> #DIV/0! | O25: =AVERAGE(U25,Z25,AE25,AJ25,AO25,AT25) -> #DIV/0! | Q25: 0.90600522 | R25: 0.79396092 | V25: 0.88772846 | W25: 0.72468917 | AA25: 0.76240209 | AB25: 0.76198934 | AF25: 0.7310705 | AG25: 0.77797513 | AK25: 0.85117493 | AL25: 0.85612789 | AV25: =A8 -> 1 | AW25: Task 2 | AX25: Task 3 | AY25: Task 4 | AZ25: Task 5 | BA25: Task 6
J26: 0.99354839 | K26: =AVERAGE(Q26,V26,AA26,AF26,AK26,AP26) -> 0.84623656 | L26: =AVERAGE(R26,W26,AB26,AG26,AL26,AQ26) -> 0.78798587 | M26: =AVERAGE(S26,X26,AC26,AH26,AM26,AR26) -> #DIV/0! | N26: =AVERAGE(T26,Y26,AD26,AI26,AN26,AS26) -> #DIV/0! | O26: =AVERAGE(U26,Z26,AE26,AJ26,AO26,AT26) -> #DIV/0! | Q26: 0.82795699 | R26: 0.68374558 | V26: 0.91397849 | W26: 0.86042403 | AA26: 0.89247312 | AB26: 0.80388693 | AF26: 0.84946237 | AG26: 0.74911661 | AK26: 0.74731183 | AL26: 0.84275618 | AV26: 1 | AW26: =$Q$111 -> 0.91467365 | AX26: =$R$111 -> 0.80377509 | AY26: =$S$111 -> #DIV/0! | AZ26: =$T$111 -> #DIV/0! | BA26: =$U$111 -> #DIV/0!
J27: 0.99812207 | K27: =AVERAGE(Q27,V27,AA27,AF27,AK27,AP27) -> 0.96056338 | L27: =AVERAGE(R27,W27,AB27,AG27,AL27,AQ27) -> 0.85165049 | M27: =AVERAGE(S27,X27,AC27,AH27,AM27,AR27) -> #DIV/0! | N27: =AVERAGE(T27,Y27,AD27,AI27,AN27,AS27) -> #DIV/0! | O27: =AVERAGE(U27,Z27,AE27,AJ27,AO27,AT27) -> #DIV/0! | Q27: 0.95305164 | R27: 0.93398058 | V27: 0.97652582 | W27: 0.71456311 | AA27: 0.93896714 | AB27: 0.93009709 | AF27: 0.94835681 | AG27: 0.92621359 | AK27: 0.98591549 | AL27: 0.75339806 | AV27: 2 | AW27: =$V$111 -> 0.9140956 | AX27: =$W$111 -> 0.79008739 | AY27: =$X$111 -> #DIV/0! | AZ27: =$Y$111 -> #DIV/0! | BA27: =$Z$111 -> #DIV/0!
J28: 0.9994709 | K28: =AVERAGE(Q28,V28,AA28,AF28,AK28,AP28) -> 0.8005291 | L28: =AVERAGE(R28,W28,AB28,AG28,AL28,AQ28) -> 0.55329768 | M28: =AVERAGE(S28,X28,AC28,AH28,AM28,AR28) -> #DIV/0! | N28: =AVERAGE(T28,Y28,AD28,AI28,AN28,AS28) -> #DIV/0! | O28: =AVERAGE(U28,Z28,AE28,AJ28,AO28,AT28) -> #DIV/0! | Q28: 0.74867725 | R28: 0.42424242 | V28: 0.95767196 | W28: 0.42067736 | AA28: 0.62698413 | AB28: 0.42602496 | AF28: 0.93121693 | AG28: 0.78787879 | AK28: 0.73809524 | AL28: 0.70766488 | AV28: 3 | AW28: =$AA$111 -> 0.90908977 | AX28: =$AB$111 -> 0.77899269 | AY28: =$AC$111 -> #DIV/0! | AZ28: =$AD$111 -> #DIV/0! | BA28: =$AE$111 -> #DIV/0!
J29: 0.99908257 | K29: =AVERAGE(Q29,V29,AA29,AF29,AK29,AP29) -> 0.9412844 | L29: =AVERAGE(R29,W29,AB29,AG29,AL29,AQ29) -> 0.73783304 | M29: =AVERAGE(S29,X29,AC29,AH29,AM29,AR29) -> #DIV/0! | N29: =AVERAGE(T29,Y29,AD29,AI29,AN29,AS29) -> #DIV/0! | O29: =AVERAGE(U29,Z29,AE29,AJ29,AO29,AT29) -> #DIV/0! | Q29: 0.9587156 | R29: 0.8277087 | V29: 0.91743119 | W29: 0.77442274 | AA29: 0.9266055 | AB29: 0.73001776 | AF29: 0.97706422 | AG29: 0.70515098 | AK29: 0.9266055 | AL29: 0.65186501 | AV29: 4 | AW29: =$AF$111 -> 0.88873659 | AX29: =$AG$111 -> 0.78496224 | AY29: =$AH$111 -> #DIV/0! | AZ29: =$AI$111 -> #DIV/0! | BA29: =$AJ$111 -> #DIV/0!
J30: 0.99166667 | K30: =AVERAGE(Q30,V30,AA30,AF30,AK30,AP30) -> 0.94074074 | L30: =AVERAGE(R30,W30,AB30,AG30,AL30,AQ30) -> 0.79929329 | M30: =AVERAGE(S30,X30,AC30,AH30,AM30,AR30) -> #DIV/0! | N30: =AVERAGE(T30,Y30,AD30,AI30,AN30,AS30) -> #DIV/0! | O30: =AVERAGE(U30,Z30,AE30,AJ30,AO30,AT30) -> #DIV/0! | Q30: 0.94444444 | R30: 0.82155477 | V30: 0.96759259 | W30: 0.85159011 | AA30: 0.93981481 | AB30: 0.86572438 | AF30: 0.93981481 | AG30: 0.77385159 | AK30: 0.91203704 | AL30: 0.68374558 | AV30: 5 | AW30: =$AK$111 -> 0.92359354 | AX30: =$AL$111 -> 0.79443227 | AY30: =$AM$111 -> #DIV/0! | AZ30: =$AN$111 -> #DIV/0! | BA30: =$AO$111 -> #DIV/0!
J31: 0.99316239 | K31: =AVERAGE(Q31,V31,AA31,AF31,AK31,AP31) -> 0.93846154 | L31: =AVERAGE(R31,W31,AB31,AG31,AL31,AQ31) -> 0.88617021 | M31: =AVERAGE(S31,X31,AC31,AH31,AM31,AR31) -> #DIV/0! | N31: =AVERAGE(T31,Y31,AD31,AI31,AN31,AS31) -> #DIV/0! | O31: =AVERAGE(U31,Z31,AE31,AJ31,AO31,AT31) -> #DIV/0! | Q31: 0.95726496 | R31: 0.84574468 | V31: 0.93447293 | W31: 0.91134752 | AA31: 0.95156695 | AB31: 0.89893617 | AF31: 0.91452991 | AG31: 0.85283688 | AK31: 0.93447293 | AL31: 0.92198582 | AV31: 6 | AW31: =$AP$111 -> #DIV/0! | AX31: =$AQ$111 -> #DIV/0! | AY31: =$AR$111 -> #DIV/0! | AZ31: =$AS$111 -> #DIV/0! | BA31: =$AT$111 -> #DIV/0!
