Workbook

Sheet Person_0
K3: k=0.25
S4: 1 | Y4: 2 | AE4: 3 | AK4: 4 | AQ4: 5 | AW4: 6
A5: k | B5: Task 1 | C5: Task 2 | D5: Task 3 | E5: Task 4 | F5: Task 5 | G5: Task 6 | J5: ID | K5: Task 1 | L5: Task 2 | M5: Task 3 | N5: Task 4 | O5: Task 5 | P5: Task 6 | R5: Task 1 | S5: Task 2 | T5: Task 3 | U5: Task 4 | V5: Task 5 | W5: Task 6 | X5: Task 1 | Y5: Task 2 | Z5: Task 3 | AA5: Task 4 | AB5: Task 5 | AC5: Task 6 | AD5: Task 1 | AE5: Task 2 | AF5: Task 3 | AG5: Task 4 | AH5: Task 5 | AI5: Task 6 | AJ5: Task 1 | AK5: Task 2 | AL5: Task 3 | AM5: Task 4 | AN5: Task 5 | AO5: Task 6 | AP5: Task 1 | AQ5: Task 2 | AR5: Task 3 | AS5: Task 4 | AT5: Task 5 | AU5: Task 6 | AV5: Task 1 | AW5: Task 2 | AX5: Task 3 | AY5: Task 4 | AZ5: Task 5 | BA5: Task 6 | BD5: =A6 -> 0.25 | BE5: Task 1 | BF5: Task 2 | BG5: Task 3 | BH5: Task 4 | BI5: Task 5 | BJ5: Task 6
A6: 0.25 | B6: =AVERAGE(K6:K35) -> 0.95913484 | C6: =AVERAGE(L6:L35) -> 0.91040963 | D6: =AVERAGE(M6:M35) -> 0.76581373 | E6: =AVERAGE(N6:N35) -> 0.63133176 | F6: =AVERAGE(O6:O35) -> 0.53794176 | G6: =AVERAGE(P6:P35) -> #DIV/0! | J6: 1 | K6: =AVERAGE(R6,X6,AD6,AJ6,AP6,AV6) -> 0.90639269 | L6: =AVERAGE(S6,Y6,AE6,AK6,AQ6,AW6) -> 0.91206544 | M6: =AVERAGE(T6,Z6,AF6,AL6,AR6,AX6) -> 0.68367347 | N6: =AVERAGE(U6,AA6,AG6,AM6,AS6,AY6) -> 0.68763103 | O6: =AVERAGE(V6,AB6,AH6,AN6,AT6,AZ6) -> 0.62383376 | P6: =AVERAGE(W6,AC6,AI6,AO6,AU6,BA6) -> #DIV/0! | R6: 0.93150685 | S6: 0.88343558 | T6: 0.73061224 | U6: 0.74213836 | V6: 0.6259542 | X6: 0.90410959 | Y6: 0.93251534 | Z6: 0.72244898 | AA6: 0.72327044 | AB6: 0.57506361 | AD6: 0.90410959 | AE6: 0.92638037 | AF6: 0.62857143 | AG6: 0.58805031 | AH6: 0.56997455 | AJ6: 0.89041096 | AK6: 0.88343558 | AL6: 0.64081633 | AM6: 0.63207547 | AN6: 0.67175573 | AP6: 0.93150685 | AQ6: 0.91411043 | AR6: 0.67346939 | AS6: 0.69496855 | AT6: 0.60559796 | AV6: 0.87671233 | AW6: 0.93251534 | AX6: 0.70612245 | AY6: 0.74528302 | AZ6: 0.69465649 | BD6: 1 | BE6: =$R$37 -> 0.96066166 | BF6: =$S$37 -> 0.909311 | BG6: =$T$37 -> 0.75435746 | BH6: =$U$37 -> 0.63331915 | BI6: =$V$37 -> 0.53129771 | BJ6: =$W$37 -> #DIV/0!
A7: 0.5 | B7: =AVERAGE(K43:K72) -> 0.95714522 | C7: =AVERAGE(L43:L72) -> 0.91861624 | D7: =AVERAGE(M43:M72) -> 0.78132419 | E7: =AVERAGE(N43:N72) -> 0.64805988 | F7: =AVERAGE(O43:O72) -> 0.53319197 | G7: =AVERAGE(P43:P72) -> #DIV/0! | J7: 2 | K7: =AVERAGE(R7,X7,AD7,AJ7,AP7,AV7) -> 0.83141762 | L7: =AVERAGE(S7,Y7,AE7,AK7,AQ7,AW7) -> 0.82525253 | M7: =AVERAGE(T7,Z7,AF7,AL7,AR7,AX7) -> 0.83134921 | N7: =AVERAGE(U7,AA7,AG7,AM7,AS7,AY7) -> 0.70715037 | O7: =AVERAGE(V7,AB7,AH7,AN7,AT7,AZ7) -> 0.60687023 | P7: =AVERAGE(W7,AC7,AI7,AO7,AU7,BA7) -> #DIV/0! | R7: 0.81609195 | S7: 0.83030303 | T7: 0.73809524 | U7: 0.64353312 | V7: 0.62340967 | X7: 0.87356322 | Y7: 0.87272727 | Z7: 0.89285714 | AA7: 0.73501577 | AB7: 0.73536896 | AD7: 0.87356322 | AE7: 0.83030303 | AF7: 0.80555556 | AG7: 0.7192429 | AH7: 0.60814249 | AJ7: 0.82758621 | AK7: 0.8 | AL7: 0.8452381 | AM7: 0.62776025 | AN7: 0.55979644 | AP7: 0.74712644 | AQ7: 0.87272727 | AR7: 0.8531746 | AS7: 0.83911672 | AT7: 0.55979644 | AV7: 0.85057471 | AW7: 0.74545455 | AX7: 0.8531746 | AY7: 0.67823344 | AZ7: 0.55470738 | BD7: 2 | BE7: =$X$37 -> 0.95883493 | BF7: =$Y$37 -> 0.92190656 | BG7: =$Z$37 -> 0.77537592 | BH7: =$AA$37 -> 0.62538014 | BI7: =$AB$37 -> 0.53443596 | BJ7: =$AC$37 -> #DIV/0!
A8: 1 | B8: =AVERAGE(K80:K109) -> 0.95770502 | C8: =AVERAGE(L80:L109) -> 0.91745538 | D8: =AVERAGE(M80:M109) -> 0.78630776 | E8: =AVERAGE(N80:N109) -> 0.65379017 | F8: =AVERAGE(O80:O109) -> 0.53970879 | G8: =AVERAGE(P80:P109) -> #DIV/0! | J8: 3 | K8: =AVERAGE(R8,X8,AD8,AJ8,AP8,AV8) -> 0.9875 | L8: =AVERAGE(S8,Y8,AE8,AK8,AQ8,AW8) -> 0.97634409 | M8: =AVERAGE(T8,Z8,AF8,AL8,AR8,AX8) -> 0.89593114 | N8: =AVERAGE(U8,AA8,AG8,AM8,AS8,AY8) -> 0.56105611 | O8: =AVERAGE(V8,AB8,AH8,AN8,AT8,AZ8) -> 0.50932994 | P8: =AVERAGE(W8,AC8,AI8,AO8,AU8,BA8) -> #DIV/0! | R8: 0.9875 | S8: 0.96774194 | T8: 0.92957746 | U8: 0.50165017 | V8: 0.43002545 | X8: 0.9875 | Y8: 0.98064516 | Z8: 0.81220657 | AA8: 0.42574257 | AB8: 0.38422392 | AD8: 0.9875 | AE8: 0.98064516 | AF8: 0.90140845 | AG8: 0.72937294 | AH8: 0.63358779 | AJ8: 0.9875 | AK8: 0.98709677 | AL8: 0.89201878 | AM8: 0.6369637 | AN8: 0.58778626 | AP8: 0.9875 | AQ8: 0.96774194 | AR8: 0.90610329 | AS8: 0.55775578 | AT8: 0.5648855 | AV8: 0.9875 | AW8: 0.97419355 | AX8: 0.9342723 | AY8: 0.51485149 | AZ8: 0.45547074 | BD8: 3 | BE8: =$AD$37 -> 0.9589045 | BF8: =$AE$37 -> 0.91045012 | BG8: =$AF$37 -> 0.76749577 | BH8: =$AG$37 -> 0.61392903 | BI8: =$AH$37 -> 0.52731128 | BJ8: =$AI$37 -> #DIV/0!
A9: 2 | B9: =AVERAGE(K117:K146) -> 0.95651239 | C9: =AVERAGE(L117:L146) -> 0.92162091 | D9: =AVERAGE(M117:M146) -> 0.77953284 | E9: =AVERAGE(N117:N146) -> 0.63142062 | F9: =AVERAGE(O117:O146) -> 0.51210065 | G9: =AVERAGE(P117:P146) -> #DIV/0! | J9: 4 | K9: =AVERAGE(R9,X9,AD9,AJ9,AP9,AV9) -> 0.98684211 | L9: =AVERAGE(S9,Y9,AE9,AK9,AQ9,AW9) -> 0.94008715 | M9: =AVERAGE(T9,Z9,AF9,AL9,AR9,AX9) -> 0.74013605 | N9: =AVERAGE(U9,AA9,AG9,AM9,AS9,AY9) -> 0.50327869 | O9: =AVERAGE(V9,AB9,AH9,AN9,AT9,AZ9) -> 0.50678541 | P9: =AVERAGE(W9,AC9,AI9,AO9,AU9,BA9) -> #DIV/0! | R9: 0.98684211 | S9: 0.95424837 | T9: 0.73061224 | U9: 0.53114754 | V9: 0.57251908 | X9: 0.98684211 | Y9: 0.93464052 | Z9: 0.73877551 | AA9: 0.55737705 | AB9: 0.48600509 | AD9: 0.98684211 | AE9: 0.95424837 | AF9: 0.79183673 | AG9: 0.47213115 | AH9: 0.47582697 | AJ9: 0.98684211 | AK9: 0.96078431 | AL9: 0.77959184 | AM9: 0.38360656 | AN9: 0.46564885 | AP9: 0.98684211 | AQ9: 0.96078431 | AR9: 0.76734694 | AS9: 0.6852459 | AT9: 0.51908397 | AV9: 0.98684211 | AW9: 0.87581699 | AX9: 0.63265306 | AY9: 0.39016393 | AZ9: 0.5216285 | BD9: 4 | BE9: =$AJ$37 -> 0.95919644 | BF9: =$AK$37 -> 0.91025681 | BG9: =$AL$37 -> 0.75650788 | BH9: =$AM$37 -> 0.63390113 | BI9: =$AN$37 -> 0.54775233 | BJ9: =$AO$37 -> #DIV/0!
A10: 3 | B10: =AVERAGE(K154:K183) -> 0.95817956 | C10: =AVERAGE(L154:L183) -> 0.91900857 | D10: =AVERAGE(M154:M183) -> 0.76348459 | E10: =AVERAGE(N154:N183) -> 0.6187973 | F10: =AVERAGE(O154:O183) -> 0.49652248 | G10: =AVERAGE(P154:P183) -> #DIV/0! | J10: 5 | K10: =AVERAGE(R10,X10,AD10,AJ10,AP10,AV10) -> 0.97727273 | L10: =AVERAGE(S10,Y10,AE10,AK10,AQ10,AW10) -> 0.92883895 | M10: =AVERAGE(T10,Z10,AF10,AL10,AR10,AX10) -> 0.75625823 | N10: =AVERAGE(U10,AA10,AG10,AM10,AS10,AY10) -> 0.63403614 | O10: =AVERAGE(V10,AB10,AH10,AN10,AT10,AZ10) -> 0.49406277 | P10: =AVERAGE(W10,AC10,AI10,AO10,AU10,BA10) -> #DIV/0! | R10: 0.97727273 | S10: 0.95505618 | T10: 0.73517787 | U10: 0.67771084 | V10: 0.49109415 | X10: 0.97727273 | Y10: 0.93820225 | Z10: 0.80237154 | AA10: 0.73493976 | AB10: 0.5394402 | AD10: 0.97727273 | AE10: 0.85393258 | AF10: 0.75494071 | AG10: 0.54819277 | AH10: 0.52926209 | AJ10: 0.97727273 | AK10: 0.92134831 | AL10: 0.71146245 | AM10: 0.59939759 | AN10: 0.45038168 | AP10: 0.97727273 | AQ10: 0.95505618 | AR10: 0.7826087 | AS10: 0.72891566 | AT10: 0.44529262 | AV10: 0.97727273 | AW10: 0.9494382 | AX10: 0.75098814 | AY10: 0.51506024 | AZ10: 0.50890585 | BD10: 5 | BE10: =$AP$37 -> 0.95503 | BF10: =$AQ$37 -> 0.91673101 | BG10: =$AR$37 -> 0.77947922 | BH10: =$AS$37 -> 0.65291421 | BI10: =$AT$37 -> 0.53918575 | BJ10: =$AU$37 -> #DIV/0!
J11: 6 | K11: =AVERAGE(R11,X11,AD11,AJ11,AP11,AV11) -> 0.95925926 | L11: =AVERAGE(S11,Y11,AE11,AK11,AQ11,AW11) -> 0.86605317 | M11: =AVERAGE(T11,Z11,AF11,AL11,AR11,AX11) -> 0.79459064 | N11: =AVERAGE(U11,AA11,AG11,AM11,AS11,AY11) -> 0.71342134 | O11: =AVERAGE(V11,AB11,AH11,AN11,AT11,AZ11) -> 0.57675997 | P11: =AVERAGE(W11,AC11,AI11,AO11,AU11,BA11) -> #DIV/0! | R11: 0.96666667 | S11: 0.95092025 | T11: 0.86842105 | U11: 0.74917492 | V11: 0.5394402 | X11: 0.97777778 | Y11: 0.9202454 | Z11: 0.88157895 | AA11: 0.67986799 | AB11: 0.63358779 | AD11: 0.95555556 | AE11: 0.8404908 | AF11: 0.63596491 | AG11: 0.72277228 | AH11: 0.57506361 | AJ11: 0.95555556 | AK11: 0.91411043 | AL11: 0.74122807 | AM11: 0.67326733 | AN11: 0.50381679 | AP11: 0.95555556 | AQ11: 0.93251534 | AR11: 0.87719298 | AS11: 0.68646865 | AT11: 0.5648855 | AV11: 0.94444444 | AW11: 0.63803681 | AX11: 0.76315789 | AY11: 0.7689769 | AZ11: 0.6437659 | BD11: 6 | BE11: =$AV$37 -> 0.96218151 | BF11: =$AW$37 -> 0.89380227 | BG11: =$AX$37 -> 0.7616661 | BH11: =$AY$37 -> 0.62854689 | BI11: =$AZ$37 -> 0.54766751 | BJ11: =$BA$37 -> #DIV/0!
J12: 7 | K12: =AVERAGE(R12,X12,AD12,AJ12,AP12,AV12) -> 0.93958333 | L12: =AVERAGE(S12,Y12,AE12,AK12,AQ12,AW12) -> 0.90952381 | M12: =AVERAGE(T12,Z12,AF12,AL12,AR12,AX12) -> 0.64220183 | N12: =AVERAGE(U12,AA12,AG12,AM12,AS12,AY12) -> 0.69415808 | O12: =AVERAGE(V12,AB12,AH12,AN12,AT12,AZ12) -> 0.71119593 | P12: =AVERAGE(W12,AC12,AI12,AO12,AU12,BA12) -> #DIV/0! | R12: 0.925 | S12: 0.92142857 | T12: 0.55045872 | U12: 0.67697595 | V12: 0.7480916 | X12: 0.95 | Y12: 0.9 | Z12: 0.60550459 | AA12: 0.61512027 | AB12: 0.62340967 | AD12: 0.9375 | AE12: 0.88571429 | AF12: 0.6146789 | AG12: 0.69415808 | AH12: 0.66412214 | AJ12: 0.9625 | AK12: 0.92857143 | AL12: 0.68348624 | AM12: 0.6838488 | AN12: 0.70992366 | AP12: 0.925 | AQ12: 0.93571429 | AR12: 0.75688073 | AS12: 0.76632302 | AT12: 0.76081425 | AV12: 0.9375 | AW12: 0.88571429 | AX12: 0.64220183 | AY12: 0.72852234 | AZ12: 0.76081425
J13: 8 | K13: =AVERAGE(R13,X13,AD13,AJ13,AP13,AV13) -> 0.93859649 | L13: =AVERAGE(S13,Y13,AE13,AK13,AQ13,AW13) -> 0.89301802 | M13: =AVERAGE(T13,Z13,AF13,AL13,AR13,AX13) -> 0.74035813 | N13: =AVERAGE(U13,AA13,AG13,AM13,AS13,AY13) -> 0.43492063 | O13: =AVERAGE(V13,AB13,AH13,AN13,AT13,AZ13) -> 0.43723494 | P13: =AVERAGE(W13,AC13,AI13,AO13,AU13,BA13) -> #DIV/0! | R13: 0.94736842 | S13: 0.85810811 | T13: 0.72727273 | U13: 0.38730159 | V13: 0.27735369 | X13: 0.94736842 | Y13: 0.91216216 | Z13: 0.79338843 | AA13: 0.48571429 | AB13: 0.52417303 | AD13: 0.92105263 | AE13: 0.93243243 | AF13: 0.83884298 | AG13: 0.47619048 | AH13: 0.44529262 | AJ13: 0.97368421 | AK13: 0.89189189 | AL13: 0.71900826 | AM13: 0.48888889 | AN13: 0.5394402 | AP13: 0.92105263 | AQ13: 0.89864865 | AR13: 0.69008264 | AS13: 0.30793651 | AT13: 0.41475827 | AV13: 0.92105263 | AW13: 0.86486486 | AX13: 0.67355372 | AY13: 0.46349206 | AZ13: 0.42239186 | BD13: =A7 -> 0.5 | BE13: Task 1 | BF13: Task 2 | BG13: Task 3 | BH13: Task 4 | BI13: Task 5 | BJ13: Task 6
J14: 9 | K14: =AVERAGE(R14,X14,AD14,AJ14,AP14,AV14) -> 0.98717949 | L14: =AVERAGE(S14,Y14,AE14,AK14,AQ14,AW14) -> 0.94111776 | M14: =AVERAGE(T14,Z14,AF14,AL14,AR14,AX14) -> 0.75069444 | N14: =AVERAGE(U14,AA14,AG14,AM14,AS14,AY14) -> 0.58142077 | O14: =AVERAGE(V14,AB14,AH14,AN14,AT14,AZ14) -> 0.51950806 | P14: =AVERAGE(W14,AC14,AI14,AO14,AU14,BA14) -> #DIV/0! | R14: 0.98717949 | S14: 0.95209581 | T14: 0.725 | U14: 0.59344262 | V14: 0.48600509 | X14: 0.98717949 | Y14: 0.90419162 | Z14: 0.72083333 | AA14: 0.6 | AB14: 0.50890585 | AD14: 0.98717949 | AE14: 0.94610778 | AF14: 0.7875 | AG14: 0.4852459 | AH14: 0.4783715 | AJ14: 0.98717949 | AK14: 0.96407186 | AL14: 0.75 | AM14: 0.69508197 | AN14: 0.56234097 | AP14: 0.98717949 | AQ14: 0.95209581 | AR14: 0.7875 | AS14: 0.62622951 | AT14: 0.51908397 | AV14: 0.98717949 | AW14: 0.92814371 | AX14: 0.73333333 | AY14: 0.48852459 | AZ14: 0.56234097 | BD14: 1 | BE14: =$R$74 -> 0.9587168 | BF14: =$S$74 -> 0.91348598 | BG14: =$T$74 -> 0.78870511 | BH14: =$U$74 -> 0.65470087 | BI14: =$V$74 -> 0.52400339 | BJ14: =$W$74 -> #DIV/0!
J15: 10 | K15: =AVERAGE(R15,X15,AD15,AJ15,AP15,AV15) -> 0.98684211 | L15: =AVERAGE(S15,Y15,AE15,AK15,AQ15,AW15) -> 0.95522388 | M15: =AVERAGE(T15,Z15,AF15,AL15,AR15,AX15) -> 0.81067251 | N15: =AVERAGE(U15,AA15,AG15,AM15,AS15,AY15) -> 0.65079365 | O15: =AVERAGE(V15,AB15,AH15,AN15,AT15,AZ15) -> 0.46819338 | P15: =AVERAGE(W15,AC15,AI15,AO15,AU15,BA15) -> #DIV/0! | R15: 0.98684211 | S15: 0.95522388 | T15: 0.8377193 | U15: 0.63492063 | V15: 0.52417303 | X15: 0.98684211 | Y15: 0.96268657 | Z15: 0.74122807 | AA15: 0.70793651 | AB15: 0.4605598 | AD15: 0.98684211 | AE15: 0.96268657 | AF15: 0.80263158 | AG15: 0.62539683 | AH15: 0.43765903 | AJ15: 0.98684211 | AK15: 0.96268657 | AL15: 0.80263158 | AM15: 0.69206349 | AN15: 0.51653944 | AP15: 0.98684211 | AQ15: 0.94029851 | AR15: 0.82894737 | AS15: 0.61587302 | AT15: 0.38167939 | AV15: 0.98684211 | AW15: 0.94776119 | AX15: 0.85087719 | AY15: 0.62857143 | AZ15: 0.48854962 | BD15: 2 | BE15: =$X$74 -> 0.95890558 | BF15: =$Y$74 -> 0.9205368 | BG15: =$Z$74 -> 0.770656 | BH15: =$AA$74 -> 0.64390258 | BI15: =$AB$74 -> 0.52917727 | BJ15: =$AC$74 -> #DIV/0!
J16: 11 | K16: =AVERAGE(R16,X16,AD16,AJ16,AP16,AV16) -> 0.89726027 | L16: =AVERAGE(S16,Y16,AE16,AK16,AQ16,AW16) -> 0.89845475 | M16: =AVERAGE(T16,Z16,AF16,AL16,AR16,AX16) -> 0.79355281 | N16: =AVERAGE(U16,AA16,AG16,AM16,AS16,AY16) -> 0.66226623 | O16: =AVERAGE(V16,AB16,AH16,AN16,AT16,AZ16) -> 0.56743003 | P16: =AVERAGE(W16,AC16,AI16,AO16,AU16,BA16) -> #DIV/0! | R16: 0.91780822 | S16: 0.9205298 | T16: 0.76954733 | U16: 0.68646865 | V16: 0.51145038 | X16: 0.84931507 | Y16: 0.83443709 | Z16: 0.74897119 | AA16: 0.66336634 | AB16: 0.50381679 | AD16: 0.89041096 | AE16: 0.91390728 | AF16: 0.83950617 | AG16: 0.63036304 | AH16: 0.59033079 | AJ16: 0.90410959 | AK16: 0.92715232 | AL16: 0.79012346 | AM16: 0.64686469 | AN16: 0.61832061 | AP16: 0.89041096 | AQ16: 0.90728477 | AR16: 0.79012346 | AS16: 0.69966997 | AT16: 0.68956743 | AV16: 0.93150685 | AW16: 0.88741722 | AX16: 0.82304527 | AY16: 0.64686469 | AZ16: 0.49109415 | BD16: 3 | BE16: =$AD$74 -> 0.95654643 | BF16: =$AE$74 -> 0.92310344 | BG16: =$AF$74 -> 0.77916575 | BH16: =$AG$74 -> 0.64962732 | BI16: =$AH$74 -> 0.53061917 | BJ16: =$AI$74 -> #DIV/0!
J17: 12 | K17: =AVERAGE(R17,X17,AD17,AJ17,AP17,AV17) -> 0.98907104 | L17: =AVERAGE(S17,Y17,AE17,AK17,AQ17,AW17) -> 0.84191176 | M17: =AVERAGE(T17,Z17,AF17,AL17,AR17,AX17) -> 0.79559748 | N17: =AVERAGE(U17,AA17,AG17,AM17,AS17,AY17) -> 0.75328947 | O17: =AVERAGE(V17,AB17,AH17,AN17,AT17,AZ17) -> 0.68871925 | P17: =AVERAGE(W17,AC17,AI17,AO17,AU17,BA17) -> #DIV/0! | R17: 1 | S17: 0.77941176 | T17: 0.82075472 | U17: 0.75 | V17: 0.65394402 | X17: 0.98360656 | Y17: 0.85294118 | Z17: 0.78773585 | AA17: 0.68421053 | AB17: 0.5648855 | AD17: 0.98360656 | AE17: 0.81617647 | AF17: 0.76415094 | AG17: 0.81578947 | AH17: 0.7302799 | AJ17: 0.98360656 | AK17: 0.88235294 | AL17: 0.80660377 | AM17: 0.74342105 | AN17: 0.69211196 | AP17: 0.98360656 | AQ17: 0.86764706 | AR17: 0.79716981 | AS17: 0.73684211 | AT17: 0.75318066 | AV17: 1 | AW17: 0.85294118 | AX17: 0.79716981 | AY17: 0.78947368 | AZ17: 0.73791349 | BD17: 4 | BE17: =$AJ$74 -> 0.95511406 | BF17: =$AK$74 -> 0.91818809 | BG17: =$AL$74 -> 0.79223283 | BH17: =$AM$74 -> 0.63869411 | BI17: =$AN$74 -> 0.54215437 | BJ17: =$AO$74 -> #DIV/0!
J18: 13 | K18: =AVERAGE(R18,X18,AD18,AJ18,AP18,AV18) -> 0.94078947 | L18: =AVERAGE(S18,Y18,AE18,AK18,AQ18,AW18) -> 0.84926471 | M18: =AVERAGE(T18,Z18,AF18,AL18,AR18,AX18) -> 0.74778761 | N18: =AVERAGE(U18,AA18,AG18,AM18,AS18,AY18) -> 0.61521972 | O18: =AVERAGE(V18,AB18,AH18,AN18,AT18,AZ18) -> 0.50254453 | P18: =AVERAGE(W18,AC18,AI18,AO18,AU18,BA18) -> #DIV/0! | R18: 0.94736842 | S18: 0.83823529 | T18: 0.78761062 | U18: 0.66881029 | V18: 0.55725191 | X18: 0.96052632 | Y18: 0.81617647 | Z18: 0.73451327 | AA18: 0.47266881 | AB18: 0.4783715 | AD18: 0.94736842 | AE18: 0.78676471 | AF18: 0.69469027 | AG18: 0.57877814 | AH18: 0.4173028 | AJ18: 0.93421053 | AK18: 0.89705882 | AL18: 0.73451327 | AM18: 0.65916399 | AN18: 0.51908397 | AP18: 0.94736842 | AQ18: 0.88970588 | AR18: 0.75663717 | AS18: 0.7170418 | AT18: 0.53435115 | AV18: 0.90789474 | AW18: 0.86764706 | AX18: 0.77876106 | AY18: 0.59485531 | AZ18: 0.50890585 | BD18: 5 | BE18: =$AP$74 -> 0.9589093 | BF18: =$AQ$74 -> 0.92062392 | BG18: =$AR$74 -> 0.77658046 | BH18: =$AS$74 -> 0.65431158 | BI18: =$AT$74 -> 0.53282443 | BJ18: =$AU$74 -> #DIV/0!
J19: 14 | K19: =AVERAGE(R19,X19,AD19,AJ19,AP19,AV19) -> 0.98863636 | L19: =AVERAGE(S19,Y19,AE19,AK19,AQ19,AW19) -> 0.95098039 | M19: =AVERAGE(T19,Z19,AF19,AL19,AR19,AX19) -> 0.76118326 | N19: =AVERAGE(U19,AA19,AG19,AM19,AS19,AY19) -> 0.64485981 | O19: =AVERAGE(V19,AB19,AH19,AN19,AT19,AZ19) -> 0.57294317 | P19: =AVERAGE(W19,AC19,AI19,AO19,AU19,BA19) -> #DIV/0! | R19: 1 | S19: 0.95294118 | T19: 0.77056277 | U19: 0.72274143 | V19: 0.46310433 | X19: 0.97727273 | Y19: 0.94705882 | Z19: 0.74891775 | AA19: 0.46417445 | AB19: 0.50636132 | AD19: 0.98863636 | AE19: 0.93529412 | AF19: 0.81385281 | AG19: 0.74454829 | AH19: 0.73536896 | AJ19: 0.98863636 | AK19: 0.96470588 | AL19: 0.68398268 | AM19: 0.65420561 | AN19: 0.49363868 | AP19: 0.97727273 | AQ19: 0.93529412 | AR19: 0.77922078 | AS19: 0.62928349 | AT19: 0.6259542 | AV19: 1 | AW19: 0.97058824 | AX19: 0.77056277 | AY19: 0.65420561 | AZ19: 0.61323155 | BD19: 6 | BE19: =$AV$74 -> 0.95467915 | BF19: =$AW$74 -> 0.91575922 | BG19: =$AX$74 -> 0.78060497 | BH19: =$AY$74 -> 0.6471228 | BI19: =$AZ$74 -> 0.5403732 | BJ19: =$BA$74 -> #DIV/0!
J20: 15 | K20: =AVERAGE(R20,X20,AD20,AJ20,AP20,AV20) -> 0.98039216 | L20: =AVERAGE(S20,Y20,AE20,AK20,AQ20,AW20) -> 0.88229755 | M20: =AVERAGE(T20,Z20,AF20,AL20,AR20,AX20) -> 0.73933333 | N20: =AVERAGE(U20,AA20,AG20,AM20,AS20,AY20) -> 0.58941799 | O20: =AVERAGE(V20,AB20,AH20,AN20,AT20,AZ20) -> 0.49321459 | P20: =AVERAGE(W20,AC20,AI20,AO20,AU20,BA20) -> #DIV/0! | R20: 0.98039216 | S20: 0.88700565 | T20: 0.76 | U20: 0.66984127 | V20: 0.53689567 | X20: 0.98039216 | Y20: 0.93220339 | Z20: 0.744 | AA20: 0.64126984 | AB20: 0.51399491 | AD20: 0.98039216 | AE20: 0.88135593 | AF20: 0.724 | AG20: 0.46984127 | AH20: 0.39949109 | AJ20: 0.98039216 | AK20: 0.88135593 | AL20: 0.804 | AM20: 0.66666667 | AN20: 0.54452926 | AP20: 0.98039216 | AQ20: 0.82485876 | AR20: 0.652 | AS20: 0.46666667 | AT20: 0.4173028 | AV20: 0.98039216 | AW20: 0.88700565 | AX20: 0.752 | AY20: 0.62222222 | AZ20: 0.54707379
J21: 16 | K21: =AVERAGE(R21,X21,AD21,AJ21,AP21,AV21) -> 0.98666667 | L21: =AVERAGE(S21,Y21,AE21,AK21,AQ21,AW21) -> 0.97904192 | M21: =AVERAGE(T21,Z21,AF21,AL21,AR21,AX21) -> 0.83847283 | N21: =AVERAGE(U21,AA21,AG21,AM21,AS21,AY21) -> 0.67665615 | O21: =AVERAGE(V21,AB21,AH21,AN21,AT21,AZ21) -> 0.55343511 | P21: =AVERAGE(W21,AC21,AI21,AO21,AU21,BA21) -> #DIV/0! | R21: 0.98666667 | S21: 0.9760479 | T21: 0.84140969 | U21: 0.66876972 | V21: 0.5394402 | X21: 0.98666667 | Y21: 0.98203593 | Z21: 0.92951542 | AA21: 0.75078864 | AB21: 0.53435115 | AD21: 0.98666667 | AE21: 0.98203593 | AF21: 0.76211454 | AG21: 0.6466877 | AH21: 0.57251908 | AJ21: 0.98666667 | AK21: 0.9760479 | AL21: 0.85462555 | AM21: 0.8170347 | AN21: 0.65648855 | AP21: 0.98666667 | AQ21: 0.9760479 | AR21: 0.8061674 | AS21: 0.50473186 | AT21: 0.43256997 | AV21: 0.98666667 | AW21: 0.98203593 | AX21: 0.83700441 | AY21: 0.67192429 | AZ21: 0.58524173 | BD21: =A8 -> 1 | BE21: Task 1 | BF21: Task 2 | BG21: Task 3 | BH21: Task 4 | BI21: Task 5 | BJ21: Task 6
J22: 17 | K22: =AVERAGE(R22,X22,AD22,AJ22,AP22,AV22) -> 0.98666667 | L22: =AVERAGE(S22,Y22,AE22,AK22,AQ22,AW22) -> 0.95432099 | M22: =AVERAGE(T22,Z22,AF22,AL22,AR22,AX22) -> 0.84044234 | N22: =AVERAGE(U22,AA22,AG22,AM22,AS22,AY22) -> 0.67766777 | O22: =AVERAGE(V22,AB22,AH22,AN22,AT22,AZ22) -> 0.58948261 | P22: =AVERAGE(W22,AC22,AI22,AO22,AU22,BA22) -> #DIV/0! | R22: 0.98666667 | S22: 0.95555556 | T22: 0.84834123 | U22: 0.63366337 | V22: 0.65648855 | X22: 0.98666667 | Y22: 0.94814815 | Z22: 0.82938389 | AA22: 0.61386139 | AB22: 0.52926209 | AD22: 0.98666667 | AE22: 0.96296296 | AF22: 0.87677725 | AG22: 0.7359736 | AH22: 0.58778626 | AJ22: 0.98666667 | AK22: 0.96296296 | AL22: 0.81042654 | AM22: 0.65016502 | AN22: 0.60305344 | AP22: 0.98666667 | AQ22: 0.97037037 | AR22: 0.92417062 | AS22: 0.68976898 | AT22: 0.63867684 | AV22: 0.98666667 | AW22: 0.92592593 | AX22: 0.7535545 | AY22: 0.74257426 | AZ22: 0.5216285 | BD22: 1 | BE22: =$R$111 -> 0.96047629 | BF22: =$S$111 -> 0.91949299 | BG22: =$T$111 -> 0.77784978 | BH22: =$U$111 -> 0.64644003 | BI22: =$V$111 -> 0.54334182 | BJ22: =$W$111 -> #DIV/0!
J23: 18 | K23: =AVERAGE(R23,X23,AD23,AJ23,AP23,AV23) -> 0.97988506 | L23: =AVERAGE(S23,Y23,AE23,AK23,AQ23,AW23) -> 0.92808219 | M23: =AVERAGE(T23,Z23,AF23,AL23,AR23,AX23) -> 0.81674208 | N23: =AVERAGE(U23,AA23,AG23,AM23,AS23,AY23) -> 0.78403001 | O23: =AVERAGE(V23,AB23,AH23,AN23,AT23,AZ23) -> 0.65224767 | P23: =AVERAGE(W23,AC23,AI23,AO23,AU23,BA23) -> #DIV/0! | R23: 0.98275862 | S23: 0.95205479 | T23: 0.82352941 | U23: 0.78456592 | V23: 0.59287532 | X23: 0.98275862 | Y23: 0.96575342 | Z23: 0.83257919 | AA23: 0.80064309 | AB23: 0.72773537 | AD23: 0.98275862 | AE23: 0.92465753 | AF23: 0.85067873 | AG23: 0.77813505 | AH23: 0.63613232 | AJ23: 0.96551724 | AK23: 0.89726027 | AL23: 0.76923077 | AM23: 0.73633441 | AN23: 0.67175573 | AP23: 0.98275862 | AQ23: 0.95205479 | AR23: 0.89140271 | AS23: 0.83279743 | AT23: 0.68956743 | AV23: 0.98275862 | AW23: 0.87671233 | AX23: 0.73303167 | AY23: 0.77170418 | AZ23: 0.59541985 | BD23: 2 | BE23: =$X$111 -> 0.95482694 | BF23: =$Y$111 -> 0.9179397 | BG23: =$Z$111 -> 0.81057155 | BH23: =$AA$111 -> 0.66072235 | BI23: =$AB$111 -> 0.55657337 | BJ23: =$AC$111 -> #DIV/0!
J24: 19 | K24: =AVERAGE(R24,X24,AD24,AJ24,AP24,AV24) -> 0.98666667 | L24: =AVERAGE(S24,Y24,AE24,AK24,AQ24,AW24) -> 0.84 | M24: =AVERAGE(T24,Z24,AF24,AL24,AR24,AX24) -> 0.82011747 | N24: =AVERAGE(U24,AA24,AG24,AM24,AS24,AY24) -> 0.65846995 | O24: =AVERAGE(V24,AB24,AH24,AN24,AT24,AZ24) -> 0.53095844 | P24: =AVERAGE(W24,AC24,AI24,AO24,AU24,BA24) -> #DIV/0! | R24: 0.98666667 | S24: 0.73333333 | T24: 0.74449339 | U24: 0.69836066 | V24: 0.5394402 | X24: 0.98666667 | Y24: 0.92666667 | Z24: 0.89427313 | AA24: 0.67868852 | AB24: 0.61323155 | AD24: 0.98666667 | AE24: 0.83333333 | AF24: 0.81057269 | AG24: 0.58360656 | AH24: 0.43765903 | AJ24: 0.98666667 | AK24: 0.78666667 | AL24: 0.75770925 | AM24: 0.5704918 | AN24: 0.45292621 | AP24: 0.98666667 | AQ24: 0.94666667 | AR24: 0.88986784 | AS24: 0.71803279 | AT24: 0.60305344 | AV24: 0.98666667 | AW24: 0.81333333 | AX24: 0.82378855 | AY24: 0.70163934 | AZ24: 0.5394402 | BD24: 3 | BE24: =$AD$111 -> 0.95666172 | BF24: =$AE$111 -> 0.91658132 | BG24: =$AF$111 -> 0.7896671 | BH24: =$AG$111 -> 0.64442422 | BI24: =$AH$111 -> 0.542324 | BJ24: =$AI$111 -> #DIV/0!
J25: 20 | K25: =AVERAGE(R25,X25,AD25,AJ25,AP25,AV25) -> 0.97179487 | L25: =AVERAGE(S25,Y25,AE25,AK25,AQ25,AW25) -> 0.96815287 | M25: =AVERAGE(T25,Z25,AF25,AL25,AR25,AX25) -> 0.8211731 | N25: =AVERAGE(U25,AA25,AG25,AM25,AS25,AY25) -> 0.70833333 | O25: =AVERAGE(V25,AB25,AH25,AN25,AT25,AZ25) -> 0.62425785 | P25: =AVERAGE(W25,AC25,AI25,AO25,AU25,BA25) -> #DIV/0! | R25: 0.95384615 | S25: 0.96178344 | T25: 0.60515021 | U25: 0.68125 | V25: 0.57760814 | X25: 0.98461538 | Y25: 0.98089172 | Z25: 0.84978541 | AA25: 0.653125 | AB25: 0.5648855 | AD25: 0.98461538 | AE25: 0.94267516 | AF25: 0.86695279 | AG25: 0.690625 | AH25: 0.61323155 | AJ25: 0.98461538 | AK25: 0.96815287 | AL25: 0.84549356 | AM25: 0.740625 | AN25: 0.5216285 | AP25: 0.93846154 | AQ25: 0.97452229 | AR25: 0.84549356 | AS25: 0.759375 | AT25: 0.72519084 | AV25: 0.98461538 | AW25: 0.98089172 | AX25: 0.91416309 | AY25: 0.725 | AZ25: 0.74300254 | BD25: 4 | BE25: =$AJ$111 -> 0.95975313 | BF25: =$AK$111 -> 0.91919535 | BG25: =$AL$111 -> 0.78976268 | BH25: =$AM$111 -> 0.66577576 | BI25: =$AN$111 -> 0.55055131 | BJ25: =$AO$111 -> #DIV/0!
J26: 21 | K26: =AVERAGE(R26,X26,AD26,AJ26,AP26,AV26) -> 0.98461538 | L26: =AVERAGE(S26,Y26,AE26,AK26,AQ26,AW26) -> 0.92907801 | M26: =AVERAGE(T26,Z26,AF26,AL26,AR26,AX26) -> 0.71205008 | N26: =AVERAGE(U26,AA26,AG26,AM26,AS26,AY26) -> 0.56338798 | O26: =AVERAGE(V26,AB26,AH26,AN26,AT26,AZ26) -> 0.45547074 | P26: =AVERAGE(W26,AC26,AI26,AO26,AU26,BA26) -> #DIV/0! | R26: 0.98461538 | S26: 0.89361702 | T26: 0.5915493 | U26: 0.53114754 | V26: 0.48346056 | X26: 0.98461538 | Y26: 0.95744681 | Z26: 0.62910798 | AA26: 0.63278689 | AB26: 0.46310433 | AD26: 0.98461538 | AE26: 0.94326241 | AF26: 0.83098592 | AG26: 0.51147541 | AH26: 0.44783715 | AJ26: 0.98461538 | AK26: 0.93617021 | AL26: 0.77934272 | AM26: 0.52786885 | AN26: 0.40458015 | AP26: 0.98461538 | AQ26: 0.90070922 | AR26: 0.76995305 | AS26: 0.6295082 | AT26: 0.48346056 | AV26: 0.98461538 | AW26: 0.94326241 | AX26: 0.6713615 | AY26: 0.54754098 | AZ26: 0.45038168 | BD26: 5 | BE26: =$AP$111 -> 0.95909027 | BF26: =$AQ$111 -> 0.9209209 | BG26: =$AR$111 -> 0.77587876 | BH26: =$AS$111 -> 0.66447639 | BI26: =$AT$111 -> 0.5216285 | BJ26: =$AU$111 -> #DIV/0!
J27: 22 | K27: =AVERAGE(R27,X27,AD27,AJ27,AP27,AV27) -> 0.93506494 | L27: =AVERAGE(S27,Y27,AE27,AK27,AQ27,AW27) -> 0.89444444 | M27: =AVERAGE(T27,Z27,AF27,AL27,AR27,AX27) -> 0.69005848 | N27: =AVERAGE(U27,AA27,AG27,AM27,AS27,AY27) -> 0.58085809 | O27: =AVERAGE(V27,AB27,AH27,AN27,AT27,AZ27) -> 0.4495335 | P27: =AVERAGE(W27,AC27,AI27,AO27,AU27,BA27) -> #DIV/0! | R27: 0.94805195 | S27: 0.88666667 | T27: 0.74561404 | U27: 0.55115512 | V27: 0.4605598 | X27: 0.94805195 | Y27: 0.9 | Z27: 0.79385965 | AA27: 0.62046205 | AB27: 0.51399491 | AD27: 0.93506494 | AE27: 0.88 | AF27: 0.68421053 | AG27: 0.59735974 | AH27: 0.38931298 | AJ27: 0.90909091 | AK27: 0.87333333 | AL27: 0.61403509 | AM27: 0.54785479 | AN27: 0.44529262 | AP27: 0.92207792 | AQ27: 0.91333333 | AR27: 0.65789474 | AS27: 0.669967 | AT27: 0.46819338 | AV27: 0.94805195 | AW27: 0.91333333 | AX27: 0.64473684 | AY27: 0.49834983 | AZ27: 0.41984733 | BD27: 6 | BE27: =$AV$111 -> 0.95542179 | BF27: =$AW$111 -> 0.910602 | BG27: =$AX$111 -> 0.77411669 | BH27: =$AY$111 -> 0.64090226 | BI27: =$AZ$111 -> 0.52383376 | BJ27: =$BA$111 -> #DIV/0!
J28: 23 | K28: =AVERAGE(R28,X28,AD28,AJ28,AP28,AV28) -> 0.92857143 | L28: =AVERAGE(S28,Y28,AE28,AK28,AQ28,AW28) -> 0.92504931 | M28: =AVERAGE(T28,Z28,AF28,AL28,AR28,AX28) -> 0.70661157 | N28: =AVERAGE(U28,AA28,AG28,AM28,AS28,AY28) -> 0.54942166 | O28: =AVERAGE(V28,AB28,AH28,AN28,AT28,AZ28) -> 0.40712468 | P28: =AVERAGE(W28,AC28,AI28,AO28,AU28,BA28) -> #DIV/0! | R28: 0.92207792 | S28: 0.93491124 | T28: 0.65289256 | U28: 0.58044164 | V28: 0.42239186 | X28: 0.90909091 | Y28: 0.92307692 | Z28: 0.78099174 | AA28: 0.51735016 | AB28: 0.40458015 | AD28: 0.93506494 | AE28: 0.92899408 | AF28: 0.60743802 | AG28: 0.55520505 | AH28: 0.39185751 | AJ28: 0.93506494 | AK28: 0.92307692 | AL28: 0.76033058 | AM28: 0.58359621 | AN28: 0.39440204 | AP28: 0.92207792 | AQ28: 0.92307692 | AR28: 0.70247934 | AS28: 0.57728707 | AT28: 0.40966921 | AV28: 0.94805195 | AW28: 0.91715976 | AX28: 0.73553719 | AY28: 0.48264984 | AZ28: 0.41984733
J29: 24 | K29: =AVERAGE(R29,X29,AD29,AJ29,AP29,AV29) -> 0.94736842 | L29: =AVERAGE(S29,Y29,AE29,AK29,AQ29,AW29) -> 0.82719836 | M29: =AVERAGE(T29,Z29,AF29,AL29,AR29,AX29) -> 0.6108631 | N29: =AVERAGE(U29,AA29,AG29,AM29,AS29,AY29) -> 0.55115512 | O29: =AVERAGE(V29,AB29,AH29,AN29,AT29,AZ29) -> 0.51399491 | P29: =AVERAGE(W29,AC29,AI29,AO29,AU29,BA29) -> #DIV/0! | R29: 0.94736842 | S29: 0.84662577 | T29: 0.64732143 | U29: 0.62376238 | V29: 0.5826972 | X29: 0.96052632 | Y29: 0.88957055 | Z29: 0.58928571 | AA29: 0.5709571 | AB29: 0.48854962 | AD29: 0.94736842 | AE29: 0.8404908 | AF29: 0.62946429 | AG29: 0.56435644 | AH29: 0.52671756 | AJ29: 0.94736842 | AK29: 0.79754601 | AL29: 0.61160714 | AM29: 0.49834983 | AN29: 0.6437659 | AP29: 0.93421053 | AQ29: 0.80981595 | AR29: 0.60714286 | AS29: 0.53135314 | AT29: 0.43256997 | AV29: 0.94736842 | AW29: 0.7791411 | AX29: 0.58035714 | AY29: 0.51815182 | AZ29: 0.40966921 | BD29: =A9 -> 2 | BE29: Task 1 | BF29: Task 2 | BG29: Task 3 | BH29: Task 4 | BI29: Task 5 | BJ29: Task 6
J30: 25 | K30: =AVERAGE(R30,X30,AD30,AJ30,AP30,AV30) -> 0.98888889 | L30: =AVERAGE(S30,Y30,AE30,AK30,AQ30,AW30) -> 0.93046358 | M30: =AVERAGE(T30,Z30,AF30,AL30,AR30,AX30) -> 0.73726346 | N30: =AVERAGE(U30,AA30,AG30,AM30,AS30,AY30) -> 0.65963203 | O30: =AVERAGE(V30,AB30,AH30,AN30,AT30,AZ30) -> 0.52332485 | P30: =AVERAGE(W30,AC30,AI30,AO30,AU30,BA30) -> #DIV/0! | R30: 0.98888889 | S30: 0.96688742 | T30: 0.70305677 | U30: 0.61038961 | V30: 0.52417303 | X30: 0.98888889 | Y30: 0.97350993 | Z30: 0.71179039 | AA30: 0.6038961 | AB30: 0.51399491 | AD30: 0.98888889 | AE30: 0.97350993 | AF30: 0.68995633 | AG30: 0.58766234 | AH30: 0.47328244 | AJ30: 0.98888889 | AK30: 0.79470199 | AL30: 0.69432314 | AM30: 0.64935065 | AN30: 0.43765903 | AP30: 0.98888889 | AQ30: 0.89403974 | AR30: 0.77292576 | AS30: 0.76948052 | AT30: 0.59033079 | AV30: 0.98888889 | AW30: 0.98013245 | AX30: 0.85152838 | AY30: 0.73701299 | AZ30: 0.60050891 | BD30: 1 | BE30: =$R$148 -> 0.9585684 | BF30: =$S$148 -> 0.91989745 | BG30: =$T$148 -> 0.79390208 | BH30: =$U$148 -> 0.64237473 | BI30: =$V$148 -> 0.51094148 | BJ30: =$W$148 -> #DIV/0!
J31: 26 | K31: =AVERAGE(R31,X31,AD31,AJ31,AP31,AV31) -> 0.98333333 | L31: =AVERAGE(S31,Y31,AE31,AK31,AQ31,AW31) -> 0.9702381 | M31: =AVERAGE(T31,Z31,AF31,AL31,AR31,AX31) -> 0.8 | N31: =AVERAGE(U31,AA31,AG31,AM31,AS31,AY31) -> 0.52539683 | O31: =AVERAGE(V31,AB31,AH31,AN31,AT31,AZ31) -> 0.40924512 | P31: =AVERAGE(W31,AC31,AI31,AO31,AU31,BA31) -> #DIV/0! | R31: 0.975 | S31: 0.97619048 | T31: 0.82083333 | U31: 0.48253968 | V31: 0.45801527 | X31: 0.975 | Y31: 0.9702381 | Z31: 0.8125 | AA31: 0.56190476 | AB31: 0.36132316 | AD31: 0.9875 | AE31: 0.94642857 | AF31: 0.84166667 | AG31: 0.46349206 | AH31: 0.38931298 | AJ31: 0.975 | AK31: 0.97619048 | AL31: 0.63333333 | AM31: 0.46984127 | AN31: 0.46310433 | AP31: 0.9875 | AQ31: 0.98214286 | AR31: 0.8125 | AS31: 0.56190476 | AT31: 0.37150127 | AV31: 1 | AW31: 0.9702381 | AX31: 0.87916667 | AY31: 0.61269841 | AZ31: 0.41221374 | BD31: 2 | BE31: =$X$148 -> 0.95382731 | BF31: =$Y$148 -> 0.92913812 | BG31: =$Z$148 -> 0.77207627 | BH31: =$AA$148 -> 0.63866071 | BI31: =$AB$148 -> 0.54537744 | BJ31: =$AC$148 -> #DIV/0!
J32: 27 | K32: =AVERAGE(R32,X32,AD32,AJ32,AP32,AV32) -> 0.98684211 | L32: =AVERAGE(S32,Y32,AE32,AK32,AQ32,AW32) -> 0.95364238 | M32: =AVERAGE(T32,Z32,AF32,AL32,AR32,AX32) -> 0.74435028 | N32: =AVERAGE(U32,AA32,AG32,AM32,AS32,AY32) -> 0.62116402 | O32: =AVERAGE(V32,AB32,AH32,AN32,AT32,AZ32) -> 0.47582697 | P32: =AVERAGE(W32,AC32,AI32,AO32,AU32,BA32) -> #DIV/0! | R32: 0.98684211 | S32: 0.97350993 | T32: 0.80084746 | U32: 0.62539683 | V32: 0.50381679 | X32: 0.98684211 | Y32: 0.95364238 | Z32: 0.75423729 | AA32: 0.67936508 | AB32: 0.50127226 | AD32: 0.98684211 | AE32: 0.9602649 | AF32: 0.81779661 | AG32: 0.51111111 | AH32: 0.45547074 | AJ32: 0.98684211 | AK32: 0.93377483 | AL32: 0.68644068 | AM32: 0.62222222 | AN32: 0.45292621 | AP32: 0.98684211 | AQ32: 0.95364238 | AR32: 0.75 | AS32: 0.73968254 | AT32: 0.38676845 | AV32: 0.98684211 | AW32: 0.94701987 | AX32: 0.65677966 | AY32: 0.54920635 | AZ32: 0.55470738 | BD32: 3 | BE32: =$AD$148 -> 0.96204811 | BF32: =$AE$148 -> 0.91949428 | BG32: =$AF$148 -> 0.7658658 | BH32: =$AG$148 -> 0.63570869 | BI32: =$AH$148 -> 0.51374046 | BJ32: =$AI$148 -> #DIV/0!
J33: 28 | K33: =AVERAGE(R33,X33,AD33,AJ33,AP33,AV33) -> 0.98630137 | L33: =AVERAGE(S33,Y33,AE33,AK33,AQ33,AW33) -> 0.95608782 | M33: =AVERAGE(T33,Z33,AF33,AL33,AR33,AX33) -> 0.84489796 | N33: =AVERAGE(U33,AA33,AG33,AM33,AS33,AY33) -> 0.63879781 | O33: =AVERAGE(V33,AB33,AH33,AN33,AT33,AZ33) -> 0.57379135 | P33: =AVERAGE(W33,AC33,AI33,AO33,AU33,BA33) -> #DIV/0! | R33: 0.98630137 | S33: 0.96407186 | T33: 0.86122449 | U33: 0.62622951 | V33: 0.54452926 | X33: 0.98630137 | Y33: 0.95808383 | Z33: 0.90204082 | AA33: 0.65245902 | AB33: 0.64885496 | AD33: 0.98630137 | AE33: 0.95209581 | AF33: 0.89795918 | AG33: 0.69180328 | AH33: 0.57251908 | AJ33: 0.98630137 | AK33: 0.94610778 | AL33: 0.86938776 | AM33: 0.65901639 | AN33: 0.6692112 | AP33: 0.98630137 | AQ33: 0.95808383 | AR33: 0.73469388 | AS33: 0.58032787 | AT33: 0.42748092 | AV33: 0.98630137 | AW33: 0.95808383 | AX33: 0.80408163 | AY33: 0.62295082 | AZ33: 0.58015267 | BD33: 4 | BE33: =$AJ$148 -> 0.95484924 | BF33: =$AK$148 -> 0.92121747 | BG33: =$AL$148 -> 0.78184346 | BH33: =$AM$148 -> 0.62119355 | BI33: =$AN$148 -> 0.51832061 | BJ33: =$AO$148 -> #DIV/0!
J34: 29 | K34: =AVERAGE(R34,X34,AD34,AJ34,AP34,AV34) -> 0.83716475 | L34: =AVERAGE(S34,Y34,AE34,AK34,AQ34,AW34) -> 0.7454955 | M34: =AVERAGE(T34,Z34,AF34,AL34,AR34,AX34) -> 0.64680851 | N34: =AVERAGE(U34,AA34,AG34,AM34,AS34,AY34) -> 0.64430245 | O34: =AVERAGE(V34,AB34,AH34,AN34,AT34,AZ34) -> 0.62171332 | P34: =AVERAGE(W34,AC34,AI34,AO34,AU34,BA34) -> #DIV/0! | R34: 0.83908046 | S34: 0.77027027 | T34: 0.67234043 | U34: 0.60702875 | V34: 0.62340967 | X34: 0.7816092 | Y34: 0.74324324 | Z34: 0.67659574 | AA34: 0.68690096 | AB34: 0.63104326 | AD34: 0.79310345 | AE34: 0.82432432 | AF34: 0.55319149 | AG34: 0.61341853 | AH34: 0.59033079 | AJ34: 0.83908046 | AK34: 0.80405405 | AL34: 0.6893617 | AM34: 0.67412141 | AN34: 0.64122137 | AP34: 0.88505747 | AQ34: 0.64189189 | AR34: 0.64680851 | AS34: 0.65175719 | AT34: 0.63104326 | AV34: 0.88505747 | AW34: 0.68918919 | AX34: 0.64255319 | AY34: 0.63258786 | AZ34: 0.61323155 | BD34: 5 | BE34: =$AP$148 -> 0.95651663 | BF34: =$AQ$148 -> 0.92442674 | BG34: =$AR$148 -> 0.79079379 | BH34: =$AS$148 -> 0.63873464 | BI34: =$AT$148 -> 0.48863444 | BJ34: =$AU$148 -> #DIV/0!
J35: 30 | K35: =AVERAGE(R35,X35,AD35,AJ35,AP35,AV35) -> 0.98717949 | L35: =AVERAGE(S35,Y35,AE35,AK35,AQ35,AW35) -> 0.94055944 | M35: =AVERAGE(T35,Z35,AF35,AL35,AR35,AX35) -> 0.86124031 | N35: =AVERAGE(U35,AA35,AG35,AM35,AS35,AY35) -> 0.66775956 | O35: =AVERAGE(V35,AB35,AH35,AN35,AT35,AZ35) -> 0.47921968 | P35: =AVERAGE(W35,AC35,AI35,AO35,AU35,BA35) -> #DIV/0! | R35: 0.98717949 | S35: 0.88111888 | T35: 0.79069767 | U35: 0.65901639 | V35: 0.38931298 | X35: 0.98717949 | Y35: 0.94405594 | Z35: 0.8 | AA35: 0.54754098 | AB35: 0.49872774 | AD35: 0.98717949 | AE35: 0.97202797 | AF35: 0.90697674 | AG35: 0.58688525 | AH35: 0.44529262 | AJ35: 0.98717949 | AK35: 0.96503497 | AL35: 0.93488372 | AM35: 0.78688525 | AN35: 0.5394402 | AP35: 0.98717949 | AQ35: 0.95104895 | AR35: 0.8744186 | AS35: 0.61311475 | AT35: 0.52926209 | AV35: 0.98717949 | AW35: 0.93006993 | AX35: 0.86046512 | AY35: 0.81311475 | AZ35: 0.47328244 | BD35: 6 | BE35: =$AV$148 -> 0.95326466 | BF35: =$AW$148 -> 0.91555141 | BG35: =$AX$148 -> 0.77271567 | BH35: =$AY$148 -> 0.61185139 | BI35: =$AZ$148 -> 0.49558948 | BJ35: =$BA$148 -> #DIV/0!
K37: =AVERAGE(K6:K35) -> 0.95913484 | L37: =AVERAGE(L6:L35) -> 0.91040963 | M37: =AVERAGE(M6:M35) -> 0.76581373 | N37: =AVERAGE(N6:N35) -> 0.63133176 | O37: =AVERAGE(O6:O35) -> 0.53794176 | P37: =AVERAGE(P6:P35) -> #DIV/0! | R37: =AVERAGE(R6:R35) -> 0.96066166 | S37: =AVERAGE(S6:S35) -> 0.909311 | T37: =AVERAGE(T6:T35) -> 0.75435746 | U37: =AVERAGE(U6:U35) -> 0.63331915 | V37: =AVERAGE(V6:V35) -> 0.53129771 | W37: =AVERAGE(W6:W35) -> #DIV/0! | X37: =AVERAGE(X6:X35) -> 0.95883493 | Y37: =AVERAGE(Y6:Y35) -> 0.92190656 | ... BA37: =AVERAGE(BA6:BA35) -> #DIV/0! | BD37: =A10 -> 3 | BE37: Task 1 | BF37: Task 2 | BG37: Task 3 | BH37: Task 4 | BI37: Task 5 | BJ37: Task 6
BD38: 1 | BE38: =$R$185 -> 0.9608017 | BF38: =$S$185 -> 0.91511612 | BG38: =$T$185 -> 0.77317323 | BH38: =$U$185 -> 0.60254736 | BI38: =$V$185 -> 0.49117897 | BJ38: =$W$185 -> #DIV/0!
BD39: 2 | BE39: =$X$185 -> 0.95644192 | BF39: =$Y$185 -> 0.92071235 | BG39: =$Z$185 -> 0.77024925 | BH39: =$AA$185 -> 0.60070491 | BI39: =$AB$185 -> 0.47888041 | BJ39: =$AC$185 -> #DIV/0!
K40: k=0.5 | BD40: 3 | BE40: =$AD$185 -> 0.95918876 | BF40: =$AE$185 -> 0.91909944 | BG40: =$AF$185 -> 0.76420078 | BH40: =$AG$185 -> 0.62472625 | BI40: =$AH$185 -> 0.48761662 | BJ40: =$AI$185 -> #DIV/0!
S41: 1 | Y41: 2 | AE41: 3 | AK41: 4 | AQ41: 5 | AW41: 6 | BD41: 4 | BE41: =$AJ$185 -> 0.95876313 | BF41: =$AK$185 -> 0.91979795 | BG41: =$AL$185 -> 0.76737421 | BH41: =$AM$185 -> 0.62906478 | BI41: =$AN$185 -> 0.51026293 | BJ41: =$AO$185 -> #DIV/0!
J42: ID | K42: Task 1 | L42: Task 2 | M42: Task 3 | N42: Task 4 | O42: Task 5 | P42: Task 6 | R42: Task 1 | S42: Task 2 | T42: Task 3 | U42: Task 4 | V42: Task 5 | W42: Task 6 | X42: Task 1 | Y42: Task 2 | Z42: Task 3 | AA42: Task 4 | AB42: Task 5 | AC42: Task 6 | AD42: Task 1 | AE42: Task 2 | AF42: Task 3 | AG42: Task 4 | AH42: Task 5 | AI42: Task 6 | AJ42: Task 1 | AK42: Task 2 | AL42: Task 3 | AM42: Task 4 | AN42: Task 5 | AO42: Task 6 | AP42: Task 1 | AQ42: Task 2 | AR42: Task 3 | AS42: Task 4 | AT42: Task 5 | AU42: Task 6 | AV42: Task 1 | AW42: Task 2 | AX42: Task 3 | AY42: Task 4 | AZ42: Task 5 | BA42: Task 6 | BD42: 5 | BE42: =$AP$185 -> 0.95148231 | BF42: =$AQ$185 -> 0.91340366 | BG42: =$AR$185 -> 0.7280829 | BH42: =$AS$185 -> 0.6155594 | BI42: =$AT$185 -> 0.49185751 | BJ42: =$AU$185 -> #DIV/0!
J43: 1 | K43: =AVERAGE(R43,X43,AD43,AJ43,AP43,AV43) -> 0.89269406 | L43: =AVERAGE(S43,Y43,AE43,AK43,AQ43,AW43) -> 0.89877301 | M43: =AVERAGE(T43,Z43,AF43,AL43,AR43,AX43) -> 0.68095238 | N43: =AVERAGE(U43,AA43,AG43,AM43,AS43,AY43) -> 0.60062893 | O43: =AVERAGE(V43,AB43,AH43,AN43,AT43,AZ43) -> 0.62128923 | P43: =AVERAGE(W43,AC43,AI43,AO43,AU43,BA43) -> #DIV/0! | R43: 0.90410959 | S43: 0.89570552 | T43: 0.68163265 | U43: 0.59433962 | V43: 0.67175573 | X43: 0.91780822 | Y43: 0.95092025 | Z43: 0.68979592 | AA43: 0.74528302 | AB43: 0.58524173 | AD43: 0.89041096 | AE43: 0.87730061 | AF43: 0.68571429 | AG43: 0.6509434 | AH43: 0.51145038 | AJ43: 0.89041096 | AK43: 0.86503067 | AL43: 0.66938776 | AM43: 0.59748428 | AN43: 0.61068702 | AP43: 0.8630137 | AQ43: 0.89570552 | AR43: 0.69795918 | AS43: 0.52515723 | AT43: 0.69720102 | AV43: 0.89041096 | AW43: 0.90797546 | AX43: 0.66122449 | AY43: 0.49056604 | AZ43: 0.65139949 | BD43: 6 | BE43: =$AV$185 -> 0.96239956 | BF43: =$AW$185 -> 0.92592191 | BG43: =$AX$185 -> 0.77782717 | BH43: =$AY$185 -> 0.64018108 | BI43: =$AZ$185 -> 0.51933842 | BJ43: =$BA$185 -> #DIV/0!
...

Sheet Person_1
K3: k=0.25
S4: 1 | Y4: 2 | AE4: 3 | AK4: 4 | AQ4: 5 | AW4: 6
A5: k | B5: Task 1 | C5: Task 2 | D5: Task 3 | E5: Task 4 | F5: Task 5 | G5: Task 6 | J5: ID | K5: Task 1 | L5: Task 2 | M5: Task 3 | N5: Task 4 | O5: Task 5 | P5: Task 6 | R5: Task 1 | S5: Task 2 | T5: Task 3 | U5: Task 4 | V5: Task 5 | W5: Task 6 | X5: Task 1 | Y5: Task 2 | Z5: Task 3 | AA5: Task 4 | AB5: Task 5 | AC5: Task 6 | AD5: Task 1 | AE5: Task 2 | AF5: Task 3 | AG5: Task 4 | AH5: Task 5 | AI5: Task 6 | AJ5: Task 1 | AK5: Task 2 | AL5: Task 3 | AM5: Task 4 | AN5: Task 5 | AO5: Task 6 | AP5: Task 1 | AQ5: Task 2 | AR5: Task 3 | AS5: Task 4 | AT5: Task 5 | AU5: Task 6 | AV5: Task 1 | AW5: Task 2 | AX5: Task 3 | AY5: Task 4 | AZ5: Task 5 | BA5: Task 6 | BD5: =A6 -> 0.25 | BE5: Task 1 | BF5: Task 2 | BG5: Task 3 | BH5: Task 4 | BI5: Task 5 | BJ5: Task 6
A6: 0.25 | B6: =AVERAGE(K6:K35) -> 0.92993827 | C6: =AVERAGE(L6:L35) -> 0.88725019 | D6: =AVERAGE(M6:M35) -> 0.7596864 | E6: =AVERAGE(N6:N35) -> 0.6297988 | F6: =AVERAGE(O6:O35) -> 0.52846491 | G6: =AVERAGE(P6:P35) -> #DIV/0! | J6: 1 | K6: =AVERAGE(R6,X6,AD6,AJ6,AP6,AV6) -> 0.87229437 | L6: =AVERAGE(S6,Y6,AE6,AK6,AQ6,AW6) -> 0.88203463 | M6: =AVERAGE(T6,Z6,AF6,AL6,AR6,AX6) -> 0.7177305 | N6: =AVERAGE(U6,AA6,AG6,AM6,AS6,AY6) -> 0.56545655 | O6: =AVERAGE(V6,AB6,AH6,AN6,AT6,AZ6) -> 0.58289474 | P6: =AVERAGE(W6,AC6,AI6,AO6,AU6,BA6) -> #DIV/0! | R6: 0.92207792 | S6: 0.88961039 | T6: 0.73191489 | U6: 0.6039604 | V6: 0.46578947 | X6: 0.88311688 | Y6: 0.87012987 | Z6: 0.74468085 | AA6: 0.51815182 | AB6: 0.64473684 | AD6: 0.87012987 | AE6: 0.88961039 | AF6: 0.73191489 | AG6: 0.65346535 | AH6: 0.59210526 | AJ6: 0.85714286 | AK6: 0.90909091 | AL6: 0.73191489 | AM6: 0.55115512 | AN6: 0.53947368 | AP6: 0.84415584 | AQ6: 0.84415584 | AR6: 0.63829787 | AS6: 0.54785479 | AT6: 0.62368421 | AV6: 0.85714286 | AW6: 0.88961039 | AX6: 0.72765957 | AY6: 0.51815182 | AZ6: 0.63157895 | BD6: 1 | BE6: =$R$37 -> 0.93328865 | BF6: =$S$37 -> 0.8808287 | BG6: =$T$37 -> 0.76286472 | BH6: =$U$37 -> 0.62899179 | BI6: =$V$37 -> 0.52947368 | BJ6: =$W$37 -> #DIV/0!
A7: 0.5 | B7: =AVERAGE(K43:K72) -> 0.93034527 | C7: =AVERAGE(L43:L72) -> 0.90085465 | D7: =AVERAGE(M43:M72) -> 0.77328329 | E7: =AVERAGE(N43:N72) -> 0.63316974 | F7: =AVERAGE(O43:O72) -> 0.53258772 | G7: =AVERAGE(P43:P72) -> #DIV/0! | J7: 2 | K7: =AVERAGE(R7,X7,AD7,AJ7,AP7,AV7) -> 0.92777778 | L7: =AVERAGE(S7,Y7,AE7,AK7,AQ7,AW7) -> 0.81573499 | M7: =AVERAGE(T7,Z7,AF7,AL7,AR7,AX7) -> 0.80296896 | N7: =AVERAGE(U7,AA7,AG7,AM7,AS7,AY7) -> 0.73344371 | O7: =AVERAGE(V7,AB7,AH7,AN7,AT7,AZ7) -> 0.47587719 | P7: =AVERAGE(W7,AC7,AI7,AO7,AU7,BA7) -> #DIV/0! | R7: 0.93333333 | S7: 0.90062112 | T7: 0.87854251 | U7: 0.76821192 | V7: 0.56315789 | X7: 0.9 | Y7: 0.9068323 | Z7: 0.70850202 | AA7: 0.82450331 | AB7: 0.47105263 | AD7: 0.95555556 | AE7: 0.7515528 | AF7: 0.80566802 | AG7: 0.82781457 | AH7: 0.4 | AJ7: 0.93333333 | AK7: 0.80745342 | AL7: 0.82995951 | AM7: 0.66556291 | AN7: 0.49736842 | AP7: 0.91111111 | AQ7: 0.76397516 | AR7: 0.80566802 | AS7: 0.65562914 | AT7: 0.37368421 | AV7: 0.93333333 | AW7: 0.76397516 | AX7: 0.78947368 | AY7: 0.6589404 | AZ7: 0.55 | BD7: 2 | BE7: =$X$37 -> 0.93028058 | BF7: =$Y$37 -> 0.8957486 | BG7: =$Z$37 -> 0.76834499 | BH7: =$AA$37 -> 0.65850386 | BI7: =$AB$37 -> 0.53877193 | BJ7: =$AC$37 -> #DIV/0!
A8: 1 | B8: =AVERAGE(K80:K109) -> 0.92894141 | C8: =AVERAGE(L80:L109) -> 0.90059358 | D8: =AVERAGE(M80:M109) -> 0.77407565 | E8: =AVERAGE(N80:N109) -> 0.62943851 | F8: =AVERAGE(O80:O109) -> 0.54109649 | G8: =AVERAGE(P80:P109) -> #DIV/0! | J8: 3 | K8: =AVERAGE(R8,X8,AD8,AJ8,AP8,AV8) -> 0.94623656 | L8: =AVERAGE(S8,Y8,AE8,AK8,AQ8,AW8) -> 0.95203837 | M8: =AVERAGE(T8,Z8,AF8,AL8,AR8,AX8) -> 0.86125212 | N8: =AVERAGE(U8,AA8,AG8,AM8,AS8,AY8) -> 0.60652921 | O8: =AVERAGE(V8,AB8,AH8,AN8,AT8,AZ8) -> 0.55877193 | P8: =AVERAGE(W8,AC8,AI8,AO8,AU8,BA8) -> #DIV/0! | R8: 0.93548387 | S8: 0.95683453 | T8: 0.88832487 | U8: 0.54295533 | V8: 0.55 | X8: 0.93548387 | Y8: 0.96402878 | Z8: 0.8680203 | AA8: 0.65635739 | AB8: 0.57894737 | AD8: 0.93548387 | AE8: 0.9352518 | AF8: 0.87817259 | AG8: 0.51546392 | AH8: 0.56578947 | AJ8: 0.96774194 | AK8: 0.9352518 | AL8: 0.80203046 | AM8: 0.56701031 | AN8: 0.59736842 | AP8: 0.93548387 | AQ8: 0.95683453 | AR8: 0.86294416 | AS8: 0.58075601 | AT8: 0.56578947 | AV8: 0.96774194 | AW8: 0.96402878 | AX8: 0.8680203 | AY8: 0.7766323 | AZ8: 0.49473684 | BD8: 3 | BE8: =$AD$37 -> 0.92782022 | BF8: =$AE$37 -> 0.88719598 | BG8: =$AF$37 -> 0.76343774 | BH8: =$AG$37 -> 0.61318762 | BI8: =$AH$37 -> 0.51640351 | BJ8: =$AI$37 -> #DIV/0!
A9: 2 | B9: =AVERAGE(K117:K146) -> 0.92826772 | C9: =AVERAGE(L117:L146) -> 0.90442022 | D9: =AVERAGE(M117:M146) -> 0.76064326 | E9: =AVERAGE(N117:N146) -> 0.62387425 | F9: =AVERAGE(O117:O146) -> 0.52355263 | G9: =AVERAGE(P117:P146) -> #DIV/0! | J9: 4 | K9: =AVERAGE(R9,X9,AD9,AJ9,AP9,AV9) -> 0.92929293 | L9: =AVERAGE(S9,Y9,AE9,AK9,AQ9,AW9) -> 0.88297872 | M9: =AVERAGE(T9,Z9,AF9,AL9,AR9,AX9) -> 0.75175809 | N9: =AVERAGE(U9,AA9,AG9,AM9,AS9,AY9) -> 0.5182025 | O9: =AVERAGE(V9,AB9,AH9,AN9,AT9,AZ9) -> 0.53464912 | P9: =AVERAGE(W9,AC9,AI9,AO9,AU9,BA9) -> #DIV/0! | R9: 0.93939394 | S9: 0.88652482 | T9: 0.70886076 | U9: 0.45733788 | V9: 0.47368421 | X9: 0.92424242 | Y9: 0.90070922 | Z9: 0.70464135 | AA9: 0.54948805 | AB9: 0.58157895 | AD9: 0.92424242 | AE9: 0.90780142 | AF9: 0.89451477 | AG9: 0.63822526 | AH9: 0.61842105 | AJ9: 0.93939394 | AK9: 0.85106383 | AL9: 0.72995781 | AM9: 0.50511945 | AN9: 0.58421053 | AP9: 0.92424242 | AQ9: 0.87943262 | AR9: 0.80590717 | AS9: 0.48122867 | AT9: 0.56578947 | AV9: 0.92424242 | AW9: 0.87234043 | AX9: 0.66666667 | AY9: 0.4778157 | AZ9: 0.38421053 | BD9: 4 | BE9: =$AJ$37 -> 0.93222686 | BF9: =$AK$37 -> 0.8885684 | BG9: =$AL$37 -> 0.7508717 | BH9: =$AM$37 -> 0.6176805 | BI9: =$AN$37 -> 0.52745614 | BJ9: =$AO$37 -> #DIV/0!
A10: 3 | B10: =AVERAGE(K154:K183) -> 0.93037753 | C10: =AVERAGE(L154:L183) -> 0.91208718 | D10: =AVERAGE(M154:M183) -> 0.7605043 | E10: =AVERAGE(N154:N183) -> 0.63051373 | F10: =AVERAGE(O154:O183) -> 0.52135965 | G10: =AVERAGE(P154:P183) -> #DIV/0! | J10: 5 | K10: =AVERAGE(R10,X10,AD10,AJ10,AP10,AV10) -> 0.98275862 | L10: =AVERAGE(S10,Y10,AE10,AK10,AQ10,AW10) -> 0.94308943 | M10: =AVERAGE(T10,Z10,AF10,AL10,AR10,AX10) -> 0.84072581 | N10: =AVERAGE(U10,AA10,AG10,AM10,AS10,AY10) -> 0.68587747 | O10: =AVERAGE(V10,AB10,AH10,AN10,AT10,AZ10) -> 0.46798246 | P10: =AVERAGE(W10,AC10,AI10,AO10,AU10,BA10) -> #DIV/0! | R10: 0.98850575 | S10: 0.9695122 | T10: 0.85483871 | U10: 0.7165109 | V10: 0.51315789 | X10: 0.97701149 | Y10: 0.94512195 | Z10: 0.84677419 | AA10: 0.71339564 | AB10: 0.39473684 | AD10: 0.98850575 | AE10: 0.93902439 | AF10: 0.81451613 | AG10: 0.62305296 | AH10: 0.33421053 | AJ10: 0.97701149 | AK10: 0.92073171 | AL10: 0.80645161 | AM10: 0.74143302 | AN10: 0.39473684 | AP10: 1 | AQ10: 0.95731707 | AR10: 0.84274194 | AS10: 0.68535826 | AT10: 0.6 | AV10: 0.96551724 | AW10: 0.92682927 | AX10: 0.87903226 | AY10: 0.63551402 | AZ10: 0.57105263 | BD10: 5 | BE10: =$AP$37 -> 0.92469991 | BF10: =$AQ$37 -> 0.88540441 | BG10: =$AR$37 -> 0.75214539 | BH10: =$AS$37 -> 0.63964421 | BI10: =$AT$37 -> 0.52561404 | BJ10: =$AU$37 -> #DIV/0!
J11: 6 | K11: =AVERAGE(R11,X11,AD11,AJ11,AP11,AV11) -> 0.90842491 | L11: =AVERAGE(S11,Y11,AE11,AK11,AQ11,AW11) -> 0.84935897 | M11: =AVERAGE(T11,Z11,AF11,AL11,AR11,AX11) -> 0.69352291 | N11: =AVERAGE(U11,AA11,AG11,AM11,AS11,AY11) -> 0.62703963 | O11: =AVERAGE(V11,AB11,AH11,AN11,AT11,AZ11) -> 0.55307018 | P11: =AVERAGE(W11,AC11,AI11,AO11,AU11,BA11) -> #DIV/0! | R11: 0.9010989 | S11: 0.80128205 | T11: 0.76303318 | U11: 0.64335664 | V11: 0.53157895 | X11: 0.91208791 | Y11: 0.84615385 | Z11: 0.55924171 | AA11: 0.55944056 | AB11: 0.57368421 | AD11: 0.89010989 | AE11: 0.83974359 | AF11: 0.65402844 | AG11: 0.41958042 | AH11: 0.53421053 | AJ11: 0.92307692 | AK11: 0.88461538 | AL11: 0.72037915 | AM11: 0.63286713 | AN11: 0.54736842 | AP11: 0.92307692 | AQ11: 0.87179487 | AR11: 0.78199052 | AS11: 0.77272727 | AT11: 0.59210526 | AV11: 0.9010989 | AW11: 0.8525641 | AX11: 0.68246445 | AY11: 0.73426573 | AZ11: 0.53947368 | BD11: 6 | BE11: =$AV$37 -> 0.9313134 | BF11: =$AW$37 -> 0.88575507 | BG11: =$AX$37 -> 0.76045384 | BH11: =$AY$37 -> 0.6207848 | BI11: =$AZ$37 -> 0.53307018 | BJ11: =$BA$37 -> #DIV/0!
J12: 7 | K12: =AVERAGE(R12,X12,AD12,AJ12,AP12,AV12) -> 0.95495495 | L12: =AVERAGE(S12,Y12,AE12,AK12,AQ12,AW12) -> 0.87051282 | M12: =AVERAGE(T12,Z12,AF12,AL12,AR12,AX12) -> 0.71937984 | N12: =AVERAGE(U12,AA12,AG12,AM12,AS12,AY12) -> 0.63630952 | O12: =AVERAGE(V12,AB12,AH12,AN12,AT12,AZ12) -> 0.56666667 | P12: =AVERAGE(W12,AC12,AI12,AO12,AU12,BA12) -> #DIV/0! | R12: 0.95945946 | S12: 0.85384615 | T12: 0.70697674 | U12: 0.6 | V12: 0.51052632 | X12: 0.97297297 | Y12: 0.81538462 | Z12: 0.81860465 | AA12: 0.74642857 | AB12: 0.57368421 | AD12: 0.94594595 | AE12: 0.86153846 | AF12: 0.66976744 | AG12: 0.825 | AH12: 0.56315789 | AJ12: 0.94594595 | AK12: 0.84615385 | AL12: 0.6372093 | AM12: 0.50714286 | AN12: 0.55789474 | AP12: 0.93243243 | AQ12: 0.91538462 | AR12: 0.60465116 | AS12: 0.625 | AT12: 0.56578947 | AV12: 0.97297297 | AW12: 0.93076923 | AX12: 0.87906977 | AY12: 0.51428571 | AZ12: 0.62894737
J13: 8 | K13: =AVERAGE(R13,X13,AD13,AJ13,AP13,AV13) -> 0.85042735 | L13: =AVERAGE(S13,Y13,AE13,AK13,AQ13,AW13) -> 0.78030303 | M13: =AVERAGE(T13,Z13,AF13,AL13,AR13,AX13) -> 0.76694329 | N13: =AVERAGE(U13,AA13,AG13,AM13,AS13,AY13) -> 0.5 | O13: =AVERAGE(V13,AB13,AH13,AN13,AT13,AZ13) -> 0.49649123 | P13: =AVERAGE(W13,AC13,AI13,AO13,AU13,BA13) -> #DIV/0! | R13: 0.84615385 | S13: 0.81818182 | T13: 0.78008299 | U13: 0.49514563 | V13: 0.46315789 | X13: 0.84615385 | Y13: 0.74675325 | Z13: 0.77178423 | AA13: 0.46601942 | AB13: 0.5 | AD13: 0.83333333 | AE13: 0.79220779 | AF13: 0.78008299 | AG13: 0.50485437 | AH13: 0.48947368 | AJ13: 0.87179487 | AK13: 0.82467532 | AL13: 0.7593361 | AM13: 0.4789644 | AN13: 0.48684211 | AP13: 0.83333333 | AQ13: 0.77922078 | AR13: 0.76763485 | AS13: 0.57281553 | AT13: 0.49473684 | AV13: 0.87179487 | AW13: 0.72077922 | AX13: 0.74273859 | AY13: 0.48220065 | AZ13: 0.54473684 | BD13: =A7 -> 0.5 | BE13: Task 1 | BF13: Task 2 | BG13: Task 3 | BH13: Task 4 | BI13: Task 5 | BJ13: Task 6
J14: 9 | K14: =AVERAGE(R14,X14,AD14,AJ14,AP14,AV14) -> 0.97188755 | L14: =AVERAGE(S14,Y14,AE14,AK14,AQ14,AW14) -> 0.91325536 | M14: =AVERAGE(T14,Z14,AF14,AL14,AR14,AX14) -> 0.68466667 | N14: =AVERAGE(U14,AA14,AG14,AM14,AS14,AY14) -> 0.51584699 | O14: =AVERAGE(V14,AB14,AH14,AN14,AT14,AZ14) -> 0.39254386 | P14: =AVERAGE(W14,AC14,AI14,AO14,AU14,BA14) -> #DIV/0! | R14: 0.97590361 | S14: 0.94736842 | T14: 0.68 | U14: 0.57377049 | V14: 0.36315789 | X14: 0.97590361 | Y14: 0.95906433 | Z14: 0.644 | AA14: 0.57377049 | AB14: 0.47368421 | AD14: 0.97590361 | AE14: 0.85964912 | AF14: 0.668 | AG14: 0.38032787 | AH14: 0.35 | AJ14: 0.96385542 | AK14: 0.9005848 | AL14: 0.712 | AM14: 0.41967213 | AN14: 0.36578947 | AP14: 0.96385542 | AQ14: 0.93567251 | AR14: 0.664 | AS14: 0.51147541 | AT14: 0.45526316 | AV14: 0.97590361 | AW14: 0.87719298 | AX14: 0.74 | AY14: 0.63606557 | AZ14: 0.34736842 | BD14: 1 | BE14: =$R$74 -> 0.92976777 | BF14: =$S$74 -> 0.89994934 | BG14: =$T$74 -> 0.77303413 | BH14: =$U$74 -> 0.62407043 | BI14: =$V$74 -> 0.53885965 | BJ14: =$W$74 -> #DIV/0!
J15: 10 | K15: =AVERAGE(R15,X15,AD15,AJ15,AP15,AV15) -> 0.93489583 | L15: =AVERAGE(S15,Y15,AE15,AK15,AQ15,AW15) -> 0.8852459 | M15: =AVERAGE(T15,Z15,AF15,AL15,AR15,AX15) -> 0.81419458 | N15: =AVERAGE(U15,AA15,AG15,AM15,AS15,AY15) -> 0.68813559 | O15: =AVERAGE(V15,AB15,AH15,AN15,AT15,AZ15) -> 0.54692982 | P15: =AVERAGE(W15,AC15,AI15,AO15,AU15,BA15) -> #DIV/0! | R15: 0.9375 | S15: 0.90983607 | T15: 0.77990431 | U15: 0.66779661 | V15: 0.51315789 | X15: 0.921875 | Y15: 0.86885246 | Z15: 0.83732057 | AA15: 0.69830508 | AB15: 0.54473684 | AD15: 0.9375 | AE15: 0.87704918 | AF15: 0.80382775 | AG15: 0.63050847 | AH15: 0.54473684 | AJ15: 0.9375 | AK15: 0.90163934 | AL15: 0.83253589 | AM15: 0.74576271 | AN15: 0.59736842 | AP15: 0.9375 | AQ15: 0.86885246 | AR15: 0.84688995 | AS15: 0.68474576 | AT15: 0.56578947 | AV15: 0.9375 | AW15: 0.8852459 | AX15: 0.784689 | AY15: 0.70169492 | AZ15: 0.51578947 | BD15: 2 | BE15: =$X$74 -> 0.92620174 | BF15: =$Y$74 -> 0.8984745 | BG15: =$Z$74 -> 0.77906431 | BH15: =$AA$74 -> 0.62950191 | BI15: =$AB$74 -> 0.53175439 | BJ15: =$AC$74 -> #DIV/0!
J16: 11 | K16: =AVERAGE(R16,X16,AD16,AJ16,AP16,AV16) -> 0.87229437 | L16: =AVERAGE(S16,Y16,AE16,AK16,AQ16,AW16) -> 0.8590535 | M16: =AVERAGE(T16,Z16,AF16,AL16,AR16,AX16) -> 0.73481781 | N16: =AVERAGE(U16,AA16,AG16,AM16,AS16,AY16) -> 0.62651265 | O16: =AVERAGE(V16,AB16,AH16,AN16,AT16,AZ16) -> 0.59473684 | P16: =AVERAGE(W16,AC16,AI16,AO16,AU16,BA16) -> #DIV/0! | R16: 0.92207792 | S16: 0.86419753 | T16: 0.70850202 | U16: 0.54455446 | V16: 0.50789474 | X16: 0.85714286 | Y16: 0.86419753 | Z16: 0.72874494 | AA16: 0.71287129 | AB16: 0.62368421 | AD16: 0.87012987 | AE16: 0.88271605 | AF16: 0.7611336 | AG16: 0.58745875 | AH16: 0.62105263 | AJ16: 0.87012987 | AK16: 0.82716049 | AL16: 0.72874494 | AM16: 0.55775578 | AN16: 0.57894737 | AP16: 0.85714286 | AQ16: 0.85802469 | AR16: 0.69230769 | AS16: 0.73267327 | AT16: 0.62631579 | AV16: 0.85714286 | AW16: 0.85802469 | AX16: 0.78947368 | AY16: 0.62376238 | AZ16: 0.61052632 | BD16: 3 | BE16: =$AD$74 -> 0.93018018 | BF16: =$AE$74 -> 0.90356846 | BG16: =$AF$74 -> 0.77499169 | BH16: =$AG$74 -> 0.64047584 | BI16: =$AH$74 -> 0.52070175 | BJ16: =$AI$74 -> #DIV/0!
J17: 12 | K17: =AVERAGE(R17,X17,AD17,AJ17,AP17,AV17) -> 0.91812865 | L17: =AVERAGE(S17,Y17,AE17,AK17,AQ17,AW17) -> 0.8356974 | M17: =AVERAGE(T17,Z17,AF17,AL17,AR17,AX17) -> 0.77536232 | N17: =AVERAGE(U17,AA17,AG17,AM17,AS17,AY17) -> 0.7619863 | O17: =AVERAGE(V17,AB17,AH17,AN17,AT17,AZ17) -> 0.66403509 | P17: =AVERAGE(W17,AC17,AI17,AO17,AU17,BA17) -> #DIV/0! | R17: 0.9122807 | S17: 0.79432624 | T17: 0.7826087 | U17: 0.75342466 | V17: 0.60526316 | X17: 0.92982456 | Y17: 0.90070922 | Z17: 0.89371981 | AA17: 0.80136986 | AB17: 0.75789474 | AD17: 0.89473684 | AE17: 0.81560284 | AF17: 0.79227053 | AG17: 0.69863014 | AH17: 0.61578947 | AJ17: 0.9122807 | AK17: 0.79432624 | AL17: 0.76328502 | AM17: 0.78424658 | AN17: 0.68157895 | AP17: 0.92982456 | AQ17: 0.82269504 | AR17: 0.62801932 | AS17: 0.75342466 | AT17: 0.63684211 | AV17: 0.92982456 | AW17: 0.88652482 | AX17: 0.79227053 | AY17: 0.78082192 | AZ17: 0.68684211 | BD17: 4 | BE17: =$AJ$74 -> 0.92929876 | BF17: =$AK$74 -> 0.90289842 | BG17: =$AL$74 -> 0.77607114 | BH17: =$AM$74 -> 0.63447408 | BI17: =$AN$74 -> 0.53236842 | BJ17: =$AO$74 -> #DIV/0!
J18: 13 | K18: =AVERAGE(R18,X18,AD18,AJ18,AP18,AV18) -> 0.84188034 | L18: =AVERAGE(S18,Y18,AE18,AK18,AQ18,AW18) -> 0.77985075 | M18: =AVERAGE(T18,Z18,AF18,AL18,AR18,AX18) -> 0.74723539 | N18: =AVERAGE(U18,AA18,AG18,AM18,AS18,AY18) -> 0.59754738 | O18: =AVERAGE(V18,AB18,AH18,AN18,AT18,AZ18) -> 0.58026316 | P18: =AVERAGE(W18,AC18,AI18,AO18,AU18,BA18) -> #DIV/0! | R18: 0.85897436 | S18: 0.71641791 | T18: 0.76777251 | U18: 0.5451505 | V18: 0.61578947 | X18: 0.85897436 | Y18: 0.7761194 | Z18: 0.76777251 | AA18: 0.73578595 | AB18: 0.65526316 | AD18: 0.80769231 | AE18: 0.7761194 | AF18: 0.73459716 | AG18: 0.53846154 | AH18: 0.56842105 | AJ18: 0.83333333 | AK18: 0.8358209 | AL18: 0.73459716 | AM18: 0.53846154 | AN18: 0.57368421 | AP18: 0.84615385 | AQ18: 0.78358209 | AR18: 0.72511848 | AS18: 0.64548495 | AT18: 0.58421053 | AV18: 0.84615385 | AW18: 0.79104478 | AX18: 0.7535545 | AY18: 0.5819398 | AZ18: 0.48421053 | BD18: 5 | BE18: =$AP$74 -> 0.93444644 | BF18: =$AQ$74 -> 0.89995084 | BG18: =$AR$74 -> 0.76735435 | BH18: =$AS$74 -> 0.63346646 | BI18: =$AT$74 -> 0.5354386 | BJ18: =$AU$74 -> #DIV/0!
J19: 14 | K19: =AVERAGE(R19,X19,AD19,AJ19,AP19,AV19) -> 0.95131086 | L19: =AVERAGE(S19,Y19,AE19,AK19,AQ19,AW19) -> 0.95784314 | M19: =AVERAGE(T19,Z19,AF19,AL19,AR19,AX19) -> 0.75968992 | N19: =AVERAGE(U19,AA19,AG19,AM19,AS19,AY19) -> 0.68421053 | O19: =AVERAGE(V19,AB19,AH19,AN19,AT19,AZ19) -> 0.53991228 | P19: =AVERAGE(W19,AC19,AI19,AO19,AU19,BA19) -> #DIV/0! | R19: 0.92134831 | S19: 0.98235294 | T19: 0.76744186 | U19: 0.70723684 | V19: 0.59473684 | X19: 0.95505618 | Y19: 0.98823529 | Z19: 0.7627907 | AA19: 0.73026316 | AB19: 0.46052632 | AD19: 0.95505618 | AE19: 0.92941176 | AF19: 0.68372093 | AG19: 0.61513158 | AH19: 0.55263158 | AJ19: 0.96629213 | AK19: 0.98235294 | AL19: 0.76744186 | AM19: 0.68421053 | AN19: 0.49736842 | AP19: 0.93258427 | AQ19: 0.88235294 | AR19: 0.79069767 | AS19: 0.72368421 | AT19: 0.49210526 | AV19: 0.97752809 | AW19: 0.98235294 | AX19: 0.78604651 | AY19: 0.64473684 | AZ19: 0.64210526 | BD19: 6 | BE19: =$AV$74 -> 0.93217673 | BF19: =$AW$74 -> 0.90028635 | BG19: =$AX$74 -> 0.76918411 | BH19: =$AY$74 -> 0.63702971 | BI19: =$AZ$74 -> 0.53640351 | BJ19: =$BA$74 -> #DIV/0!
J20: 15 | K20: =AVERAGE(R20,X20,AD20,AJ20,AP20,AV20) -> 0.995 | L20: =AVERAGE(S20,Y20,AE20,AK20,AQ20,AW20) -> 0.9472693 | M20: =AVERAGE(T20,Z20,AF20,AL20,AR20,AX20) -> 0.84986226 | N20: =AVERAGE(U20,AA20,AG20,AM20,AS20,AY20) -> 0.60662177 | O20: =AVERAGE(V20,AB20,AH20,AN20,AT20,AZ20) -> 0.48377193 | P20: =AVERAGE(W20,AC20,AI20,AO20,AU20,BA20) -> #DIV/0! | R20: 0.99 | S20: 0.91525424 | T20: 0.82644628 | U20: 0.58585859 | V20: 0.37894737 | X20: 1 | Y20: 0.94915254 | Z20: 0.79752066 | AA20: 0.52861953 | AB20: 0.46052632 | AD20: 0.99 | AE20: 0.95480226 | AF20: 0.87190083 | AG20: 0.72053872 | AH20: 0.61842105 | AJ20: 1 | AK20: 0.95480226 | AL20: 0.88842975 | AM20: 0.64646465 | AN20: 0.49473684 | AP20: 1 | AQ20: 0.97175141 | AR20: 0.91322314 | AS20: 0.57912458 | AT20: 0.51578947 | AV20: 0.99 | AW20: 0.93785311 | AX20: 0.80165289 | AY20: 0.57912458 | AZ20: 0.43421053
J21: 16 | K21: =AVERAGE(R21,X21,AD21,AJ21,AP21,AV21) -> 0.96626984 | L21: =AVERAGE(S21,Y21,AE21,AK21,AQ21,AW21) -> 0.9566075 | M21: =AVERAGE(T21,Z21,AF21,AL21,AR21,AX21) -> 0.73333333 | N21: =AVERAGE(U21,AA21,AG21,AM21,AS21,AY21) -> 0.61975717 | O21: =AVERAGE(V21,AB21,AH21,AN21,AT21,AZ21) -> 0.44429825 | P21: =AVERAGE(W21,AC21,AI21,AO21,AU21,BA21) -> #DIV/0! | R21: 0.96428571 | S21: 0.93491124 | T21: 0.76 | U21: 0.59933775 | V21: 0.47631579 | X21: 0.96428571 | Y21: 0.95857988 | Z21: 0.77333333 | AA21: 0.62913907 | AB21: 0.46578947 | AD21: 0.96428571 | AE21: 0.96449704 | AF21: 0.76444444 | AG21: 0.53642384 | AH21: 0.39210526 | AJ21: 0.97619048 | AK21: 0.9408284 | AL21: 0.71555556 | AM21: 0.68211921 | AN21: 0.41842105 | AP21: 0.96428571 | AQ21: 0.97633136 | AR21: 0.60888889 | AS21: 0.61258278 | AT21: 0.41842105 | AV21: 0.96428571 | AW21: 0.96449704 | AX21: 0.77777778 | AY21: 0.6589404 | AZ21: 0.49473684 | BD21: =A8 -> 1 | BE21: Task 1 | BF21: Task 2 | BG21: Task 3 | BH21: Task 4 | BI21: Task 5 | BJ21: Task 6
J22: 17 | K22: =AVERAGE(R22,X22,AD22,AJ22,AP22,AV22) -> 0.97619048 | L22: =AVERAGE(S22,Y22,AE22,AK22,AQ22,AW22) -> 0.92738095 | M22: =AVERAGE(T22,Z22,AF22,AL22,AR22,AX22) -> 0.87663399 | N22: =AVERAGE(U22,AA22,AG22,AM22,AS22,AY22) -> 0.59976932 | O22: =AVERAGE(V22,AB22,AH22,AN22,AT22,AZ22) -> 0.50394737 | P22: =AVERAGE(W22,AC22,AI22,AO22,AU22,BA22) -> #DIV/0! | R22: 0.98809524 | S22: 0.84285714 | T22: 0.86764706 | U22: 0.58477509 | V22: 0.47894737 | X22: 0.98809524 | Y22: 0.95 | Z22: 0.88235294 | AA22: 0.56401384 | AB22: 0.46315789 | AD22: 0.95238095 | AE22: 0.95714286 | AF22: 0.90686275 | AG22: 0.61937716 | AH22: 0.51315789 | AJ22: 0.97619048 | AK22: 0.95 | AL22: 0.83333333 | AM22: 0.66089965 | AN22: 0.54736842 | AP22: 0.98809524 | AQ22: 0.95714286 | AR22: 0.90196078 | AS22: 0.56747405 | AT22: 0.51578947 | AV22: 0.96428571 | AW22: 0.90714286 | AX22: 0.86764706 | AY22: 0.60207612 | AZ22: 0.50526316 | BD22: 1 | BE22: =$R$111 -> 0.92827553 | BF22: =$S$111 -> 0.89412483 | BG22: =$T$111 -> 0.78910188 | BH22: =$U$111 -> 0.63518676 | BI22: =$V$111 -> 0.55473684 | BJ22: =$W$111 -> #DIV/0!
J23: 18 | K23: =AVERAGE(R23,X23,AD23,AJ23,AP23,AV23) -> 0.89367816 | L23: =AVERAGE(S23,Y23,AE23,AK23,AQ23,AW23) -> 0.8707483 | M23: =AVERAGE(T23,Z23,AF23,AL23,AR23,AX23) -> 0.83809524 | N23: =AVERAGE(U23,AA23,AG23,AM23,AS23,AY23) -> 0.76755853 | O23: =AVERAGE(V23,AB23,AH23,AN23,AT23,AZ23) -> 0.66929825 | P23: =AVERAGE(W23,AC23,AI23,AO23,AU23,BA23) -> #DIV/0! | R23: 0.87931034 | S23: 0.85034014 | T23: 0.84761905 | U23: 0.77926421 | V23: 0.70263158 | X23: 0.89655172 | Y23: 0.84353741 | Z23: 0.87142857 | AA23: 0.8361204 | AB23: 0.69736842 | AD23: 0.87931034 | AE23: 0.87755102 | AF23: 0.85714286 | AG23: 0.67892977 | AH23: 0.62631579 | AJ23: 0.89655172 | AK23: 0.87755102 | AL23: 0.82380952 | AM23: 0.72575251 | AN23: 0.64473684 | AP23: 0.9137931 | AQ23: 0.88435374 | AR23: 0.82857143 | AS23: 0.84949833 | AT23: 0.74210526 | AV23: 0.89655172 | AW23: 0.89115646 | AX23: 0.8 | AY23: 0.73578595 | AZ23: 0.60263158 | BD23: 2 | BE23: =$X$111 -> 0.92858377 | BF23: =$Y$111 -> 0.90285864 | BG23: =$Z$111 -> 0.7764955 | BH23: =$AA$111 -> 0.63795074 | BI23: =$AB$111 -> 0.54298246 | BJ23: =$AC$111 -> #DIV/0!
J24: 19 | K24: =AVERAGE(R24,X24,AD24,AJ24,AP24,AV24) -> 0.95 | L24: =AVERAGE(S24,Y24,AE24,AK24,AQ24,AW24) -> 0.87844612 | M24: =AVERAGE(T24,Z24,AF24,AL24,AR24,AX24) -> 0.8661859 | N24: =AVERAGE(U24,AA24,AG24,AM24,AS24,AY24) -> 0.54948805 | O24: =AVERAGE(V24,AB24,AH24,AN24,AT24,AZ24) -> 0.4745614 | P24: =AVERAGE(W24,AC24,AI24,AO24,AU24,BA24) -> #DIV/0! | R24: 0.95714286 | S24: 0.81954887 | T24: 0.86538462 | U24: 0.63139932 | V24: 0.52894737 | X24: 0.95714286 | Y24: 0.87969925 | Z24: 0.85096154 | AA24: 0.58703072 | AB24: 0.45526316 | AD24: 0.94285714 | AE24: 0.88721805 | AF24: 0.83653846 | AG24: 0.64163823 | AH24: 0.4 | AJ24: 0.95714286 | AK24: 0.92481203 | AL24: 0.86538462 | AM24: 0.46075085 | AN24: 0.53947368 | AP24: 0.94285714 | AQ24: 0.87218045 | AR24: 0.90865385 | AS24: 0.4778157 | AT24: 0.43157895 | AV24: 0.94285714 | AW24: 0.88721805 | AX24: 0.87019231 | AY24: 0.49829352 | AZ24: 0.49210526 | BD24: 3 | BE24: =$AD$111 -> 0.92792707 | BF24: =$AE$111 -> 0.89620538 | BG24: =$AF$111 -> 0.77655353 | BH24: =$AG$111 -> 0.62348306 | BI24: =$AH$111 -> 0.51885965 | BJ24: =$AI$111 -> #DIV/0!
