Workbook

Sheet Person_0
K3: k=0.25
S4: 1 | Y4: 2 | AE4: 3 | AK4: 4 | AQ4: 5 | AW4: 6
A5: k | B5: Task 1 | C5: Task 2 | D5: Task 3 | E5: Task 4 | F5: Task 5 | G5: Task 6 | J5: ID | K5: Task 1 | L5: Task 2 | M5: Task 3 | N5: Task 4 | O5: Task 5 | P5: Task 6 | R5: Task 1 | S5: Task 2 | T5: Task 3 | U5: Task 4 | V5: Task 5 | W5: Task 6 | X5: Task 1 | Y5: Task 2 | Z5: Task 3 | AA5: Task 4 | AB5: Task 5 | AC5: Task 6 | AD5: Task 1 | AE5: Task 2 | AF5: Task 3 | AG5: Task 4 | AH5: Task 5 | AI5: Task 6 | AJ5: Task 1 | AK5: Task 2 | AL5: Task 3 | AM5: Task 4 | AN5: Task 5 | AO5: Task 6 | AP5: Task 1 | AQ5: Task 2 | AR5: Task 3 | AS5: Task 4 | AT5: Task 5 | AU5: Task 6 | AV5: Task 1 | AW5: Task 2 | AX5: Task 3 | AY5: Task 4 | AZ5: Task 5 | BA5: Task 6 | BD5: =A6 -> 0.25 | BE5: Task 1 | BF5: Task 2 | BG5: Task 3 | BH5: Task 4 | BI5: Task 5 | BJ5: Task 6
A6: 0.25 | B6: =AVERAGE(K6:K35) -> 0.96013147 | C6: =AVERAGE(L6:L35) -> 0.90837553 | D6: =AVERAGE(M6:M35) -> 0.77159923 | E6: =AVERAGE(N6:N35) -> 0.5841391 | F6: =AVERAGE(O6:O35) -> #DIV/0! | G6: =AVERAGE(P6:P35) -> #DIV/0! | J6: 1 | K6: =AVERAGE(R6,X6,AD6,AJ6,AP6,AV6) -> 0.9109589 | L6: =AVERAGE(S6,Y6,AE6,AK6,AQ6,AW6) -> 0.90406504 | M6: =AVERAGE(T6,Z6,AF6,AL6,AR6,AX6) -> 0.72676056 | N6: =AVERAGE(U6,AA6,AG6,AM6,AS6,AY6) -> 0.56658185 | O6: =AVERAGE(V6,AB6,AH6,AN6,AT6,AZ6) -> #DIV/0! | P6: =AVERAGE(W6,AC6,AI6,AO6,AU6,BA6) -> #DIV/0! | R6: 0.90410959 | S6: 0.90243902 | T6: 0.71549296 | U6: 0.54961832 | X6: 0.89041096 | Y6: 0.91219512 | Z6: 0.70422535 | AA6: 0.57506361 | AD6: 0.90410959 | AE6: 0.89268293 | AF6: 0.73802817 | AG6: 0.61323155 | AJ6: 0.93150685 | AK6: 0.86341463 | AL6: 0.67042254 | AM6: 0.5648855 | AP6: 0.91780822 | AQ6: 0.93170732 | AR6: 0.75774648 | AS6: 0.54198473 | AV6: 0.91780822 | AW6: 0.92195122 | AX6: 0.77464789 | AY6: 0.55470738 | BD6: 1 | BE6: =$R$37 -> 0.95618924 | BF6: =$S$37 -> 0.91811358 | BG6: =$T$37 -> 0.77050422 | BH6: =$U$37 -> 0.58312129 | BI6: =$V$37 -> #DIV/0! | BJ6: =$W$37 -> #DIV/0!
A7: 0.5 | B7: =AVERAGE(K43:K72) -> 0.95679081 | C7: =AVERAGE(L43:L72) -> 0.90697748 | D7: =AVERAGE(M43:M72) -> 0.78543633 | E7: =AVERAGE(N43:N72) -> 0.59601357 | F7: =AVERAGE(O43:O72) -> #DIV/0! | G7: =AVERAGE(P43:P72) -> #DIV/0! | J7: 2 | K7: =AVERAGE(R7,X7,AD7,AJ7,AP7,AV7) -> 0.84099617 | L7: =AVERAGE(S7,Y7,AE7,AK7,AQ7,AW7) -> 0.85643564 | M7: =AVERAGE(T7,Z7,AF7,AL7,AR7,AX7) -> 0.83615023 | N7: =AVERAGE(U7,AA7,AG7,AM7,AS7,AY7) -> 0.65903308 | O7: =AVERAGE(V7,AB7,AH7,AN7,AT7,AZ7) -> #DIV/0! | P7: =AVERAGE(W7,AC7,AI7,AO7,AU7,BA7) -> #DIV/0! | R7: 0.85057471 | S7: 0.85643564 | T7: 0.82535211 | U7: 0.65903308 | X7: 0.81609195 | Y7: 0.7970297 | Z7: 0.81690141 | AA7: 0.54961832 | AD7: 0.85057471 | AE7: 0.85643564 | AF7: 0.83098592 | AG7: 0.60050891 | AJ7: 0.83908046 | AK7: 0.9009901 | AL7: 0.85915493 | AM7: 0.76335878 | AP7: 0.85057471 | AQ7: 0.85643564 | AR7: 0.86478873 | AS7: 0.69974555 | AV7: 0.83908046 | AW7: 0.87128713 | AX7: 0.81971831 | AY7: 0.68193384 | BD7: 2 | BE7: =$X$37 -> 0.95855383 | BF7: =$Y$37 -> 0.90340455 | BG7: =$Z$37 -> 0.76019136 | BH7: =$AA$37 -> 0.59414758 | BI7: =$AB$37 -> #DIV/0! | BJ7: =$AC$37 -> #DIV/0!
A8: 1 | B8: =AVERAGE(K80:K109) -> 0.95746304 | C8: =AVERAGE(L80:L109) -> 0.90798493 | D8: =AVERAGE(M80:M109) -> 0.78884562 | E8: =AVERAGE(N80:N109) -> 0.59971727 | F8: =AVERAGE(O80:O109) -> #DIV/0! | G8: =AVERAGE(P80:P109) -> #DIV/0! | J8: 3 | K8: =AVERAGE(R8,X8,AD8,AJ8,AP8,AV8) -> 0.9875 | L8: =AVERAGE(S8,Y8,AE8,AK8,AQ8,AW8) -> 0.97752809 | M8: =AVERAGE(T8,Z8,AF8,AL8,AR8,AX8) -> 0.79530516 | N8: =AVERAGE(U8,AA8,AG8,AM8,AS8,AY8) -> 0.49151824 | O8: =AVERAGE(V8,AB8,AH8,AN8,AT8,AZ8) -> #DIV/0! | P8: =AVERAGE(W8,AC8,AI8,AO8,AU8,BA8) -> #DIV/0! | R8: 0.9875 | S8: 0.98314607 | T8: 0.81971831 | U8: 0.45292621 | X8: 0.9875 | Y8: 0.97752809 | Z8: 0.72394366 | AA8: 0.55470738 | AD8: 0.9875 | AE8: 0.96067416 | AF8: 0.74647887 | AG8: 0.55979644 | AJ8: 0.9875 | AK8: 0.98314607 | AL8: 0.85352113 | AM8: 0.47328244 | AP8: 0.9875 | AQ8: 0.97752809 | AR8: 0.8084507 | AS8: 0.44020356 | AV8: 0.9875 | AW8: 0.98314607 | AX8: 0.81971831 | AY8: 0.46819338 | BD8: 3 | BE8: =$AD$37 -> 0.96404637 | BF8: =$AE$37 -> 0.90574875 | BG8: =$AF$37 -> 0.77416861 | BH8: =$AG$37 -> 0.58176421 | BI8: =$AH$37 -> #DIV/0! | BJ8: =$AI$37 -> #DIV/0!
A9: 2 | B9: =AVERAGE(K117:K146) -> 0.9590878 | C9: =AVERAGE(L117:L146) -> 0.91231169 | D9: =AVERAGE(M117:M146) -> 0.78278547 | E9: =AVERAGE(N117:N146) -> 0.59074074 | F9: =AVERAGE(O117:O146) -> #DIV/0! | G9: =AVERAGE(P117:P146) -> #DIV/0! | J9: 4 | K9: =AVERAGE(R9,X9,AD9,AJ9,AP9,AV9) -> 0.98684211 | L9: =AVERAGE(S9,Y9,AE9,AK9,AQ9,AW9) -> 0.87398374 | M9: =AVERAGE(T9,Z9,AF9,AL9,AR9,AX9) -> 0.70657277 | N9: =AVERAGE(U9,AA9,AG9,AM9,AS9,AY9) -> 0.52841391 | O9: =AVERAGE(V9,AB9,AH9,AN9,AT9,AZ9) -> #DIV/0! | P9: =AVERAGE(W9,AC9,AI9,AO9,AU9,BA9) -> #DIV/0! | R9: 0.98684211 | S9: 0.86829268 | T9: 0.72394366 | U9: 0.59796438 | X9: 0.98684211 | Y9: 0.89268293 | Z9: 0.61408451 | AA9: 0.52926209 | AD9: 0.98684211 | AE9: 0.88292683 | AF9: 0.78028169 | AG9: 0.55216285 | AJ9: 0.98684211 | AK9: 0.89756098 | AL9: 0.73521127 | AM9: 0.4605598 | AP9: 0.98684211 | AQ9: 0.85853659 | AR9: 0.69859155 | AS9: 0.48600509 | AV9: 0.98684211 | AW9: 0.84390244 | AX9: 0.68732394 | AY9: 0.54452926 | BD9: 4 | BE9: =$AJ$37 -> 0.96191532 | BF9: =$AK$37 -> 0.907289 | BG9: =$AL$37 -> 0.77893435 | BH9: =$AM$37 -> 0.58575064 | BI9: =$AN$37 -> #DIV/0! | BJ9: =$AO$37 -> #DIV/0!
A10: 3 | B10: =AVERAGE(K154:K183) -> 0.95777156 | C10: =AVERAGE(L154:L183) -> 0.91028447 | D10: =AVERAGE(M154:M183) -> 0.77239124 | E10: =AVERAGE(N154:N183) -> 0.57684478 | F10: =AVERAGE(O154:O183) -> #DIV/0! | G10: =AVERAGE(P154:P183) -> #DIV/0! | J10: 5 | K10: =AVERAGE(R10,X10,AD10,AJ10,AP10,AV10) -> 0.97537879 | L10: =AVERAGE(S10,Y10,AE10,AK10,AQ10,AW10) -> 0.87558685 | M10: =AVERAGE(T10,Z10,AF10,AL10,AR10,AX10) -> 0.7527027 | N10: =AVERAGE(U10,AA10,AG10,AM10,AS10,AY10) -> 0.58142494 | O10: =AVERAGE(V10,AB10,AH10,AN10,AT10,AZ10) -> #DIV/0! | P10: =AVERAGE(W10,AC10,AI10,AO10,AU10,BA10) -> #DIV/0! | R10: 0.96590909 | S10: 0.90610329 | T10: 0.69459459 | U10: 0.58524173 | X10: 0.97727273 | Y10: 0.84507042 | Z10: 0.72702703 | AA10: 0.56743003 | AD10: 0.97727273 | AE10: 0.88262911 | AF10: 0.77027027 | AG10: 0.58015267 | AJ10: 0.97727273 | AK10: 0.90610329 | AL10: 0.76486486 | AM10: 0.6437659 | AP10: 0.97727273 | AQ10: 0.88732394 | AR10: 0.77837838 | AS10: 0.54707379 | AV10: 0.97727273 | AW10: 0.82629108 | AX10: 0.78108108 | AY10: 0.5648855 | BD10: 5 | BE10: =$AP$37 -> 0.95928353 | BF10: =$AQ$37 -> 0.91100814 | BG10: =$AR$37 -> 0.77420577 | BH10: =$AS$37 -> 0.58023749 | BI10: =$AT$37 -> #DIV/0! | BJ10: =$AU$37 -> #DIV/0!
J11: 6 | K11: =AVERAGE(R11,X11,AD11,AJ11,AP11,AV11) -> 0.96296296 | L11: =AVERAGE(S11,Y11,AE11,AK11,AQ11,AW11) -> 0.91935484 | M11: =AVERAGE(T11,Z11,AF11,AL11,AR11,AX11) -> 0.8202138 | N11: =AVERAGE(U11,AA11,AG11,AM11,AS11,AY11) -> 0.66157761 | O11: =AVERAGE(V11,AB11,AH11,AN11,AT11,AZ11) -> #DIV/0! | P11: =AVERAGE(W11,AC11,AI11,AO11,AU11,BA11) -> #DIV/0! | R11: 0.95555556 | S11: 0.90322581 | T11: 0.82215743 | U11: 0.60050891 | X11: 0.97777778 | Y11: 0.89247312 | Z11: 0.82215743 | AA11: 0.62849873 | AD11: 0.95555556 | AE11: 0.92473118 | AF11: 0.86005831 | AG11: 0.7302799 | AJ11: 0.96666667 | AK11: 0.94086022 | AL11: 0.89212828 | AM11: 0.6870229 | AP11: 0.95555556 | AQ11: 0.94623656 | AR11: 0.85422741 | AS11: 0.70229008 | AV11: 0.96666667 | AW11: 0.90860215 | AX11: 0.67055394 | AY11: 0.62086514 | BD11: 6 | BE11: =$AV$37 -> 0.96080056 | BF11: =$AW$37 -> 0.90468914 | BG11: =$AX$37 -> 0.77159108 | BH11: =$AY$37 -> 0.5798134 | BI11: =$AZ$37 -> #DIV/0! | BJ11: =$BA$37 -> #DIV/0!
J12: 7 | K12: =AVERAGE(R12,X12,AD12,AJ12,AP12,AV12) -> 0.95208333 | L12: =AVERAGE(S12,Y12,AE12,AK12,AQ12,AW12) -> 0.94351852 | M12: =AVERAGE(T12,Z12,AF12,AL12,AR12,AX12) -> 0.76686217 | N12: =AVERAGE(U12,AA12,AG12,AM12,AS12,AY12) -> 0.59838846 | O12: =AVERAGE(V12,AB12,AH12,AN12,AT12,AZ12) -> #DIV/0! | P12: =AVERAGE(W12,AC12,AI12,AO12,AU12,BA12) -> #DIV/0! | R12: 0.95 | S12: 0.96111111 | T12: 0.68621701 | U12: 0.61323155 | X12: 0.9375 | Y12: 0.92777778 | Z12: 0.78005865 | AA12: 0.66157761 | AD12: 0.9625 | AE12: 0.96111111 | AF12: 0.79765396 | AG12: 0.58015267 | AJ12: 0.95 | AK12: 0.95 | AL12: 0.79472141 | AM12: 0.57506361 | AP12: 0.9375 | AQ12: 0.95 | AR12: 0.76539589 | AS12: 0.55216285 | AV12: 0.975 | AW12: 0.91111111 | AX12: 0.7771261 | AY12: 0.60814249
J13: 8 | K13: =AVERAGE(R13,X13,AD13,AJ13,AP13,AV13) -> 0.9495614 | L13: =AVERAGE(S13,Y13,AE13,AK13,AQ13,AW13) -> 0.84122807 | M13: =AVERAGE(T13,Z13,AF13,AL13,AR13,AX13) -> 0.74366197 | N13: =AVERAGE(U13,AA13,AG13,AM13,AS13,AY13) -> 0.38167939 | O13: =AVERAGE(V13,AB13,AH13,AN13,AT13,AZ13) -> #DIV/0! | P13: =AVERAGE(W13,AC13,AI13,AO13,AU13,BA13) -> #DIV/0! | R13: 0.94736842 | S13: 0.88421053 | T13: 0.74366197 | U13: 0.3740458 | X13: 0.96052632 | Y13: 0.87368421 | Z13: 0.75211268 | AA13: 0.30279898 | AD13: 0.94736842 | AE13: 0.84736842 | AF13: 0.78873239 | AG13: 0.47328244 | AJ13: 0.93421053 | AK13: 0.80526316 | AL13: 0.69014085 | AM13: 0.37659033 | AP13: 0.96052632 | AQ13: 0.81052632 | AR13: 0.72112676 | AS13: 0.33587786 | AV13: 0.94736842 | AW13: 0.82631579 | AX13: 0.76619718 | AY13: 0.42748092 | BD13: =A7 -> 0.5 | BE13: Task 1 | BF13: Task 2 | BG13: Task 3 | BH13: Task 4 | BI13: Task 5 | BJ13: Task 6
J14: 9 | K14: =AVERAGE(R14,X14,AD14,AJ14,AP14,AV14) -> 0.98717949 | L14: =AVERAGE(S14,Y14,AE14,AK14,AQ14,AW14) -> 0.84240924 | M14: =AVERAGE(T14,Z14,AF14,AL14,AR14,AX14) -> 0.6686103 | N14: =AVERAGE(U14,AA14,AG14,AM14,AS14,AY14) -> 0.53689567 | O14: =AVERAGE(V14,AB14,AH14,AN14,AT14,AZ14) -> #DIV/0! | P14: =AVERAGE(W14,AC14,AI14,AO14,AU14,BA14) -> #DIV/0! | R14: 0.98717949 | S14: 0.86633663 | T14: 0.62682216 | U14: 0.54452926 | X14: 0.98717949 | Y14: 0.81683168 | Z14: 0.6180758 | AA14: 0.48091603 | AD14: 0.98717949 | AE14: 0.83663366 | AF14: 0.6851312 | AG14: 0.49872774 | AJ14: 0.98717949 | AK14: 0.87128713 | AL14: 0.75218659 | AM14: 0.55470738 | AP14: 0.98717949 | AQ14: 0.84158416 | AR14: 0.60932945 | AS14: 0.50890585 | AV14: 0.98717949 | AW14: 0.82178218 | AX14: 0.72011662 | AY14: 0.63358779 | BD14: 1 | BE14: =$R$74 -> 0.95395729 | BF14: =$S$74 -> 0.90786413 | BG14: =$T$74 -> 0.78707186 | BH14: =$U$74 -> 0.58498728 | BI14: =$V$74 -> #DIV/0! | BJ14: =$W$74 -> #DIV/0!
J15: 10 | K15: =AVERAGE(R15,X15,AD15,AJ15,AP15,AV15) -> 0.98684211 | L15: =AVERAGE(S15,Y15,AE15,AK15,AQ15,AW15) -> 0.94602273 | M15: =AVERAGE(T15,Z15,AF15,AL15,AR15,AX15) -> 0.79342723 | N15: =AVERAGE(U15,AA15,AG15,AM15,AS15,AY15) -> 0.55810008 | O15: =AVERAGE(V15,AB15,AH15,AN15,AT15,AZ15) -> #DIV/0! | P15: =AVERAGE(W15,AC15,AI15,AO15,AU15,BA15) -> #DIV/0! | R15: 0.98684211 | S15: 0.96022727 | T15: 0.81690141 | U15: 0.57760814 | X15: 0.98684211 | Y15: 0.89772727 | Z15: 0.78028169 | AA15: 0.48600509 | AD15: 0.98684211 | AE15: 0.96022727 | AF15: 0.78028169 | AG15: 0.52926209 | AJ15: 0.98684211 | AK15: 0.94318182 | AL15: 0.78873239 | AM15: 0.54198473 | AP15: 0.98684211 | AQ15: 0.95454545 | AR15: 0.78309859 | AS15: 0.64122137 | AV15: 0.98684211 | AW15: 0.96022727 | AX15: 0.81126761 | AY15: 0.57251908 | BD15: 2 | BE15: =$X$74 -> 0.96050802 | BF15: =$Y$74 -> 0.91099111 | BG15: =$Z$74 -> 0.7883972 | BH15: =$AA$74 -> 0.60500424 | BI15: =$AB$74 -> #DIV/0! | BJ15: =$AC$74 -> #DIV/0!
J16: 11 | K16: =AVERAGE(R16,X16,AD16,AJ16,AP16,AV16) -> 0.90182648 | L16: =AVERAGE(S16,Y16,AE16,AK16,AQ16,AW16) -> 0.91542289 | M16: =AVERAGE(T16,Z16,AF16,AL16,AR16,AX16) -> 0.75024438 | N16: =AVERAGE(U16,AA16,AG16,AM16,AS16,AY16) -> 0.65691264 | O16: =AVERAGE(V16,AB16,AH16,AN16,AT16,AZ16) -> #DIV/0! | P16: =AVERAGE(W16,AC16,AI16,AO16,AU16,BA16) -> #DIV/0! | R16: 0.87671233 | S16: 0.93034826 | T16: 0.71554252 | U16: 0.66666667 | X16: 0.89041096 | Y16: 0.93532338 | Z16: 0.73020528 | AA16: 0.6259542 | AD16: 0.93150685 | AE16: 0.93532338 | AF16: 0.73900293 | AG16: 0.66157761 | AJ16: 0.90410959 | AK16: 0.92039801 | AL16: 0.72727273 | AM16: 0.6437659 | AP16: 0.89041096 | AQ16: 0.84079602 | AR16: 0.80938416 | AS16: 0.71246819 | AV16: 0.91780822 | AW16: 0.93034826 | AX16: 0.78005865 | AY16: 0.63104326 | BD16: 3 | BE16: =$AD$74 -> 0.95775986 | BF16: =$AE$74 -> 0.90780538 | BG16: =$AF$74 -> 0.78783583 | BH16: =$AG$74 -> 0.60152672 | BI16: =$AH$74 -> #DIV/0! | BJ16: =$AI$74 -> #DIV/0!
J17: 12 | K17: =AVERAGE(R17,X17,AD17,AJ17,AP17,AV17) -> 0.98360656 | L17: =AVERAGE(S17,Y17,AE17,AK17,AQ17,AW17) -> 0.90038314 | M17: =AVERAGE(T17,Z17,AF17,AL17,AR17,AX17) -> 0.86314761 | N17: =AVERAGE(U17,AA17,AG17,AM17,AS17,AY17) -> 0.71458863 | O17: =AVERAGE(V17,AB17,AH17,AN17,AT17,AZ17) -> #DIV/0! | P17: =AVERAGE(W17,AC17,AI17,AO17,AU17,BA17) -> #DIV/0! | R17: 0.98360656 | S17: 0.94827586 | T17: 0.89442815 | U17: 0.6870229 | X17: 0.98360656 | Y17: 0.87931034 | Z17: 0.82404692 | AA17: 0.72519084 | AD17: 0.98360656 | AE17: 0.89655172 | AF17: 0.85630499 | AG17: 0.6870229 | AJ17: 0.98360656 | AK17: 0.84482759 | AL17: 0.88856305 | AM17: 0.61832061 | AP17: 0.98360656 | AQ17: 0.9137931 | AR17: 0.85630499 | AS17: 0.80152672 | AV17: 0.98360656 | AW17: 0.91954023 | AX17: 0.85923754 | AY17: 0.76844784 | BD17: 4 | BE17: =$AJ$74 -> 0.95310587 | BF17: =$AK$74 -> 0.90479445 | BG17: =$AL$74 -> 0.7831837 | BH17: =$AM$74 -> 0.59236641 | BI17: =$AN$74 -> #DIV/0! | BJ17: =$AO$74 -> #DIV/0!
J18: 13 | K18: =AVERAGE(R18,X18,AD18,AJ18,AP18,AV18) -> 0.94078947 | L18: =AVERAGE(S18,Y18,AE18,AK18,AQ18,AW18) -> 0.87452107 | M18: =AVERAGE(T18,Z18,AF18,AL18,AR18,AX18) -> 0.75826251 | N18: =AVERAGE(U18,AA18,AG18,AM18,AS18,AY18) -> 0.55089059 | O18: =AVERAGE(V18,AB18,AH18,AN18,AT18,AZ18) -> #DIV/0! | P18: =AVERAGE(W18,AC18,AI18,AO18,AU18,BA18) -> #DIV/0! | R18: 0.90789474 | S18: 0.90229885 | T18: 0.74787535 | U18: 0.59033079 | X18: 0.94736842 | Y18: 0.87931034 | Z18: 0.77903683 | AA18: 0.58015267 | AD18: 0.97368421 | AE18: 0.86781609 | AF18: 0.76487252 | AG18: 0.57506361 | AJ18: 0.93421053 | AK18: 0.7816092 | AL18: 0.71388102 | AM18: 0.51653944 | AP18: 0.94736842 | AQ18: 0.93103448 | AR18: 0.7733711 | AS18: 0.54961832 | AV18: 0.93421053 | AW18: 0.88505747 | AX18: 0.77053824 | AY18: 0.49363868 | BD18: 5 | BE18: =$AP$74 -> 0.95443317 | BF18: =$AQ$74 -> 0.90670513 | BG18: =$AR$74 -> 0.78672168 | BH18: =$AS$74 -> 0.59219678 | BI18: =$AT$74 -> #DIV/0! | BJ18: =$AU$74 -> #DIV/0!
J19: 14 | K19: =AVERAGE(R19,X19,AD19,AJ19,AP19,AV19) -> 0.98674242 | L19: =AVERAGE(S19,Y19,AE19,AK19,AQ19,AW19) -> 0.95673077 | M19: =AVERAGE(T19,Z19,AF19,AL19,AR19,AX19) -> 0.7877095 | N19: =AVERAGE(U19,AA19,AG19,AM19,AS19,AY19) -> 0.59584394 | O19: =AVERAGE(V19,AB19,AH19,AN19,AT19,AZ19) -> #DIV/0! | P19: =AVERAGE(W19,AC19,AI19,AO19,AU19,BA19) -> #DIV/0! | R19: 0.98863636 | S19: 0.97596154 | T19: 0.71787709 | U19: 0.47328244 | X19: 0.97727273 | Y19: 0.96634615 | Z19: 0.7877095 | AA19: 0.7302799 | AD19: 1 | AE19: 0.92788462 | AF19: 0.8575419 | AG19: 0.70737913 | AJ19: 0.97727273 | AK19: 0.95192308 | AL19: 0.77094972 | AM19: 0.51908397 | AP19: 0.98863636 | AQ19: 0.95673077 | AR19: 0.83240223 | AS19: 0.59796438 | AV19: 0.98863636 | AW19: 0.96153846 | AX19: 0.75977654 | AY19: 0.54707379 | BD19: 6 | BE19: =$AV$74 -> 0.96098067 | BF19: =$AW$74 -> 0.90370467 | BG19: =$AX$74 -> 0.77940772 | BH19: =$AY$74 -> 0.6 | BI19: =$AZ$74 -> #DIV/0! | BJ19: =$BA$74 -> #DIV/0!
J20: 15 | K20: =AVERAGE(R20,X20,AD20,AJ20,AP20,AV20) -> 0.98039216 | L20: =AVERAGE(S20,Y20,AE20,AK20,AQ20,AW20) -> 0.90620155 | M20: =AVERAGE(T20,Z20,AF20,AL20,AR20,AX20) -> 0.81079812 | N20: =AVERAGE(U20,AA20,AG20,AM20,AS20,AY20) -> 0.557676 | O20: =AVERAGE(V20,AB20,AH20,AN20,AT20,AZ20) -> #DIV/0! | P20: =AVERAGE(W20,AC20,AI20,AO20,AU20,BA20) -> #DIV/0! | R20: 0.98039216 | S20: 0.94883721 | T20: 0.84225352 | U20: 0.58778626 | X20: 0.98039216 | Y20: 0.86046512 | Z20: 0.70140845 | AA20: 0.52926209 | AD20: 0.98039216 | AE20: 0.83255814 | AF20: 0.85070423 | AG20: 0.5648855 | AJ20: 0.98039216 | AK20: 0.9627907 | AL20: 0.83943662 | AM20: 0.54707379 | AP20: 0.98039216 | AQ20: 0.91162791 | AR20: 0.81690141 | AS20: 0.62086514 | AV20: 0.98039216 | AW20: 0.92093023 | AX20: 0.81408451 | AY20: 0.49618321
J21: 16 | K21: =AVERAGE(R21,X21,AD21,AJ21,AP21,AV21) -> 0.98666667 | L21: =AVERAGE(S21,Y21,AE21,AK21,AQ21,AW21) -> 0.9745614 | M21: =AVERAGE(T21,Z21,AF21,AL21,AR21,AX21) -> 0.81877934 | N21: =AVERAGE(U21,AA21,AG21,AM21,AS21,AY21) -> 0.60602205 | O21: =AVERAGE(V21,AB21,AH21,AN21,AT21,AZ21) -> #DIV/0! | P21: =AVERAGE(W21,AC21,AI21,AO21,AU21,BA21) -> #DIV/0! | R21: 0.98666667 | S21: 0.97368421 | T21: 0.81971831 | U21: 0.57506361 | X21: 0.98666667 | Y21: 0.97894737 | Z21: 0.7971831 | AA21: 0.59796438 | AD21: 0.98666667 | AE21: 0.97894737 | AF21: 0.83943662 | AG21: 0.64122137 | AJ21: 0.98666667 | AK21: 0.96315789 | AL21: 0.85915493 | AM21: 0.57506361 | AP21: 0.98666667 | AQ21: 0.97894737 | AR21: 0.74366197 | AS21: 0.60814249 | AV21: 0.98666667 | AW21: 0.97368421 | AX21: 0.85352113 | AY21: 0.63867684 | BD21: =A8 -> 1 | BE21: Task 1 | BF21: Task 2 | BG21: Task 3 | BH21: Task 4 | BI21: Task 5 | BJ21: Task 6
J22: 17 | K22: =AVERAGE(R22,X22,AD22,AJ22,AP22,AV22) -> 0.98666667 | L22: =AVERAGE(S22,Y22,AE22,AK22,AQ22,AW22) -> 0.96146435 | M22: =AVERAGE(T22,Z22,AF22,AL22,AR22,AX22) -> 0.88025415 | N22: =AVERAGE(U22,AA22,AG22,AM22,AS22,AY22) -> 0.72900763 | O22: =AVERAGE(V22,AB22,AH22,AN22,AT22,AZ22) -> #DIV/0! | P22: =AVERAGE(W22,AC22,AI22,AO22,AU22,BA22) -> #DIV/0! | R22: 0.98666667 | S22: 0.94219653 | T22: 0.86510264 | U22: 0.70483461 | X22: 0.98666667 | Y22: 0.96531792 | Z22: 0.91202346 | AA22: 0.8346056 | AD22: 0.98666667 | AE22: 0.96531792 | AF22: 0.85630499 | AG22: 0.73536896 | AJ22: 0.98666667 | AK22: 0.98265896 | AL22: 0.88856305 | AM22: 0.75572519 | AP22: 0.98666667 | AQ22: 0.94219653 | AR22: 0.8856305 | AS22: 0.68193384 | AV22: 0.98666667 | AW22: 0.97109827 | AX22: 0.87390029 | AY22: 0.66157761 | BD22: 1 | BE22: =$R$111 -> 0.95630987 | BF22: =$S$111 -> 0.90963579 | BG22: =$T$111 -> 0.80080467 | BH22: =$U$111 -> 0.60229008 | BI22: =$V$111 -> #DIV/0! | BJ22: =$W$111 -> #DIV/0!
J23: 18 | K23: =AVERAGE(R23,X23,AD23,AJ23,AP23,AV23) -> 0.98275862 | L23: =AVERAGE(S23,Y23,AE23,AK23,AQ23,AW23) -> 0.95833333 | M23: =AVERAGE(T23,Z23,AF23,AL23,AR23,AX23) -> 0.81861349 | N23: =AVERAGE(U23,AA23,AG23,AM23,AS23,AY23) -> 0.63273961 | O23: =AVERAGE(V23,AB23,AH23,AN23,AT23,AZ23) -> #DIV/0! | P23: =AVERAGE(W23,AC23,AI23,AO23,AU23,BA23) -> #DIV/0! | R23: 0.98275862 | S23: 0.93478261 | T23: 0.83760684 | U23: 0.54707379 | X23: 0.98275862 | Y23: 0.97282609 | Z23: 0.81481481 | AA23: 0.70483461 | AD23: 0.98275862 | AE23: 0.98369565 | AF23: 0.83760684 | AG23: 0.72010178 | AJ23: 0.98275862 | AK23: 0.96195652 | AL23: 0.83190883 | AM23: 0.71501272 | AP23: 0.98275862 | AQ23: 0.97282609 | AR23: 0.81481481 | AS23: 0.63358779 | AV23: 0.98275862 | AW23: 0.92391304 | AX23: 0.77492877 | AY23: 0.47582697 | BD23: 2 | BE23: =$X$111 -> 0.95882844 | BF23: =$Y$111 -> 0.90740115 | BG23: =$Z$111 -> 0.77634917 | BH23: =$AA$111 -> 0.59160305 | BI23: =$AB$111 -> #DIV/0! | BJ23: =$AC$111 -> #DIV/0!
J24: 19 | K24: =AVERAGE(R24,X24,AD24,AJ24,AP24,AV24) -> 0.98666667 | L24: =AVERAGE(S24,Y24,AE24,AK24,AQ24,AW24) -> 0.82612613 | M24: =AVERAGE(T24,Z24,AF24,AL24,AR24,AX24) -> 0.8202138 | N24: =AVERAGE(U24,AA24,AG24,AM24,AS24,AY24) -> 0.6475827 | O24: =AVERAGE(V24,AB24,AH24,AN24,AT24,AZ24) -> #DIV/0! | P24: =AVERAGE(W24,AC24,AI24,AO24,AU24,BA24) -> #DIV/0! | R24: 0.98666667 | S24: 0.88648649 | T24: 0.88338192 | U24: 0.74300254 | X24: 0.98666667 | Y24: 0.82162162 | Z24: 0.81924198 | AA24: 0.69974555 | AD24: 0.98666667 | AE24: 0.79459459 | AF24: 0.83381924 | AG24: 0.62086514 | AJ24: 0.98666667 | AK24: 0.79459459 | AL24: 0.77842566 | AM24: 0.62086514 | AP24: 0.98666667 | AQ24: 0.88108108 | AR24: 0.8425656 | AS24: 0.69720102 | AV24: 0.98666667 | AW24: 0.77837838 | AX24: 0.7638484 | AY24: 0.50381679 | BD24: 3 | BE24: =$AD$111 -> 0.95846937 | BF24: =$AE$111 -> 0.90838559 | BG24: =$AF$111 -> 0.79061017 | BH24: =$AG$111 -> 0.60602205 | BI24: =$AH$111 -> #DIV/0! | BJ24: =$AI$111 -> #DIV/0!
J25: 20 | K25: =AVERAGE(R25,X25,AD25,AJ25,AP25,AV25) -> 0.98461538 | L25: =AVERAGE(S25,Y25,AE25,AK25,AQ25,AW25) -> 0.86923077 | M25: =AVERAGE(T25,Z25,AF25,AL25,AR25,AX25) -> 0.76056338 | N25: =AVERAGE(U25,AA25,AG25,AM25,AS25,AY25) -> 0.64291773 | O25: =AVERAGE(V25,AB25,AH25,AN25,AT25,AZ25) -> #DIV/0! | P25: =AVERAGE(W25,AC25,AI25,AO25,AU25,BA25) -> #DIV/0! | R25: 0.98461538 | S25: 0.86666667 | T25: 0.76619718 | U25: 0.63358779 | X25: 0.98461538 | Y25: 0.88717949 | Z25: 0.70140845 | AA25: 0.61577608 | AD25: 0.98461538 | AE25: 0.85641026 | AF25: 0.8 | AG25: 0.60050891 | AJ25: 0.98461538 | AK25: 0.87692308 | AL25: 0.76056338 | AM25: 0.67684478 | AP25: 0.98461538 | AQ25: 0.86153846 | AR25: 0.76619718 | AS25: 0.61068702 | AV25: 0.98461538 | AW25: 0.86666667 | AX25: 0.76901408 | AY25: 0.72010178 | BD25: 4 | BE25: =$AJ$111 -> 0.95776976 | BF25: =$AK$111 -> 0.91299102 | BG25: =$AL$111 -> 0.78517951 | BH25: =$AM$111 -> 0.60992366 | BI25: =$AN$111 -> #DIV/0! | BJ25: =$AO$111 -> #DIV/0!
J26: 21 | K26: =AVERAGE(R26,X26,AD26,AJ26,AP26,AV26) -> 0.97179487 | L26: =AVERAGE(S26,Y26,AE26,AK26,AQ26,AW26) -> 0.92883895 | M26: =AVERAGE(T26,Z26,AF26,AL26,AR26,AX26) -> 0.73517979 | N26: =AVERAGE(U26,AA26,AG26,AM26,AS26,AY26) -> 0.54452926 | O26: =AVERAGE(V26,AB26,AH26,AN26,AT26,AZ26) -> #DIV/0! | P26: =AVERAGE(W26,AC26,AI26,AO26,AU26,BA26) -> #DIV/0! | R26: 0.95384615 | S26: 0.92134831 | T26: 0.82798834 | U26: 0.65903308 | X26: 0.98461538 | Y26: 0.92134831 | Z26: 0.70262391 | AA26: 0.55470738 | AD26: 0.98461538 | AE26: 0.93820225 | AF26: 0.69387755 | AG26: 0.41221374 | AJ26: 0.98461538 | AK26: 0.93820225 | AL26: 0.6909621 | AM26: 0.55470738 | AP26: 0.98461538 | AQ26: 0.94382022 | AR26: 0.76093294 | AS26: 0.48854962 | AV26: 0.93846154 | AW26: 0.91011236 | AX26: 0.73469388 | AY26: 0.59796438 | BD26: 5 | BE26: =$AP$111 -> 0.95645444 | BF26: =$AQ$111 -> 0.89931211 | BG26: =$AR$111 -> 0.78651165 | BH26: =$AS$111 -> 0.59067006 | BI26: =$AT$111 -> #DIV/0! | BJ26: =$AU$111 -> #DIV/0!
J27: 22 | K27: =AVERAGE(R27,X27,AD27,AJ27,AP27,AV27) -> 0.93073593 | L27: =AVERAGE(S27,Y27,AE27,AK27,AQ27,AW27) -> 0.91843972 | M27: =AVERAGE(T27,Z27,AF27,AL27,AR27,AX27) -> 0.76099707 | N27: =AVERAGE(U27,AA27,AG27,AM27,AS27,AY27) -> 0.54622561 | O27: =AVERAGE(V27,AB27,AH27,AN27,AT27,AZ27) -> #DIV/0! | P27: =AVERAGE(W27,AC27,AI27,AO27,AU27,BA27) -> #DIV/0! | R27: 0.90909091 | S27: 0.93085106 | T27: 0.64809384 | U27: 0.53435115 | X27: 0.94805195 | Y27: 0.93085106 | Z27: 0.86510264 | AA27: 0.56743003 | AD27: 0.93506494 | AE27: 0.93085106 | AF27: 0.74193548 | AG27: 0.56743003 | AJ27: 0.93506494 | AK27: 0.95744681 | AL27: 0.73020528 | AM27: 0.52671756 | AP27: 0.92207792 | AQ27: 0.89361702 | AR27: 0.81818182 | AS27: 0.57251908 | AV27: 0.93506494 | AW27: 0.86702128 | AX27: 0.76246334 | AY27: 0.50890585 | BD27: 6 | BE27: =$AV$111 -> 0.95694636 | BF27: =$AW$111 -> 0.91018393 | BG27: =$AX$111 -> 0.79361854 | BH27: =$AY$111 -> 0.59779474 | BI27: =$AZ$111 -> #DIV/0! | BJ27: =$BA$111 -> #DIV/0!
J28: 23 | K28: =AVERAGE(R28,X28,AD28,AJ28,AP28,AV28) -> 0.93073593 | L28: =AVERAGE(S28,Y28,AE28,AK28,AQ28,AW28) -> 0.91704718 | M28: =AVERAGE(T28,Z28,AF28,AL28,AR28,AX28) -> 0.6657277 | N28: =AVERAGE(U28,AA28,AG28,AM28,AS28,AY28) -> 0.54368109 | O28: =AVERAGE(V28,AB28,AH28,AN28,AT28,AZ28) -> #DIV/0! | P28: =AVERAGE(W28,AC28,AI28,AO28,AU28,BA28) -> #DIV/0! | R28: 0.93506494 | S28: 0.92694064 | T28: 0.66478873 | U28: 0.46564885 | X28: 0.93506494 | Y28: 0.92694064 | Z28: 0.63380282 | AA28: 0.52671756 | AD28: 0.92207792 | AE28: 0.88584475 | AF28: 0.71267606 | AG28: 0.57760814 | AJ28: 0.94805195 | AK28: 0.93607306 | AL28: 0.65352113 | AM28: 0.53689567 | AP28: 0.92207792 | AQ28: 0.94063927 | AR28: 0.66197183 | AS28: 0.48854962 | AV28: 0.92207792 | AW28: 0.88584475 | AX28: 0.66760563 | AY28: 0.66666667
J29: 24 | K29: =AVERAGE(R29,X29,AD29,AJ29,AP29,AV29) -> 0.94517544 | L29: =AVERAGE(S29,Y29,AE29,AK29,AQ29,AW29) -> 0.82752902 | M29: =AVERAGE(T29,Z29,AF29,AL29,AR29,AX29) -> 0.68318756 | N29: =AVERAGE(U29,AA29,AG29,AM29,AS29,AY29) -> 0.60729432 | O29: =AVERAGE(V29,AB29,AH29,AN29,AT29,AZ29) -> #DIV/0! | P29: =AVERAGE(W29,AC29,AI29,AO29,AU29,BA29) -> #DIV/0! | R29: 0.94736842 | S29: 0.84079602 | T29: 0.74927114 | U29: 0.65648855 | X29: 0.93421053 | Y29: 0.78109453 | Z29: 0.66472303 | AA29: 0.60050891 | AD29: 0.96052632 | AE29: 0.80597015 | AF29: 0.63556851 | AG29: 0.56743003 | AJ29: 0.94736842 | AK29: 0.8159204 | AL29: 0.64431487 | AM29: 0.51653944 | AP29: 0.92105263 | AQ29: 0.85572139 | AR29: 0.69387755 | AS29: 0.65648855 | AV29: 0.96052632 | AW29: 0.86567164 | AX29: 0.71137026 | AY29: 0.64631043 | BD29: =A9 -> 2 | BE29: Task 1 | BF29: Task 2 | BG29: Task 3 | BH29: Task 4 | BI29: Task 5 | BJ29: Task 6
J30: 25 | K30: =AVERAGE(R30,X30,AD30,AJ30,AP30,AV30) -> 0.98888889 | L30: =AVERAGE(S30,Y30,AE30,AK30,AQ30,AW30) -> 0.95943563 | M30: =AVERAGE(T30,Z30,AF30,AL30,AR30,AX30) -> 0.77048417 | N30: =AVERAGE(U30,AA30,AG30,AM30,AS30,AY30) -> 0.64673452 | O30: =AVERAGE(V30,AB30,AH30,AN30,AT30,AZ30) -> #DIV/0! | P30: =AVERAGE(W30,AC30,AI30,AO30,AU30,BA30) -> #DIV/0! | R30: 0.98888889 | S30: 0.96296296 | T30: 0.77653631 | U30: 0.65903308 | X30: 0.98888889 | Y30: 0.96296296 | Z30: 0.75977654 | AA30: 0.65394402 | AD30: 0.98888889 | AE30: 0.94708995 | AF30: 0.76536313 | AG30: 0.59033079 | AJ30: 0.98888889 | AK30: 0.96296296 | AL30: 0.82402235 | AM30: 0.70483461 | AP30: 0.98888889 | AQ30: 0.96296296 | AR30: 0.74581006 | AS30: 0.5648855 | AV30: 0.98888889 | AW30: 0.95767196 | AX30: 0.75139665 | AY30: 0.70737913 | BD30: 1 | BE30: =$R$148 -> 0.95684818 | BF30: =$S$148 -> 0.91693878 | BG30: =$T$148 -> 0.7913047 | BH30: =$U$148 -> 0.58651399 | BI30: =$V$148 -> #DIV/0! | BJ30: =$W$148 -> #DIV/0!
J31: 26 | K31: =AVERAGE(R31,X31,AD31,AJ31,AP31,AV31) -> 0.98958333 | L31: =AVERAGE(S31,Y31,AE31,AK31,AQ31,AW31) -> 0.93577236 | M31: =AVERAGE(T31,Z31,AF31,AL31,AR31,AX31) -> 0.74225352 | N31: =AVERAGE(U31,AA31,AG31,AM31,AS31,AY31) -> 0.44783715 | O31: =AVERAGE(V31,AB31,AH31,AN31,AT31,AZ31) -> #DIV/0! | P31: =AVERAGE(W31,AC31,AI31,AO31,AU31,BA31) -> #DIV/0! | R31: 1 | S31: 0.91219512 | T31: 0.8056338 | U31: 0.5826972 | X31: 0.975 | Y31: 0.95609756 | Z31: 0.82253521 | AA31: 0.44783715 | AD31: 1 | AE31: 0.93170732 | AF31: 0.70140845 | AG31: 0.34605598 | AJ31: 1 | AK31: 0.96097561 | AL31: 0.73521127 | AM31: 0.52417303 | AP31: 0.975 | AQ31: 0.90731707 | AR31: 0.70704225 | AS31: 0.32061069 | AV31: 0.9875 | AW31: 0.94634146 | AX31: 0.68169014 | AY31: 0.46564885 | BD31: 2 | BE31: =$X$148 -> 0.95897402 | BF31: =$Y$148 -> 0.91544605 | BG31: =$Z$148 -> 0.78364866 | BH31: =$AA$148 -> 0.57871077 | BI31: =$AB$148 -> #DIV/0! | BJ31: =$AC$148 -> #DIV/0!
J32: 27 | K32: =AVERAGE(R32,X32,AD32,AJ32,AP32,AV32) -> 0.98684211 | L32: =AVERAGE(S32,Y32,AE32,AK32,AQ32,AW32) -> 0.88978495 | M32: =AVERAGE(T32,Z32,AF32,AL32,AR32,AX32) -> 0.73333333 | N32: =AVERAGE(U32,AA32,AG32,AM32,AS32,AY32) -> 0.60729432 | O32: =AVERAGE(V32,AB32,AH32,AN32,AT32,AZ32) -> #DIV/0! | P32: =AVERAGE(W32,AC32,AI32,AO32,AU32,BA32) -> #DIV/0! | R32: 0.98684211 | S32: 0.88709677 | T32: 0.69295775 | U32: 0.55216285 | X32: 0.98684211 | Y32: 0.89784946 | Z32: 0.76619718 | AA32: 0.64885496 | AD32: 0.98684211 | AE32: 0.90860215 | AF32: 0.67605634 | AG32: 0.60050891 | AJ32: 0.98684211 | AK32: 0.85483871 | AL32: 0.74929577 | AM32: 0.63358779 | AP32: 0.98684211 | AQ32: 0.87634409 | AR32: 0.74647887 | AS32: 0.63867684 | AV32: 0.98684211 | AW32: 0.91397849 | AX32: 0.76901408 | AY32: 0.56997455 | BD32: 3 | BE32: =$AD$148 -> 0.96014491 | BF32: =$AE$148 -> 0.90912682 | BG32: =$AF$148 -> 0.77070713 | BH32: =$AG$148 -> 0.58651399 | BI32: =$AH$148 -> #DIV/0! | BJ32: =$AI$148 -> #DIV/0!
J33: 28 | K33: =AVERAGE(R33,X33,AD33,AJ33,AP33,AV33) -> 0.98630137 | L33: =AVERAGE(S33,Y33,AE33,AK33,AQ33,AW33) -> 0.94390244 | M33: =AVERAGE(T33,Z33,AF33,AL33,AR33,AX33) -> 0.83624879 | N33: =AVERAGE(U33,AA33,AG33,AM33,AS33,AY33) -> 0.57675997 | O33: =AVERAGE(V33,AB33,AH33,AN33,AT33,AZ33) -> #DIV/0! | P33: =AVERAGE(W33,AC33,AI33,AO33,AU33,BA33) -> #DIV/0! | R33: 0.98630137 | S33: 0.94146341 | T33: 0.88921283 | U33: 0.59033079 | X33: 0.98630137 | Y33: 0.93170732 | Z33: 0.80174927 | AA33: 0.61577608 | AD33: 0.98630137 | AE33: 0.94634146 | AF33: 0.76093294 | AG33: 0.51399491 | AJ33: 0.98630137 | AK33: 0.95121951 | AL33: 0.89504373 | AM33: 0.59541985 | AP33: 0.98630137 | AQ33: 0.94634146 | AR33: 0.82798834 | AS33: 0.55216285 | AV33: 0.98630137 | AW33: 0.94634146 | AX33: 0.8425656 | AY33: 0.59287532 | BD33: 4 | BE33: =$AJ$148 -> 0.95675018 | BF33: =$AK$148 -> 0.91278194 | BG33: =$AL$148 -> 0.7826588 | BH33: =$AM$148 -> 0.60347752 | BI33: =$AN$148 -> #DIV/0! | BJ33: =$AO$148 -> #DIV/0!
J34: 29 | K34: =AVERAGE(R34,X34,AD34,AJ34,AP34,AV34) -> 0.8256705 | L34: =AVERAGE(S34,Y34,AE34,AK34,AQ34,AW34) -> 0.85185185 | M34: =AVERAGE(T34,Z34,AF34,AL34,AR34,AX34) -> 0.74358974 | N34: =AVERAGE(U34,AA34,AG34,AM34,AS34,AY34) -> 0.64291773 | O34: =AVERAGE(V34,AB34,AH34,AN34,AT34,AZ34) -> #DIV/0! | P34: =AVERAGE(W34,AC34,AI34,AO34,AU34,BA34) -> #DIV/0! | R34: 0.8045977 | S34: 0.86868687 | T34: 0.75213675 | U34: 0.66412214 | X34: 0.81609195 | Y34: 0.86363636 | Z34: 0.76638177 | AA34: 0.73282443 | AD34: 0.82758621 | AE34: 0.88888889 | AF34: 0.73219373 | AG34: 0.54961832 | AJ34: 0.83908046 | AK34: 0.78282828 | AL34: 0.72649573 | AM34: 0.61323155 | AP34: 0.83908046 | AQ34: 0.84848485 | AR34: 0.73504274 | AS34: 0.66157761 | AV34: 0.82758621 | AW34: 0.85858586 | AX34: 0.74928775 | AY34: 0.63613232 | BD34: 5 | BE34: =$AP$148 -> 0.9595214 | BF34: =$AQ$148 -> 0.91171375 | BG34: =$AR$148 -> 0.79200504 | BH34: =$AS$148 -> 0.59957591 | BI34: =$AT$148 -> #DIV/0! | BJ34: =$AU$148 -> #DIV/0!
J35: 30 | K35: =AVERAGE(R35,X35,AD35,AJ35,AP35,AV35) -> 0.98717949 | L35: =AVERAGE(S35,Y35,AE35,AK35,AQ35,AW35) -> 0.95555556 | M35: =AVERAGE(T35,Z35,AF35,AL35,AR35,AX35) -> 0.79812207 | N35: =AVERAGE(U35,AA35,AG35,AM35,AS35,AY35) -> 0.46310433 | O35: =AVERAGE(V35,AB35,AH35,AN35,AT35,AZ35) -> #DIV/0! | P35: =AVERAGE(W35,AC35,AI35,AO35,AU35,BA35) -> #DIV/0! | R35: 0.98717949 | S35: 0.95 | T35: 0.74366197 | U35: 0.36641221 | X35: 0.98717949 | Y35: 0.95 | Z35: 0.81690141 | AA35: 0.49618321 | AD35: 0.98717949 | AE35: 0.94444444 | AF35: 0.7915493 | AG35: 0.49618321 | AJ35: 0.98717949 | AK35: 0.95555556 | AL35: 0.85915493 | AM35: 0.53689567 | AP35: 0.98717949 | AQ35: 0.95 | AR35: 0.74647887 | AS35: 0.49363868 | AV35: 0.98717949 | AW35: 0.98333333 | AX35: 0.83098592 | AY35: 0.38931298 | BD35: 6 | BE35: =$AV$148 -> 0.9622881 | BF35: =$AW$148 -> 0.90786282 | BG35: =$AX$148 -> 0.77638848 | BH35: =$AY$148 -> 0.58965225 | BI35: =$AZ$148 -> #DIV/0! | BJ35: =$BA$148 -> #DIV/0!
K37: =AVERAGE(K6:K35) -> 0.96013147 | L37: =AVERAGE(L6:L35) -> 0.90837553 | M37: =AVERAGE(M6:M35) -> 0.77159923 | N37: =AVERAGE(N6:N35) -> 0.5841391 | O37: =AVERAGE(O6:O35) -> #DIV/0! | P37: =AVERAGE(P6:P35) -> #DIV/0! | R37: =AVERAGE(R6:R35) -> 0.95618924 | S37: =AVERAGE(S6:S35) -> 0.91811358 | T37: =AVERAGE(T6:T35) -> 0.77050422 | U37: =AVERAGE(U6:U35) -> 0.58312129 | V37: =AVERAGE(V6:V35) -> #DIV/0! | W37: =AVERAGE(W6:W35) -> #DIV/0! | X37: =AVERAGE(X6:X35) -> 0.95855383 | Y37: =AVERAGE(Y6:Y35) -> 0.90340455 | ... BA37: =AVERAGE(BA6:BA35) -> #DIV/0! | BD37: =A10 -> 3 | BE37: Task 1 | BF37: Task 2 | BG37: Task 3 | BH37: Task 4 | BI37: Task 5 | BJ37: Task 6
BD38: 1 | BE38: =$R$185 -> 0.95628071 | BF38: =$S$185 -> 0.90964839 | BG38: =$T$185 -> 0.77795966 | BH38: =$U$185 -> 0.57684478 | BI38: =$V$185 -> #DIV/0! | BJ38: =$W$185 -> #DIV/0!
BD39: 2 | BE39: =$X$185 -> 0.96246577 | BF39: =$Y$185 -> 0.91732327 | BG39: =$Z$185 -> 0.76896957 | BH39: =$AA$185 -> 0.58575064 | BI39: =$AB$185 -> #DIV/0! | BJ39: =$AC$185 -> #DIV/0!
K40: k=0.5 | BD40: 3 | BE40: =$AD$185 -> 0.95227389 | BF40: =$AE$185 -> 0.90791342 | BG40: =$AF$185 -> 0.75428385 | BH40: =$AG$185 -> 0.58286684 | BI40: =$AH$185 -> #DIV/0! | BJ40: =$AI$185 -> #DIV/0!
S41: 1 | Y41: 2 | AE41: 3 | AK41: 4 | AQ41: 5 | AW41: 6 | BD41: 4 | BE41: =$AJ$185 -> 0.95547964 | BF41: =$AK$185 -> 0.90611578 | BG41: =$AL$185 -> 0.77748234 | BH41: =$AM$185 -> 0.5942324 | BI41: =$AN$185 -> #DIV/0! | BJ41: =$AO$185 -> #DIV/0!
J42: ID | K42: Task 1 | L42: Task 2 | M42: Task 3 | N42: Task 4 | O42: Task 5 | P42: Task 6 | R42: Task 1 | S42: Task 2 | T42: Task 3 | U42: Task 4 | V42: Task 5 | W42: Task 6 | X42: Task 1 | Y42: Task 2 | Z42: Task 3 | AA42: Task 4 | AB42: Task 5 | AC42: Task 6 | AD42: Task 1 | AE42: Task 2 | AF42: Task 3 | AG42: Task 4 | AH42: Task 5 | AI42: Task 6 | AJ42: Task 1 | AK42: Task 2 | AL42: Task 3 | AM42: Task 4 | AN42: Task 5 | AO42: Task 6 | AP42: Task 1 | AQ42: Task 2 | AR42: Task 3 | AS42: Task 4 | AT42: Task 5 | AU42: Task 6 | AV42: Task 1 | AW42: Task 2 | AX42: Task 3 | AY42: Task 4 | AZ42: Task 5 | BA42: Task 6 | BD42: 5 | BE42: =$AP$185 -> 0.96289961 | BF42: =$AQ$185 -> 0.91047495 | BG42: =$AR$185 -> 0.77165072 | BH42: =$AS$185 -> 0.56573367 | BI42: =$AT$185 -> #DIV/0! | BJ42: =$AU$185 -> #DIV/0!
J43: 1 | K43: =AVERAGE(R43,X43,AD43,AJ43,AP43,AV43) -> 0.90410959 | L43: =AVERAGE(S43,Y43,AE43,AK43,AQ43,AW43) -> 0.90406504 | M43: =AVERAGE(T43,Z43,AF43,AL43,AR43,AX43) -> 0.74413146 | N43: =AVERAGE(U43,AA43,AG43,AM43,AS43,AY43) -> 0.57251908 | O43: =AVERAGE(V43,AB43,AH43,AN43,AT43,AZ43) -> #DIV/0! | P43: =AVERAGE(W43,AC43,AI43,AO43,AU43,BA43) -> #DIV/0! | R43: 0.90410959 | S43: 0.90731707 | T43: 0.78309859 | U43: 0.57760814 | X43: 0.87671233 | Y43: 0.90731707 | Z43: 0.69859155 | AA43: 0.52417303 | AD43: 0.91780822 | AE43: 0.92195122 | AF43: 0.77183099 | AG43: 0.60814249 | AJ43: 0.93150685 | AK43: 0.89756098 | AL43: 0.71267606 | AM43: 0.61832061 | AP43: 0.8630137 | AQ43: 0.90243902 | AR43: 0.74647887 | AS43: 0.54961832 | AV43: 0.93150685 | AW43: 0.88780488 | AX43: 0.75211268 | AY43: 0.55725191 | BD43: 6 | BE43: =$AV$185 -> 0.95722974 | BF43: =$AW$185 -> 0.91023099 | BG43: =$AX$185 -> 0.78400131 | BH43: =$AY$185 -> 0.55564037 | BI43: =$AZ$185 -> #DIV/0! | BJ43: =$BA$185 -> #DIV/0!
...

Sheet Person_1
K3: k=0.25
S4: 1 | Y4: 2 | AE4: 3 | AK4: 4 | AQ4: 5 | AW4: 6
A5: k | B5: Task 1 | C5: Task 2 | D5: Task 3 | E5: Task 4 | F5: Task 5 | G5: Task 6 | J5: ID | K5: Task 1 | L5: Task 2 | M5: Task 3 | N5: Task 4 | O5: Task 5 | P5: Task 6 | R5: Task 1 | S5: Task 2 | T5: Task 3 | U5: Task 4 | V5: Task 5 | W5: Task 6 | X5: Task 1 | Y5: Task 2 | Z5: Task 3 | AA5: Task 4 | AB5: Task 5 | AC5: Task 6 | AD5: Task 1 | AE5: Task 2 | AF5: Task 3 | AG5: Task 4 | AH5: Task 5 | AI5: Task 6 | AJ5: Task 1 | AK5: Task 2 | AL5: Task 3 | AM5: Task 4 | AN5: Task 5 | AO5: Task 6 | AP5: Task 1 | AQ5: Task 2 | AR5: Task 3 | AS5: Task 4 | AT5: Task 5 | AU5: Task 6 | AV5: Task 1 | AW5: Task 2 | AX5: Task 3 | AY5: Task 4 | AZ5: Task 5 | BA5: Task 6 | BD5: =A6 -> 0.25 | BE5: Task 1 | BF5: Task 2 | BG5: Task 3 | BH5: Task 4 | BI5: Task 5 | BJ5: Task 6
A6: 0.25 | B6: =AVERAGE(K6:K35) -> 0.92971863 | C6: =AVERAGE(L6:L35) -> 0.88805193 | D6: =AVERAGE(M6:M35) -> 0.74197054 | E6: =AVERAGE(N6:N35) -> 0.51333333 | F6: =AVERAGE(O6:O35) -> #DIV/0! | G6: =AVERAGE(P6:P35) -> #DIV/0! | J6: 1 | K6: =AVERAGE(R6,X6,AD6,AJ6,AP6,AV6) -> 0.86147186 | L6: =AVERAGE(S6,Y6,AE6,AK6,AQ6,AW6) -> 0.86754386 | M6: =AVERAGE(T6,Z6,AF6,AL6,AR6,AX6) -> 0.6995098 | N6: =AVERAGE(U6,AA6,AG6,AM6,AS6,AY6) -> 0.4872807 | O6: =AVERAGE(V6,AB6,AH6,AN6,AT6,AZ6) -> #DIV/0! | P6: =AVERAGE(W6,AC6,AI6,AO6,AU6,BA6) -> #DIV/0! | R6: 0.85714286 | S6: 0.88421053 | T6: 0.69117647 | U6: 0.51842105 | X6: 0.84415584 | Y6: 0.87368421 | Z6: 0.70588235 | AA6: 0.52368421 | AD6: 0.85714286 | AE6: 0.84210526 | AF6: 0.72352941 | AG6: 0.47894737 | AJ6: 0.85714286 | AK6: 0.87368421 | AL6: 0.73529412 | AM6: 0.53947368 | AP6: 0.87012987 | AQ6: 0.85789474 | AR6: 0.66764706 | AS6: 0.4 | AV6: 0.88311688 | AW6: 0.87368421 | AX6: 0.67352941 | AY6: 0.46315789 | BD6: 1 | BE6: =$R$37 -> 0.92454943 | BF6: =$S$37 -> 0.88894681 | BG6: =$T$37 -> 0.74978147 | BH6: =$U$37 -> 0.54350877 | BI6: =$V$37 -> #DIV/0! | BJ6: =$W$37 -> #DIV/0!
A7: 0.5 | B7: =AVERAGE(K43:K72) -> 0.92907023 | C7: =AVERAGE(L43:L72) -> 0.89442432 | D7: =AVERAGE(M43:M72) -> 0.7569665 | E7: =AVERAGE(N43:N72) -> 0.53188596 | F7: =AVERAGE(O43:O72) -> #DIV/0! | G7: =AVERAGE(P43:P72) -> #DIV/0! | J7: 2 | K7: =AVERAGE(R7,X7,AD7,AJ7,AP7,AV7) -> 0.92407407 | L7: =AVERAGE(S7,Y7,AE7,AK7,AQ7,AW7) -> 0.87037037 | M7: =AVERAGE(T7,Z7,AF7,AL7,AR7,AX7) -> 0.80294118 | N7: =AVERAGE(U7,AA7,AG7,AM7,AS7,AY7) -> 0.50175439 | O7: =AVERAGE(V7,AB7,AH7,AN7,AT7,AZ7) -> #DIV/0! | P7: =AVERAGE(W7,AC7,AI7,AO7,AU7,BA7) -> #DIV/0! | R7: 0.92222222 | S7: 0.88383838 | T7: 0.84117647 | U7: 0.55789474 | X7: 0.91111111 | Y7: 0.86868687 | Z7: 0.79411765 | AA7: 0.56052632 | AD7: 0.95555556 | AE7: 0.88383838 | AF7: 0.78823529 | AG7: 0.34736842 | AJ7: 0.88888889 | AK7: 0.79292929 | AL7: 0.82941176 | AM7: 0.53684211 | AP7: 0.91111111 | AQ7: 0.88383838 | AR7: 0.76470588 | AS7: 0.58684211 | AV7: 0.95555556 | AW7: 0.90909091 | AX7: 0.8 | AY7: 0.42105263 | BD7: 2 | BE7: =$X$37 -> 0.93086948 | BF7: =$Y$37 -> 0.88320975 | BG7: =$Z$37 -> 0.71676989 | BH7: =$AA$37 -> 0.46482456 | BI7: =$AB$37 -> #DIV/0! | BJ7: =$AC$37 -> #DIV/0!
A8: 1 | B8: =AVERAGE(K80:K109) -> 0.93035864 | C8: =AVERAGE(L80:L109) -> 0.9019494 | D8: =AVERAGE(M80:M109) -> 0.777685 | E8: =AVERAGE(N80:N109) -> 0.57226608 | F8: =AVERAGE(O80:O109) -> #DIV/0! | G8: =AVERAGE(P80:P109) -> #DIV/0! | J8: 3 | K8: =AVERAGE(R8,X8,AD8,AJ8,AP8,AV8) -> 0.94354839 | L8: =AVERAGE(S8,Y8,AE8,AK8,AQ8,AW8) -> 0.90506329 | M8: =AVERAGE(T8,Z8,AF8,AL8,AR8,AX8) -> 0.83333333 | N8: =AVERAGE(U8,AA8,AG8,AM8,AS8,AY8) -> 0.55701754 | O8: =AVERAGE(V8,AB8,AH8,AN8,AT8,AZ8) -> #DIV/0! | P8: =AVERAGE(W8,AC8,AI8,AO8,AU8,BA8) -> #DIV/0! | R8: 0.98387097 | S8: 0.92405063 | T8: 0.88888889 | U8: 0.61315789 | X8: 0.93548387 | Y8: 0.80379747 | Z8: 0.80994152 | AA8: 0.52368421 | AD8: 0.93548387 | AE8: 0.91772152 | AF8: 0.86842105 | AG8: 0.51315789 | AJ8: 0.93548387 | AK8: 0.91772152 | AL8: 0.83333333 | AM8: 0.58421053 | AP8: 0.93548387 | AQ8: 0.93037975 | AR8: 0.82163743 | AS8: 0.55263158 | AV8: 0.93548387 | AW8: 0.93670886 | AX8: 0.77777778 | AY8: 0.55526316 | BD8: 3 | BE8: =$AD$37 -> 0.9318536 | BF8: =$AE$37 -> 0.89007615 | BG8: =$AF$37 -> 0.73380829 | BH8: =$AG$37 -> 0.4927193 | BI8: =$AH$37 -> #DIV/0! | BJ8: =$AI$37 -> #DIV/0!
A9: 2 | B9: =AVERAGE(K117:K146) -> 0.93095062 | C9: =AVERAGE(L117:L146) -> 0.89785644 | D9: =AVERAGE(M117:M146) -> 0.76191738 | E9: =AVERAGE(N117:N146) -> 0.54251462 | F9: =AVERAGE(O117:O146) -> #DIV/0! | G9: =AVERAGE(P117:P146) -> #DIV/0! | J9: 4 | K9: =AVERAGE(R9,X9,AD9,AJ9,AP9,AV9) -> 0.92929293 | L9: =AVERAGE(S9,Y9,AE9,AK9,AQ9,AW9) -> 0.90104167 | M9: =AVERAGE(T9,Z9,AF9,AL9,AR9,AX9) -> 0.71345029 | N9: =AVERAGE(U9,AA9,AG9,AM9,AS9,AY9) -> 0.51754386 | O9: =AVERAGE(V9,AB9,AH9,AN9,AT9,AZ9) -> #DIV/0! | P9: =AVERAGE(W9,AC9,AI9,AO9,AU9,BA9) -> #DIV/0! | R9: 0.90909091 | S9: 0.91666667 | T9: 0.84502924 | U9: 0.51842105 | X9: 0.90909091 | Y9: 0.921875 | Z9: 0.64327485 | AA9: 0.49210526 | AD9: 0.93939394 | AE9: 0.90625 | AF9: 0.68421053 | AG9: 0.55263158 | AJ9: 0.95454545 | AK9: 0.921875 | AL9: 0.71345029 | AM9: 0.52368421 | AP9: 0.93939394 | AQ9: 0.85416667 | AR9: 0.69005848 | AS9: 0.51052632 | AV9: 0.92424242 | AW9: 0.88541667 | AX9: 0.70467836 | AY9: 0.50789474 | BD9: 4 | BE9: =$AJ$37 -> 0.926222 | BF9: =$AK$37 -> 0.89009025 | BG9: =$AL$37 -> 0.75404325 | BH9: =$AM$37 -> 0.5345614 | BI9: =$AN$37 -> #DIV/0! | BJ9: =$AO$37 -> #DIV/0!
A10: 3 | B10: =AVERAGE(K154:K183) -> 0.92966111 | C10: =AVERAGE(L154:L183) -> 0.89994732 | D10: =AVERAGE(M154:M183) -> 0.74593109 | E10: =AVERAGE(N154:N183) -> 0.53216374 | F10: =AVERAGE(O154:O183) -> #DIV/0! | G10: =AVERAGE(P154:P183) -> #DIV/0! | J10: 5 | K10: =AVERAGE(R10,X10,AD10,AJ10,AP10,AV10) -> 0.98467433 | L10: =AVERAGE(S10,Y10,AE10,AK10,AQ10,AW10) -> 0.91789819 | M10: =AVERAGE(T10,Z10,AF10,AL10,AR10,AX10) -> 0.69344414 | N10: =AVERAGE(U10,AA10,AG10,AM10,AS10,AY10) -> 0.48596491 | O10: =AVERAGE(V10,AB10,AH10,AN10,AT10,AZ10) -> #DIV/0! | P10: =AVERAGE(W10,AC10,AI10,AO10,AU10,BA10) -> #DIV/0! | R10: 1 | S10: 0.90640394 | T10: 0.68421053 | U10: 0.59473684 | X10: 0.97701149 | Y10: 0.92118227 | Z10: 0.5734072 | AA10: 0.47368421 | AD10: 0.97701149 | AE10: 0.93596059 | AF10: 0.71745152 | AG10: 0.38684211 | AJ10: 0.97701149 | AK10: 0.90147783 | AL10: 0.76177285 | AM10: 0.57631579 | AP10: 1 | AQ10: 0.93103448 | AR10: 0.68975069 | AS10: 0.46842105 | AV10: 0.97701149 | AW10: 0.91133005 | AX10: 0.73407202 | AY10: 0.41578947 | BD10: 5 | BE10: =$AP$37 -> 0.93233932 | BF10: =$AQ$37 -> 0.89544869 | BG10: =$AR$37 -> 0.74877429 | BH10: =$AS$37 -> 0.5172807 | BI10: =$AT$37 -> #DIV/0! | BJ10: =$AU$37 -> #DIV/0!
J11: 6 | K11: =AVERAGE(R11,X11,AD11,AJ11,AP11,AV11) -> 0.91575092 | L11: =AVERAGE(S11,Y11,AE11,AK11,AQ11,AW11) -> 0.80571429 | M11: =AVERAGE(T11,Z11,AF11,AL11,AR11,AX11) -> 0.71097684 | N11: =AVERAGE(U11,AA11,AG11,AM11,AS11,AY11) -> 0.50394737 | O11: =AVERAGE(V11,AB11,AH11,AN11,AT11,AZ11) -> #DIV/0! | P11: =AVERAGE(W11,AC11,AI11,AO11,AU11,BA11) -> #DIV/0! | R11: 0.91208791 | S11: 0.85142857 | T11: 0.82477341 | U11: 0.62105263 | X11: 0.91208791 | Y11: 0.85142857 | Z11: 0.6918429 | AA11: 0.26315789 | AD11: 0.91208791 | AE11: 0.84571429 | AF11: 0.77945619 | AG11: 0.54473684 | AJ11: 0.92307692 | AK11: 0.82857143 | AL11: 0.71299094 | AM11: 0.51578947 | AP11: 0.91208791 | AQ11: 0.84571429 | AR11: 0.63746224 | AS11: 0.58684211 | AV11: 0.92307692 | AW11: 0.61142857 | AX11: 0.61933535 | AY11: 0.49210526 | BD11: 6 | BE11: =$AV$37 -> 0.93247796 | BF11: =$AW$37 -> 0.88053995 | BG11: =$AX$37 -> 0.74864607 | BH11: =$AY$37 -> 0.52710526 | BI11: =$AZ$37 -> #DIV/0! | BJ11: =$BA$37 -> #DIV/0!
J12: 7 | K12: =AVERAGE(R12,X12,AD12,AJ12,AP12,AV12) -> 0.94144144 | L12: =AVERAGE(S12,Y12,AE12,AK12,AQ12,AW12) -> 0.90285714 | M12: =AVERAGE(T12,Z12,AF12,AL12,AR12,AX12) -> 0.77152989 | N12: =AVERAGE(U12,AA12,AG12,AM12,AS12,AY12) -> 0.55438596 | O12: =AVERAGE(V12,AB12,AH12,AN12,AT12,AZ12) -> #DIV/0! | P12: =AVERAGE(W12,AC12,AI12,AO12,AU12,BA12) -> #DIV/0! | R12: 0.91891892 | S12: 0.86857143 | T12: 0.77203647 | U12: 0.54473684 | X12: 0.94594595 | Y12: 0.89714286 | Z12: 0.72036474 | AA12: 0.49736842 | AD12: 0.95945946 | AE12: 0.91428571 | AF12: 0.79331307 | AG12: 0.56842105 | AJ12: 0.90540541 | AK12: 0.93714286 | AL12: 0.72948328 | AM12: 0.51315789 | AP12: 0.95945946 | AQ12: 0.93714286 | AR12: 0.80547112 | AS12: 0.60263158 | AV12: 0.95945946 | AW12: 0.86285714 | AX12: 0.80851064 | AY12: 0.6
J13: 8 | K13: =AVERAGE(R13,X13,AD13,AJ13,AP13,AV13) -> 0.85042735 | L13: =AVERAGE(S13,Y13,AE13,AK13,AQ13,AW13) -> 0.81578947 | M13: =AVERAGE(T13,Z13,AF13,AL13,AR13,AX13) -> 0.75423729 | N13: =AVERAGE(U13,AA13,AG13,AM13,AS13,AY13) -> 0.42412281 | O13: =AVERAGE(V13,AB13,AH13,AN13,AT13,AZ13) -> #DIV/0! | P13: =AVERAGE(W13,AC13,AI13,AO13,AU13,BA13) -> #DIV/0! | R13: 0.80769231 | S13: 0.80526316 | T13: 0.74576271 | U13: 0.42631579 | X13: 0.85897436 | Y13: 0.81052632 | Z13: 0.72881356 | AA13: 0.58684211 | AD13: 0.85897436 | AE13: 0.81052632 | AF13: 0.71468927 | AG13: 0.28684211 | AJ13: 0.85897436 | AK13: 0.85263158 | AL13: 0.75706215 | AM13: 0.47105263 | AP13: 0.84615385 | AQ13: 0.8 | AR13: 0.78813559 | AS13: 0.40789474 | AV13: 0.87179487 | AW13: 0.81578947 | AX13: 0.79096045 | AY13: 0.36578947 | BD13: =A7 -> 0.5 | BE13: Task 1 | BF13: Task 2 | BG13: Task 3 | BH13: Task 4 | BI13: Task 5 | BJ13: Task 6
J14: 9 | K14: =AVERAGE(R14,X14,AD14,AJ14,AP14,AV14) -> 0.97590361 | L14: =AVERAGE(S14,Y14,AE14,AK14,AQ14,AW14) -> 0.89603175 | M14: =AVERAGE(T14,Z14,AF14,AL14,AR14,AX14) -> 0.6510574 | N14: =AVERAGE(U14,AA14,AG14,AM14,AS14,AY14) -> 0.45087719 | O14: =AVERAGE(V14,AB14,AH14,AN14,AT14,AZ14) -> #DIV/0! | P14: =AVERAGE(W14,AC14,AI14,AO14,AU14,BA14) -> #DIV/0! | R14: 0.97590361 | S14: 0.85238095 | T14: 0.54682779 | U14: 0.42631579 | X14: 0.97590361 | Y14: 0.88571429 | Z14: 0.69486405 | AA14: 0.41052632 | AD14: 0.97590361 | AE14: 0.90952381 | AF14: 0.60120846 | AG14: 0.45 | AJ14: 0.97590361 | AK14: 0.93333333 | AL14: 0.73716012 | AM14: 0.44736842 | AP14: 0.97590361 | AQ14: 0.93809524 | AR14: 0.6978852 | AS14: 0.48421053 | AV14: 0.97590361 | AW14: 0.85714286 | AX14: 0.62839879 | AY14: 0.48684211 | BD14: 1 | BE14: =$R$74 -> 0.93690667 | BF14: =$S$74 -> 0.89818781 | BG14: =$T$74 -> 0.78054411 | BH14: =$U$74 -> 0.56692982 | BI14: =$V$74 -> #DIV/0! | BJ14: =$W$74 -> #DIV/0!
J15: 10 | K15: =AVERAGE(R15,X15,AD15,AJ15,AP15,AV15) -> 0.92708333 | L15: =AVERAGE(S15,Y15,AE15,AK15,AQ15,AW15) -> 0.87447257 | M15: =AVERAGE(T15,Z15,AF15,AL15,AR15,AX15) -> 0.81421569 | N15: =AVERAGE(U15,AA15,AG15,AM15,AS15,AY15) -> 0.48596491 | O15: =AVERAGE(V15,AB15,AH15,AN15,AT15,AZ15) -> #DIV/0! | P15: =AVERAGE(W15,AC15,AI15,AO15,AU15,BA15) -> #DIV/0! | R15: 0.921875 | S15: 0.91139241 | T15: 0.83529412 | U15: 0.45789474 | X15: 0.9375 | Y15: 0.82278481 | Z15: 0.72941176 | AA15: 0.46578947 | AD15: 0.921875 | AE15: 0.88607595 | AF15: 0.83235294 | AG15: 0.56315789 | AJ15: 0.921875 | AK15: 0.86075949 | AL15: 0.81176471 | AM15: 0.52894737 | AP15: 0.921875 | AQ15: 0.89240506 | AR15: 0.83235294 | AS15: 0.45789474 | AV15: 0.9375 | AW15: 0.87341772 | AX15: 0.84411765 | AY15: 0.44210526 | BD15: 2 | BE15: =$X$74 -> 0.92831892 | BF15: =$Y$74 -> 0.8945126 | BG15: =$Z$74 -> 0.74050371 | BH15: =$AA$74 -> 0.48982456 | BI15: =$AB$74 -> #DIV/0! | BJ15: =$AC$74 -> #DIV/0!
J16: 11 | K16: =AVERAGE(R16,X16,AD16,AJ16,AP16,AV16) -> 0.86363636 | L16: =AVERAGE(S16,Y16,AE16,AK16,AQ16,AW16) -> 0.87914692 | M16: =AVERAGE(T16,Z16,AF16,AL16,AR16,AX16) -> 0.71023303 | N16: =AVERAGE(U16,AA16,AG16,AM16,AS16,AY16) -> 0.575 | O16: =AVERAGE(V16,AB16,AH16,AN16,AT16,AZ16) -> #DIV/0! | P16: =AVERAGE(W16,AC16,AI16,AO16,AU16,BA16) -> #DIV/0! | R16: 0.87012987 | S16: 0.84834123 | T16: 0.72036474 | U16: 0.62894737 | X16: 0.88311688 | Y16: 0.90521327 | Z16: 0.75683891 | AA16: 0.55 | AD16: 0.85714286 | AE16: 0.86729858 | AF16: 0.7112462 | AG16: 0.55263158 | AJ16: 0.85714286 | AK16: 0.87677725 | AL16: 0.70516717 | AM16: 0.62894737 | AP16: 0.87012987 | AQ16: 0.89099526 | AR16: 0.67781155 | AS16: 0.52631579 | AV16: 0.84415584 | AW16: 0.88625592 | AX16: 0.6899696 | AY16: 0.56315789 | BD16: 3 | BE16: =$AD$74 -> 0.92955781 | BF16: =$AE$74 -> 0.88877981 | BG16: =$AF$74 -> 0.73521342 | BH16: =$AG$74 -> 0.50368421 | BI16: =$AH$74 -> #DIV/0! | BJ16: =$AI$74 -> #DIV/0!
J17: 12 | K17: =AVERAGE(R17,X17,AD17,AJ17,AP17,AV17) -> 0.90935673 | L17: =AVERAGE(S17,Y17,AE17,AK17,AQ17,AW17) -> 0.84730539 | M17: =AVERAGE(T17,Z17,AF17,AL17,AR17,AX17) -> 0.80192503 | N17: =AVERAGE(U17,AA17,AG17,AM17,AS17,AY17) -> 0.64035088 | O17: =AVERAGE(V17,AB17,AH17,AN17,AT17,AZ17) -> #DIV/0! | P17: =AVERAGE(W17,AC17,AI17,AO17,AU17,BA17) -> #DIV/0! | R17: 0.9122807 | S17: 0.88622754 | T17: 0.88145897 | U17: 0.77894737 | X17: 0.89473684 | Y17: 0.77245509 | Z17: 0.78723404 | AA17: 0.37368421 | AD17: 0.89473684 | AE17: 0.86227545 | AF17: 0.78723404 | AG17: 0.57894737 | AJ17: 0.92982456 | AK17: 0.84431138 | AL17: 0.73556231 | AM17: 0.65789474 | AP17: 0.92982456 | AQ17: 0.83832335 | AR17: 0.79027356 | AS17: 0.68157895 | AV17: 0.89473684 | AW17: 0.88023952 | AX17: 0.82978723 | AY17: 0.77105263 | BD17: 4 | BE17: =$AJ$74 -> 0.92660883 | BF17: =$AK$74 -> 0.89711341 | BG17: =$AL$74 -> 0.75339504 | BH17: =$AM$74 -> 0.53578947 | BI17: =$AN$74 -> #DIV/0! | BJ17: =$AO$74 -> #DIV/0!
J18: 13 | K18: =AVERAGE(R18,X18,AD18,AJ18,AP18,AV18) -> 0.82905983 | L18: =AVERAGE(S18,Y18,AE18,AK18,AQ18,AW18) -> 0.77916667 | M18: =AVERAGE(T18,Z18,AF18,AL18,AR18,AX18) -> 0.75771144 | N18: =AVERAGE(U18,AA18,AG18,AM18,AS18,AY18) -> 0.49868421 | O18: =AVERAGE(V18,AB18,AH18,AN18,AT18,AZ18) -> #DIV/0! | P18: =AVERAGE(W18,AC18,AI18,AO18,AU18,BA18) -> #DIV/0! | R18: 0.82051282 | S18: 0.74375 | T18: 0.69850746 | U18: 0.47368421 | X18: 0.83333333 | Y18: 0.825 | Z18: 0.73134328 | AA18: 0.47105263 | AD18: 0.83333333 | AE18: 0.80625 | AF18: 0.71044776 | AG18: 0.27105263 | AJ18: 0.82051282 | AK18: 0.78125 | AL18: 0.8 | AM18: 0.62894737 | AP18: 0.82051282 | AQ18: 0.83125 | AR18: 0.7761194 | AS18: 0.52894737 | AV18: 0.84615385 | AW18: 0.6875 | AX18: 0.82985075 | AY18: 0.61842105 | BD18: 5 | BE18: =$AP$74 -> 0.92962833 | BF18: =$AQ$74 -> 0.89577257 | BG18: =$AR$74 -> 0.78803164 | BH18: =$AS$74 -> 0.55824561 | BI18: =$AT$74 -> #DIV/0! | BJ18: =$AU$74 -> #DIV/0!
J19: 14 | K19: =AVERAGE(R19,X19,AD19,AJ19,AP19,AV19) -> 0.95692884 | L19: =AVERAGE(S19,Y19,AE19,AK19,AQ19,AW19) -> 0.95153061 | M19: =AVERAGE(T19,Z19,AF19,AL19,AR19,AX19) -> 0.72776149 | N19: =AVERAGE(U19,AA19,AG19,AM19,AS19,AY19) -> 0.45526316 | O19: =AVERAGE(V19,AB19,AH19,AN19,AT19,AZ19) -> #DIV/0! | P19: =AVERAGE(W19,AC19,AI19,AO19,AU19,BA19) -> #DIV/0! | R19: 0.93258427 | S19: 0.95918367 | T19: 0.6686217 | U19: 0.40526316 | X19: 0.95505618 | Y19: 0.94897959 | Z19: 0.68621701 | AA19: 0.35263158 | AD19: 0.97752809 | AE19: 0.94897959 | AF19: 0.73607038 | AG19: 0.38157895 | AJ19: 0.94382022 | AK19: 0.96938776 | AL19: 0.70967742 | AM19: 0.47368421 | AP19: 0.97752809 | AQ19: 0.96428571 | AR19: 0.80351906 | AS19: 0.51842105 | AV19: 0.95505618 | AW19: 0.91836735 | AX19: 0.76246334 | AY19: 0.6 | BD19: 6 | BE19: =$AV$74 -> 0.92340082 | BF19: =$AW$74 -> 0.89217973 | BG19: =$AX$74 -> 0.74411106 | BH19: =$AY$74 -> 0.53684211 | BI19: =$AZ$74 -> #DIV/0! | BJ19: =$BA$74 -> #DIV/0!
J20: 15 | K20: =AVERAGE(R20,X20,AD20,AJ20,AP20,AV20) -> 0.99833333 | L20: =AVERAGE(S20,Y20,AE20,AK20,AQ20,AW20) -> 0.95484401 | M20: =AVERAGE(T20,Z20,AF20,AL20,AR20,AX20) -> 0.73196881 | N20: =AVERAGE(U20,AA20,AG20,AM20,AS20,AY20) -> 0.53684211 | O20: =AVERAGE(V20,AB20,AH20,AN20,AT20,AZ20) -> #DIV/0! | P20: =AVERAGE(W20,AC20,AI20,AO20,AU20,BA20) -> #DIV/0! | R20: 1 | S20: 0.97044335 | T20: 0.78362573 | U20: 0.56578947 | X20: 1 | Y20: 0.96059113 | Z20: 0.67836257 | AA20: 0.45789474 | AD20: 1 | AE20: 0.94581281 | AF20: 0.6754386 | AG20: 0.55526316 | AJ20: 0.99 | AK20: 0.9408867 | AL20: 0.66374269 | AM20: 0.57105263 | AP20: 1 | AQ20: 0.94581281 | AR20: 0.80409357 | AS20: 0.57105263 | AV20: 1 | AW20: 0.96551724 | AX20: 0.78654971 | AY20: 0.5
J21: 16 | K21: =AVERAGE(R21,X21,AD21,AJ21,AP21,AV21) -> 0.9781746 | L21: =AVERAGE(S21,Y21,AE21,AK21,AQ21,AW21) -> 0.95301418 | M21: =AVERAGE(T21,Z21,AF21,AL21,AR21,AX21) -> 0.69980507 | N21: =AVERAGE(U21,AA21,AG21,AM21,AS21,AY21) -> 0.57324561 | O21: =AVERAGE(V21,AB21,AH21,AN21,AT21,AZ21) -> #DIV/0! | P21: =AVERAGE(W21,AC21,AI21,AO21,AU21,BA21) -> #DIV/0! | R21: 0.97619048 | S21: 0.96276596 | T21: 0.71637427 | U21: 0.59473684 | X21: 0.98809524 | Y21: 0.95212766 | Z21: 0.67251462 | AA21: 0.46052632 | AD21: 0.98809524 | AE21: 0.96276596 | AF21: 0.67836257 | AG21: 0.63421053 | AJ21: 0.98809524 | AK21: 0.94680851 | AL21: 0.6871345 | AM21: 0.58421053 | AP21: 0.95238095 | AQ21: 0.93617021 | AR21: 0.70760234 | AS21: 0.54210526 | AV21: 0.97619048 | AW21: 0.95744681 | AX21: 0.73684211 | AY21: 0.62368421 | BD21: =A8 -> 1 | BE21: Task 1 | BF21: Task 2 | BG21: Task 3 | BH21: Task 4 | BI21: Task 5 | BJ21: Task 6
J22: 17 | K22: =AVERAGE(R22,X22,AD22,AJ22,AP22,AV22) -> 0.97420635 | L22: =AVERAGE(S22,Y22,AE22,AK22,AQ22,AW22) -> 0.93726592 | M22: =AVERAGE(T22,Z22,AF22,AL22,AR22,AX22) -> 0.81661601 | N22: =AVERAGE(U22,AA22,AG22,AM22,AS22,AY22) -> 0.52719298 | O22: =AVERAGE(V22,AB22,AH22,AN22,AT22,AZ22) -> #DIV/0! | P22: =AVERAGE(W22,AC22,AI22,AO22,AU22,BA22) -> #DIV/0! | R22: 0.96428571 | S22: 0.92696629 | T22: 0.79635258 | U22: 0.58421053 | X22: 0.97619048 | Y22: 0.92696629 | Z22: 0.75075988 | AA22: 0.48157895 | AD22: 0.98809524 | AE22: 0.94382022 | AF22: 0.86930091 | AG22: 0.56315789 | AJ22: 0.96428571 | AK22: 0.93258427 | AL22: 0.83586626 | AM22: 0.59736842 | AP22: 0.98809524 | AQ22: 0.95505618 | AR22: 0.86322188 | AS22: 0.47631579 | AV22: 0.96428571 | AW22: 0.93820225 | AX22: 0.78419453 | AY22: 0.46052632 | BD22: 1 | BE22: =$R$111 -> 0.92762104 | BF22: =$S$111 -> 0.90417098 | BG22: =$T$111 -> 0.78335655 | BH22: =$U$111 -> 0.56587719 | BI22: =$V$111 -> #DIV/0! | BJ22: =$W$111 -> #DIV/0!
J23: 18 | K23: =AVERAGE(R23,X23,AD23,AJ23,AP23,AV23) -> 0.90804598 | L23: =AVERAGE(S23,Y23,AE23,AK23,AQ23,AW23) -> 0.88535645 | M23: =AVERAGE(T23,Z23,AF23,AL23,AR23,AX23) -> 0.75920543 | N23: =AVERAGE(U23,AA23,AG23,AM23,AS23,AY23) -> 0.49868421 | O23: =AVERAGE(V23,AB23,AH23,AN23,AT23,AZ23) -> #DIV/0! | P23: =AVERAGE(W23,AC23,AI23,AO23,AU23,BA23) -> #DIV/0! | R23: 0.86206897 | S23: 0.89017341 | T23: 0.76744186 | U23: 0.51052632 | X23: 0.89655172 | Y23: 0.9132948 | Z23: 0.78488372 | AA23: 0.47368421 | AD23: 0.9137931 | AE23: 0.80924855 | AF23: 0.76162791 | AG23: 0.45526316 | AJ23: 0.94827586 | AK23: 0.89017341 | AL23: 0.75581395 | AM23: 0.46315789 | AP23: 0.93103448 | AQ23: 0.9132948 | AR23: 0.69476744 | AS23: 0.53421053 | AV23: 0.89655172 | AW23: 0.89595376 | AX23: 0.79069767 | AY23: 0.55526316 | BD23: 2 | BE23: =$X$111 -> 0.92647515 | BF23: =$Y$111 -> 0.89986882 | BG23: =$Z$111 -> 0.77953843 | BH23: =$AA$111 -> 0.56798246 | BI23: =$AB$111 -> #DIV/0! | BJ23: =$AC$111 -> #DIV/0!
J24: 19 | K24: =AVERAGE(R24,X24,AD24,AJ24,AP24,AV24) -> 0.9547619 | L24: =AVERAGE(S24,Y24,AE24,AK24,AQ24,AW24) -> 0.88953488 | M24: =AVERAGE(T24,Z24,AF24,AL24,AR24,AX24) -> 0.75276939 | N24: =AVERAGE(U24,AA24,AG24,AM24,AS24,AY24) -> 0.5122807 | O24: =AVERAGE(V24,AB24,AH24,AN24,AT24,AZ24) -> #DIV/0! | P24: =AVERAGE(W24,AC24,AI24,AO24,AU24,BA24) -> #DIV/0! | R24: 0.95714286 | S24: 0.90116279 | T24: 0.70392749 | U24: 0.63684211 | X24: 0.95714286 | Y24: 0.89534884 | Z24: 0.7734139 | AA24: 0.16052632 | AD24: 0.95714286 | AE24: 0.89534884 | AF24: 0.74018127 | AG24: 0.51578947 | AJ24: 0.94285714 | AK24: 0.88372093 | AL24: 0.67371601 | AM24: 0.61842105 | AP24: 0.95714286 | AQ24: 0.84883721 | AR24: 0.80664653 | AS24: 0.56842105 | AV24: 0.95714286 | AW24: 0.9127907 | AX24: 0.81873112 | AY24: 0.57368421 | BD24: 3 | BE24: =$AD$111 -> 0.93410574 | BF24: =$AE$111 -> 0.90121052 | BG24: =$AF$111 -> 0.78034651 | BH24: =$AG$111 -> 0.59052632 | BI24: =$AH$111 -> #DIV/0! | BJ24: =$AI$111 -> #DIV/0!
J25: 20 | K25: =AVERAGE(R25,X25,AD25,AJ25,AP25,AV25) -> 0.94545455 | L25: =AVERAGE(S25,Y25,AE25,AK25,AQ25,AW25) -> 0.90123457 | M25: =AVERAGE(T25,Z25,AF25,AL25,AR25,AX25) -> 0.7372549 | N25: =AVERAGE(U25,AA25,AG25,AM25,AS25,AY25) -> 0.55263158 | O25: =AVERAGE(V25,AB25,AH25,AN25,AT25,AZ25) -> #DIV/0! | P25: =AVERAGE(W25,AC25,AI25,AO25,AU25,BA25) -> #DIV/0! | R25: 0.94545455 | S25: 0.91005291 | T25: 0.73235294 | U25: 0.48421053 | X25: 0.94545455 | Y25: 0.92063492 | Z25: 0.67647059 | AA25: 0.50526316 | AD25: 0.94545455 | AE25: 0.88888889 | AF25: 0.68823529 | AG25: 0.48421053 | AJ25: 0.92727273 | AK25: 0.87301587 | AL25: 0.81176471 | AM25: 0.63947368 | AP25: 0.96363636 | AQ25: 0.93650794 | AR25: 0.72352941 | AS25: 0.66842105 | AV25: 0.94545455 | AW25: 0.87830688 | AX25: 0.79117647 | AY25: 0.53421053 | BD25: 4 | BE25: =$AJ$111 -> 0.93285618 | BF25: =$AK$111 -> 0.90524195 | BG25: =$AL$111 -> 0.79171687 | BH25: =$AM$111 -> 0.57912281 | BI25: =$AN$111 -> #DIV/0! | BJ25: =$AO$111 -> #DIV/0!
J26: 21 | K26: =AVERAGE(R26,X26,AD26,AJ26,AP26,AV26) -> 0.93939394 | L26: =AVERAGE(S26,Y26,AE26,AK26,AQ26,AW26) -> 0.88039216 | M26: =AVERAGE(T26,Z26,AF26,AL26,AR26,AX26) -> 0.83685801 | N26: =AVERAGE(U26,AA26,AG26,AM26,AS26,AY26) -> 0.55263158 | O26: =AVERAGE(V26,AB26,AH26,AN26,AT26,AZ26) -> #DIV/0! | P26: =AVERAGE(W26,AC26,AI26,AO26,AU26,BA26) -> #DIV/0! | R26: 0.92727273 | S26: 0.86470588 | T26: 0.82477341 | U26: 0.65263158 | X26: 0.94545455 | Y26: 0.88235294 | Z26: 0.86404834 | AA26: 0.47631579 | AD26: 0.92727273 | AE26: 0.88823529 | AF26: 0.83987915 | AG26: 0.68157895 | AJ26: 0.94545455 | AK26: 0.87647059 | AL26: 0.83081571 | AM26: 0.48157895 | AP26: 0.94545455 | AQ26: 0.86470588 | AR26: 0.81570997 | AS26: 0.50526316 | AV26: 0.94545455 | AW26: 0.90588235 | AX26: 0.84592145 | AY26: 0.51842105 | BD26: 5 | BE26: =$AP$111 -> 0.93142051 | BF26: =$AQ$111 -> 0.89748278 | BG26: =$AR$111 -> 0.78334466 | BH26: =$AS$111 -> 0.58280702 | BI26: =$AT$111 -> #DIV/0! | BJ26: =$AU$111 -> #DIV/0!
J27: 22 | K27: =AVERAGE(R27,X27,AD27,AJ27,AP27,AV27) -> 0.94444444 | L27: =AVERAGE(S27,Y27,AE27,AK27,AQ27,AW27) -> 0.9007286 | M27: =AVERAGE(T27,Z27,AF27,AL27,AR27,AX27) -> 0.71580547 | N27: =AVERAGE(U27,AA27,AG27,AM27,AS27,AY27) -> 0.54473684 | O27: =AVERAGE(V27,AB27,AH27,AN27,AT27,AZ27) -> #DIV/0! | P27: =AVERAGE(W27,AC27,AI27,AO27,AU27,BA27) -> #DIV/0! | R27: 0.92 | S27: 0.93442623 | T27: 0.68085106 | U27: 0.51315789 | X27: 0.93333333 | Y27: 0.89617486 | Z27: 0.68693009 | AA27: 0.55526316 | AD27: 0.97333333 | AE27: 0.86338798 | AF27: 0.69908815 | AG27: 0.52894737 | AJ27: 0.93333333 | AK27: 0.87978142 | AL27: 0.8449848 | AM27: 0.54210526 | AP27: 0.96 | AQ27: 0.92349727 | AR27: 0.62917933 | AS27: 0.51315789 | AV27: 0.94666667 | AW27: 0.90710383 | AX27: 0.75379939 | AY27: 0.61578947 | BD27: 6 | BE27: =$AV$111 -> 0.92967325 | BF27: =$AW$111 -> 0.90372136 | BG27: =$AX$111 -> 0.74780696 | BH27: =$AY$111 -> 0.5472807 | BI27: =$AZ$111 -> #DIV/0! | BJ27: =$BA$111 -> #DIV/0!
J28: 23 | K28: =AVERAGE(R28,X28,AD28,AJ28,AP28,AV28) -> 0.93111111 | L28: =AVERAGE(S28,Y28,AE28,AK28,AQ28,AW28) -> 0.93257576 | M28: =AVERAGE(T28,Z28,AF28,AL28,AR28,AX28) -> 0.675 | N28: =AVERAGE(U28,AA28,AG28,AM28,AS28,AY28) -> 0.4254386 | O28: =AVERAGE(V28,AB28,AH28,AN28,AT28,AZ28) -> #DIV/0! | P28: =AVERAGE(W28,AC28,AI28,AO28,AU28,BA28) -> #DIV/0! | R28: 0.92 | S28: 0.95 | T28: 0.67941176 | U28: 0.46578947 | X28: 0.93333333 | Y28: 0.9 | Z28: 0.76470588 | AA28: 0.54736842 | AD28: 0.93333333 | AE28: 0.94545455 | AF28: 0.64117647 | AG28: 0.42105263 | AJ28: 0.92 | AK28: 0.94090909 | AL28: 0.7 | AM28: 0.39736842 | AP28: 0.93333333 | AQ28: 0.92727273 | AR28: 0.61470588 | AS28: 0.3 | AV28: 0.94666667 | AW28: 0.93181818 | AX28: 0.65 | AY28: 0.42105263
J29: 24 | K29: =AVERAGE(R29,X29,AD29,AJ29,AP29,AV29) -> 0.84401709 | L29: =AVERAGE(S29,Y29,AE29,AK29,AQ29,AW29) -> 0.84450172 | M29: =AVERAGE(T29,Z29,AF29,AL29,AR29,AX29) -> 0.67321249 | N29: =AVERAGE(U29,AA29,AG29,AM29,AS29,AY29) -> 0.50175439 | O29: =AVERAGE(V29,AB29,AH29,AN29,AT29,AZ29) -> #DIV/0! | P29: =AVERAGE(W29,AC29,AI29,AO29,AU29,BA29) -> #DIV/0! | R29: 0.84615385 | S29: 0.83505155 | T29: 0.64652568 | U29: 0.49736842 | X29: 0.85897436 | Y29: 0.80412371 | Z29: 0.61329305 | AA29: 0.46842105 | AD29: 0.82051282 | AE29: 0.86082474 | AF29: 0.67673716 | AG29: 0.51052632 | AJ29: 0.85897436 | AK29: 0.86082474 | AL29: 0.71601208 | AM29: 0.47894737 | AP29: 0.83333333 | AQ29: 0.87628866 | AR29: 0.6978852 | AS29: 0.53421053 | AV29: 0.84615385 | AW29: 0.82989691 | AX29: 0.68882175 | AY29: 0.52105263 | BD29: =A9 -> 2 | BE29: Task 1 | BF29: Task 2 | BG29: Task 3 | BH29: Task 4 | BI29: Task 5 | BJ29: Task 6
J30: 25 | K30: =AVERAGE(R30,X30,AD30,AJ30,AP30,AV30) -> 0.94805195 | L30: =AVERAGE(S30,Y30,AE30,AK30,AQ30,AW30) -> 0.86302682 | M30: =AVERAGE(T30,Z30,AF30,AL30,AR30,AX30) -> 0.71603128 | N30: =AVERAGE(U30,AA30,AG30,AM30,AS30,AY30) -> 0.57149123 | O30: =AVERAGE(V30,AB30,AH30,AN30,AT30,AZ30) -> #DIV/0! | P30: =AVERAGE(W30,AC30,AI30,AO30,AU30,BA30) -> #DIV/0! | R30: 0.94805195 | S30: 0.85057471 | T30: 0.78005865 | U30: 0.63421053 | X30: 0.94805195 | Y30: 0.87356322 | Z30: 0.60703812 | AA30: 0.54210526 | AD30: 0.94805195 | AE30: 0.87356322 | AF30: 0.64809384 | AG30: 0.58947368 | AJ30: 0.94805195 | AK30: 0.84482759 | AL30: 0.71260997 | AM30: 0.60526316 | AP30: 0.94805195 | AQ30: 0.87931034 | AR30: 0.82111437 | AS30: 0.56578947 | AV30: 0.94805195 | AW30: 0.85632184 | AX30: 0.72727273 | AY30: 0.49210526 | BD30: 1 | BE30: =$R$148 -> 0.92743931 | BF30: =$S$148 -> 0.90194633 | BG30: =$T$148 -> 0.7816681 | BH30: =$U$148 -> 0.57184211 | BI30: =$V$148 -> #DIV/0! | BJ30: =$W$148 -> #DIV/0!
